Workbook

Sheet Resumo
A1: Resumo - Siviero Empreendimentos Imobiliários Ltda. (31.12.2018)
A2: Valor calculado = soma da aba Bens; 'Total no documento' transcrito do inventário; 'Dif.' deve ser zero.
A4: Grupo | B4: Qtde. itens | C4: Valor calculado (R$) | D4: Total no documento (R$) | E4: Dif. (R$)
A5: Veículos | B5: =COUNTIF(Bens!$B$5:$B$142,A5) | C5: =SUMIF(Bens!$B$5:$B$142,A5,Bens!$E$5:$E$142) | D5: 953000 | E5: =C5-D5
A6: Imóveis e móveis | B6: =COUNTIF(Bens!$B$5:$B$142,A6) | C6: =SUMIF(Bens!$B$5:$B$142,A6,Bens!$E$5:$E$142) | D6: 110000 | E6: =C6-D6
A7: Máquinas | B7: =COUNTIF(Bens!$B$5:$B$142,A7) | C7: =SUMIF(Bens!$B$5:$B$142,A7,Bens!$E$5:$E$142) | D7: 1350000 | E7: =C7-D7
A8: Lotes urbanos - Veranópolis e Bento Gonçalves | B8: =COUNTIF(Bens!$B$5:$B$142,A8) | C8: =SUMIF(Bens!$B$5:$B$142,A8,Bens!$E$5:$E$142) | D8: 2600000 | E8: =C8-D8
A9: Áreas urbanas e rurais - Veranópolis e Caxias do Sul | B9: =COUNTIF(Bens!$B$5:$B$142,A9) | C9: =SUMIF(Bens!$B$5:$B$142,A9,Bens!$E$5:$E$142) | D9: 6850000 | E9: =C9-D9
A10: Loteamentos executados e registrados | B10: =COUNTIF(Bens!$B$5:$B$142,A10) | C10: =SUMIF(Bens!$B$5:$B$142,A10,Bens!$E$5:$E$142) | D10: 64225000 | E10: =C10-D10
A11: Loteamentos executados e não registrados | B11: =COUNTIF(Bens!$B$5:$B$142,A11) | C11: =SUMIF(Bens!$B$5:$B$142,A11,Bens!$E$5:$E$142) | D11: 25690000 | E11: =C11-D11
A12: Loteamentos em execução e não registrados | B12: =COUNTIF(Bens!$B$5:$B$142,A12) | C12: =SUMIF(Bens!$B$5:$B$142,A12,Bens!$E$5:$E$142) | D12: 5400000 | E12: =C12-D12
A13: Loteamentos contratados a executar / em licenciamento | B13: =COUNTIF(Bens!$B$5:$B$142,A13) | C13: =SUMIF(Bens!$B$5:$B$142,A13,Bens!$E$5:$E$142) | D13: 1250000 | E13: =C13-D13
A14: TOTAL GERAL DA EMPRESA | B14: =SUM(B5:B13) | C14: =SUM(C5:C13) | D14: 108428000 | E14: =C14-D14
A16: (-) Ações judiciais em curso (com honorários e custas) | C16: ='Processos'!E28 | D16: 8161960 | E16: =C16-D16
A17: (-) Dívidas com sócios, terceiros, bancos etc. | C17: ='Credores'!E38 | D17: 10120000 | E17: =C17-D17
A18: (-) Previsão para administração da empresa | C18: 15000000 | D18: 15000000 | E18: =C18-D18
A19: TOTAL LÍQUIDO DA EMPRESA | C19: =C14-C16-C17-C18 | D19: 75146040 | E19: =C19-D19
A21: + Bens relacionados nos inventários de outras empresas | B21: =COUNTA('Bens em outras empresas'!A5:A13) | C21: =SUM('Bens em outras empresas'!D5:D13) | D21: (sem total no doc.)
A22: SUB-TOTAL REAL DA EMPRESA | C22: =C19+C21 | D22: 1.0594023e+08 | E22: =C22-D22
A23: + Ações judiciais, dívidas e previsão (somadas de volta, como no documento) | C23: =C16+C17+C18
A24: TOTAL GERAL E REAL DA EMPRESA | C24: =C22+C23 | D24: 1.3922219e+08 | E24: =C24-D24
A26: Observações:
A27: - Loteamentos em execução: o documento soma apenas o valor da obra já realizada (R$ 5.400.000,00); valor bruto, custo de conclusão e líquido estão na aba Bens.
A28: - Loteamento Alto das Graças I: R$ 11.730.000,00 dividido por 2 (50% da Villa Luna) = R$ 5.865.000,00.
A29: - Processos: a soma dos valores da causa (R$ 5.187.216,15) difere do total declarado no documento (R$ 6.278.430,81); no resumo foi usado o valor do documento (ver aba Processos).
A30: - Credores: a soma do saldo em aberto (R$ 10.119.900,00) difere em R$ 100,00 dos R$ 10.120.000,00 do documento; no resumo foi usado o valor do documento.
A31: - Aluguéis: a soma dos itens (R$ 39.692,00, incluindo 4 valores anuais) difere do 'aprox. R$ 36.000,00 por mês' do documento.
A32: - A tabela final de valor por sócio está sem valores em R$ no documento (só percentuais).

Sheet Bens
A1: Siviero Empreendimentos Imobiliários Ltda. - bens (inventário 31.12.2018)
A2: Fonte: 18. 1. SIVIERO EMPREENDIMENTOS IMOBILIÁRIOS LTDA. = I N V E N T Á R I O = E M P R E S A D A S I V I E R O - Dezembro de 2018.docx (data-base 31.12.2018). Valores em azul transcritos do documento; totais em preto são fórmulas.
A4: Nº | B4: Categoria | C4: Item no doc. | D4: Descrição | E4: Valor (R$) | F4: Valor bruto (R$) | G4: (-) Custo p/ conclusão (R$) | H4: Valor líquido (R$) | I4: Observação
A5: 1 | B5: Veículos | C5: 01 | D5: Um veículo caminhão basculante, marca VW = PLACA IUV 8325, cor branca, ano 2013, adquirido da empresa Dalfovo. | E5: 198000
A6: 2 | B6: Veículos | C6: 02 | D6: Um veículo caminhão basculante, marca VW = PLACA IUV 8309, cor branca, ano 2013, adquirido da empresa Dalfovo. | E6: 198000
A7: 3 | B7: Veículos | C7: 03 | D7: Um veículo caminhão basculante, marca MERCEDES BENZ, L1620 = PLACA ILQ 1739, cor cinza, ano 2003. | E7: 98000
A8: 4 | B8: Veículos | C8: 04 | D8: Um veículo caminhão basculante, marca MERCEDES BENZ, = PLACA IBP 3873, cor vermelha, ano 1990. | E8: 53000
A9: 5 | B9: Veículos | C9: 05 | D9: Um veículo DODGE = PLACA IQJ 5001, cor azul, ano 1978. VENDIDO PELO VALOR DE R$ 30.000,00, EM TROCA DE PALANQUES E POSTES DE MADEIRA. | E9: 30000
A10: 6 | B10: Veículos | C10: 06 | D10: Um veículo caminhão SCANIA = PLACA IIQ 0751, cor laranja, ano 1963. | E10: 28000
A11: 7 | B11: Veículos | C11: 07 | D11: Um semirreboque RANDON = PLACA IHP 6632, cor amarelo, ano 1990. | E11: 25000
A12: 8 | B12: Veículos | C12: 08 | D12: Um veículo Mercedinha, marca MERCEDES BENZ, L608 = PLACA BWF 0672, cor vermelha, ano 1979. | E12: 20000
A13: 9 | B13: Veículos | C13: 09 | D13: Um veículo caminhão basculante, marca MERCEDES BENZ, L1316 = PLACA IHZ 0172, cor vermelha, ano 1984. | E13: 50000
A14: 10 | B14: Veículos | C14: 10 | D14: Um veículo caminhão basculante, marca MERCDES BENZ = PLACA IHW 8294, cor grená, ano 1974. | E14: 30000
A15: 11 | B15: Veículos | C15: 11 | D15: Um veículo caminhão, marca SCÂNIA = PLACA IHK 2435, cor laranja, ano 1967. | E15: 40000
A16: 12 | B16: Veículos | C16: 12 | D16: Um semirreboque ARTESANAL = PLACA IIH 6326, cor branca, ano 1986. | E16: 20000
... A58: 54 | B58: Áreas urbanas e rurais - Veranópolis e Caxias do Sul | C58: 10 | D58: Uma área de terras rurais, ADQUIRIDA em 2014, DA FAMÍLIA CECCONELLO, localizada no Município de Caxias do Sul – RS, composto por 2,0 (Dois) hectares, dentro de um todo maior, que compõem o Loteamento = 130.446,00m². | E58: 600000
A59: 55 | B59: Loteamentos executados e registrados | C59: 01 | D59: Loteamento Sol Nascente I, localizado na cidade de Antônio Prado – RS, num saldo de 14 lotes, ao valor de R$ 200.000,00, cada lote – Valor da média considerada dentre os lotes. - FALTA A INSTALAÇÃO DA REDE DE ÁGUA. | E59: 2800000 | I59: Texto na célula de valor: 'colina do basalto'.
A60: 56 | B60: Loteamentos executados e registrados | C60: 02 | D60: Loteamento Fracionamento Simioni, localizado na cidade de Veranópolis – RS, num saldo de 04 lotes, ao valor de R$ 250.000,00, cada lote. Sobre os lotes há restrições ambientais – Fonte de Água e Mato – Valor da média considerada dentre os lotes. | E60: 1000000
A61: 57 | B61: Loteamentos executados e registrados | C61: 03 | D61: Loteamento Colina do Basalto, localizado na cidade de Nova Prata – RS, num saldo de 14 lotes, ao valor de R$ 90.000,00, cada lote – Valor da média considerada dentre os lotes. | E61: 1260000
A62: 58 | B62: Loteamentos executados e registrados | C62: 04 | D62: Loteamento Aditivo Medianeira, localizado na cidade de Veranópolis – RS, num saldo de 20 lotes, ao valor de R$ 100.000,00, cada lote – Valor da média considerada dentre os lotes. | E62: 2000000
A63: 59 | B63: Loteamentos executados e registrados | C63: 05 | D63: Loteamento Alto das Graças I, localizado na cidade de Caxias do Sul – RS, num saldo de 51 lotes, ao valor de R$ 115.000,00, cada lote. (50,00% é da empresa Villa Luna: total = 102 lotes) – Valor da média considerada dentre os lotes. | E63: 5865000 | F63: 11730000 | I63: Valor bruto R$ 11.730.000,00 dividido por 2 (50% da Villa Luna).
A64: 60 | B64: Loteamentos executados e registrados | C64: 06 | D64: Loteamento Cichelero, localizado na cidade de Carlos Barbosa – RS, num saldo de 10 lotes, ao valor de R$ 100.000,00, cada lote – Valor da média considerada dentre os lotes. | E64: 1000000
A65: 61 | B65: Loteamentos executados e registrados | C65: 07 | D65: Loteamento Firminio Dalzóchio, localizado na cidade de Farroupilha – RS, num saldo de 15 lotes, ao valor de R$ 100.000,00, cada lote – Valor da média considerada dentre os lotes. | E65: 1500000
A66: 62 | B66: Loteamentos executados e registrados | C66: 08 | D66: Loteamento Industrial Pedra Lisa, localizado na cidade de Veranópolis – RS, num saldo de 39 lotes, ao valor de R$ VARIÁVEL, cada lote. 01 LOTE – R$ 550.000,00. 01 LOTE – R$ 450.000,00. 37 LOTES – R$ 230.000,00, cada um. (Mínimo de R$ 150.000,00 e Máximo de R$ 300.000,00). – Valor da média considerada dentre os lotes. | E66: 9510000
A67: 63 | B67: Loteamentos executados e registrados | C67: 09 | D67: Loteamento Industrial Vicentino, localizado na cidade de Farroupilha – RS, num saldo de 12 lotes, ao valor de R$ 800.000,00, cada lote – Valor da média considerada dentre os lotes. | E67: 9600000
A68: 64 | B68: Loteamentos executados e registrados | C68: 10 | D68: Loteamento Monte Vêneto, localizado na cidade de Carlos Barbosa – RS, num saldo de 01 lote, ao valor de R$ 110.000,00, cada lote – Valor da média considerada dentre os lotes. | E68: 110000
A69: 65 | B69: Loteamentos executados e registrados | C69: 11 | D69: Loteamento Nossa Senhora da Saúde, localizado na cidade de Guaporé – RS, num saldo de 03 lotes, ao valor de R$ 80.000,00, cada lote – Valor da média considerada dentre os lotes. | E69: 240000
A70: 66 | B70: Loteamentos executados e registrados | C70: 12 | D70: Loteamento Perini, localizado na cidade de Farroupilha – RS, num saldo de 10 lotes, ao valor de R$ VARIÁVEL, cada lote. 04 LOTES – R$ 500.000,00, cada um. 06 LOTES – R$ 95.000,00, cada um. – Valor da média considerada dentre os lotes. | E70: 2570000
A71: 67 | B71: Loteamentos executados e registrados | C71: 13 | D71: Loteamento Princesa dos Vales, localizado na cidade de Carlos Barbosa – RS, num saldo de 01 lote, ao valor de R$ 90.000,00, cada lote – Valor da média considerada dentre os lotes. | E71: 90000
A72: 68 | B72: Loteamentos executados e registrados | C72: 14 | D72: Loteamento Morada da Colina, localizado na cidade de Veranópolis – RS, num saldo de 00 lotes, ao valor de R$ 500.000,00, cada lote – Valor da média considerada dentre os lotes. | E72: 0
A73: 69 | B73: Loteamentos executados e registrados | C73: 15 | D73: Loteamento Araçá, localizado na cidade de Nova Araçá – RS, num saldo de 01 lote, ao valor de R$ 60.000,00, cada lote – Valor da média considerada dentre os lotes. | E73: 60000
A74: 70 | B74: Loteamentos executados e registrados | C74: 16 | D74: Loteamento Baú, localizado na cidade de Carlos Barbosa – RS, num saldo de 02 lotes, ao valor de R$ 130.000,00, cada lote – Valor da média considerada dentre os lotes. | E74: 260000
A75: 71 | B75: Loteamentos executados e registrados | C75: 17 | D75: Loteamento Bella Visione, localizado na cidade de Carlos Barbosa – RS, num saldo de 00 lotes, ao valor de R$ 100.000,00, cada lote – Valor da média considerada dentre os lotes. | E75: 0
... A111: 107 | B111: Loteamentos executados e não registrados | C111: 07 | D111: Loteamento Barbiero – Barbiero, localizado na cidade de Nova Prata – RS, num total de aproximadamente 20 lotes, ao valor de R$ 130.000,00, cada lote – Valor da média considerada dentre os lotes. Área total de 47.550,52m². – Obras todas OK, com a falta do pagamento de parte da pavimentação, conforme medição final. Falta o Registro. | E111: 2600000
A112: 108 | B112: Loteamentos em execução e não registrados | C112: 01 | D112: Loteamento Caminhos do Sol – Boff, localizado na cidade de Caxias do Sul – RS, num total de aproximadamente 577 lotes, ao valor de R$ 100.000,00, cada lote. Área total de 457.425,87m². SIVIERO: 290 LOTES. CUSTO TOTAL DA OBRA: R$ 16.500.000,00. VALOR DA OBRA JÁ REALIZADA: R$ 2.800.000,00. CUSTO PARA CONCLUSÃO DO LOTEAMENTO: R$ 13.700.000,00. | E112: 2800000 | F112: 29000000 | G112: 13700000 | H112: 15300000 | I112: Valor considerado = valor da obra já realizada (critério do documento: 'somente o valor investido nas obras realizadas').
A113: 109 | B113: Loteamentos em execução e não registrados | C113: 02 | D113: Loteamento Santa Corona III – Paulety, localizado na cidade de Caxias do Sul – RS, num total de aproximadamente 88 lotes, ao valor de R$ 100.000,00, cada lote – Valor da média considerada dentre os lotes. Área total de 7,7 ha. SIVIERO: 44 LOTES. CUSTO TOTAL DA OBRA: R$ 2.850.000,00. VALOR DA OBRA JÁ REALIZADA: R$ 500.000,00. CUSTO PARA CONCLUSÃO DO LOTEAMENTO: R$ 2.350.000,00. | E113: 500000 | F113: 4400000 | G113: 2350000 | H113: 2050000 | I113: Valor considerado = valor da obra já realizada (critério do documento: 'somente o valor investido nas obras realizadas').
A114: 110 | B114: Loteamentos em execução e não registrados | C114: 03 | D114: Loteamento Vale das Colinas – Piccoli + Gasparin + Zanrosso, localizado na cidade de Caxias do Sul – RS, num total de aproximadamente 359 lotes, ao valor de R$ 100.000,00, cada lote. Área total de 364.480,67m². SIVIERO: 180 LOTES. CUSTO TOTAL DA OBRA: R$ 9.650.000,00. VALOR DA OBRA JÁ REALIZADA: R$ 600.000,00. CUSTO PARA CONCLUSÃO DO LOTEAMENTO: R$ 9.050.000,00. | E114: 600000 | F114: 18000000 | G114: 9050000 | H114: 8950000 | I114: Valor considerado = valor da obra já realizada (critério do documento: 'somente o valor investido nas obras realizadas').
A115: 111 | B115: Loteamentos em execução e não registrados | C115: 04 | D115: Loteamento da Família Falavigha, localizado na cidade de Flores da Cunha – RS, num total de aproximadamente 101 lotes, ao valor de R$ 100.000,00, cada lote. Área total de 102.741,72m². SIVIERO: 50 LOTES. CUSTO TOTAL DA OBRA: R$ 2.550.000,00. VALOR DA OBRA JÁ REALIZADA: R$ 100.000,00. CUSTO PARA CONCLUSÃO DO LOTEAMENTO: R$ 2.450.000,00. OBSERVAÇÃO: Os valores dos lotes, neste Loteamento, terão um valor comercial de venda superior ao estimado, visto a área estar localizada no centro da cidade. Se, o valor comercial for de R$ 300.000,00, cada lote, por exemplo, agregará uma lucratividade de MAIS R$ 10.000.000,00, porque o CUSTO DA EXECUÇÃO DO LOTEAMENTO não sofrerá grandes alterações, ao valor estimado para a execução do mesmo, com as obras de infraestrutura. | E115: 100000 | F115: 5000000 | G115: 2450000 | H115: 2550000 | I115: Valor considerado = valor da obra já realizada (critério do documento: 'somente o valor investido nas obras realizadas').
A116: 112 | B116: Loteamentos em execução e não registrados | C116: 05 | D116: Loteamento da Família Zanella – CONDOMÍNIO FECHADO, localizado na cidade de Passo Fundo – RS, num total de aproximadamente 63 lotes, ao valor de R$ 150.000,00, cada lote. Área total de 49.998,00m². SIVIERO: 29 LOTES. CUSTO TOTAL DA OBRA: R$ 3.150.000,00. VALOR DA OBRA JÁ REALIZADA: R$ 1.000.000,00. CUSTO PARA CONCLUSÃO DO LOTEAMENTO: R$ 2.150.000,00 | E116: 1000000 | F116: 4350000 | G116: 2150000 | H116: 2200000 | I116: Valor considerado = valor da obra já realizada (critério do documento: 'somente o valor investido nas obras realizadas').
A117: 113 | B117: Loteamentos em execução e não registrados | C117: 06 | D117: Loteamento Caminho das Flores – Palavro, localizado na cidade de Caxias do Sul – RS, num total de aproximadamente 163 lotes, ao valor de R$ 100.000,00, cada lote. Área total de 176.805,00m². SIVIERO: 81 LOTES. CUSTO TOTAL DA OBRA: R$ 5.300.000,00. VALOR DA OBRA JÁ REALIZADA: R$ 400.000,00. CUSTO PARA CONCLUSÃO DO LOTEAMENTO: R$ 4.900.000,00 | E117: 400000 | F117: 8100000 | G117: 4900000 | H117: 3200000 | I117: Valor considerado = valor da obra já realizada (critério do documento: 'somente o valor investido nas obras realizadas').
...

Sheet Bens em outras empresas
A1: Bens da Siviero Empreendimentos relacionados nos inventários de outras empresas
A2: Fonte: 18. 1. SIVIERO EMPREENDIMENTOS IMOBILIÁRIOS LTDA. = I N V E N T Á R I O = E M P R E S A D A S I V I E R O - Dezembro de 2018.docx (data-base 31.12.2018). Valores em azul transcritos do documento; totais em preto são fórmulas.
A4: Item no doc. | B4: Descrição | C4: Relacionado no inventário da empresa | D4: Valor (R$) | E4: Observação
A5: 06 | B5: Um terreno – lote urbano, localizado na Rodovia BR 470, ao lado da Abastecedora de Combustíveis Siviero Ltda., devidamente registrado no Ofício de Registro de Imóveis da Comarca de Veranópolis, sob Matrícula nº 3.751, com área de 7.200,00m², onde está instalada a ANTENA de TRANSMISSÃO da RÁDIO, ao valor de mercado considerado sua localização e referência comercial = R$ 992,78, ao metro quadrado. | C5: RÁDIO | D5: 7148016
A6: 06 | B6: Um terreno urbano, com a área de 4.986,00m², localizado na Rodovia BR 470, Km 175,4, no Bairro São Pelegrino, devidamente registrado no Ofício de Registro de Imóveis da Comarca de Veranópolis, sob Matrícula nº 3.754, localizado na lateral da Abastecedora de Combustíveis Siviero Ltda., onde estava instalada a SERRARIA, considerado o valor de R$ 992,78, ao metro quadrado, conforme sua localização e referência comercial. | C6: OFICINA | D6: 4950000
A7: 07 | B7: Um terreno urbano, com a área de 1.942,03m², localizado na Rodovia BR 470, Km 175,4, no Bairro Valverde, devidamente registrado no Ofício de Registro de Imóveis da Comarca de Veranópolis, sob a Matrícula nº 17.409, localizado ao lado da empresa Oleoplan S/A, considerado o valor de R$ 2.000,00, ao metro quadrado, conforme sua localização e referência comercial = R$ 3.884.060,00. Um terreno urbano, com a área de 2.850,00m², localizado na Rodovia BR 470, Km 175,4, no Bairro Valverde, devidamente registrado no Ofício de Registro de Imóveis da Comarca de Veranópolis, sob a Matrícula nº 6.136, localizado ao lado da empresa Oleoplan S/A, considerado o valor de R$ 2.000,00, ao metro quadrado, conforme sua localização e referência comercial = R$ 5.700.000,00. Sob estes imóveis estão construídos os PAVILHÕES, com área total construída de 4.170,00m², atualmente locados para a empresa Oleoplan S/A, avaliado conforme o CUB da construção civil referente ao mês de AGOSTO/2017 = R$ 746,60, ao metro quadrado = R$ 3.113.322,00. Valor dos Pavilhões construídos – obra civil = 30,00% (Trinta por cento) da obra feita: R$ 933.996,60 (considerado o valor agregado à coisa feita, como tal se encontra). | C7: OFICINA | D7: 13631379
A8: 02 | B8: Uma área de terras rurais, denominada de PARTE DO LOTE RURAL Nº 24 e 24/E, com área total de 10,2 hectares, localizada na Linha Júlio de Castilhos, no Município de Cotiporã – RS, adquirida do Senhor CELITO PIEROZAN, área esta registrada sob Matrículas nº.: 2.424 e 2.425. Matrículas nº 2.424 e 2.425 = 10,2 hectares X R$ 40.000,00 Cadastrada no CCIR – Receita Federal sob nº 2.481.949-2 Vendido em 2018, a área total para o Senhor ANGELI, pelo valor de R$ 510.000,00 (Quinhentos e dez mil reais), de forma, À VISTA. | C8: AGROPECUÁRIA | D8: 408000
A9: 03 | B9: Uma área de terras rurais, denominada de PARTE DO LOTE RURAL Nº 12, com área total de 13,0 hectares + 7,5 hectares, localizada na Linha Júlio de Castilhos, no Município de Veranópolis – RS, adquirida da FAMÍLIA SANGALI, área esta registrada sob Matrícula nº.: 3.062. Matrícula nº 3.062 = 20,5 hectares X 11.000,00 Cadastrada no CCIR – Receita Federal sob nº 2.481.950-6 | C9: AGROPECUÁRIA | D9: 225500
A10: 04 | B10: Uma área de terras rurais, denominada de PARTE DO LOTE RURAL Nº 89, com área total de 27,8 hectares, localizada na Linha Barão do Triunfo, no Município de Fagundes Varela – RS, adquirida do Senhor SÉRGIO BALDISSERA, área esta registrada sob Matrícula nº.: 8.486. Matrícula nº 8.486 = 27,8 hectares X R$ 9.000,00 Cadastrada no CCIR – Receita Federal sob nº 2.481.951-4 | C10: AGROPECUÁRIA | D10: 250200
A11: 05 | B11: Uma área de terras rurais, denominada de LOTE Nº 33, com área total de 15,1 hectares, localizada no Município de Cotiporã – RS, na Linha Júlio de Castilhos, adquirida do Senhor ARMELINDO CALZA, área esta registrada sob Matrícula nº.: 1.218. Matrícula nº 1.218 = 15,1 hectares X R$ 5.000,00 | C11: AGROPECUÁRIA | D11: 75500
A12: 06 | B12: Uma área de terras rurais, denominada de PARTE DO LOTE RURAL Nº 52, com área total de 15,1 hectares, localizada na Linha Júlio de Castilhos, no Município de Cotiporã – RS, adquirida da Senhora GLORIA E GERALDO BASSANI, área esta registrada sob Matrícula nº.: 7.391 - Matrícula nº 7.391 = 15,1 hectares X R$ 15.000,00 Cadastrada no CCIR – Receita Federal sob nº 2.481.952-2 | C12: AGROPECUÁRIA | D12: 226500
A13: 04 | B13: Um terreno rural, com a área de 9,4 hectares, localizado na Rua Luiz Siviero, no Bairro Femaçã, devidamente registrado no Ofício de Registro de Imóveis da Comarca de Veranópolis, sob Matrículas nº 1.941 e 7.104, conhecido como SEDE CAMPESTRE, composta por pavilhão, piscinas, casa, campos de futebol, lagos e alicerces para construção de cabanas. Cadastrada no CCIR – Receita Federal sob nº 2.481.947-6. Valor da área de terras = 9,4ha X R$ 300.000,00 ao hectare = R$ 2.820.000,00. Valor do Pavilhão Construído – obra civil = 01 andar = 891,00m² de área construída: 891,00m² x R$ 746,00 = R$ 664.686,00 (considerado o valor ao metro quadrado da construção – CUB/AGOSTO DE 2017 e o valor da área conforme sua localização comercial). Valor da casa de alvenaria localizada nos fundos da Sede Campestre = ...............m² de área construída: R$ 150.000,00. Valor da obra feita e infraestrutura = 30,00% (Trinta por cento) da obra feita: R$ 244.405,80 (considerado o valor agregado à coisa feita, como tal se encontra). | C13: HOTEL | D13: 3879091.8

Sheet Processos
A1: Processos judiciais e administrativos
A2: Fonte: 18. 1. SIVIERO EMPREENDIMENTOS IMOBILIÁRIOS LTDA. = I N V E N T Á R I O = E M P R E S A D A S I V I E R O - Dezembro de 2018.docx (data-base 31.12.2018). Valores em azul transcritos do documento; totais em preto são fórmulas.
A4: Item no doc. | B4: Descrição | C4: Comarca | D4: Nº do processo | E4: Valor da causa (R$) | F4: Observação
A5: 01 | B5: Processo Judicial dos Sócios da empresa Mecânica Serafina Ltda. X Domingos Gregianin – Divisão de Bens - A empresa Siviero Empreendimentos Imobiliários Ltda. está envolvida faz-se a Dação em Pagamento e a execução das obras do Loteamento. Valor da causa: R$ 377.605,00 + 20,00% de Honorários Advocatícios + 10,00% de Custas de Fórum | C5: Guaporé | D5: 053/1.10.0002419-0 | E5: 377605
A6: 02 | B6: Processo Judicial do Município de Nova Prata contra a empresa Siviero Empreendimentos Imobiliários Ltda. para cobrança do IPTU do Loteamento Carnevalli – lotes. Valor da causa: R$ 52.818,30+correção de 05 anos = +/- R$ 200.000,00 + 20,00% de Honorários Advocatícios + 10,00% de Custas de Fórum | C6: Nova Prata | D6: 058/1.11.0002580-7 | E6: 200000 | F6: Valor da causa R$ 52.818,30 + correção de 5 anos; usado o valor estimado de R$ 200.000,00.
A7: 03 | B7: Processo Judicial do Senhor Angelo Devanir Coitinho Lopes e Luciane Santos de Barros contra a empresa Siviero Empreendimentos Imobiliários Ltda., visto a demora da entrega da Escritura do lote no Loteamento Colina do Basalto. Existe a Família Bolzan envolvida, faz-se o terreno ser do Bolzan, conforme Termo de Divisão. Valor da causa: R$ 40.000,00 + 20,00% de Honorários Advocatícios + 10,00% de Custas de Fórum | C7: Nova Prata | D7: 058/1.12.0000489-5 | E7: 40000
A8: 04 | B8: Processo Judicial do Município de Nova Prata contra a empresa Siviero Empreendimentos Imobiliários Ltda. para cobrança do IPTU do Loteamento Carnevalli – área total. Ação de Execução Fiscal. Valor da causa: R$ 1.264,97 + 20,00% de Honorários Advocatícios + 10,00% de Custas de Fórum | C8: Nova Prata | D8: 058/1.13.0002950-4 | E8: 1264.97
A9: 05 | B9: Processo Judicial da Senhora Neuza Maria Astofoli contra a empresa Siviero Empreendimentos Imobiliários Ltda. com relação à concordância de uma divisa no Loteamento Nossa Senhora da Saúde. A empresa concordou com a confrontação apresentada, não apresentando contestação. Valor da causa: R$ 1.404,50 + 20,00% de Honorários Advocatícios + 10,00% de Custas de Fórum | C9: Guaporé | D9: 053/1.14.0003260-2 | E9: 1404.5
A10: 06 | B10: Processo Judicial da Senhora Josiane Marafiga Fragosso e Aguiler Viana de Rosa contra a empresa Siviero Empreendimentos Imobiliários Ltda. com relação ao acidente do Senhor Válter Siviero, em Bom Jesus, em Janeiro de 2015. A empresa está arrolada, visto o carro estar em nome da empresa Siviero. Valor da causa: R$ 8.380,00 + 20,00% de Honorários Advocatícios + 10,00% de Custas de Fórum | C10: Vacaria | D10: 083/1.16.0000373-4 | E10: 8380
A11: 07 | B11: Processo Judicial do Senhor Reinaldo Degregori e Adriane Luisa Tisott Degregori contra a empresa Siviero Empreendimentos Imobiliários Ltda. – vizinhos do Loteamento Altos das Graças I – Caxias do Sul, Valor da causa: R$ 31.271,00 + 20,00% de Honorários Advocatícios + 10,00% de Custas de Fórum | C11: Farroupilha | D11: 010/1.16.0022816-0 | E11: 31271
A12: 08 | B12: Processo Judicial do Ministério Público contra a empresa Siviero – Ação Civil Pública – Ivanor Carlos Dalzóchio e Siviero Empreendimentos Imobiliários Ltda. – Fonte da Água. Valor da causa: R$ 935,50 + 20,00% de Honorários Advocatícios + 10,00% de Custas de Fórum | C12: Farroupilha | D12: 048/1.08.0001924-5 | E12: 935.5
A13: 09 | B13: Processo Judicial do Senhor Severino Silvestrin e Cluadina Thereza Silvestrin contra a empresa Siviero Empreendimentos Imobiliários Ltda., referente à divisão de um lote no Loteamento Primavera, mas que na época foi acertado pela legalização de 02 quadras por Processo de Usucapião. Valor da causa: R$ 210.000,00 + 20,00% de Honorários Advocatícios + 10,00% de Custas de Fórum Promovido acordo em 2018, com 01 lote + parte em espécie. Total do acordo: R$ 177.000,00 01 lote no Loteamento Altos da Julieta: Lote 09 – Quadra 1729 R$ 79.000,00 – lote. R$ 98.000,00 – em 08 parcelas. | C13: Farroupilha | D13: 048/1.15.0002471-3 | E13: 210000
A14: 10 | B14: Processo Judicial do Ministério Público contra a empresa Siviero Empreendimentos Imobiliários Ltda. – Ação Civil Pública – Área de APP – lotes no Loteamento Lago Negro = 07 lotes em área de APP, que deverão ser preservados (Prejuízo de aproximadamente R$ 1.750.000,00) – Deverão ser permutados pelo mesmo número de lotes no Loteamento. Valor da causa: R$ 8.635,00 + 20,00% de Honorários Advocatícios + 10,00% de Custas de Fórum | C14: Gramado | D14: 101/1.16.0002642-2 | E14: 8635
A15: 11 | B15: Processo Judicial do Senhor Edoardo Soave e Janete Basso Soave contra a empresa Siviero Empreendimentos Imobiliários Ltda., tendo em vista a demora da entrega das Matrículas do Loteamento Jardim Itália – Farroupilha. Rede da água da CORSAN. Valor da causa: R$ 66.000,00 + 20,00% de Honorários Advocatícios + 10,00% de Custas de Fórum | C15: Farroupilha | D15: 048/1.16.0002799-4 | E15: 66000
A16: 12 | B16: Processo Judicial do Senhor Guilherme Darcy Scholz e Santa Aristina Nair Scholz contra a empresa Siviero Empreendimentos Imobiliários Ltda. Processo de Usucapião de um lote em Carlos Barbosa. Valor da causa: R$ 8.652,50 + 20,00% de Honorários Advocatícios + 10,00% de Custas de Fórum | C16: Carlos Barbosa | D16: 144/1.17.0000438-3 | E16: 8652.5
A17: 13 | B17: Processo Judicial da Família Farina contra a empresa Siviero Empreendimentos Imobiliários Ltda., tendo em vista a demora da entrega das Matrículas do Loteamento Industrial Vicentino. O atraso é de aproximadamente 30 dias. Valor da causa: R$ 1.013.580,55 = TOTAL, sendo: R$ 600.000,00 – Indenização + R$ 400.000,00 – Honorários advocatícios (mas haverá redução nos honorários em aproximadamente 1/4 = 12 lotes. + 20,00% de Honorários Advocatícios + 10,00% de Custas de Fórum | C17: Farroupilha | D17: 005/1.10.0002938-3 | E17: 1013580.6
A18: 14 | B18: Processo Judicial do Senhor Rogério Rodrigues da Rosa contra a empresa Siviero Empreendimentos Imobiliários Ltda. Processo de Indenização pela rescisão de um contrato em Carlos Barbosa. Valor da causa: R$ 332.150,34 + 20,00% de Honorários Advocatícios + 10,00% de Custas de Fórum PROCESSO JÁ SENTENCIADO E DADO DECISÃO EM FAVOR DA EMPRESA SIVIERO EMPREENDIMENTOS IMOBILIÁRIOS LTDA. | C18: Carlos Barbosa | D18: 144/1.17.0000451-0 | E18: 332150.34
... A23: 19 | B23: Processo Judicial do Senhor Valdemar Egidio Nalin contra a empresa Siviero Empreendimentos Imobiliários Ltda. Processo de Usucapião de um lote em Nova Prata. Valor da causa: R$ 25.000,00 + 20,00% de Honorários Advocatícios + 10,00% de Custas de Fórum | C23: Nova Prata | D23: 058/1.18.0000911-1 | E23: 25000
B24: Soma dos valores da causa (calculada) | E24: =SUM(E5:E23)
B25: Valor total das ações declarado no documento | E25: 6278430.8
B26: Dif. (calculada - documento) | E26: =E24-E25 | F26: O documento não detalha como chegou a este total.
B27: + 20% honorários + 10% custas (no documento) | E27: 1883529.2
B28: Total no documento (usado no Resumo) | E28: 8161960

Sheet Credores
A1: Credores e compromissos (posição em janeiro de 2019)
A2: Fonte: 18. 1. SIVIERO EMPREENDIMENTOS IMOBILIÁRIOS LTDA. = I N V E N T Á R I O = E M P R E S A D A S I V I E R O - Dezembro de 2018.docx (data-base 31.12.2018). Valores em azul transcritos do documento; totais em preto são fórmulas.
A4: Item no doc. | B4: Descrição | C4: Valor no doc. (R$) | D4: Situação | E4: Saldo em aberto (R$) | F4: Texto original do valor
A5: 01 | B5: Aquisição da Escavadeira Hidráulica e equipamentos em DEZEMBRO de 2014, pelo valor total de R$ 576.640,07 (Valor da máquina e equipamentos = R$ 510.000,00), com início do pagamento em setembro de 2015 e término em fevereiro de 2020 = 54 parcelas. | C5: 120000 | D5: Em aberto | E5: 120000 | F5: 12 parcelas de +/_ R$ 10.000,00 = R$ 120.000,00
A6: 02 | B6: Aquisição de UM VEÍCULO CAMINHÃO CAÇAMBA, marca-modelo VW/31 280 CRM 6X4, combustível DIESEL, ano 2013, modelo 2013, cor BRANCA, placa IUV 8309, cujo valor total da compra e venda é de R$ 230.000,00, de cujo valor já foi pago R$ 100.000,00, restando ainda R$ 130.995,39, que serão pagos em 34 parcelas correspondentes as de nº 025 a 058, conforme planilha de financiamento – FINAME – apresentada pela empresa VENDEDORA - DALFOVO, com vencimento da primeira parcela no dia 15 de janeiro de 2016 e a última no dia 15 de outubro de 2018. | D6: Pago | E6: 0 | F6: R$ PAGO
A7: 03 | B7: Adélia Frizon Siviero – Valor emprestado para a empresa Siviero a juros de 1,50%, ao mês. | C7: 90000 | D7: Pago | E7: 0 | F7: R$ 90.000,00 - PAGO
A8: 04 | B8: Adélia Frizon Siviero – Valor emprestado para a empresa Siviero a juros de 1,50%, ao mês. | C8: 50000 | D8: Pago parcial | E8: 20000 | F8: R$ 50.000,00 - PAGO FALTA: R$ 20.000,00
A9: 05 | B9: André Luiz Siviero – Valor emprestado para a empresa Siviero a juros de 1,30%, ao mês. | C9: 100000 | D9: Em aberto | E9: 100000 | F9: R$ 100.000,00
A10: 06 | B10: Aldir José Marini – Valor emprestado para a empresa Siviero a juros de 1,25%, ao mês. | C10: 140000 | D10: Em aberto | E10: 140000 | F10: R$ 140.000,00
A11: 07 | B11: Celito Antônio Pierozan – Valor emprestado para a empresa Siviero a juros de 1,50%, ao mês. | C11: 150000 | D11: Em aberto | E11: 150000 | F11: R$ 150.000,00
A12: 08 | B12: Irineu Siviero – Valor emprestado para a empresa Siviero a juros de 1,30%, ao mês. | C12: 50000 | D12: Em aberto | E12: 50000 | F12: R$ 50.000,00
A13: 09 | B13: Irineu Siviero – Valor emprestado para a empresa Siviero a juros de 1,30%, ao mês. | C13: 50000 | D13: Em aberto | E13: 50000 | F13: R$ 50.000,00
A14: 10 | B14: Irineu Siviero – Valor emprestado para a empresa Siviero a juros de 1.30%, ao mês. NÃO SÃO PAGOS OS JUROS E SOMADOS CUMULATIVAMENTE. | C14: 800000 | D14: Em aberto | E14: 800000 | F14: R$ 800.000,00
A15: 11 | B15: Luis Carlos Mercali – Valor emprestado para a empresa Siviero a juros de 1,30%, ao mês. | C15: 160000 | D15: Em aberto | E15: 160000 | F15: R$ 160.000,00
A16: 12 | B16: Olivio Criveletto – Valor emprestado para a empresa Siviero a juros de 1,50%, ao mês. | C16: 34000 | D16: Em aberto | E16: 34000 | F16: R$ 34.000,00
A17: 13 | B17: Pedro Siviero – Valor emprestado para a empresa Siviero a juros de 1,30%, ao mês. | C17: 50000 | D17: Em aberto | E17: 50000 | F17: R$ 50.000,00
A18: 14 | B18: Pedro Siviero – Valor emprestado para a empresa Siviero a juros de 1,30%, ao mês. | C18: 80000 | D18: Em aberto | E18: 80000 | F18: R$ 80.000,00
... A36: 32 | B36: Caixa Econômica Federal, Agência de Veranópolis – Empréstimo conta empresarial – HOTEL – com limite de crédito de R$ 700.000,00. | C36: 700000 | D36: Em aberto | E36: 700000 | F36: R$ 700.000,00
B37: Soma do saldo em aberto | E37: =SUM(E5:E36)
B38: Total no documento | E38: 10120000
B39: Dif. (soma - documento) | E39: =E37-E38

Sheet Aluguéis
A1: Aluguéis recebidos
A2: Fonte: 18. 1. SIVIERO EMPREENDIMENTOS IMOBILIÁRIOS LTDA. = I N V E N T Á R I O = E M P R E S A D A S I V I E R O - Dezembro de 2018.docx (data-base 31.12.2018). Valores em azul transcritos do documento; totais em preto são fórmulas.
A4: Item no doc. | B4: Descrição | C4: Valor (R$) | D4: Observação
A5: 01 | B5: Pavilhões alugados para a empresa Oleoplan S/A, localizados na Rodovia BR 470, Km 175,4 – Bairro Valverde. | C5: 17000
A6: 02 | B6: Abastecedora de Combustíveis Siviero Ltda., locada para a empresa Abastecedora de Combustíveis Certo Ltda. | C6: 8000
A7: 03 | B7: Lancharia e Restaurante anexo a Abastecedora de Combustíveis Siviero Ltda., locados para o Senhor Cristiano Rodrigo Lucchetta. | C7: 4100
A8: 04 | B8: Rampa de Lavagem de caminhões e carros leves, anexa a Abastecedora de Combustíveis Siviero Ltda. | C8: 1500
A9: 05 | B9: Borracharia, anexa a Abastecedora de Combustíveis Siviero Ltda. | C9: 800
A10: 06 | B10: Sala do Escritório velho, localizado na Avenida Osvaldo Aranha, Bairro Palugana, locado para o Senhor ZARDO. Investimento no valor de R$ 36.000,00 = 36 MESES DE ALUGUEL. | C10: 1000
A11: 07 | B11: Lote localizado na Avenida Osvaldo Aranha, esquina com a Rua Eduardo Duarte, locado para o Sr. Paulo Ricardo Palludo – Baterias. | C11: 300
A12: 08 | B12: Apartamento 401 – Edifício Luiz Siviero, localizado na Avenida Pinheiro Machado, nº 710, locado para o Senhor Marcos Antônio Bergamin. | C12: 650
A13: 09 | B13: Administração do contrato locatício do Senhor Mário Cesca, da propriedade que possui locada para o Senhor Osmar Variza. | C13: 330
A14: 10 | B14: Casa localizada em Vila Azul, na área de terras adquirida da Família Fogali, locada para o Senhor Hilário Gabrielli e Pimentel. | C14: 300
A15: 11 | B15: Espaço dado em locação para a empresa Estofados Encanto Ltda., para a colocação de uma PLACA PUBLICITÁRIA, que paga a importância de um salário mínimo anual. | C15: 954 | D15: Valor anual
A16: 12 | B16: Espaço dado em locação para o Restaurante Giratório, para a colocação de uma PLACA PUBLICITÁRIA, que paga a importância de um salário mínimo anual. | C16: 954 | D16: Valor anual
A17: 13 | B17: Espaço dado em locação para a empresa Pretto Veículos, para a colocação de uma PLACA PUBLICITÁRIA, que paga a importância de um salário mínimo anual. | C17: 954 | D17: Valor anual
A18: 14 | B18: Área de terras rurais, adquiridas do Senhor Moacir Zanin, localizadas próximo da Abastecedora de Combustíveis Siviero Ltda., arrendadas para o Senhor Volmir Marinello, que paga uma importância anual. | C18: 1900 | D18: Valor anual
A19: 15 | B19: Apartamento localizado no Edifício ESPERENÇA - GELATTI, localizado no Bairro Valverde, adquirido do Sottili, locado para um Funcionário do Sr. Paulo Maranho – Senhor Edvaldo da Silva. | C19: 300
A20: 16 | B20: CASA, localizada na Avenida Dr. José Montaury, Bairro São Pelegrino, locado para o Senhor Rodrigo Rodrigues. | C20: 650
B21: Soma | C21: =SUM(C5:C20)
B22: Total no documento (aprox., por mês) | C22: 36000 | D22: +/- R$ 36.000,00 por mês

Sheet Saldo de lotes
A1: Quantidade de lotes por loteamento
A2: Fonte: 18. 1. SIVIERO EMPREENDIMENTOS IMOBILIÁRIOS LTDA. = I N V E N T Á R I O = E M P R E S A D A S I V I E R O - Dezembro de 2018.docx (data-base 31.12.2018). Valores em azul transcritos do documento; totais em preto são fórmulas.
A4: Grupo | B4: Item no doc. | C4: Loteamento | D4: Qtde. lotes | E4: No documento
A5: Executados e registrados | B5: 01 | C5: Loteamento Sol Nascente I - Antônio Prado – RS | D5: 14
A6: Executados e registrados | B6: 02 | C6: Loteamento Fracionamento Simioni - Veranópolis – RS | D6: 4
A7: Executados e registrados | B7: 03 | C7: Loteamento Colina do Basalto - Nova Prata – RS | D7: 14
A8: Executados e registrados | B8: 04 | C8: Loteamento Aditivo Medianeira - Veranópolis – RS | D8: 20
A9: Executados e registrados | B9: 05 | C9: Loteamento Alto das Graças I - Caxias do Sul – RS = 102/2 | D9: 51
A10: Executados e registrados | B10: 06 | C10: Loteamento Cichelero - Carlos Barbosa – RS | D10: 10
A11: Executados e registrados | B11: 07 | C11: Loteamento Firminio Dalzóchio - Farroupilha – RS | D11: 15
A12: Executados e registrados | B12: 08 | C12: Loteamento Industrial Pedra Lisa - Veranópolis – RS | D12: 39
A13: Executados e registrados | B13: 09 | C13: Loteamento Industrial Vicentino - Farroupilha – RS | D13: 12
A14: Executados e registrados | B14: 10 | C14: Loteamento Monte Vêneto - Carlos Barbosa – RS | D14: 1
A15: Executados e registrados | B15: 11 | C15: Loteamento Nossa Senhora da Saúde - Guaporé – RS | D15: 3
A16: Executados e registrados | B16: 12 | C16: Loteamento Perini - Farroupilha – RS | D16: 10
... A44: Executados e não registrados | B44: 05 | C44: Loteamento Colina do Retiro II - Frainer - Veranópolis – RS | D44: 105
A46: Total executados e registrados | C46: Soma / no documento | D46: =SUMIF(A5:A44,"Executados e registrados",D5:D44) | E46: 447
A47: Total executados e não registrados | C47: Soma / no documento | D47: =SUMIF(A5:A44,"Executados e não registrados",D5:D44) | E47: 245
A48: Total geral de lotes urbanizados | C48: Soma / no documento | D48: =SUM(D5:D44) | E48: 692

Sheet Investimentos
A1: Planilha de investimentos / despesas
A2: Fonte: 18. 1. SIVIERO EMPREENDIMENTOS IMOBILIÁRIOS LTDA. = I N V E N T Á R I O = E M P R E S A D A S I V I E R O - Dezembro de 2018.docx (data-base 31.12.2018). Valores em azul transcritos do documento; totais em preto são fórmulas.
A4: Item no doc. | B4: Descrição | C4: Valor (R$)
A5: 01 | B5: Pago dívidas da Siviero Transportes Ltda., de 2011 a 2015. Desde 2011 a empresa NÃO divide mais nenhuma despesa administrativa e de impostos. | C5: 762000
A6: 02 | B6: Pago combustíveis da Siviero Transportes Ltda., em troca de aluguéis no Posto até 2011. | C6: 180000
A7: 03 | B7: Pago as bombas do Posto e obras de infraestrutura – banheiros + conveniências. | C7: 200000
A8: 04 | B8: Compra de 6,0 há de terras – Família Ansolin – Caminhão Antônio Ansolin. | C8: 525000
A9: 05 | B9: Compra de lotes no Loteamento Industrial Pedra Lisa. | C9: 625000
A10: 06 | B10: Pago dívida do Senhor Leonildo Anzolin, em troca de 01 lote – Nota Promissória. | C10: 90000
A11: 07 | B11: Compra de lotes da Família Fioreze. | C11: 148000
A12: 08 | B12: Pago despesas do Senhor Arlindo Piccoli – dívidas bancárias e de terceiros em troca de lotes. | C12: 300000
A13: 09 | B13: Aquisição da área de terras da Família Fogali, em Vila Azul. | C13: 205000
A14: 10 | B14: Compra de lotes no Loteamento Caminhos do Sol – Dorval Boff. | C14: 165000
A15: 11 | B15: Pago uma dívida trabalhista do Senhor Dorval Boff, em troca de lotes no Loteamento Caminhos do Sol. | C15: 220000
A16: 12 | B16: Compra de lotes no Loteamento Caminhos do Sol – Ludovico Boff e mais pagamento de dívidas de impostos. | C16: 1473000
... A23: 19 | B23: Déficit das Receitas X Despesas. – 01.01.2016 a 30.04.2017 Receitas – R$ 8.487.000,00 : Despesas – R$ 9.965.000,00 | C23: 1478000
B24: Soma | C24: =SUM(C5:C23)
B25: Total no documento | C25: 10376000
B26: Dif. | C26: =C24-C25

Sheet Sócios
A1: Quadros societários
A2: Fonte: 18. 1. SIVIERO EMPREENDIMENTOS IMOBILIÁRIOS LTDA. = I N V E N T Á R I O = E M P R E S A D A S I V I E R O - Dezembro de 2018.docx (data-base 31.12.2018). Valores em azul transcritos do documento; totais em preto são fórmulas.
A4: Quadro | B4: Sócio | C4: CPF/MF | D4: Valor cotas (R$) | E4: % cotas
A5: Quadro societário real, de fato e de direito | B5: IRINEU SIVIERO | C5: 005.682.870-53 | D5: 1818 | E5: 0.1818
A6: Quadro societário real, de fato e de direito | B6: RAUL SIVIERO | C6: 026.666.930-15 | D6: 1818 | E6: 0.1818
A7: Quadro societário real, de fato e de direito | B7: VALTER SIVIERO | C7: 202.511.810-49 | D7: 1818 | E7: 0.1818
A8: Quadro societário real, de fato e de direito | B8: ELCIO SIVIERO | C8: 114.987.900-97 | D8: 1818 | E8: 0.1818
A9: Quadro societário real, de fato e de direito | B9: ADÉLIA FRIZON SIVIERO | C9: 647.482.600-25 | D9: 1818 | E9: 0.1818
A10: Quadro societário real, de fato e de direito | B10: PEDRO SIVIERO | C10: 227.128.100-82 | D10: 710 | E10: 0.071
A11: Quadro societário real, de fato e de direito | B11: ROVILIO SIVIERO | C11: 225.676.150-91 | D11: 200 | E11: 0.02
A12: Novo quadro societário a contar de 01.12.2003 (NÃO REAL) | B12: PEDRO SIVIERO | C12: 227.128.100-82 | D12: 99000 | E12: 0.99
A13: Novo quadro societário a contar de 01.12.2003 (NÃO REAL) | B13: ELGIDES SIVIERO BINDA | C13: 134.449.800-00 | D13: 1000 | E13: 0.01
A14: Valor real de cada sócio conforme a cota de capital (sem valores R$ no documento) | B14: IRINEU SIVIERO | C14: 005.682.870-53 | E14: 0.16333
A15: Valor real de cada sócio conforme a cota de capital (sem valores R$ no documento) | B15: RAUL SIVIERO | C15: 026.666.930-15 | E15: 0.16333
A16: Valor real de cada sócio conforme a cota de capital (sem valores R$ no documento) | B16: VALTER SIVIERO | C16: 202.511.810-49 | E16: 0.16333
A17: Valor real de cada sócio conforme a cota de capital (sem valores R$ no documento) | B17: ELCIO SIVIERO | C17: 114.987.900-97 | E17: 0.16333
A18: Valor real de cada sócio conforme a cota de capital (sem valores R$ no documento) | B18: ADÉLIA FRIZON SIVIERO | C18: 647.482.600-25 | E18: 0.16333
A19: Valor real de cada sócio conforme a cota de capital (sem valores R$ no documento) | B19: PEDRO SIVIERO | C19: 227.128.100-82 | E19: 0.16333
A20: Valor real de cada sócio conforme a cota de capital (sem valores R$ no documento) | B20: ROVILIO SIVIERO | C20: 225.676.150-91 | E20: 0.02
