Workbook

Sheet Ativos
A1: Ativos com avaliação de valor - selecionados pela Valter Participações Societárias Ltda.
A2: Fonte: inventário-estudo-rafael.pdf (Diretrizes para seleção de ativos na separação patrimonial). Valores em azul transcritos do documento.
A3: Participação atribuível à Valter (documento: 1/6): | E3: =1/6 | F3: Células amarelas são editáveis: participação da Valter (E3) e participação da sociedade titular (coluna L, padrão 100%, a confirmar por ativo).
A5: Nº | B5: Empresa | C5: Categoria | D5: Item no doc. | E5: Descrição | F5: Loteamento | G5: Lote | H5: Quadra / ref. | I5: Matrícula | J5: Área | K5: Valor avaliado (R$) | L5: Particip. sociedade titular | M5: Quinhão Valter (R$) | N5: Página | O5: Observações
A6: 1 | B6: 05 - Hotel Princesa dos Vales Ltda. | C6: Imóvel rural | D6: 04 | E6: Terreno rural - SEDE CAMPESTRE (pavilhão, piscinas, casa, campos de futebol, lagos, alicerces de cabanas), Rua Luiz Siviero, Bairro Femaçã, Veranópolis-RS | I6: 1.941 e 7.104 | J6: 9,4 ha | K6: 5560857.5 | L6: 1 | M6: =K6*L6*$E$3 | N6: 4-5 | O6: Composição detalhada na aba 'Composição'. CCIR 2.481.947-6.
A7: 2 | B7: 05 - Hotel Princesa dos Vales Ltda. | C7: Imóvel rural | D7: 05 | E7: FAZENDA SÃO CRISPIN - Capela de São Sebastião, Distrito do Chimarrão, André da Rocha-RS | I7: 14.221, 13.615, 13.650, 00.760, 11.462, 05.435, 09.959, 04.443, 12.473 | J7: 407,53 ha (de 491,0 ha) | K7: 44828300 | L7: 1 | M7: =K7*L7*$E$3 | N7: 5 | O7: 83,47 ha da Matrícula 00.760 VENDIDOS à Família Rigo; avaliados 407,53 ha a R$ 110.000,00/ha. Composição na aba 'Composição'. CCIR 2.898.196-0.
A8: 3 | B8: 05 - Hotel Princesa dos Vales Ltda. | C8: Imóvel rural | D8: 06 | E8: FAZENDA SÃO CRISPIN - área dentro de um todo maior, adquirida de Dirceu Prestes e Lairton (contrato de compra e venda, dez/2015), André da Rocha-RS | I8: 11.090 | J8: 4,0 ha | K8: 440000 | L8: 1 | M8: =K8*L8*$E$3 | N8: 5 | O8: 4,0 ha x R$ 110.000,00/ha.
A9: 4 | B9: 05 - Hotel Princesa dos Vales Ltda. | C9: Veículo | D9: 08 | E9: Mercedinha MB 709 com boiadeiro, Mercedes-Benz, ano/modelo 1991, placa JTB 8585 | K9: 85000 | L9: 1 | M9: =K9*L9*$E$3 | N9: 5-6
A10: 5 | B10: 06 - Hotel Araçá Ltda. | C10: Imóvel urbano | D10: 12 | E10: Lote urbano nº 10 - Quadra 38, próximo ao Hotel Araçá, Capão da Canoa-RS. Adquirido de Hugo Ferri | G10: 10 | H10: 38 | I10: 11.990 | J10: 360,00 m² | K10: 390000 | L10: 1 | M10: =K10*L10*$E$3 | N10: 6 | O10: Inscrição 360.0038.010.000; Código 039411.
A11: 6 | B11: 06 - Hotel Araçá Ltda. | C11: Imóvel urbano | D11: 11 | E11: Lote urbano nº 09 - Quadra 38, próximo ao Hotel Araçá, Capão da Canoa-RS. Adquirido de Hugo Ferri | G11: 09 | H11: 38 | I11: 37.846 | J11: 360,00 m² | K11: 390000 | L11: 1 | M11: =K11*L11*$E$3 | N11: 6 | O11: Inscrição 360.0038.009.000; Código 039410.
A12: 7 | B12: 06 - Hotel Araçá Ltda. | C12: Imóvel urbano | D12: 02 | E12: Lote urbano nº 03 - Quadra 19 - Casa da Praça, próximo ao Hotel Araçá, Capão da Canoa-RS | G12: 03 | H12: 19 | I12: 77.832 (antiga 37.549) | J12: 450,00 m² | K12: 400000 | L12: 1 | M12: =K12*L12*$E$3 | N12: 6 | O12: Inscrição 360.0019.003.000; Código 038998.
A13: 8 | B13: 06 - Hotel Araçá Ltda. | C13: Imóvel urbano | D13: 18 | E13: Lote urbano nº 27 - Quadra 38 - Lote Estacionamento do Bigode, Capão da Canoa-RS | G13: 27 | H13: 38 | I13: 73.482 | J13: 360,00 m² | K13: 350000 | L13: 1 | M13: =K13*L13*$E$3 | N13: 6-7 | O13: Inscrição 360.0038.027.000; Código 039426. Documento indica a mesma matrícula do item 19.
A14: 9 | B14: 06 - Hotel Araçá Ltda. | C14: Imóvel urbano | D14: 19 | E14: Lote urbano nº 28 - Quadra 38 - Lote Estacionamento do Bigode, Capão da Canoa-RS | G14: 28 | H14: 38 | I14: 73.482 | J14: 360,00 m² | K14: 350000 | L14: 1 | M14: =K14*L14*$E$3 | N14: 7 | O14: Inscrição 360.0038.028.000; Código 039427. Documento indica a mesma matrícula do item 18.
A15: 10 | B15: 07 - Rádio Comunidade Princesa dos Vales FM Ltda. | C15: Veículo | E15: Toyota Bandeirante, diesel, ano/modelo 1980, verde, placa IHW 0285 | K15: 70000 | L15: 1 | M15: =K15*L15*$E$3 | N15: 7
A16: 11 | B16: 10 - Siviero Empreendimentos Imobiliários Ltda. | C16: Veículo | D16: 14 | E16: Camionete Ford Ranger, prata, ano 2010, placa NPQ OI67 | K16: 67000 | L16: 1 | M16: =K16*L16*$E$3 | N16: 8
A17: 12 | B17: 10 - Siviero Empreendimentos Imobiliários Ltda. | C17: Imóvel urbano | D17: 03 | E17: Lote urbano com casa/prédio - escritório velho, Av. Osvaldo Aranha, 1398, Bairro Palugana, Veranópolis-RS (alugado - Bar do André) | I17: 9 | J17: 570,00 m² (19 x 30 m) | K17: 850000 | L17: 1 | M17: =K17*L17*$E$3 | N17: 8
A18: 13 | B18: 10 - Siviero Empreendimentos Imobiliários Ltda. | C18: Imóvel urbano | D18: 05 | E18: Lote urbano, Av. Osvaldo Aranha esq. Rua Eduardo Duarte, Veranópolis-RS (alugado - Paulinho das baterias) | I18: 1.507 | J18: 345,00 m² (23 x 15 m) | K18: 550000 | L18: 1 | M18: =K18*L18*$E$3 | N18: 8
A19: 14 | B19: 10 - Siviero Empreendimentos Imobiliários Ltda. | C19: Imóvel urbano | D19: 06 | E19: Lote urbano nº 0092, quadra 020, zona 02, Rua General Flores da Cunha, Centro, Veranópolis-RS (adquirido da Família Dal Ponte) | G19: 0092 | H19: 020 | I19: 3.788 | J19: 750,00 m² | K19: 1010000 | L19: 1 | M19: =K19*L19*$E$3 | N19: 8
A20: 15 | B20: 10 - Siviero Empreendimentos Imobiliários Ltda. | C20: Imóvel urbano | D20: 08 | E20: Lote urbano nº 188/62 - Quadra 163/G, Loteamento Verona, Bento Gonçalves-RS (cadastro PM 12482700) | G20: 188/62 | H20: 163/G | I20: (em branco no documento) | J20: (em branco no documento) | K20: 160000 | L20: 1 | M20: =K20*L20*$E$3 | N20: 8 | O20: Área e matrícula não preenchidas no documento.
A21: 16 | B21: 10 - Siviero Empreendimentos Imobiliários Ltda. | C21: Imóvel urbano | D21: 04 | E21: Imóvel urbano com PAVILHÕES (4.170,00 m² construídos), Rodovia BR 470, Km 175,4, Bairro Valverde, Veranópolis-RS - locado à Oleoplan S/A | I21: 29.954 (unificação 17.409 e 6.136) | J21: 4.792,03 m² | K21: 10631379 | L21: 1 | M21: =K21*L21*$E$3 | N21: 8-9 | O21: Valor total conforme documento. A soma das parcelas descritas dá R$ 13.631.378,60 (diferença de R$ 3.000.000,00) - ver aba 'Composição'.
A22: 17 | B22: 10 - Siviero Empreendimentos Imobiliários Ltda. | C22: Imóvel urbano | D22: 02 | E22: Área de terras urbanas, lote nº 0292, quadra 009, zona 12, Linha Tomaz Flores, Estrada Velha da Vacaria, Sapopema, Veranópolis-RS (adquirida da Família Lago) | G22: 0292 | H22: 009 | I22: 33.516 | J22: 4,0 ha (40.027,41 m²) | K22: 1500000 | L22: 1 | M22: =K22*L22*$E$3 | N22: 9 | O22: Listado sob o título 'Áreas rurais', mas descrito como área urbana.
A23: 18 | B23: 10 - Siviero Empreendimentos Imobiliários Ltda. | C23: Lote em loteamento | E23: Lote 021 - D - 01. Loteamento Sol Nascente I | F23: 01. Loteamento Sol Nascente I | G23: 021 | H23: D | K23: 389000 | L23: 1 | M23: =K23*L23*$E$3 | N23: 9
A24: 19 | B24: 10 - Siviero Empreendimentos Imobiliários Ltda. | C24: Lote em loteamento | E24: Lote 022 - D - 01. Loteamento Sol Nascente I | F24: 01. Loteamento Sol Nascente I | G24: 022 | H24: D | K24: 354000 | L24: 1 | M24: =K24*L24*$E$3 | N24: 9
A25: 20 | B25: 10 - Siviero Empreendimentos Imobiliários Ltda. | C25: Lote em loteamento | E25: Lote 003 - 1 - 06. Loteamento Aditivo Medianeira | F25: 06. Loteamento Aditivo Medianeira | G25: 003 | H25: 1 | K25: 214000 | L25: 1 | M25: =K25*L25*$E$3 | N25: 9
A26: 21 | B26: 10 - Siviero Empreendimentos Imobiliários Ltda. | C26: Lote em loteamento | E26: Lote 002 - 6 - 06. Loteamento Aditivo Medianeira | F26: 06. Loteamento Aditivo Medianeira | G26: 002 | H26: 6 | K26: 156000 | L26: 1 | M26: =K26*L26*$E$3 | N26: 9
A27: 22 | B27: 10 - Siviero Empreendimentos Imobiliários Ltda. | C27: Lote em loteamento | E27: Lote 003 - 6 - 06. Loteamento Aditivo Medianeira | F27: 06. Loteamento Aditivo Medianeira | G27: 003 | H27: 6 | K27: 156000 | L27: 1 | M27: =K27*L27*$E$3 | N27: 9
A28: 23 | B28: 10 - Siviero Empreendimentos Imobiliários Ltda. | C28: Lote em loteamento | E28: Lote 007 - 8 - 06. Loteamento Aditivo Medianeira | F28: 06. Loteamento Aditivo Medianeira | G28: 007 | H28: 8 | K28: 152000 | L28: 1 | M28: =K28*L28*$E$3 | N28: 9
A29: 24 | B29: 10 - Siviero Empreendimentos Imobiliários Ltda. | C29: Lote em loteamento | E29: Lote 002 - 05 - 07. Colina do Retiro | F29: 07. Colina do Retiro | G29: 002 | H29: 05 | K29: 160000 | L29: 1 | M29: =K29*L29*$E$3 | N29: 9
A30: 25 | B30: 10 - Siviero Empreendimentos Imobiliários Ltda. | C30: Lote em loteamento | E30: Lote 002 - 09 - 07. Colina do Retiro | F30: 07. Colina do Retiro | G30: 002 | H30: 09 | K30: 159000 | L30: 1 | M30: =K30*L30*$E$3 | N30: 9
A31: 26 | B31: 10 - Siviero Empreendimentos Imobiliários Ltda. | C31: Lote em loteamento | E31: Lote 003 - 09 - 07. Colina do Retiro | F31: 07. Colina do Retiro | G31: 003 | H31: 09 | K31: 159000 | L31: 1 | M31: =K31*L31*$E$3 | N31: 9
A32: 27 | B32: 10 - Siviero Empreendimentos Imobiliários Ltda. | C32: Lote em loteamento | E32: Lote 002 - 02 - 08. Loteamento Salvador - Alberto Salvador - Femaçã II | F32: 08. Loteamento Salvador - Alberto Salvador - Femaçã II | G32: 002 | H32: 02 | K32: 413000 | L32: 1 | M32: =K32*L32*$E$3 | N32: 10
A33: 28 | B33: 10 - Siviero Empreendimentos Imobiliários Ltda. | C33: Lote em loteamento | E33: Lote 004 - 02 - 08. Loteamento Salvador - Alberto Salvador - Femaçã II | F33: 08. Loteamento Salvador - Alberto Salvador - Femaçã II | G33: 004 | H33: 02 | K33: 440000 | L33: 1 | M33: =K33*L33*$E$3 | N33: 10
A34: 29 | B34: 10 - Siviero Empreendimentos Imobiliários Ltda. | C34: Lote em loteamento | E34: Lote 005 - 02 - 08. Loteamento Salvador - Alberto Salvador - Femaçã II | F34: 08. Loteamento Salvador - Alberto Salvador - Femaçã II | G34: 005 | H34: 02 | K34: 326000 | L34: 1 | M34: =K34*L34*$E$3 | N34: 10
... A74: 69 | B74: 10 - Siviero Empreendimentos Imobiliários Ltda. | C74: Lote em loteamento | E74: Lote 003 - 1676 - 20. Loteamento San Marino | F74: 20. Loteamento San Marino | G74: 003 | H74: 1676 | K74: 253000 | L74: 1 | M74: =K74*L74*$E$3 | N74: 11
A75: 70 | B75: 10 - Siviero Empreendimentos Imobiliários Ltda. | C75: Lote em loteamento | E75: Lote 013 - 0907 - 21. Loteamento Firminio Dalzóchio | F75: 21. Loteamento Firminio Dalzóchio | G75: 013 | H75: 0907 | K75: 360000 | L75: 1 | M75: =K75*L75*$E$3 | N75: 11 | O75: No documento consta 'O13' (letra O); interpretado como 013.
A76: 71 | B76: 10 - Siviero Empreendimentos Imobiliários Ltda. | C76: Lote em loteamento | E76: Lote 003 - 1046 - 21. Loteamento Firminio Dalzóchio | F76: 21. Loteamento Firminio Dalzóchio | G76: 003 | H76: 1046 | K76: 385000 | L76: 1 | M76: =K76*L76*$E$3 | N76: 11
A77: 72 | B77: 10 - Siviero Empreendimentos Imobiliários Ltda. | C77: Lote em loteamento | E77: Lote 007 - 1303 - 24. Loteamento Industrial Vicentino | F77: 24. Loteamento Industrial Vicentino | G77: 007 | H77: 1303 | K77: 1355000 | L77: 1 | M77: =K77*L77*$E$3 | N77: 11
A78: 73 | B78: 10 - Siviero Empreendimentos Imobiliários Ltda. | C78: Lote em loteamento | E78: Lote 001 - 1736 - 25. Loteamento Residencial Jardim Itália I, II, III | F78: 25. Loteamento Residencial Jardim Itália I, II, III | G78: 001 | H78: 1736 | K78: 198000 | L78: 1 | M78: =K78*L78*$E$3 | N78: 11
A79: 74 | B79: 10 - Siviero Empreendimentos Imobiliários Ltda. | C79: Lote em loteamento | E79: Lote 009 - 1736 - 25. Loteamento Residencial Jardim Itália I, II, III | F79: 25. Loteamento Residencial Jardim Itália I, II, III | G79: 009 | H79: 1736 | K79: 220000 | L79: 1 | M79: =K79*L79*$E$3 | N79: 11
A80: 75 | B80: 10 - Siviero Empreendimentos Imobiliários Ltda. | C80: Lote em loteamento | E80: Lote 007 - 1738 - 25. Loteamento Residencial Jardim Itália I, II, III | F80: 25. Loteamento Residencial Jardim Itália I, II, III | G80: 007 | H80: 1738 | K80: 253000 | L80: 1 | M80: =K80*L80*$E$3 | N80: 11
...

Sheet Resumo
A1: Resumo por empresa e categoria
A3: Empresa | B3: Qtde. ativos | C3: Valor avaliado (R$) | D3: Quinhão Valter (R$) | E3: % do total
A4: 05 - Hotel Princesa dos Vales Ltda. | B4: =COUNTIF(Ativos!$B$6:$B$113,A4) | C4: =SUMIF(Ativos!$B$6:$B$113,A4,Ativos!$K$6:$K$113) | D4: =SUMIF(Ativos!$B$6:$B$113,A4,Ativos!$M$6:$M$113) | E4: =IF($C$8=0,0,C4/$C$8)
A5: 06 - Hotel Araçá Ltda. | B5: =COUNTIF(Ativos!$B$6:$B$113,A5) | C5: =SUMIF(Ativos!$B$6:$B$113,A5,Ativos!$K$6:$K$113) | D5: =SUMIF(Ativos!$B$6:$B$113,A5,Ativos!$M$6:$M$113) | E5: =IF($C$8=0,0,C5/$C$8)
A6: 07 - Rádio Comunidade Princesa dos Vales FM Ltda. | B6: =COUNTIF(Ativos!$B$6:$B$113,A6) | C6: =SUMIF(Ativos!$B$6:$B$113,A6,Ativos!$K$6:$K$113) | D6: =SUMIF(Ativos!$B$6:$B$113,A6,Ativos!$M$6:$M$113) | E6: =IF($C$8=0,0,C6/$C$8)
A7: 10 - Siviero Empreendimentos Imobiliários Ltda. | B7: =COUNTIF(Ativos!$B$6:$B$113,A7) | C7: =SUMIF(Ativos!$B$6:$B$113,A7,Ativos!$K$6:$K$113) | D7: =SUMIF(Ativos!$B$6:$B$113,A7,Ativos!$M$6:$M$113) | E7: =IF($C$8=0,0,C7/$C$8)
A8: TOTAL | B8: =SUM(B4:B7) | C8: =SUM(C4:C7) | D8: =SUM(D4:D7) | E8: =SUM(E4:E7)
A11: Categoria | B11: Qtde. ativos | C11: Valor avaliado (R$) | D11: Quinhão Valter (R$) | E11: % do total
A12: Imóvel rural | B12: =COUNTIF(Ativos!$C$6:$C$113,A12) | C12: =SUMIF(Ativos!$C$6:$C$113,A12,Ativos!$K$6:$K$113) | D12: =SUMIF(Ativos!$C$6:$C$113,A12,Ativos!$M$6:$M$113) | E12: =IF($C$16=0,0,C12/$C$16)
A13: Imóvel urbano | B13: =COUNTIF(Ativos!$C$6:$C$113,A13) | C13: =SUMIF(Ativos!$C$6:$C$113,A13,Ativos!$K$6:$K$113) | D13: =SUMIF(Ativos!$C$6:$C$113,A13,Ativos!$M$6:$M$113) | E13: =IF($C$16=0,0,C13/$C$16)
A14: Lote em loteamento | B14: =COUNTIF(Ativos!$C$6:$C$113,A14) | C14: =SUMIF(Ativos!$C$6:$C$113,A14,Ativos!$K$6:$K$113) | D14: =SUMIF(Ativos!$C$6:$C$113,A14,Ativos!$M$6:$M$113) | E14: =IF($C$16=0,0,C14/$C$16)
A15: Veículo | B15: =COUNTIF(Ativos!$C$6:$C$113,A15) | C15: =SUMIF(Ativos!$C$6:$C$113,A15,Ativos!$K$6:$K$113) | D15: =SUMIF(Ativos!$C$6:$C$113,A15,Ativos!$M$6:$M$113) | E15: =IF($C$16=0,0,C15/$C$16)
A16: TOTAL | B16: =SUM(B12:B15) | C16: =SUM(C12:C15) | D16: =SUM(D12:D15) | E16: =SUM(E12:E15)
A19: Loteamento (Empresa 10) | B19: Qtde. lotes | C19: Valor avaliado (R$) | D19: Quinhão Valter (R$) | E19: % do total
A20: 01. Loteamento Sol Nascente I | B20: =COUNTIF(Ativos!$F$6:$F$113,A20) | C20: =SUMIF(Ativos!$F$6:$F$113,A20,Ativos!$K$6:$K$113) | D20: =SUMIF(Ativos!$F$6:$F$113,A20,Ativos!$M$6:$M$113) | E20: =IF($C$38=0,0,C20/$C$38)
A21: 06. Loteamento Aditivo Medianeira | B21: =COUNTIF(Ativos!$F$6:$F$113,A21) | C21: =SUMIF(Ativos!$F$6:$F$113,A21,Ativos!$K$6:$K$113) | D21: =SUMIF(Ativos!$F$6:$F$113,A21,Ativos!$M$6:$M$113) | E21: =IF($C$38=0,0,C21/$C$38)
A22: 07. Colina do Retiro | B22: =COUNTIF(Ativos!$F$6:$F$113,A22) | C22: =SUMIF(Ativos!$F$6:$F$113,A22,Ativos!$K$6:$K$113) | D22: =SUMIF(Ativos!$F$6:$F$113,A22,Ativos!$M$6:$M$113) | E22: =IF($C$38=0,0,C22/$C$38)
A23: 08. Loteamento Salvador - Alberto Salvador - Femaçã II | B23: =COUNTIF(Ativos!$F$6:$F$113,A23) | C23: =SUMIF(Ativos!$F$6:$F$113,A23,Ativos!$K$6:$K$113) | D23: =SUMIF(Ativos!$F$6:$F$113,A23,Ativos!$M$6:$M$113) | E23: =IF($C$38=0,0,C23/$C$38)
A24: 09. Loteamento Colina do Retiro II | B24: =COUNTIF(Ativos!$F$6:$F$113,A24) | C24: =SUMIF(Ativos!$F$6:$F$113,A24,Ativos!$K$6:$K$113) | D24: =SUMIF(Ativos!$F$6:$F$113,A24,Ativos!$M$6:$M$113) | E24: =IF($C$38=0,0,C24/$C$38)
A25: 10. Loteamento Industrial Pedra Lisa | B25: =COUNTIF(Ativos!$F$6:$F$113,A25) | C25: =SUMIF(Ativos!$F$6:$F$113,A25,Ativos!$K$6:$K$113) | D25: =SUMIF(Ativos!$F$6:$F$113,A25,Ativos!$M$6:$M$113) | E25: =IF($C$38=0,0,C25/$C$38)
A26: 12. Loteamento Baldasso | B26: =COUNTIF(Ativos!$F$6:$F$113,A26) | C26: =SUMIF(Ativos!$F$6:$F$113,A26,Ativos!$K$6:$K$113) | D26: =SUMIF(Ativos!$F$6:$F$113,A26,Ativos!$M$6:$M$113) | E26: =IF($C$38=0,0,C26/$C$38)
A27: 13. Loteamento Colina do Basalto | B27: =COUNTIF(Ativos!$F$6:$F$113,A27) | C27: =SUMIF(Ativos!$F$6:$F$113,A27,Ativos!$K$6:$K$113) | D27: =SUMIF(Ativos!$F$6:$F$113,A27,Ativos!$M$6:$M$113) | E27: =IF($C$38=0,0,C27/$C$38)
A28: 14. Loteamento Carnevalli | B28: =COUNTIF(Ativos!$F$6:$F$113,A28) | C28: =SUMIF(Ativos!$F$6:$F$113,A28,Ativos!$K$6:$K$113) | D28: =SUMIF(Ativos!$F$6:$F$113,A28,Ativos!$M$6:$M$113) | E28: =IF($C$38=0,0,C28/$C$38)
A29: 18. Loteamento Lago Negro | B29: =COUNTIF(Ativos!$F$6:$F$113,A29) | C29: =SUMIF(Ativos!$F$6:$F$113,A29,Ativos!$K$6:$K$113) | D29: =SUMIF(Ativos!$F$6:$F$113,A29,Ativos!$M$6:$M$113) | E29: =IF($C$38=0,0,C29/$C$38)
A30: 20. Loteamento San Marino | B30: =COUNTIF(Ativos!$F$6:$F$113,A30) | C30: =SUMIF(Ativos!$F$6:$F$113,A30,Ativos!$K$6:$K$113) | D30: =SUMIF(Ativos!$F$6:$F$113,A30,Ativos!$M$6:$M$113) | E30: =IF($C$38=0,0,C30/$C$38)
A31: 21. Loteamento Firminio Dalzóchio | B31: =COUNTIF(Ativos!$F$6:$F$113,A31) | C31: =SUMIF(Ativos!$F$6:$F$113,A31,Ativos!$K$6:$K$113) | D31: =SUMIF(Ativos!$F$6:$F$113,A31,Ativos!$M$6:$M$113) | E31: =IF($C$38=0,0,C31/$C$38)
... A37: 30. Loteamento Falavigna | B37: =COUNTIF(Ativos!$F$6:$F$113,A37) | C37: =SUMIF(Ativos!$F$6:$F$113,A37,Ativos!$K$6:$K$113) | D37: =SUMIF(Ativos!$F$6:$F$113,A37,Ativos!$M$6:$M$113) | E37: =IF($C$38=0,0,C37/$C$38)
A38: TOTAL LOTES | B38: =SUM(B20:B37) | C38: =SUM(C20:C37) | D38: =SUM(D20:D37) | E38: =SUM(E20:E37)

Sheet Composição
A1: Composição dos valores dos itens com memória de cálculo
A2: Valores e parâmetros em azul transcritos do documento; totais calculados por fórmula e comparados ao valor declarado.
A4: Parcela | B4: Quantidade | C4: Unidade | D4: Valor unitário / % (R$) | E4: Valor (R$) | F4: Observação
A5: Empresa 05 - Item 04 - Sede Campestre (9,4 ha)
A6: Área de terras | B6: 9.4 | C6: ha | D6: 450000 | E6: =B6*D6
A7: Pavilhão construído - obra civil (CUB ago/2017) | B7: 891 | C7: m² | D7: 746 | E7: =B7*D7
A8: Benfeitoria - Quiosque | E8: 150000
A9: Casa de alvenaria nos fundos | E9: 250000 | F9: Área construída em branco no documento.
A10: Obras e infraestrutura = 25% de (pavilhão + quiosque + casa) | D10: 0.25 | E10: =D10*SUM(E7:E9) | F10: Documento escreve '25,00% (Vinte por cento)'; o valor R$ 266.171,50 corresponde a 25% de R$ 1.064.686,00.
A11: Total calculado | E11: =SUM(E6:E10)
A12: Total declarado no documento | E12: 5560857.5
A13: Diferença (calculado - declarado) | E13: =E11-E12
A15: Empresa 05 - Item 05 - Fazenda São Crispin (407,53 ha avaliados de 491,0 ha)
A16: Área Dona Rita - parte produtiva (35%) | B16: 100 | C16: ha | D16: 110000 | E16: =B16*D16
A17: Área Dona Rita - parte não produtiva (65%) | B17: 186 | C17: ha | D17: 110000 | E17: =B17*D17
A18: Área Zancheta - parte produtiva (80%) | B18: 45.6 | C18: ha | D18: 110000 | E18: =B18*D18
A19: Área Zancheta - parte não produtiva (20%) | B19: 11.4 | C19: ha | D19: 110000 | E19: =B19*D19
A20: Área Jane/João Paulo - produtiva (148,0 ha - 83,47 ha vendidos) | B20: =148-83.47 | C20: ha | D20: 110000 | E20: =B20*D20 | F20: 83,47 ha da Matrícula 00.760 vendidos à Família Rigo.
A21: Total de hectares avaliados | B21: =SUM(B16:B20) | C21: ha
A22: Total calculado | E22: =SUM(E16:E20)
A23: Total declarado no documento | E23: 44828300
A24: Diferença (calculado - declarado) | E24: =E22-E23
A26: Empresa 10 - Item 04 - Imóvel BR 470, Km 175,4 (Oleoplan)
A27: Terreno (R$ 2.000,00/m²) | B27: 4792.03 | C27: m² | D27: 2000 | E27: =B27*D27 | F27: Documento: R$ 9.584.060,00.
A28: Pavilhões - CUB ago/2017 | B28: 4170 | C28: m² | D28: 746.6 | E28: =B28*D28 | F28: Documento: R$ 3.113.322,00.
A29: Obra civil dos pavilhões = 30% da obra feita | D29: 0.3 | E29: =D29*E28 | F29: Documento: R$ 933.996,60.
A30: Total calculado | E30: =SUM(E27:E29)
A31: Total declarado no documento | E31: 10631379
A32: Diferença (calculado - declarado) | E32: =E30-E31 | F32: Diferença de R$ 3.000.000,00: o total declarado só fecha se o terreno valer R$ 6.584.060,00 (e não R$ 9.584.060,00). Confirmar com o autor do documento.
