Workbook

Sheet Resumo
A1: Mês | B1: ABASTECEDORA DE COMBUSTIVEIS SIVIERO LTD | C1: SIVIERO EMPREENDIMENTOS IMOBILIARIOS LTD | D1: TRANSPORTADORA IRMAOS SIVIERO LTDA. | E1: Total
A2: 45108 | B2: =SUMIFS(Consolidado!$H:$H,Consolidado!$A:$A,$A2,Consolidado!$C:$C,B$1) | C2: =SUMIFS(Consolidado!$H:$H,Consolidado!$A:$A,$A2,Consolidado!$C:$C,C$1) | D2: =SUMIFS(Consolidado!$H:$H,Consolidado!$A:$A,$A2,Consolidado!$C:$C,D$1) | E2: =SUM(B2:D2)
A3: 45139 | B3: =SUMIFS(Consolidado!$H:$H,Consolidado!$A:$A,$A3,Consolidado!$C:$C,B$1) | C3: =SUMIFS(Consolidado!$H:$H,Consolidado!$A:$A,$A3,Consolidado!$C:$C,C$1) | D3: =SUMIFS(Consolidado!$H:$H,Consolidado!$A:$A,$A3,Consolidado!$C:$C,D$1) | E3: =SUM(B3:D3)
A4: 45200 | B4: =SUMIFS(Consolidado!$H:$H,Consolidado!$A:$A,$A4,Consolidado!$C:$C,B$1) | C4: =SUMIFS(Consolidado!$H:$H,Consolidado!$A:$A,$A4,Consolidado!$C:$C,C$1) | D4: =SUMIFS(Consolidado!$H:$H,Consolidado!$A:$A,$A4,Consolidado!$C:$C,D$1) | E4: =SUM(B4:D4)
A5: 45231 | B5: =SUMIFS(Consolidado!$H:$H,Consolidado!$A:$A,$A5,Consolidado!$C:$C,B$1) | C5: =SUMIFS(Consolidado!$H:$H,Consolidado!$A:$A,$A5,Consolidado!$C:$C,C$1) | D5: =SUMIFS(Consolidado!$H:$H,Consolidado!$A:$A,$A5,Consolidado!$C:$C,D$1) | E5: =SUM(B5:D5)
A6: 45261 | B6: =SUMIFS(Consolidado!$H:$H,Consolidado!$A:$A,$A6,Consolidado!$C:$C,B$1) | C6: =SUMIFS(Consolidado!$H:$H,Consolidado!$A:$A,$A6,Consolidado!$C:$C,C$1) | D6: =SUMIFS(Consolidado!$H:$H,Consolidado!$A:$A,$A6,Consolidado!$C:$C,D$1) | E6: =SUM(B6:D6)
A7: 45292 | B7: =SUMIFS(Consolidado!$H:$H,Consolidado!$A:$A,$A7,Consolidado!$C:$C,B$1) | C7: =SUMIFS(Consolidado!$H:$H,Consolidado!$A:$A,$A7,Consolidado!$C:$C,C$1) | D7: =SUMIFS(Consolidado!$H:$H,Consolidado!$A:$A,$A7,Consolidado!$C:$C,D$1) | E7: =SUM(B7:D7)
A8: 45323 | B8: =SUMIFS(Consolidado!$H:$H,Consolidado!$A:$A,$A8,Consolidado!$C:$C,B$1) | C8: =SUMIFS(Consolidado!$H:$H,Consolidado!$A:$A,$A8,Consolidado!$C:$C,C$1) | D8: =SUMIFS(Consolidado!$H:$H,Consolidado!$A:$A,$A8,Consolidado!$C:$C,D$1) | E8: =SUM(B8:D8)
A9: 45352 | B9: =SUMIFS(Consolidado!$H:$H,Consolidado!$A:$A,$A9,Consolidado!$C:$C,B$1) | C9: =SUMIFS(Consolidado!$H:$H,Consolidado!$A:$A,$A9,Consolidado!$C:$C,C$1) | D9: =SUMIFS(Consolidado!$H:$H,Consolidado!$A:$A,$A9,Consolidado!$C:$C,D$1) | E9: =SUM(B9:D9)
A10: 45383 | B10: =SUMIFS(Consolidado!$H:$H,Consolidado!$A:$A,$A10,Consolidado!$C:$C,B$1) | C10: =SUMIFS(Consolidado!$H:$H,Consolidado!$A:$A,$A10,Consolidado!$C:$C,C$1) | D10: =SUMIFS(Consolidado!$H:$H,Consolidado!$A:$A,$A10,Consolidado!$C:$C,D$1) | E10: =SUM(B10:D10)
A11: 45413 | B11: =SUMIFS(Consolidado!$H:$H,Consolidado!$A:$A,$A11,Consolidado!$C:$C,B$1) | C11: =SUMIFS(Consolidado!$H:$H,Consolidado!$A:$A,$A11,Consolidado!$C:$C,C$1) | D11: =SUMIFS(Consolidado!$H:$H,Consolidado!$A:$A,$A11,Consolidado!$C:$C,D$1) | E11: =SUM(B11:D11)
A12: 45444 | B12: =SUMIFS(Consolidado!$H:$H,Consolidado!$A:$A,$A12,Consolidado!$C:$C,B$1) | C12: =SUMIFS(Consolidado!$H:$H,Consolidado!$A:$A,$A12,Consolidado!$C:$C,C$1) | D12: =SUMIFS(Consolidado!$H:$H,Consolidado!$A:$A,$A12,Consolidado!$C:$C,D$1) | E12: =SUM(B12:D12)
A13: 45474 | B13: =SUMIFS(Consolidado!$H:$H,Consolidado!$A:$A,$A13,Consolidado!$C:$C,B$1) | C13: =SUMIFS(Consolidado!$H:$H,Consolidado!$A:$A,$A13,Consolidado!$C:$C,C$1) | D13: =SUMIFS(Consolidado!$H:$H,Consolidado!$A:$A,$A13,Consolidado!$C:$C,D$1) | E13: =SUM(B13:D13)
... A16: 45566 | B16: =SUMIFS(Consolidado!$H:$H,Consolidado!$A:$A,$A16,Consolidado!$C:$C,B$1) | C16: =SUMIFS(Consolidado!$H:$H,Consolidado!$A:$A,$A16,Consolidado!$C:$C,C$1) | D16: =SUMIFS(Consolidado!$H:$H,Consolidado!$A:$A,$A16,Consolidado!$C:$C,D$1) | E16: =SUM(B16:D16)
A17: Total | B17: =SUM(B2:B16) | C17: =SUM(C2:C16) | D17: =SUM(D2:D16) | E17: =SUM(E2:E16)

Sheet Consolidado
A1: Mês | B1: Página | C1: Empresa | D1: Fornecedor | E1: Vencimento | F1: Pagamento | G1: Valor NF | H1: Valor Dupl. | I1: Observações
A2: 45108 | B2: 1 | C2: SIVIERO EMPREENDIMENTOS IMOBILIARIOS LTD | D2: DORVAL FRANCISCO BOFF - CAXIAS DO SUL | E2: 45110 | F2: 45110 | G2: 100000 | H2: 10000 | I2: P.04/10-CFE CONTRATO ANTECIPACAO VALORES - LO
A3: 45108 | B3: 1 | C3: SIVIERO EMPREENDIMENTOS IMOBILIARIOS LTD | D3: PROGETEC - ALENCAR TRINDADE - P.FUNDO | E3: 45110 | F3: 45110 | G3: 25000 | H3: 5000 | I3: P.3/5-INSTALACAO D+ HASTES CERCA ELETRICA+INS
A4: 45108 | B4: 1 | C4: SIVIERO EMPREENDIMENTOS IMOBILIARIOS LTD | D4: PREFEITURA MUNICIPAL DE NOVA PRATA | E4: 45110 | F4: 45110 | G4: 36.96 | H4: 36.96 | I4: CERTIDAO DE LOCALIZAÇAO AREA-BELLA VISIONE-NO
A5: 45108 | B5: 1 | C5: SIVIERO EMPREENDIMENTOS IMOBILIARIOS LTD | D5: SIM REDE DE POSTOS LTDA. - VERANOPOLI | E5: 45109 | F5: 45110 | G5: 521.89 | H5: 521.89 | I5: ABASTECIMENTOS CARROS+CACAMBAS+OFICINA=VER
A6: 45108 | B6: 1 | C6: SIVIERO EMPREENDIMENTOS IMOBILIARIOS LTD | D6: INES TREVISAN PICCOLI - JUROS | E6: 45108 | F6: 45110 | G6: 250000 | H6: 2500 | I6: JUROS 1.00% S/ R$ 250.000,00 - EMPRESTIMO
A7: 45108 | B7: 1 | C7: SIVIERO EMPREENDIMENTOS IMOBILIARIOS LTD | D7: ANDRE LUIZ SIVIERO - JUROS | E7: 45108 | F7: 45110 | G7: 100000 | H7: 800 | I7: JUROS 0,80% S/ R$ 100.000,00 - EMPRESTIMO
A8: 45108 | B8: 1 | C8: SIVIERO EMPREENDIMENTOS IMOBILIARIOS LTD | D8: SAMIR TREVISAN PICCOLI - JUROS | E8: 45108 | F8: 45110 | G8: 350000 | H8: 3500 | I8: JUROS 1.00% S/ R$ 350.000,00 - EMPRESTIMO
A9: 45108 | B9: 1 | C9: SIVIERO EMPREENDIMENTOS IMOBILIARIOS LTD | D9: SAMIR TREVISAN PICCOLI - JUROS | E9: 45108 | F9: 45110 | G9: 150000 | H9: 1500 | I9: JUROS 1.00% S/ R$ 150.000,00 - EMPRESTIMO
A10: 45108 | B10: 1 | C10: SIVIERO EMPREENDIMENTOS IMOBILIARIOS LTD | D10: SAMIR TREVISAN PICCOLI - JUROS | E10: 45108 | F10: 45110 | G10: 250000 | H10: 2500 | I10: JUROS 1.00% S/ R$ 250.000,00 - EMPRESTIMO
A11: 45108 | B11: 1 | C11: SIVIERO EMPREENDIMENTOS IMOBILIARIOS LTD | D11: SAMIR TREVISAN PICCOLI - JUROS | E11: 45108 | F11: 45110 | G11: 250000 | H11: 2500 | I11: JUROS 1.00% S/ R$ 250.000,00 - EMPRESTIMO EM
A12: 45108 | B12: 1 | C12: SIVIERO EMPREENDIMENTOS IMOBILIARIOS LTD | D12: BANCO SICREDI - VERANÓPOLIS | E12: 45110 | F12: 45110 | G12: 0.18 | H12: 0.18 | I12: JUROS BANCO CREDITO ROTATIVO MES JUNHO/2023
A13: 45108 | B13: 1 | C13: SIVIERO EMPREENDIMENTOS IMOBILIARIOS LTD | D13: IOF BANCARIO SIVIERO EMP IMOBILIARIOS | E13: 45110 | F13: 45110 | G13: 308.55 | H13: 308.55 | I13: IOF CONTA SEI MES DE JUNHO DE 2023 - BANRISUL
... A3786: 45566 | B3786: 5 | C3786: ABASTECEDORA DE COMBUSTIVEIS SIVIERO LTD | D3786: CONT. SOCIAL - ABAST. COMB. SIVIERO L | E3786: 45596 | F3786: 45596 | G3786: 765.5 | H3786: 765.5 | I3786: FATURAMENTO MES SETEMBRO/2024 - R$ 26.580,00

Sheet Conferência
A1: Mês | B1: Arquivo | C1: Empresa | D1: Linhas | E1: Soma Valor Dupl. | F1: Subtotal impresso | G1: Diferença | H1: Notas
A2: 45108 | B2: 2023-07 | C2: SIVIERO EMPREENDIMENTOS IMOBILIARIOS LTD | D2: 177 | E2: 1165697.9 | F2: 1165697.9 | G2: 0 | H2: Periodo impresso 01/07/2023 - 31/07/2023 confere com a tag 2023-07; emissao 02/08/2023; 5 paginas; 3 secoes (SIVIERO EMPREENDIMENTOS, TRANSPORTADORA IRMAOS SIVIERO, ABASTECEDORA).; Observacoes cortadas na margem direita do scan: mantido o texto visivel; letra parcialmente cortada na borda foi mantida quando reconhecivel (ex.: 'MOTONIVELADO', 'JUNHO').; Fornecedor encostado na data de Venc.: o 37o caractere aparece pela metade. Gravado como 'LTI' quando era a metade de um D (D KEKOS, PROMED, SAO JOAO), 'MATRICU' (OPERADOR NACIONAL DO REGISTRO) e 'ELETRICO' (ENERTEC) quando a meia-letra era reconhecivel como U/O.; L.R. BETT PAVIMENTACOES (p2): Venc. impresso 13/05/23 com Pgto. 13/07/23 - mantido como impresso.; Erros de digitacao do proprio relatorio mantidos: 'EMPRREND.', 'EMPREEEND.', 'PRESTRADOS', 'RALATORIO', 'CAIXIAS', 'PROGAMA', 'MAMOMETRO'.; RADAX DO BRASIL (p4): Valor NF 3.582,13 com Valor Dupl. 358,00 (P. 02/10) - conferido com zoom, impresso assim.
A3: 45108 | B3: 2023-07 | C3: TRANSPORTADORA IRMAOS SIVIERO LTDA. | D3: 67 | E3: 170937.95 | F3: 170937.95 | G3: 0
A4: 45108 | B4: 2023-07 | C4: ABASTECEDORA DE COMBUSTIVEIS SIVIERO LTD | D4: 16 | E4: 14885.25 | F4: 14885.25 | G4: 0
A5: 45139 | B5: 2023-08 | C5: SIVIERO EMPREENDIMENTOS IMOBILIARIOS LTD | D5: 181 | E5: 668125.99 | F5: 668125.99 | G5: 0 | H5: Periodo impresso 01/08/2023 - 31/08/2023 confere com a tag 2023-08; emissao 06/09/2023; 5 paginas; 3 secoes (SIVIERO EMPREENDIMENTOS, TRANSPORTADORA IRMAOS SIVIERO, ABASTECEDORA). Nenhuma celula ilegivel.; Observacoes cortadas na margem direita do scan: mantido o texto visivel; letra parcialmente cortada na borda mantida quando reconhecivel (ex.: 'PRACA G', 'TIS/SEI/A', 'MARCO', 'RETRO+CAC', 'DE 202'); omitida quando irreconhecivel (ex.: depois de 'PAVIMENTACAO' p1 RODRIGO KAISER, 'IUV' p1 RAMPA, 'GELATINA+' p3 SUPERMERCADO FRASSUL).; Fornecedor encostado na data de Venc.: 37o caractere pela metade. Gravado como 'LTI' (D KEKOS, SAO JOAO, PROMED), 'MATRICU' (OPERADOR NACIONAL DO REGISTRO), 'ELETRICO' (ENERTEC), 'VERANOPOL' (RAMPA DE LAVAGEM VALVERDE), seguindo a convencao de 2023-07.; L.R. BETT PAVIMENTACOES (p2): Venc. impresso 13/06/23 com Pgto. 14/08/23 - conferido com zoom, mantido como impresso.; Valores conferidos com zoom e impressos assim: CARBONERA (p3) NF 2.400,00 / Dupl 819,39 (P.1/3); RADAX (p5) NF 1.542,38 / Dupl 428,51 (P. 01/04); RADAX (p4) NF 3.582,13 / Dupl 358,00; TSD (p4) 831,13 / 207,79 e (p5) 831,13 / 207,78; ANTONIO ANSOLIN (p2) NF 586.666,00.; Pontilhados copiados com a contagem impressa: LADIR MADRUGA (p2) 'EM ............. - A' (13 pontos); PREFEITURA DE GUAPORE (p3) 'QDRA ..........' (10 pontos).; 'O1' com letra O (nao zero) em 'O1 PULVERIZADOR' (p3 ORSO) e 'CONST-O1' (p3 ZANELLA), como impresso.; Erros de digitacao do proprio relatorio mantidos: 'EMPRREND.' (PIS p3), 'EMPREEEND.', 'PROGAMA', 'MAMOMETRO', 'ELETRECISTA', 'HERBECIDAS', 'P.20/22--COMPRA'.; Linhas impressas com distorcao do scan (MOLIN & SLOMP p1, POSITIVA p2, HOTEL ARACA p3) lidas sem ambiguidade.
A6: 45139 | B6: 2023-08 | C6: TRANSPORTADORA IRMAOS SIVIERO LTDA. | D6: 71 | E6: 183210.32 | F6: 183210.32 | G6: 0
A7: 45139 | B7: 2023-08 | C7: ABASTECEDORA DE COMBUSTIVEIS SIVIERO LTD | D7: 14 | E7: 4275.02 | F7: 4275.02 | G7: 0
A8: 45200 | B8: 2023-10 | C8: SIVIERO EMPREENDIMENTOS IMOBILIARIOS LTD | D8: 184 | E8: 385521.64 | F8: 385521.64 | G8: 0 | H8: Periodo impresso 01/10/2023 - 31/10/2023 confere com a tag 2023-10; emissao 07/11/2023; 6 paginas; 3 secoes (SIVIERO EMPREENDIMENTOS, TRANSPORTADORA IRMAOS SIVIERO, ABASTECEDORA). A pagina 6 contem apenas o Subtotal da ABASTECEDORA (3.790,28) e o Total; suas linhas estao todas na pagina 5. A metade inferior da pagina 6 esta em branco.; Observacoes cortadas na margem direita do scan: mantido o texto visivel; letra parcialmente cortada mantida quando reconhecivel (ex.: 'BIA', 'SETEMBRO', 'MARCO', 'VERA', 'MOTONIVELADO', 'BOBINA=V'). Fragmentos irreconheciveis na borda foram omitidos: DIGITAL WAY p3 ('COMPUTADOR SUZI' + meia letra) e ANTONINHO JOSE ZANELLA p3 25/10 ('ENTULHO O' + meia letra).; Fornecedor encostado na data de Venc.: o 37o caractere aparece pela metade. Seguindo a convencao do mes 2023-07: 'LTI' para a metade de um D (D KEKOS x3, PROMED, SAO JOAO x2), 'MATRICU' (OPERADOR NACIONAL DO REGISTRO x2), 'ELETRICO' (ENERTEC) e 'CHAPEAC' (CLAIRTON VENDRAMIN, p2). 'SIMONETTO ... LTDA' (p1 e p3) cabe inteiro antes da data.; CONSULTAMB - JAQUELINE BONATT0 (p3): o ultimo caractere e impresso como algarismo zero (mais estreito que a letra O) - mantido como impresso.; Venc. posterior ao Pgto. mantido como impresso (ex.: L.R. BETT e LUIS CARLOS MERCALI 13/10 pagos 11/10; COOPERATIVA SANTA CLARA 13/10 paga 11/10). Venc. de setembro pagos em outubro: SIMONETTO 27/09/23, CHAPEACAO BIDJA 29/09/23.; Erros de digitacao do proprio relatorio mantidos: 'EMPRREND.', 'EMPREEEND.', 'CONTRUCAO', 'CATTERPILAR', 'PROGAMA', 'MAMOMETRO', 'SETEEMBRO', 'PINHERIOS', 'THINER'. TSD LOGISTICA NF 1.146,44: Dupl. 229,28 (p4) e 229,29 (p5, duas vezes) - conferido, impresso assim. RADAX (p4) NF 3.582,13 com Dupl. 358,00 (P. 05/10), igual ao padrao de 2023-07.; Linhas RESTAURANTE - CAXIAS DO SUL (p1), POSITIVA COMUNICACAO E MARKETING LTDA (p2) e BANCO SICREDI 26/10 (p3) impressas em fonte menor; lidas com zoom.
A9: 45200 | B9: 2023-10 | C9: TRANSPORTADORA IRMAOS SIVIERO LTDA. | D9: 75 | E9: 157363.96 | F9: 157363.96 | G9: 0
A10: 45200 | B10: 2023-10 | C10: ABASTECEDORA DE COMBUSTIVEIS SIVIERO LTD | D10: 13 | E10: 3790.28 | F10: 3790.28 | G10: 0
A11: 45231 | B11: 2023-11 | C11: SIVIERO EMPREENDIMENTOS IMOBILIARIOS LTD | D11: 163 | E11: 666440.05 | F11: 666440.05 | G11: 0 | H11: Periodo impresso 01/11/2023 - 30/11/2023 confere com a tag 2023-11; emissao 12/12/2023; 5 paginas (metade inferior da p5 em branco); 3 secoes (SIVIERO EMPREENDIMENTOS, TRANSPORTADORA IRMAOS SIVIERO, ABASTECEDORA). Secao TRANSPORTADORA comeca na p4 (titulo no fim da p3) e continua na p5 sem repetir o titulo.; Anotacoes manuscritas no scan (nao transcritas): 'Visto' e rubrica no cabecalho da p1; tracos a caneta apos a data de Pgto. nas linhas 1-10 da p1.; Observacoes cortadas na margem direita do scan: mantido o texto visivel; letra parcialmente cortada na borda foi mantida quando reconhecivel (ex.: 'CHAPEAC' no fornecedor CLAIRTON, 'WOLKS', 'SAFRA', 'NOVO', 'BOFF-REPO', 'CALCAMENTO', 'OUTUB', 'BOBINA=V'). Fornecedor encostado na data de Venc.: meia-letra gravada como 'LTI' (PROMED, metade de D) e 'COL/' (CHAPEACAO TRANSFORMES), como impresso.; Linhas impressas comprimidas/achatadas verticalmente (falha de impressao, mas legiveis e conferidas com zoom): p1 FABIANO ROGERIO MINOZZO 825,00; p2 VILSON JOSE RIBEIRO 3.000,00; p3 FORUM DE NOVA PRATA 380,78; p4 BRADESCO 4.216,63/1.054,16.; p3 PREFEITURA MUNICIPAL DE PASSO FUNDO 210,33: Observacao termina em 'IPE - I' (letra I, sem a serifa do digito 1, conferido com zoom), mantido como impresso; a linha seguinte termina em 'IPE - 2'.; Erros de digitacao do proprio relatorio mantidos: 'IMOBILARIOS' (JDRX), 'BONATT0' (com zero), 'O1 PAR' (letra O), 'PROGAMA', 'CAIXAS DO SUL', 'EMPREEEND.', 'EMPRREND.', 'NOVEMRO', 'TACOGROFO', 'MAMOMETRO', 'CHAMFRADO'.; Valores NF/Dupl. de todas as paginas conferidos com recortes ampliados; nenhuma celula ilegivel.
A12: 45231 | B12: 2023-11 | C12: TRANSPORTADORA IRMAOS SIVIERO LTDA. | D12: 58 | E12: 154753.09 | F12: 154753.09 | G12: 0
A13: 45231 | B13: 2023-11 | C13: ABASTECEDORA DE COMBUSTIVEIS SIVIERO LTD | D13: 14 | E13: 4056.08 | F13: 4056.08 | G13: 0
A14: 45261 | B14: 2023-12 | C14: SIVIERO EMPREENDIMENTOS IMOBILIARIOS LTD | D14: 185 | E14: 1022872.6 | F14: 1022872.6 | G14: 0 | H14: Periodo impresso 01/12/2023 - 31/12/2023 confere com a tag 2023-12; emissao 11/01/2024; 6 paginas (p6 so com 5 linhas da ABASTECEDORA, Subtotal e Total; metade inferior da p6 em branco); 3 secoes (SIVIERO EMPREENDIMENTOS, TRANSPORTADORA IRMAOS SIVIERO, ABASTECEDORA).; Observacoes cortadas na margem direita do scan: mantido o texto visivel; letra parcialmente cortada mantida quando reconhecivel (ex.: 'NOVEMBR', 'VAGNER', 'RESERVATORIOS', 'MATRICULA', 'BOBINA=V'); fragmento irreconhecivel omitido (ex.: 'CAMPES' p3) ou gravado como aparece ('NOVEMBRO DI' p5, 'FRANCEL' p4).; Fornecedor encostado na data de Venc.: gravado 'LTI' para meia-letra D (D KEKOS p1, SAO JOAO TRANSPORTES p4, PROMED p5), 'MATRICU' (OPERADOR NACIONAL DO REGISTRO p1/p2), 'VERANOPOL' (MARCOS ROSSA p2, RAMPA DE LAVAGEM p4), 'L' (RODOBENS), 'PRA' (CVC CONSTRUCOES), 'LTD' (ARDRILL, D inteiro visivel), 'LTDA' (EQUIPAMENTOS ESCRITORIO REGIONAL).; ANTONINHO JOSE ZANELLA (p1, venc 01/12/23): Valor Dupl. 910,05 maior que Valor NF 887,00 - conferido com zoom, impresso assim.; Vencimentos anteriores ao periodo mantidos como impressos (29/11/23, 24/11/23, 28/11/23 na p1); PARANA EQUIPAMENTOS e SIM REDE (p4) e SIM REDE FLORES DA CU (p5) com Venc. 31/12/23 e Pgto. 28/12/23, e ANTONINHO ZANELLA (p4) Venc. 29/12/23 Pgto. 28/12/23 - mantidos como impressos.; Erros de digitacao do proprio relatorio mantidos: 'EMPRREND.', 'EMPREEEND.', 'EMPREED.', 'PROGAMA', 'DEZEMRO', 'MAMOMETRO', 'RENOVAAO', 'PLAHET'.; Varias linhas repetidas identicas impressas (ex.: 4x e 7x BANCO ESTADO - TIS 11,50; 3x BANCO ESTADO - SEI 207,87; 2x DIANA FIORI 100,59) - todas transcritas; a soma confere com os subtotais.
A15: 45261 | B15: 2023-12 | C15: TRANSPORTADORA IRMAOS SIVIERO LTDA. | D15: 78 | E15: 216221.5 | F15: 216221.5 | G15: 0
A16: 45261 | B16: 2023-12 | C16: ABASTECEDORA DE COMBUSTIVEIS SIVIERO LTD | D16: 14 | E16: 3840.28 | F16: 3840.28 | G16: 0
A17: 45292 | B17: 2024-01 | C17: SIVIERO EMPREENDIMENTOS IMOBILIARIOS LTD | D17: 148 | E17: 343100.52 | F17: 343100.52 | G17: 0 | H17: Periodo impresso 01/01/2024 - 31/01/2024 confere com a tag 2024-01; emissao 21/02/2024; 5 paginas (pagina 5 so tem a metade superior impressa; metade inferior em branco); 3 secoes (SIVIERO EMPREENDIMENTOS, TRANSPORTADORA IRMAOS SIVIERO, ABASTECEDORA).; Observacoes cortadas na margem direita do scan: mantido o texto visivel; letra parcialmente cortada mantida quando reconhecivel (ex.: 'FORD RANGE', 'CONTAS-TIS/SEI/A', 'SENHORA DE LOUR', 'FLORES DA CUNHA', 'PERTO DO', 'CONTRATO FAMILIA', 'MORADA DO', 'CARRO-ACIDENT', 'PNEUS CACAM', 'RS.COM.BR-DEZEM', 'CONTABEIS-DEZEMBRO DE'). Traco vertical solto nao identificavel na borda foi omitido (p1 'ANTAS=24 M', 'TABELIONATO/VERANOPOLIS-', 'FRETES+CORREIOS+'; p2 'LOTE PERTO HOSPI' (resto de possivel T), 'RECONHECIMENTOS = DEZEMBRO/'; p4 'ESCRITORIO SIVIERO-VERANOPOLI').; Fornecedor encostado na data de Venc.: o 37o caractere aparece pela metade. Gravado como 'LTI' quando era a metade de um D (PROMED, SAO JOAO), 'ELETRICO' (ENERTEC), 'MATRICU' (OPERADOR NACIONAL DO REGISTRO) e 'CHAPEAC' (CLAIRTON VENDRAMIN) conforme a meia-letra visivel.; PAULO RICARDO PALUDO (p1, 04/01/24, 770,00): Observacao comeca com 'O1' (letra O, como impresso, nao zero) - conferido com zoom.; CONSULTAMB - JAQUELINE BONATT0 (p1): ultimo caractere impresso como digito zero ('BONATT0'), mantido.; BANCO ESTADO RIO GRANDE DO SUL - TIS (p5, 30/01/24, 43,44): mancha sobre o O de 'ESCRITORIO' parece sujeira do scan, nao acento; gravado 'ESCRITORIO' (mesmo texto da linha de 02/01/24 na p3).; MULTI CELTACAR (p2): Valor NF 1.005,00 com Valor Dupl. 502,00 (P. 1/2) - conferido com zoom, impresso assim (nao 502,50).; SUL TURBOS (p1 P.2/3 = 833,33; p3 P.3/3 = 833,34) e RSC COMERCIO KIT EMBREAGEM (p4 P.01/03 = 1.108,34; P.02/03 = 1.108,33) - centavos de arredondamento conferidos.; MARQUESFRIO (p3): Venc. impresso 28/12/23 com Pgto. 24/01/24 - mantido como impresso.; Erros de digitacao do proprio relatorio mantidos: 'EMPRREND.', 'EMPREEEND.', 'PRESTRADOS', 'PROGAMA', 'MAMOMETRO', 'UINICA', 'JEPP', 'ESPUMATES', 'TRASSEIRA', 'MOTOSSERA', 'VIVIERO', 'SIVIEROU', 'RAVA', '1.00%'.; Acentos impressos mantidos: 'VERANÓPOLIS' (BANCO SICREDI), 'INFORMÁTICA' (RS MICRO), 'PAVILHÃO', 'QUÍMICA' (BOFF ENGENHARIA), 'IPÊS', 'ÁREA', 'M²'.; Espacos duplos estimados pelo espacamento visivel: 'ADYL NET - INTERNET LTDA.' (p1, p4), 'FLAVIA MANICA - ENGENHEIRA CIVIL' (p2), 'LADIR MADRUGA - CAXIAS DO SUL' (p3), 'CH 024074' (p3, MARQUESFRIO).
A18: 45292 | B18: 2024-01 | C18: TRANSPORTADORA IRMAOS SIVIERO LTDA. | D18: 73 | E18: 154069.3 | F18: 154069.3 | G18: 0
A19: 45292 | B19: 2024-01 | C19: ABASTECEDORA DE COMBUSTIVEIS SIVIERO LTD | D19: 13 | E19: 3812.25 | F19: 3812.25 | G19: 0
A20: 45323 | B20: 2024-02 | C20: SIVIERO EMPREENDIMENTOS IMOBILIARIOS LTD | D20: 140 | E20: 295923.8 | F20: 295923.8 | G20: 0 | H20: Periodo impresso 01/02/2024 - 29/02/2024 confere com a tag 2024-02; emissao 28/03/2024; 4 paginas; 3 secoes (SIVIERO EMPREENDIMENTOS, TRANSPORTADORA IRMAOS SIVIERO, ABASTECEDORA).; Observacoes cortadas na margem direita do scan: mantido o texto visivel; letra parcialmente cortada na borda mantida quando reconhecivel.; Fornecedor encostado na data de Venc.: gravado 'LTI' para meia-letra D (D KEKOS p2, PROMED p4, SAO JOAO p4), como na referencia 2023-07; 'CONSORCIOS L', 'DE IMOV', 'TOPOGRAFI', 'LTDA.' gravados como visiveis.; L.R. BETT PAVIMENTACOES (p1): Venc. impresso 13/07/23 com Pgto. 14/02/24, mesmo valor e obs (P. 07/10) que a linha L.R. BETT de 21/02/24 na p2 - mantido como impresso.; Venc. posterior ao Pgto. impresso em OFICINA MECANICA VACCARI (p1, 02/02/24 x 01/02/24) e MARANGONI (p3, 02/02/24 x 01/02/24) - mantido.; Erros de digitacao do proprio relatorio mantidos: 'EMPRREND.', 'EMPREEEND.', 'EMPREED.', 'PROGAMA', 'MAMOMETRO', 'REREAPROVACAO', 'ELETRECISTA', 'FRANCELICIOC'.; RADAX DO BRASIL (p4): Valor NF 3.582,13 com Valor Dupl. 358,00 (P. 10/10); RGE (p4) 0,01; BANCO SICREDI (p1) 0,17 - conferidos com zoom, impressos assim.
A21: 45323 | B21: 2024-02 | C21: TRANSPORTADORA IRMAOS SIVIERO LTDA. | D21: 58 | E21: 158589.35 | F21: 158589.35 | G21: 0
A22: 45323 | B22: 2024-02 | C22: ABASTECEDORA DE COMBUSTIVEIS SIVIERO LTD | D22: 13 | E22: 5319.73 | F22: 5319.73 | G22: 0
A23: 45352 | B23: 2024-03 | C23: SIVIERO EMPREENDIMENTOS IMOBILIARIOS LTD | D23: 177 | E23: 674950.76 | F23: 674950.76 | G23: 0 | H23: Periodo impresso 01/03/2024 - 31/03/2024 confere com a tag 2024-03; emissao 17/05/2024; 5 paginas; 3 secoes (SIVIERO EMPREENDIMENTOS, TRANSPORTADORA IRMAOS SIVIERO, ABASTECEDORA). Pagina 5 (metade inferior) contem apenas o Total.; Observacoes cortadas na margem direita do scan: mantido o texto visivel; meia-letra na borda gravada conforme a forma visivel/reconhecivel (ex.: 'COMPRA A', 'CALCADA', 'FEVEREIRO/202', 'ARQUIVO', 'ESPACO SO', 'ESPACO SOC', 'AREA CAMP', 'GESSO ESP', 'VERANOPOLIS OU'); quando so aparece um traco vertical foi gravado 'I' (ex.: 'ARBORIZACAO UI', 'CAMIONETI', 'LOTEAMENTO I', 'RETROESCAVAI', 'TANQUI', 'FEVEREIRO DI').; Fornecedor encostado na data de Venc.: 'OPERADOR NACIONAL DO REGISTRO-MATRICU' (p1 e p4, meia-letra lida como U, mesma convencao de 2023-07); 'RAMPA DE LAVAGEM VALVERDE - VERANOPOL' (p3, L meio visivel).; Linhas com impressao achatada/cortada na base mas legiveis (conferidas com zoom): INST. ELETRICA LIDER LTDA. (p1), SAO LUIZ CONSTRUCOES E SERVICOS LTDA. x2 (p3), COMABE AUTOMACAO ... 18/03/24 (p4).; Venc. anterior ao mes mantido como impresso: INST. ELETRICA LIDER (p1) venc 10/02/24; ROVILIO ANTONIO DAL MAS (p1) venc 27/02/24; L.R. BETT PAVIMENTACOES (p3) venc 13/10/23; SAO LUIZ CONSTRUCOES x2 (p3) venc 27/11/23.; Erros/grafias do proprio relatorio mantidos: 'EMPRREND.' (PIS p3), 'EMPREEEND.', 'LEMPEZA', 'PROGAMA', 'PINHERIOS', 'QADRA', 'PLAHET', 'VIVIERO NPR', 'NPQ 0I67', 'IYJ 8I14', 'MATRICULA ATUALIZADA 28. 118 ......... ???' (p2, impresso assim).; Valor NF x Valor Dupl. atipicos conferidos com zoom e impressos assim: SUPER PNEUS (p2) NF 4.900,00 / Dupl 1.634,00 (P.01/03); CARBONERA (p3) NF 4.057,28 / Dupl 1.012,28 (P.4/4); EDIR DAL SASSO (p2) duas linhas NF 1.300,00 com Dupl 1.050,00 e 250,00; LUBIA CORSO (p1) duas linhas P.2/2 NF 7.800,00 com Dupl 3.100,00 e 800,00; SAO LUIZ (p3) NF 18.500,00 com Dupl 6.000,00 e 1.500,00; SANDRA MARIA MORO NF 8.200,00 com Dupl 4.200,00 (p2) e 4.000,00 (p3).
A24: 45352 | B24: 2024-03 | C24: TRANSPORTADORA IRMAOS SIVIERO LTDA. | D24: 47 | E24: 148559.03 | F24: 148559.03 | G24: 0
A25: 45352 | B25: 2024-03 | C25: ABASTECEDORA DE COMBUSTIVEIS SIVIERO LTD | D25: 13 | E25: 5867.78 | F25: 5867.78 | G25: 0
A26: 45383 | B26: 2024-04 | C26: SIVIERO EMPREENDIMENTOS IMOBILIARIOS LTD | D26: 192 | E26: 881710.15 | F26: 881710.16 | G26: -0.01 | H26: Diferenca de -0,01 no subtotal SIVIERO EMPREENDIMENTOS confirmada no proprio relatorio (releitura independente das 192 linhas): AZUL COMPANHIA DE SEGUROS GERAIS (p3) imprime 1.500,17 como parcela P.4/4 de NF 6.000,72 (6.000,72/4 = 1.500,18); o sistema provavelmente somou 1.500,18 no subtotal. Mantido o valor impresso.; Periodo impresso 01/04/2024 - 30/04/2024 confere com a tag 2024-04; emissao 22/05/2024; 5 paginas; 3 secoes (SIVIERO EMPREENDIMENTOS, TRANSPORTADORA IRMAOS SIVIERO, ABASTECEDORA).; SIVIERO EMPREENDIMENTOS: soma das 192 linhas = 881.710,15, subtotal impresso = 881.710,16 (diferenca de 0,01 nao reconciliada). Todos os Valor Dupl. da secao foram relidos com zoom (2,5x-4x) e conferem com o impresso; parcelas nao exatas (ex.: SUL TURBOS 766,66 = 2.300,00/3; DELL 291,35; SUHAI 479,42; RADAX 781,09) sugerem arredondamento de centavos interno do sistema. Nenhum valor foi ajustado. As outras duas secoes e o Total (881.710,16 + 168.891,18 + 7.283,77 = 1.057.885,11) conferem.; Observacoes cortadas na margem direita do scan: mantido o texto visivel; letra parcialmente cortada mantida quando reconhecivel (ex.: 'BARBIERO' p1, 'MOTONIVELADORA' p2, 'EQUIPAMENT' p2, 'HIDRAUL' p2). Meia-letra irreconhecivel omitida: 'LISA-NA' (p2 FEPAM), 'MANGUEIRA' (p2 CAVEMAQ 188,20), 'ESCAVADEIRA - O' (p3 D KEKOS 822,25), 'DAS EMP' (p4 DIGITAL WAY 50,00), 'MARC' (p5 PRESSA), 'IKR 2' (p5 INSPESUL), 'MARCO DE 20' (p5 MERCATO/ABASTECEDORA).; Fornecedor encostado na data de Venc.: meia-letra final gravada como 'LTI' (D KEKOS p2/p3, SAO JOAO p4, PROMED p4), seguindo a convencao do mes de referencia; 'CONSORCIOS L', 'LTD' (CAVEMAQ), 'NOVA PRA', 'VALVER', 'VERANOPO', 'REGIONAL LTDA' como impressos.; Datas fora do padrao mantidas como impressas: PEDRO SIVIERO venc 30/11/23 (p2 e p3) e 28/12/23 (p3); HOTEL ARACA LTDA venc 28/04/24 com pgto 24/04/24 (p3); RAUL SIVIERO venc 28/04/24 e IRINEU SIVIERO venc 25/04/24 com pgto 24/04/24 (p3).; Erros de digitacao do proprio relatorio mantidos: 'EMPREEEND.', 'EMPRREND.' (PIS p3), 'PROGAMA', 'D0S' (zero, p3 MARCIO FRESCHI), 'RETICIACAO', 'TONNER', 'VIVIERO NPR'.; BANCO ESTADO RIO GRANDE DO SUL - SEI 25/04/24 232,26 aparece na ultima linha da p3 e na primeira da p4: sao linhas distintas no impresso (cada uma em sua pagina), ambas transcritas.; Valores pequenos conferidos com zoom: BANCO SICREDI 0,16 (p1) e RGE 0,01 (p5).
A27: 45383 | B27: 2024-04 | C27: TRANSPORTADORA IRMAOS SIVIERO LTDA. | D27: 55 | E27: 168891.18 | F27: 168891.18 | G27: 0
A28: 45383 | B28: 2024-04 | C28: ABASTECEDORA DE COMBUSTIVEIS SIVIERO LTD | D28: 14 | E28: 7283.77 | F28: 7283.77 | G28: 0
A29: 45413 | B29: 2024-05 | C29: SIVIERO EMPREENDIMENTOS IMOBILIARIOS LTD | D29: 187 | E29: 824089.36 | F29: 824089.36 | G29: 0 | H29: Periodo impresso 01/05/2024 - 31/05/2024 confere com a tag 2024-05; emissao 18/07/2024; 5 paginas; 3 secoes (SIVIERO EMPREENDIMENTOS, TRANSPORTADORA IRMAOS SIVIERO, ABASTECEDORA).; MARIA TEREZA FILIPPIN DAL PONTE/FAMIL (p3, 2 linhas): Valor NF impresso '1.010.000,0' - o numero excede a largura da coluna e o ultimo digito nao foi impresso (conferido com zoom). Mantido como impresso; o validador acusa formato nesses 2 campos. Valor Dupl. (70.000,00 e 8.750,74) legivel e conferido.; MARIA TEREZA FILIPPIN DAL PONTE/FAMIL (p3): segunda linha com Venc. 10/06/24 e Pgto. 20/05/24 - mantido como impresso.; CONNECT SISTEMAS LTDA. - NICOLAS SART (p4): Venc. impresso 12/09/24 com Pgto. 28/05/24 - mantido como impresso.; ABASTECEDORA (p5): BANCO ESTADO RIO GRANDE DO SUL - ABA 09/05/24 127,79 aparece duas vezes (ultima linha de p5_a e primeira de p5_b); conferido na emenda das metades: sao duas linhas distintas, e o subtotal 7.726,51 so fecha com as duas.; Observacoes cortadas na margem direita do scan: mantido o texto visivel; letra parcialmente cortada mantida quando reconhecivel (ex.: 'TOYOTAIWB 5G54', 'LTDA', 'CAMPO', 'PAVILHAO', 'ENCHEN', 'TIS/SEI/A', 'PEDRO SIVIERO', 'ESCAVA', 'LOT COL', 'PARTIDA', 'PECA', 'MOTONIVELADO', '- ES'); tracos nao reconheciveis na borda foram omitidos (ex.: apos 'LOTEAMENTO SOLAR', 'AUTENTICACOES', 'CASA FUNCIONARIOS PASSO').; Fornecedor encostado na data de Venc. (37o caractere pela metade), seguindo a convencao de 2023-07: 'LTI' (D KEKOS), 'MATRICU' (OPERADOR NACIONAL DO REGISTRO), 'ELETRICO' (ENERTEC). RODOBENS ADMINISTRADORA CONSORCIOS L: o 'L' aparece inteiro, encostado na data.; Erros de digitacao/grafias do proprio relatorio mantidos: 'PROGAMA', 'EMPREEEND.', 'EMPRREND.', 'TACOGROFOS', 'MOTOSSERA', 'TONNER', 'MAUSES', 'VIVIERO NPR', 'O1 PLACA', '2024-O1 AREA' (letra O no lugar de zero), 'MORADA D0S' (zero no lugar de O, conferido com zoom).
A30: 45413 | B30: 2024-05 | C30: TRANSPORTADORA IRMAOS SIVIERO LTDA. | D30: 50 | E30: 148233.29 | F30: 148233.29 | G30: 0
A31: 45413 | B31: 2024-05 | C31: ABASTECEDORA DE COMBUSTIVEIS SIVIERO LTD | D31: 16 | E31: 7726.51 | F31: 7726.51 | G31: 0
A32: 45444 | B32: 2024-06 | C32: SIVIERO EMPREENDIMENTOS IMOBILIARIOS LTD | D32: 167 | E32: 472050.79 | F32: 472050.79 | G32: 0 | H32: Periodo impresso 01/06/2024 - 30/06/2024 confere com a tag 2024-06; emissao 18/07/2024; 5 paginas (p5 sem linhas da TRANSPORTADORA: so o Subtotal dela no topo); 3 secoes (SIVIERO EMPREENDIMENTOS, TRANSPORTADORA IRMAOS SIVIERO, ABASTECEDORA).; MARIA TEREZA FILIPPIN DAL PONTE/FAMIL (p1): Valor NF impresso '1.010.000,0' (coluna estreita cortou o ultimo digito decimal) - mantido exatamente como impresso; nao completado para ',00'. Unico campo fora do formato 1.234,56 do validador.; Observacoes cortadas na margem direita do scan (campo de 45 caracteres): mantido o texto visivel; letra parcialmente cortada mantida quando reconhecivel (ex.: 'CACAMBAS', 'F.CUNHA', 'DESMEMBRAMENTO A', 'RETIFICACAO A', 'SALVADOR / S', 'KLEITON CANSAN - PF', 'OFICINA=VE', 'PASQUAL-RE', 'PARTIDA', 'ESCA'). Fragmento irreconhecivel omitido em: 'LAVAGEM MOTOR -' (p1), 'ANTONIO PRADO/FLORES' (p2 e p3), 'AUTENTICACOES' (p3), 'HIDRAULICA NO' (p3).; Fornecedor encostado na data de Venc.: meia-letra gravada como 'MATRICU' (OPERADOR NACIONAL DO REGISTRO, p1), 'SERVICOS' (ROBSON DAMMER, p2) e 'LTI' para a metade de um D (D KEKOS, p2), seguindo a convencao de 2023-07.; ROBSON DAMMER - PRESTADOR DE SERVICOS (p2): Venc. 14/06/24 posterior ao Pgto. 13/06/24 - mantido como impresso. IVO JOSE FRAINER (p1): Venc. 25/05/24 com Pgto. 05/06/24 - impresso assim.; Letra O no lugar do zero mantida como impressa: 'O1 AREA' (NOVA PRATA, p2) e 'O2 LOTES' (DESPESAS DIVERSAS, p2).; Erros de digitacao do proprio relatorio mantidos: 'EMPRREND.', 'EMPREEEND.', 'PROGAMA', 'MOTOSSERA', 'TONNER', 'CONEXAO', 'FERRAMENTAIS'.; I.C.M.S. - IMPOSTO ESTADUAL (p4): linha impressa mais clara/fina que as demais, mas legivel (115,93 / 115,93).
A33: 45444 | B33: 2024-06 | C33: TRANSPORTADORA IRMAOS SIVIERO LTDA. | D33: 52 | E33: 142941.11 | F33: 142941.11 | G33: 0
A34: 45444 | B34: 2024-06 | C34: ABASTECEDORA DE COMBUSTIVEIS SIVIERO LTD | D34: 13 | E34: 5867.77 | F34: 5867.77 | G34: 0
A35: 45474 | B35: 2024-07 | C35: SIVIERO EMPREENDIMENTOS IMOBILIARIOS LTD | D35: 192 | E35: 425155.67 | F35: 425155.67 | G35: 0 | H35: Periodo impresso 01/07/2024 - 31/07/2024 confere com a tag 2024-07; emissao 19/11/2024; 6 paginas (a pagina 6 contem apenas o Total : 605.892,81 e uma rubrica manuscrita); 3 secoes (SIVIERO EMPREENDIMENTOS, TRANSPORTADORA IRMAOS SIVIERO, ABASTECEDORA).; MARIA TEREZA FILIPPIN DAL PONTE/FAMIL (p2, Venc. 10/07/24): Valor NF impresso '1.010.000,0' - o valor nao cabe na coluna e o ultimo digito dos centavos foi cortado pela propria impressao (conferido com zoom). Mantido exatamente como impresso; nao segue o formato 1.234,56 e por isso o validador acusa erro de formato nesta celula. Valor Dupl. 13.800,00 legivel e normal.; Observacoes cortadas na margem direita do scan: mantido o texto visivel. Meia-letra na borda: gravada como a letra quando reconhecivel pelo formato+contexto (=VE, CONTRAT, CAMPEST, VENDA LO, GEOLOG, MERCADO, RETRO, ESCA, INDENIZAC, SEI/A, JUNHO); gravada como 'I' quando so aparece uma haste vertical, seguindo a convencao de 'LTI' (FLORES I, COMPRADOI, PAGTO COI, SERVI, COMBUSTIVEI).; Fornecedor encostado na data de Venc.: 'D KEKOS COM MANGUEIRAS E CONEXOES LTI' (p1) e 'PROMED CONSULT ASSES SEG TRABALHO LTI' (p2 e p4) gravados como 'LTI' (meia-letra D), mesma convencao do mes de referencia; 'EQUIPAMENTOS ESCRITORIO REGIONAL LTDA', 'SEUBONE ... PERSONALIZ', 'ALEXANDRA ... IMOV', 'RODOBENS ... L' e 'CVC ... NOVA PRA' encostam na data mas com ultima letra legivel.; Duas linhas impressas em fonte diferente (menor, espacada): LUIS CARLOS MERCALI (p2) e CLAUDIO LUCIANO RISSI - NOVA PRATA (p3); transcritas normalmente.; SANDRA MARIA MORO (p3): Venc. impresso 26/07/24 com Pgto. 25/07/24 (vencimento posterior ao pagamento) - mantido como impresso. Varias linhas tem Venc. em 30/06/24 com Pgto. em 01/07/24 (SIM REDE DE POSTOS, p1 e p4) - normal.; COOPERATIVA SANTA CLARA (p5, P.01/02): obs impressa 'RAUL SIVIER0' com o algarismo zero no lugar da letra O (glifo mais estreito, conferido com zoom) - mantido. 'O1', 'O2', 'O3' nas observacoes (ex.: 'O3 LOTES', 'O1 ALMOCO', 'O2 JANTAS', '2024-O1 AREA') gravados com a letra O, como aparentam no impresso.; Erros de digitacao do proprio relatorio mantidos: 'EMPRREND.' (PIS p3), 'EMPREEEND.' (obs p3/p4), 'PRESTRADOS', 'DESPEAS', 'CILINDO', 'TONNER', 'PARC,' (Antonio Prado p4), 'LUIZ,A BATTISTELLA' (p4; nas linhas da p5 aparece 'LUIZ A').; Valor NF bem diferente de Valor Dupl. x parcelas, impresso assim e conferido com zoom: PARANA EQUIPAMENTOS S/A (p3) NF 887.000,00 com obs 'R$ 377.000,00'; LINDOLFO LAGO MACHADO DE SOUZA (p3) NF 350.000,00 Dupl. 10.000,00 (PARC.10/10); INES ANSOLIN PESSUTTO (p3) NF 714.000,00 Dupl. 10.000,00; CVC CONSTRUCOES (p2) NF 54.000,00 Dupl. 13.000,00 (PARC. 04/04); CONCRESUL (p1) NF 2.475,00 Dupl. 1.188,00 (P.1/3), duas vezes (04/07 e 07/07).
A36: 45474 | B36: 2024-07 | C36: TRANSPORTADORA IRMAOS SIVIERO LTDA. | D36: 66 | E36: 175646.25 | F36: 175646.25 | G36: 0
A37: 45474 | B37: 2024-07 | C37: ABASTECEDORA DE COMBUSTIVEIS SIVIERO LTD | D37: 13 | E37: 5090.89 | F37: 5090.89 | G37: 0
A38: 45505 | B38: 2024-08 | C38: SIVIERO EMPREENDIMENTOS IMOBILIARIOS LTD | D38: 188 | E38: 539462.61 | F38: 539462.61 | G38: 0 | H38: Periodo impresso 01/08/2024 - 31/08/2024 confere com a tag 2024-08; emissao 19/11/2024; 5 paginas; 3 secoes (SIVIERO EMPREENDIMENTOS p1-p4, TRANSPORTADORA IRMAOS SIVIERO p4-p5, ABASTECEDORA p5).; MARIA TEREZA FILIPPIN DAL PONTE/FAMIL (p2, venc 10/08/24): Valor NF impresso '1.010.000,0' - o ultimo digito dos centavos foi cortado pela largura da coluna no proprio relatorio; mantido como impresso (conferido com zoom). Valor Dupl. 13.800,00 legivel.; VANTAGGIO CORRETORA DE SEGUROS LTDA. (p2): Valor NF 4.554,00 com Valor Dupl. 1.554,00 (P.1/3) - conferido com zoom, impresso assim.; INSS e ISSQN (p2, N.F. 09) e IRPJ (p3): Venc. 20/08/24 com Pgto. 16/08/24 (pagamento antes do vencimento) - mantido como impresso.; Fornecedor encostado na data de Venc.: meia-letra gravada como 'I' quando era so um traco vertical ('AFIF GHANNAM GUIMARAES-COMISSÃO-PAROI' p1; 'PROMED CONSULT ASSES SEG TRABALHO LTI' p5, mesma convencao de 2023-07).; Observacoes cortadas na margem direita do scan: mantido o texto visivel; letra parcialmente cortada mantida quando reconhecivel (ex.: '=VE', 'VAGNE', 'ELENIC', 'TRABALH', 'PROJET', 'RETRO', 'LOTES', 'SIVIERO', '8D09') e omitida quando era so um traco irreconhecivel (ex.: 'HIDRAU', 'JOAO C', 'LOTE SEL', '5G54-', 'CONDOMINIO M', 'CERC', 'DRAGA', 'MECA', 'AUTENTICACOES', 'JULHO DE 202').; Acentos impressos mantidos: 'VERANÓPOLIS', 'INFORMÁTICA', 'COMISSÃO', 'PAVILHÃO', 'QUÍMICA', 'IPÊS', 'M²', '2ª'.; Erros de digitacao do proprio relatorio mantidos: 'REGULARIZAZAO', 'EMPREED.', 'EMPREEEND.', 'EMPRREND.', 'COORETOR', 'MOTOSSERA STHIL', 'CAIXA2', 'TONNER', 'PARC, 02/03', 'SIVIER0' (zero no lugar de O, p4 COOPERATIVA SANTA CLARA), 'MAO-DE-0BRA' (zero, p3 FAGANELLO), 'O1' (letra O no lugar de zero em O1 TRENA / O1 BOTINA / O1 BUJAO / 2024-O1 AREA).; Linhas com fonte menor/diferente no scan (DESPESAS DIVERSAS p1 e p2, BANCO ESTADO ... 216,03 p3, ADYL NET p4) - legiveis, transcritas normalmente.; p5: rubrica manuscrita sobre a area do Subtotal/Total da ABASTECEDORA; nao encobre valores.
A39: 45505 | B39: 2024-08 | C39: TRANSPORTADORA IRMAOS SIVIERO LTDA. | D39: 59 | E39: 194956.31 | F39: 194956.31 | G39: 0
A40: 45505 | B40: 2024-08 | C40: ABASTECEDORA DE COMBUSTIVEIS SIVIERO LTD | D40: 12 | E40: 4933.15 | F40: 4933.15 | G40: 0
...

Sheet 2023-07
A1: Mês | B1: Página | C1: Empresa | D1: Fornecedor | E1: Vencimento | F1: Pagamento | G1: Valor NF | H1: Valor Dupl. | I1: Observações
A2: 45108 | B2: 1 | C2: SIVIERO EMPREENDIMENTOS IMOBILIARIOS LTD | D2: DORVAL FRANCISCO BOFF - CAXIAS DO SUL | E2: 45110 | F2: 45110 | G2: 100000 | H2: 10000 | I2: P.04/10-CFE CONTRATO ANTECIPACAO VALORES - LO
A3: 45108 | B3: 1 | C3: SIVIERO EMPREENDIMENTOS IMOBILIARIOS LTD | D3: PROGETEC - ALENCAR TRINDADE - P.FUNDO | E3: 45110 | F3: 45110 | G3: 25000 | H3: 5000 | I3: P.3/5-INSTALACAO D+ HASTES CERCA ELETRICA+INS
A4: 45108 | B4: 1 | C4: SIVIERO EMPREENDIMENTOS IMOBILIARIOS LTD | D4: PREFEITURA MUNICIPAL DE NOVA PRATA | E4: 45110 | F4: 45110 | G4: 36.96 | H4: 36.96 | I4: CERTIDAO DE LOCALIZAÇAO AREA-BELLA VISIONE-NO
A5: 45108 | B5: 1 | C5: SIVIERO EMPREENDIMENTOS IMOBILIARIOS LTD | D5: SIM REDE DE POSTOS LTDA. - VERANOPOLI | E5: 45109 | F5: 45110 | G5: 521.89 | H5: 521.89 | I5: ABASTECIMENTOS CARROS+CACAMBAS+OFICINA=VER
A6: 45108 | B6: 1 | C6: SIVIERO EMPREENDIMENTOS IMOBILIARIOS LTD | D6: INES TREVISAN PICCOLI - JUROS | E6: 45108 | F6: 45110 | G6: 250000 | H6: 2500 | I6: JUROS 1.00% S/ R$ 250.000,00 - EMPRESTIMO
A7: 45108 | B7: 1 | C7: SIVIERO EMPREENDIMENTOS IMOBILIARIOS LTD | D7: ANDRE LUIZ SIVIERO - JUROS | E7: 45108 | F7: 45110 | G7: 100000 | H7: 800 | I7: JUROS 0,80% S/ R$ 100.000,00 - EMPRESTIMO
A8: 45108 | B8: 1 | C8: SIVIERO EMPREENDIMENTOS IMOBILIARIOS LTD | D8: SAMIR TREVISAN PICCOLI - JUROS | E8: 45108 | F8: 45110 | G8: 350000 | H8: 3500 | I8: JUROS 1.00% S/ R$ 350.000,00 - EMPRESTIMO
A9: 45108 | B9: 1 | C9: SIVIERO EMPREENDIMENTOS IMOBILIARIOS LTD | D9: SAMIR TREVISAN PICCOLI - JUROS | E9: 45108 | F9: 45110 | G9: 150000 | H9: 1500 | I9: JUROS 1.00% S/ R$ 150.000,00 - EMPRESTIMO
A10: 45108 | B10: 1 | C10: SIVIERO EMPREENDIMENTOS IMOBILIARIOS LTD | D10: SAMIR TREVISAN PICCOLI - JUROS | E10: 45108 | F10: 45110 | G10: 250000 | H10: 2500 | I10: JUROS 1.00% S/ R$ 250.000,00 - EMPRESTIMO
A11: 45108 | B11: 1 | C11: SIVIERO EMPREENDIMENTOS IMOBILIARIOS LTD | D11: SAMIR TREVISAN PICCOLI - JUROS | E11: 45108 | F11: 45110 | G11: 250000 | H11: 2500 | I11: JUROS 1.00% S/ R$ 250.000,00 - EMPRESTIMO EM
A12: 45108 | B12: 1 | C12: SIVIERO EMPREENDIMENTOS IMOBILIARIOS LTD | D12: BANCO SICREDI - VERANÓPOLIS | E12: 45110 | F12: 45110 | G12: 0.18 | H12: 0.18 | I12: JUROS BANCO CREDITO ROTATIVO MES JUNHO/2023
A13: 45108 | B13: 1 | C13: SIVIERO EMPREENDIMENTOS IMOBILIARIOS LTD | D13: IOF BANCARIO SIVIERO EMP IMOBILIARIOS | E13: 45110 | F13: 45110 | G13: 308.55 | H13: 308.55 | I13: IOF CONTA SEI MES DE JUNHO DE 2023 - BANRISUL
... A261: 45108 | B261: 5 | C261: ABASTECEDORA DE COMBUSTIVEIS SIVIERO LTD | D261: CONT. SOCIAL - ABAST. COMB. SIVIERO L | E261: 45138 | F261: 45138 | G261: 456.71 | H261: 456.71 | I261: FATURAMENTO MES JUNHO/2023 - R$ 15.858,00 X 2
A263: Total | G263: =SUBTOTAL(9,G2:G261) | H263: =SUBTOTAL(9,H2:H261)

Sheet 2023-08
A1: Mês | B1: Página | C1: Empresa | D1: Fornecedor | E1: Vencimento | F1: Pagamento | G1: Valor NF | H1: Valor Dupl. | I1: Observações
A2: 45139 | B2: 1 | C2: SIVIERO EMPREENDIMENTOS IMOBILIARIOS LTD | D2: CORSAN - NOVA PRATA | E2: 45139 | F2: 45139 | G2: 2468.2 | H2: 2468.2 | I2: TAXA APROVACAO REDE AGUA LOT BELLA VISIONE -
A3: 45139 | B3: 1 | C3: SIVIERO EMPREENDIMENTOS IMOBILIARIOS LTD | D3: RS MICRO INFORMÁTICA LTDA. | E3: 45133 | F3: 45139 | G3: 3066 | H3: 1533 | I3: P.01/02-CH 023948-COMPRA 02 IMPRESSORAS (RICO
A4: 45139 | B4: 1 | C4: SIVIERO EMPREENDIMENTOS IMOBILIARIOS LTD | D4: ANDRE LUIZ SIVIERO - JUROS | E4: 45139 | F4: 45139 | G4: 100000 | H4: 800 | I4: JUROS 0,80% S/ R$ 100.000,00 - EMPRESTIMO
A5: 45139 | B5: 1 | C5: SIVIERO EMPREENDIMENTOS IMOBILIARIOS LTD | D5: INES TREVISAN PICCOLI - JUROS | E5: 45139 | F5: 45139 | G5: 250000 | H5: 2500 | I5: JUROS 1.00% S/ R$ 250.000,00 - EMPRESTIMO
A6: 45139 | B6: 1 | C6: SIVIERO EMPREENDIMENTOS IMOBILIARIOS LTD | D6: INES TREVISAN PICCOLI - JUROS | E6: 45139 | F6: 45139 | G6: 100000 | H6: 1000 | I6: JUROS 1.00% S/ R$ 100.000,00 - EMPRESTIMO EM
A7: 45139 | B7: 1 | C7: SIVIERO EMPREENDIMENTOS IMOBILIARIOS LTD | D7: SAMIR TREVISAN PICCOLI - JUROS | E7: 45139 | F7: 45139 | G7: 250000 | H7: 2500 | I7: JUROS 1.00% S/ R$ 250.000,00 - EMPRESTIMO EM
A8: 45139 | B8: 1 | C8: SIVIERO EMPREENDIMENTOS IMOBILIARIOS LTD | D8: SAMIR TREVISAN PICCOLI - JUROS | E8: 45139 | F8: 45139 | G8: 250000 | H8: 2500 | I8: JUROS 1.00% S/ R$ 250.000,00 - EMPRESTIMO
A9: 45139 | B9: 1 | C9: SIVIERO EMPREENDIMENTOS IMOBILIARIOS LTD | D9: SAMIR TREVISAN PICCOLI - JUROS | E9: 45139 | F9: 45139 | G9: 350000 | H9: 3500 | I9: JUROS 1.00% S/ R$ 350.000,00 - EMPRESTIMO
A10: 45139 | B10: 1 | C10: SIVIERO EMPREENDIMENTOS IMOBILIARIOS LTD | D10: SAMIR TREVISAN PICCOLI - JUROS | E10: 45139 | F10: 45139 | G10: 150000 | H10: 1500 | I10: JUROS 1.00% S/ R$ 150.000,00 - EMPRESTIMO
A11: 45139 | B11: 1 | C11: SIVIERO EMPREENDIMENTOS IMOBILIARIOS LTD | D11: TABELIONATO MARCOS - CAXIAS DO SUL | E11: 45139 | F11: 45139 | G11: 421.77 | H11: 421.77 | I11: CUSTAS PENDENTES ESCRITURAS GASPARIN E ZANR
A12: 45139 | B12: 1 | C12: SIVIERO EMPREENDIMENTOS IMOBILIARIOS LTD | D12: DESPESAS DIVERSAS | E12: 45139 | F12: 45139 | G12: 2440 | H12: 2440 | I12: MARCOS A SIVIERO-DESP DIVERSAS CFE NOTAS+COM
A13: 45139 | B13: 1 | C13: SIVIERO EMPREENDIMENTOS IMOBILIARIOS LTD | D13: BANCO SICREDI - VERANÓPOLIS | E13: 45139 | F13: 45139 | G13: 0.17 | H13: 0.17 | I13: JUROS BANCO CREDITO ROTATIVO MES JULHO/2023
... A267: 45139 | B267: 5 | C267: ABASTECEDORA DE COMBUSTIVEIS SIVIERO LTD | D267: CONT. SOCIAL - ABAST. COMB. SIVIERO L | E267: 45169 | F267: 45169 | G267: 456.71 | H267: 456.71 | I267: FATURAMENTO MES JULHO/2023 - R$ 15.858,00 X 2
A269: Total | G269: =SUBTOTAL(9,G2:G267) | H269: =SUBTOTAL(9,H2:H267)

Sheet 2023-10
A1: Mês | B1: Página | C1: Empresa | D1: Fornecedor | E1: Vencimento | F1: Pagamento | G1: Valor NF | H1: Valor Dupl. | I1: Observações
A2: 45200 | B2: 1 | C2: SIVIERO EMPREENDIMENTOS IMOBILIARIOS LTD | D2: SIM REDE DE POSTOS LTDA. - VERANOPOLI | E2: 45200 | F2: 45201 | G2: 859.08 | H2: 859.08 | I2: ABASTECIMENTOS CARROS+CACAMBAS+OFICINA=VER
A3: 45200 | B3: 1 | C3: SIVIERO EMPREENDIMENTOS IMOBILIARIOS LTD | D3: INES TREVISAN PICCOLI - JUROS | E3: 45200 | F3: 45201 | G3: 100000 | H3: 1000 | I3: JUROS 1.00% S/ R$ 100.000,00 - EMPRESTIMO EM
A4: 45200 | B4: 1 | C4: SIVIERO EMPREENDIMENTOS IMOBILIARIOS LTD | D4: INES TREVISAN PICCOLI - JUROS | E4: 45200 | F4: 45201 | G4: 250000 | H4: 2500 | I4: JUROS 1.00% S/ R$ 250.000,00 - EMPRESTIMO
A5: 45200 | B5: 1 | C5: SIVIERO EMPREENDIMENTOS IMOBILIARIOS LTD | D5: ANDRE LUIZ SIVIERO - JUROS | E5: 45200 | F5: 45201 | G5: 100000 | H5: 800 | I5: JUROS 0,80% S/ R$ 100.000,00 - EMPRESTIMO
A6: 45200 | B6: 1 | C6: SIVIERO EMPREENDIMENTOS IMOBILIARIOS LTD | D6: SAMIR TREVISAN PICCOLI - JUROS | E6: 45200 | F6: 45201 | G6: 250000 | H6: 2500 | I6: JUROS 1.00% S/ R$ 250.000,00 - EMPRESTIMO EM
A7: 45200 | B7: 1 | C7: SIVIERO EMPREENDIMENTOS IMOBILIARIOS LTD | D7: SAMIR TREVISAN PICCOLI - JUROS | E7: 45200 | F7: 45201 | G7: 250000 | H7: 2500 | I7: JUROS 1.00% S/ R$ 250.000,00 - EMPRESTIMO
A8: 45200 | B8: 1 | C8: SIVIERO EMPREENDIMENTOS IMOBILIARIOS LTD | D8: SAMIR TREVISAN PICCOLI - JUROS | E8: 45200 | F8: 45201 | G8: 350000 | H8: 3500 | I8: JUROS 1.00% S/ R$ 350.000,00 - EMPRESTIMO
A9: 45200 | B9: 1 | C9: SIVIERO EMPREENDIMENTOS IMOBILIARIOS LTD | D9: SAMIR TREVISAN PICCOLI - JUROS | E9: 45200 | F9: 45201 | G9: 150000 | H9: 1500 | I9: JUROS 1.00% S/ R$ 150.000,00 - EMPRESTIMO
A10: 45200 | B10: 1 | C10: SIVIERO EMPREENDIMENTOS IMOBILIARIOS LTD | D10: PORTAL EMPREENDIMENTOS IMOBILIARIOS L | E10: 45201 | F10: 45201 | G10: 10000 | H10: 4000 | I10: P.1/3-COMISSAO LT 01-QDRA 1748-JARDIM ITALIA-
A11: 45200 | B11: 1 | C11: SIVIERO EMPREENDIMENTOS IMOBILIARIOS LTD | D11: PORTAL EMPREENDIMENTOS IMOBILIARIOS L | E11: 45201 | F11: 45201 | G11: 10000 | H11: 3500 | I11: P.2/3-COMISSAO LT 01-QDRA 1748-JARDIM ITALIA-
A12: 45200 | B12: 1 | C12: SIVIERO EMPREENDIMENTOS IMOBILIARIOS LTD | D12: PORTAL EMPREENDIMENTOS IMOBILIARIOS L | E12: 45201 | F12: 45201 | G12: 10000 | H12: 2500 | I12: P.3/3-COMISSAO LT 01-QDRA 1748-JARDIM ITALIA-
A13: 45200 | B13: 1 | C13: SIVIERO EMPREENDIMENTOS IMOBILIARIOS LTD | D13: BANCO SICREDI - VERANÓPOLIS | E13: 45201 | F13: 45201 | G13: 0.17 | H13: 0.17 | I13: JUROS BANCO CREDITO ROTATIVO MES SETEMBRO/20
... A273: 45200 | B273: 5 | C273: ABASTECEDORA DE COMBUSTIVEIS SIVIERO LTD | D273: CONT. SOCIAL - ABAST. COMB. SIVIERO L | E273: 45230 | F273: 45230 | G273: 456.71 | H273: 456.71 | I273: FATURAMENTO MES SETEMBRO/2023 - R$ 15.858,00
A275: Total | G275: =SUBTOTAL(9,G2:G273) | H275: =SUBTOTAL(9,H2:H273)

Sheet 2023-11
A1: Mês | B1: Página | C1: Empresa | D1: Fornecedor | E1: Vencimento | F1: Pagamento | G1: Valor NF | H1: Valor Dupl. | I1: Observações
A2: 45231 | B2: 1 | C2: SIVIERO EMPREENDIMENTOS IMOBILIARIOS LTD | D2: JDRX NEGOCIOS IMOBILARIOS LTDA.- P.FU | E2: 45231 | F2: 45231 | G2: 11750 | H2: 11750 | I2: COMISSAO VENDA LT 12-QUADRA 04-MORADA IPE-LEA
A3: 45231 | B3: 1 | C3: SIVIERO EMPREENDIMENTOS IMOBILIARIOS LTD | D3: CLAIRTON VENDRAMIN-NOVA PRATA-CHAPEAC | E3: 45231 | F3: 45231 | G3: 2700 | H3: 1350 | I3: PARC. 02/02 - CONSERTOS E CHAPEACAO TOYOTA PR
A4: 45231 | B4: 1 | C4: SIVIERO EMPREENDIMENTOS IMOBILIARIOS LTD | D4: PARANA EQUIPAMENTOS SA | E4: 45231 | F4: 45231 | G4: 1578.37 | H4: 526.12 | I4: P. 01/03 - 02 MANCAL - ESCAVADEIRA ROMPEDOR-O
A5: 45231 | B5: 1 | C5: SIVIERO EMPREENDIMENTOS IMOBILIARIOS LTD | D5: ANDRE LUIZ SIVIERO - JUROS | E5: 45231 | F5: 45231 | G5: 100000 | H5: 800 | I5: JUROS 0,80% S/ R$ 100.000,00 - EMPRESTIMO
A6: 45231 | B6: 1 | C6: SIVIERO EMPREENDIMENTOS IMOBILIARIOS LTD | D6: INES TREVISAN PICCOLI - JUROS | E6: 45231 | F6: 45231 | G6: 100000 | H6: 1000 | I6: JUROS 1.00% S/ R$ 100.000,00 - EMPRESTIMO EM
A7: 45231 | B7: 1 | C7: SIVIERO EMPREENDIMENTOS IMOBILIARIOS LTD | D7: INES TREVISAN PICCOLI - JUROS | E7: 45231 | F7: 45231 | G7: 250000 | H7: 2500 | I7: JUROS 1.00% S/ R$ 250.000,00 - EMPRESTIMO
A8: 45231 | B8: 1 | C8: SIVIERO EMPREENDIMENTOS IMOBILIARIOS LTD | D8: SAMIR TREVISAN PICCOLI - JUROS | E8: 45231 | F8: 45231 | G8: 250000 | H8: 2500 | I8: JUROS 1.00% S/ R$ 250.000,00 - EMPRESTIMO EM
A9: 45231 | B9: 1 | C9: SIVIERO EMPREENDIMENTOS IMOBILIARIOS LTD | D9: SAMIR TREVISAN PICCOLI - JUROS | E9: 45231 | F9: 45231 | G9: 250000 | H9: 2500 | I9: JUROS 1.00% S/ R$ 250.000,00 - EMPRESTIMO EM
A10: 45231 | B10: 1 | C10: SIVIERO EMPREENDIMENTOS IMOBILIARIOS LTD | D10: SAMIR TREVISAN PICCOLI - JUROS | E10: 45231 | F10: 45231 | G10: 350000 | H10: 3500 | I10: JUROS 1.00% S/ R$ 350.000,00 - EMPRESTIMO EM
A11: 45231 | B11: 1 | C11: SIVIERO EMPREENDIMENTOS IMOBILIARIOS LTD | D11: SAMIR TREVISAN PICCOLI - JUROS | E11: 45231 | F11: 45231 | G11: 150000 | H11: 1500 | I11: JUROS 1.00% S/ R$ 150.000,00 - EMPRESTIMO EM
A12: 45231 | B12: 1 | C12: SIVIERO EMPREENDIMENTOS IMOBILIARIOS LTD | D12: BANCO SICREDI - VERANÓPOLIS | E12: 45231 | F12: 45231 | G12: 0.16 | H12: 0.16 | I12: JUROS BANCO CREDITO ROTATIVO MES OUTUBRO/202
A13: 45231 | B13: 1 | C13: SIVIERO EMPREENDIMENTOS IMOBILIARIOS LTD | D13: BANCO SICREDI - VERANÓPOLIS | E13: 45231 | F13: 45231 | G13: 5.9 | H13: 5.9 | I13: TAXA BANCO TED/DOC PESSOA JURIDICA - TRANSFER
... A236: 45231 | B236: 5 | C236: ABASTECEDORA DE COMBUSTIVEIS SIVIERO LTD | D236: CONT. SOCIAL - ABAST. COMB. SIVIERO L | E236: 45260 | F236: 45260 | G236: 456.71 | H236: 456.71 | I236: FATURAMENTO MES OUTUBRO/2023 - R$ 15.858,00 X
A238: Total | G238: =SUBTOTAL(9,G2:G236) | H238: =SUBTOTAL(9,H2:H236)

Sheet 2023-12
A1: Mês | B1: Página | C1: Empresa | D1: Fornecedor | E1: Vencimento | F1: Pagamento | G1: Valor NF | H1: Valor Dupl. | I1: Observações
A2: 45261 | B2: 1 | C2: SIVIERO EMPREENDIMENTOS IMOBILIARIOS LTD | D2: PARANA EQUIPAMENTOS SA | E2: 45261 | F2: 45261 | G2: 1578.37 | H2: 526.12 | I2: P. 02/03 - 02 MANCAL - ESCAVADEIRA ROMPEDOR-O
A3: 45261 | B3: 1 | C3: SIVIERO EMPREENDIMENTOS IMOBILIARIOS LTD | D3: MULTI CELTACAR PECAS SERVICOS LTDA. | E3: 45261 | F3: 45261 | G3: 350 | H3: 350 | I3: BIELETA+BUCHA DIANTEIRA+MAO DE OBRA -IWB 5G54
A4: 45261 | B4: 1 | C4: SIVIERO EMPREENDIMENTOS IMOBILIARIOS LTD | D4: LOCAWEB SERVICOS DE INTERNET SA | E4: 45261 | F4: 45261 | G4: 473.59 | H4: 473.59 | I4: TAXA ANUAL 2023/2024 DO DOMINIO - SIVIEROURBA
A5: 45261 | B5: 1 | C5: SIVIERO EMPREENDIMENTOS IMOBILIARIOS LTD | D5: INES TREVISAN PICCOLI - JUROS | E5: 45261 | F5: 45261 | G5: 250000 | H5: 2500 | I5: JUROS 1.00% S/ R$ 250.000,00 - EMPRESTIMO EM
A6: 45261 | B6: 1 | C6: SIVIERO EMPREENDIMENTOS IMOBILIARIOS LTD | D6: INES TREVISAN PICCOLI - JUROS | E6: 45261 | F6: 45261 | G6: 100000 | H6: 1000 | I6: JUROS 1.00% S/ R$ 100.000,00 - EMPRESTIMO EM
A7: 45261 | B7: 1 | C7: SIVIERO EMPREENDIMENTOS IMOBILIARIOS LTD | D7: SAMIR TREVISAN PICCOLI - JUROS | E7: 45261 | F7: 45261 | G7: 150000 | H7: 1500 | I7: JUROS 1.00% S/ R$ 150.000,00 - EMPRESTIMO EM
A8: 45261 | B8: 1 | C8: SIVIERO EMPREENDIMENTOS IMOBILIARIOS LTD | D8: SAMIR TREVISAN PICCOLI - JUROS | E8: 45261 | F8: 45261 | G8: 350000 | H8: 3500 | I8: JUROS 1.00% S/ R$ 350.000,00 - EMPRESTIMO EM
A9: 45261 | B9: 1 | C9: SIVIERO EMPREENDIMENTOS IMOBILIARIOS LTD | D9: SAMIR TREVISAN PICCOLI - JUROS | E9: 45261 | F9: 45261 | G9: 250000 | H9: 2500 | I9: JUROS 1.00% S/ R$ 250.000,00 - EMPRESTIMO EM
A10: 45261 | B10: 1 | C10: SIVIERO EMPREENDIMENTOS IMOBILIARIOS LTD | D10: SAMIR TREVISAN PICCOLI - JUROS | E10: 45261 | F10: 45261 | G10: 250000 | H10: 2500 | I10: JUROS 1.00% S/ R$ 250.000,00 - EMPRESTIMO EM
A11: 45261 | B11: 1 | C11: SIVIERO EMPREENDIMENTOS IMOBILIARIOS LTD | D11: TORNEARIA RD LTDA | E11: 45261 | F11: 45261 | G11: 150 | H11: 150 | I11: SERVICOS TORNO E SOLDAS EM GERAL - RETRO - OF
A12: 45261 | B12: 1 | C12: SIVIERO EMPREENDIMENTOS IMOBILIARIOS LTD | D12: SOLLARE EMP IMOB LTDA. - NATAL LACERD | E12: 45261 | F12: 45261 | G12: 15000 | H12: 15000 | I12: COMISSAO AREA CONGREGACAO SAO CARLOS - PASS
A13: 45261 | B13: 1 | C13: SIVIERO EMPREENDIMENTOS IMOBILIARIOS LTD | D13: DESPESAS DIVERSAS | E13: 45261 | F13: 45261 | G13: 500 | H13: 500 | I13: JUAREZ ROCHA-SERV REPOSICAO CALCAMENTO+COR
... A278: 45261 | B278: 6 | C278: ABASTECEDORA DE COMBUSTIVEIS SIVIERO LTD | D278: CONT. SOCIAL - ABAST. COMB. SIVIERO L | E278: 45288 | F278: 45288 | G278: 456.71 | H278: 456.71 | I278: FATURAMENTO MES NOVEMBRO/2023 - R$ 15.858,00
A280: Total | G280: =SUBTOTAL(9,G2:G278) | H280: =SUBTOTAL(9,H2:H278)

Sheet 2024-01
A1: Mês | B1: Página | C1: Empresa | D1: Fornecedor | E1: Vencimento | F1: Pagamento | G1: Valor NF | H1: Valor Dupl. | I1: Observações
A2: 45292 | B2: 1 | C2: SIVIERO EMPREENDIMENTOS IMOBILIARIOS LTD | D2: INES TREVISAN PICCOLI - JUROS | E2: 45292 | F2: 45293 | G2: 250000 | H2: 2500 | I2: JUROS 1.00% S/ R$ 250.000,00 - EMPRESTIMO EM
A3: 45292 | B3: 1 | C3: SIVIERO EMPREENDIMENTOS IMOBILIARIOS LTD | D3: INES TREVISAN PICCOLI - JUROS | E3: 45292 | F3: 45293 | G3: 100000 | H3: 1000 | I3: JUROS 1.00% S/ R$ 100.000,00 - EMPRESTIMO EM
A4: 45292 | B4: 1 | C4: SIVIERO EMPREENDIMENTOS IMOBILIARIOS LTD | D4: SAMIR TREVISAN PICCOLI - JUROS | E4: 45292 | F4: 45293 | G4: 150000 | H4: 1500 | I4: JUROS 1.00% S/ R$ 150.000,00 - EMPRESTIMO EM
A5: 45292 | B5: 1 | C5: SIVIERO EMPREENDIMENTOS IMOBILIARIOS LTD | D5: SAMIR TREVISAN PICCOLI - JUROS | E5: 45292 | F5: 45293 | G5: 350000 | H5: 3500 | I5: JUROS 1.00% S/ R$ 350.000,00 - EMPRESTIMO EM
A6: 45292 | B6: 1 | C6: SIVIERO EMPREENDIMENTOS IMOBILIARIOS LTD | D6: SAMIR TREVISAN PICCOLI - JUROS | E6: 45292 | F6: 45293 | G6: 250000 | H6: 2500 | I6: JUROS 1.00% S/ R$ 250.000,00 - EMPRESTIMO EM
A7: 45292 | B7: 1 | C7: SIVIERO EMPREENDIMENTOS IMOBILIARIOS LTD | D7: SAMIR TREVISAN PICCOLI - JUROS | E7: 45292 | F7: 45293 | G7: 250000 | H7: 2500 | I7: JUROS 1.00% S/ R$ 250.000,00 - EMPRESTIMO EM
A8: 45292 | B8: 1 | C8: SIVIERO EMPREENDIMENTOS IMOBILIARIOS LTD | D8: MULTAS DE TRANSITO | E8: 45293 | F8: 45293 | G8: 104.12 | H8: 104.12 | I8: TOYOTA IZR 2E40-SEM LUZ NEBLINA ACESSA- CARLO
A9: 45292 | B9: 1 | C9: SIVIERO EMPREENDIMENTOS IMOBILIARIOS LTD | D9: MULTAS DE TRANSITO | E9: 45293 | F9: 45293 | G9: 78.09 | H9: 78.09 | I9: TOYOTA-ELCIO SIVIERO-IWB 8F46-EXCESSO VELOC.
A10: 45292 | B10: 1 | C10: SIVIERO EMPREENDIMENTOS IMOBILIARIOS LTD | D10: BANCO SICREDI - VERANÓPOLIS | E10: 45293 | F10: 45293 | G10: 0.18 | H10: 0.18 | I10: JUROS BANCO CREDITO ROTATIVO MES DEZEMBRO/20
A11: 45292 | B11: 1 | C11: SIVIERO EMPREENDIMENTOS IMOBILIARIOS LTD | D11: DORVAL FRANCISCO BOFF - CAXIAS DO SUL | E11: 45294 | F11: 45294 | G11: 100000 | H11: 5000 | I11: P.10/10-CFE CONTRATO ANTECIPACAO VALORES - LO
A12: 45292 | B12: 1 | C12: SIVIERO EMPREENDIMENTOS IMOBILIARIOS LTD | D12: AZUL COMPANHIA DE SEGUROS GERAIS | E12: 45294 | F12: 45294 | G12: 5399.23 | H12: 1349.8 | I12: P.03/04 - SEGURO TOYOTA HILUX CINZA NCD 3J24
A13: 45292 | B13: 1 | C13: SIVIERO EMPREENDIMENTOS IMOBILIARIOS LTD | D13: SUL TURBOS TRANSP. E IMPORT. LTDA. | E13: 45294 | F13: 45294 | G13: 2500 | H13: 833.33 | I13: P. 2/3 - TURBO - RETROESCAVADEIRA
... A235: 45292 | B235: 5 | C235: ABASTECEDORA DE COMBUSTIVEIS SIVIERO LTD | D235: CONT. SOCIAL - ABAST. COMB. SIVIERO L | E235: 45322 | F235: 45322 | G235: 456.71 | H235: 456.71 | I235: FATURAMENTO MES DEZEMBRO/2023 - R$ 15.858,00
A237: Total | G237: =SUBTOTAL(9,G2:G235) | H237: =SUBTOTAL(9,H2:H235)

Sheet 2024-02
A1: Mês | B1: Página | C1: Empresa | D1: Fornecedor | E1: Vencimento | F1: Pagamento | G1: Valor NF | H1: Valor Dupl. | I1: Observações
A2: 45323 | B2: 1 | C2: SIVIERO EMPREENDIMENTOS IMOBILIARIOS LTD | D2: OFICINA MECANICA VACCARI LTDA. - CAXI | E2: 45324 | F2: 45323 | G2: 1055 | H2: 527.5 | I2: SENSOR+OLEO DIFERENCIAL+SERVICOS=FORD RAN
A3: 45323 | B3: 1 | C3: SIVIERO EMPREENDIMENTOS IMOBILIARIOS LTD | D3: INES TREVISAN PICCOLI - JUROS | E3: 45323 | F3: 45323 | G3: 100000 | H3: 1000 | I3: JUROS 1.00% S/ R$ 100.000,00 - EMPRESTIMO EM
A4: 45323 | B4: 1 | C4: SIVIERO EMPREENDIMENTOS IMOBILIARIOS LTD | D4: INES TREVISAN PICCOLI - JUROS | E4: 45323 | F4: 45323 | G4: 250000 | H4: 2500 | I4: JUROS 1.00% S/ R$ 250.000,00 - EMPRESTIMO EM
A5: 45323 | B5: 1 | C5: SIVIERO EMPREENDIMENTOS IMOBILIARIOS LTD | D5: SAMIR TREVISAN PICCOLI - JUROS | E5: 45323 | F5: 45323 | G5: 250000 | H5: 2500 | I5: JUROS 1.00% S/ R$ 250.000,00 - EMPRESTIMO EM
A6: 45323 | B6: 1 | C6: SIVIERO EMPREENDIMENTOS IMOBILIARIOS LTD | D6: SAMIR TREVISAN PICCOLI - JUROS | E6: 45323 | F6: 45323 | G6: 250000 | H6: 2500 | I6: JUROS 1.00% S/ R$ 250.000,00 - EMPRESTIMO EM
A7: 45323 | B7: 1 | C7: SIVIERO EMPREENDIMENTOS IMOBILIARIOS LTD | D7: SAMIR TREVISAN PICCOLI - JUROS | E7: 45323 | F7: 45323 | G7: 350000 | H7: 3500 | I7: JUROS 1.00% S/ R$ 350.000,00 - EMPRESTIMO EM
A8: 45323 | B8: 1 | C8: SIVIERO EMPREENDIMENTOS IMOBILIARIOS LTD | D8: SAMIR TREVISAN PICCOLI - JUROS | E8: 45323 | F8: 45323 | G8: 150000 | H8: 1500 | I8: JUROS 1.00% S/ R$ 150.000,00 - EMPRESTIMO EM
A9: 45323 | B9: 1 | C9: SIVIERO EMPREENDIMENTOS IMOBILIARIOS LTD | D9: SAMIR TREVISAN PICCOLI - JUROS | E9: 45323 | F9: 45323 | G9: 150000 | H9: 1500 | I9: JUROS 1.00% S/ R$ 150.000,00 - EMPRESTIMO EM
A10: 45323 | B10: 1 | C10: SIVIERO EMPREENDIMENTOS IMOBILIARIOS LTD | D10: DESPESAS DIVERSAS | E10: 45323 | F10: 45323 | G10: 2200 | H10: 2200 | I10: MARCOS A SIVIERO-DESP DIVERSAS CFE NOTAS+CO
A11: 45323 | B11: 1 | C11: SIVIERO EMPREENDIMENTOS IMOBILIARIOS LTD | D11: CIELLO E MARIN IND E COM DE ARTESANAT | E11: 45323 | F11: 45323 | G11: 155 | H11: 155 | I11: QUADRO CERTIDAO DE CASAMENTO DE LUIZ E ANGE
A12: 45323 | B12: 1 | C12: SIVIERO EMPREENDIMENTOS IMOBILIARIOS LTD | D12: BANCO SICREDI - VERANÓPOLIS | E12: 45323 | F12: 45323 | G12: 0.17 | H12: 0.17 | I12: JUROS BANCO CREDITO ROTATIVO MES JANEIRO/20
A13: 45323 | B13: 1 | C13: SIVIERO EMPREENDIMENTOS IMOBILIARIOS LTD | D13: RESTAURANTE E CHURRASCARIA SERRANA | E13: 45323 | F13: 45323 | G13: 33 | H13: 33 | I13: PAGO ALMOCO FUNCIONARIO MARCIANO EM 29.01.20
... A212: 45323 | B212: 4 | C212: ABASTECEDORA DE COMBUSTIVEIS SIVIERO LTD | D212: CONT. SOCIAL - ABAST. COMB. SIVIERO L | E212: 45351 | F212: 45351 | G212: 765.5 | H212: 765.5 | I212: FATURAMENTO MES JANEIRO/2024 - R$ 26.580,00 X
A214: Total | G214: =SUBTOTAL(9,G2:G212) | H214: =SUBTOTAL(9,H2:H212)

Sheet 2024-03
A1: Mês | B1: Página | C1: Empresa | D1: Fornecedor | E1: Vencimento | F1: Pagamento | G1: Valor NF | H1: Valor Dupl. | I1: Observações
A2: 45352 | B2: 1 | C2: SIVIERO EMPREENDIMENTOS IMOBILIARIOS LTD | D2: SAMIR TREVISAN PICCOLI - JUROS | E2: 45352 | F2: 45352 | G2: 150000 | H2: 1500 | I2: JUROS 1.00% S/ R$ 150.000,00 - EMPRESTIMO EM
A3: 45352 | B3: 1 | C3: SIVIERO EMPREENDIMENTOS IMOBILIARIOS LTD | D3: SAMIR TREVISAN PICCOLI - JUROS | E3: 45352 | F3: 45352 | G3: 150000 | H3: 1500 | I3: JUROS 1.00% S/ R$ 150.000,00 - EMPRESTIMO EM
A4: 45352 | B4: 1 | C4: SIVIERO EMPREENDIMENTOS IMOBILIARIOS LTD | D4: SAMIR TREVISAN PICCOLI - JUROS | E4: 45352 | F4: 45352 | G4: 350000 | H4: 3500 | I4: JUROS 1.00% S/ R$ 350.000,00 - EMPRESTIMO EM
A5: 45352 | B5: 1 | C5: SIVIERO EMPREENDIMENTOS IMOBILIARIOS LTD | D5: SAMIR TREVISAN PICCOLI - JUROS | E5: 45352 | F5: 45352 | G5: 250000 | H5: 2500 | I5: JUROS 1.00% S/ R$ 250.000,00 - EMPRESTIMO EM
A6: 45352 | B6: 1 | C6: SIVIERO EMPREENDIMENTOS IMOBILIARIOS LTD | D6: SAMIR TREVISAN PICCOLI - JUROS | E6: 45352 | F6: 45352 | G6: 250000 | H6: 2500 | I6: JUROS 1.00% S/ R$ 250.000,00 - EMPRESTIMO EM
A7: 45352 | B7: 1 | C7: SIVIERO EMPREENDIMENTOS IMOBILIARIOS LTD | D7: INES TREVISAN PICCOLI - JUROS | E7: 45352 | F7: 45352 | G7: 100000 | H7: 1000 | I7: JUROS 1.00% S/ R$ 100.000,00 - EMPRESTIMO EM
A8: 45352 | B8: 1 | C8: SIVIERO EMPREENDIMENTOS IMOBILIARIOS LTD | D8: INES TREVISAN PICCOLI - JUROS | E8: 45352 | F8: 45352 | G8: 250000 | H8: 2500 | I8: JUROS 1.00% S/ R$ 250.000,00 - EMPRESTIMO EM
A9: 45352 | B9: 1 | C9: SIVIERO EMPREENDIMENTOS IMOBILIARIOS LTD | D9: REGISTRO IMOVEIS DE NOVA PRATA - RS | E9: 45352 | F9: 45352 | G9: 190.69 | H9: 190.69 | I9: 04 MATRICULAS: 26.255 26.256 26.456 21.413-LO
A10: 45352 | B10: 1 | C10: SIVIERO EMPREENDIMENTOS IMOBILIARIOS LTD | D10: DESPESAS DIVERSAS | E10: 45352 | F10: 45352 | G10: 38 | H10: 38 | I10: RESTAURANTE-ALMOCO MARCIANO VIAGEM COMPRA A
A11: 45352 | B11: 1 | C11: SIVIERO EMPREENDIMENTOS IMOBILIARIOS LTD | D11: PEDAGIOS | E11: 45352 | F11: 45352 | G11: 17.4 | H11: 17.4 | I11: PEDAGIO COMPRA CARGA DE AREIA MARCIANO DIA 27
A12: 45352 | B12: 1 | C12: SIVIERO EMPREENDIMENTOS IMOBILIARIOS LTD | D12: PEDAGIOS | E12: 45352 | F12: 45352 | G12: 17.4 | H12: 17.4 | I12: PEDAGIO COMPRA CARGA DE AREIA MARCIANO DIA 27
A13: 45352 | B13: 1 | C13: SIVIERO EMPREENDIMENTOS IMOBILIARIOS LTD | D13: DESPESAS DIVERSAS | E13: 45352 | F13: 45352 | G13: 880 | H13: 880 | I13: CAIO-ROCADOR-ROCADA RUAS E AREAS DAS CALCADA
... A238: 45352 | B238: 5 | C238: ABASTECEDORA DE COMBUSTIVEIS SIVIERO LTD | D238: CONT. SOCIAL - ABAST. COMB. SIVIERO L | E238: 45379 | F238: 45379 | G238: 765.5 | H238: 765.5 | I238: FATURAMENTO MES FEVEREIRO/2024 - R$ 26.580,00
A240: Total | G240: =SUBTOTAL(9,G2:G238) | H240: =SUBTOTAL(9,H2:H238)

Sheet 2024-04
A1: Mês | B1: Página | C1: Empresa | D1: Fornecedor | E1: Vencimento | F1: Pagamento | G1: Valor NF | H1: Valor Dupl. | I1: Observações
A2: 45383 | B2: 1 | C2: SIVIERO EMPREENDIMENTOS IMOBILIARIOS LTD | D2: CREA - RS-CONSELHO REGIONAL ENGENHARI | E2: 45382 | F2: 45383 | G2: 64.77 | H2: 64.77 | I2: ANUIDADE ANO 2024 - ENGENHEIRO PEDRO SIVIERO
A3: 45383 | B3: 1 | C3: SIVIERO EMPREENDIMENTOS IMOBILIARIOS LTD | D3: SIM REDE DE POSTOS LTDA. - VERANOPOLI | E3: 45382 | F3: 45383 | G3: 1223.38 | H3: 1223.38 | I3: ABASTECIMENTOS CARROS+CACAMBAS+OFICINA=VER
A4: 45383 | B4: 1 | C4: SIVIERO EMPREENDIMENTOS IMOBILIARIOS LTD | D4: ANTONINHO JOSE ZANELLA - PASSO FUNDO | E4: 45382 | F4: 45383 | G4: 1121.66 | H4: 1121.66 | I4: TITULO - JR COM CIMENTO E CONCRETO LTDA. - PO
A5: 45383 | B5: 1 | C5: SIVIERO EMPREENDIMENTOS IMOBILIARIOS LTD | D5: ANTONINHO JOSE ZANELLA - PASSO FUNDO | E5: 45383 | F5: 45383 | G5: 345.7 | H5: 345.7 | I5: TITULO - ECOSOLUTION - LOCACAO DE TELEENTULH
A6: 45383 | B6: 1 | C6: SIVIERO EMPREENDIMENTOS IMOBILIARIOS LTD | D6: INES TREVISAN PICCOLI - JUROS | E6: 45383 | F6: 45383 | G6: 250000 | H6: 2500 | I6: JUROS 1.00% S/ R$ 250.000,00 - EMPRESTIMO EM
