Workbook

Sheet Resumo
A1: Mês | B1: ABASTECEDORA DE COMBUSTIVEIS SIVIERO LTD | C1: SIVIERO EMPREENDIMENTOS IMOBILIARIOS LTD | D1: TRANSPORTADORA IRMAOS SIVIERO LTDA. | E1: Total saídas | G1: Lotes vendidos | H1: Lotes com valor citado | I1: Valor citado (soma dos lotes)
A2: 45108 | B2: =SUMIFS(Consolidado!$H:$H,Consolidado!$A:$A,$A2,Consolidado!$C:$C,B$1) | C2: =SUMIFS(Consolidado!$H:$H,Consolidado!$A:$A,$A2,Consolidado!$C:$C,C$1) | D2: =SUMIFS(Consolidado!$H:$H,Consolidado!$A:$A,$A2,Consolidado!$C:$C,D$1) | E2: =SUM(B2:D2) | G2: =COUNTIFS('Lotes Vendidos (todos)'!$K:$K,$A2) | H2: =COUNTIFS('Lotes Vendidos (todos)'!$K:$K,$A2,'Lotes Vendidos (todos)'!$G:$G,"<>") | I2: =SUMIFS('Lotes Vendidos (todos)'!$G:$G,'Lotes Vendidos (todos)'!$K:$K,$A2)
A3: 45139 | B3: =SUMIFS(Consolidado!$H:$H,Consolidado!$A:$A,$A3,Consolidado!$C:$C,B$1) | C3: =SUMIFS(Consolidado!$H:$H,Consolidado!$A:$A,$A3,Consolidado!$C:$C,C$1) | D3: =SUMIFS(Consolidado!$H:$H,Consolidado!$A:$A,$A3,Consolidado!$C:$C,D$1) | E3: =SUM(B3:D3) | G3: =COUNTIFS('Lotes Vendidos (todos)'!$K:$K,$A3) | H3: =COUNTIFS('Lotes Vendidos (todos)'!$K:$K,$A3,'Lotes Vendidos (todos)'!$G:$G,"<>") | I3: =SUMIFS('Lotes Vendidos (todos)'!$G:$G,'Lotes Vendidos (todos)'!$K:$K,$A3)
A4: 45170 | B4: sem relatório | C4: sem relatório | D4: sem relatório | E4: sem relatório | G4: =COUNTIFS('Lotes Vendidos (todos)'!$K:$K,$A4) | H4: =COUNTIFS('Lotes Vendidos (todos)'!$K:$K,$A4,'Lotes Vendidos (todos)'!$G:$G,"<>") | I4: =SUMIFS('Lotes Vendidos (todos)'!$G:$G,'Lotes Vendidos (todos)'!$K:$K,$A4)
A5: 45200 | B5: =SUMIFS(Consolidado!$H:$H,Consolidado!$A:$A,$A5,Consolidado!$C:$C,B$1) | C5: =SUMIFS(Consolidado!$H:$H,Consolidado!$A:$A,$A5,Consolidado!$C:$C,C$1) | D5: =SUMIFS(Consolidado!$H:$H,Consolidado!$A:$A,$A5,Consolidado!$C:$C,D$1) | E5: =SUM(B5:D5) | G5: =COUNTIFS('Lotes Vendidos (todos)'!$K:$K,$A5) | H5: =COUNTIFS('Lotes Vendidos (todos)'!$K:$K,$A5,'Lotes Vendidos (todos)'!$G:$G,"<>") | I5: =SUMIFS('Lotes Vendidos (todos)'!$G:$G,'Lotes Vendidos (todos)'!$K:$K,$A5)
A6: 45231 | B6: =SUMIFS(Consolidado!$H:$H,Consolidado!$A:$A,$A6,Consolidado!$C:$C,B$1) | C6: =SUMIFS(Consolidado!$H:$H,Consolidado!$A:$A,$A6,Consolidado!$C:$C,C$1) | D6: =SUMIFS(Consolidado!$H:$H,Consolidado!$A:$A,$A6,Consolidado!$C:$C,D$1) | E6: =SUM(B6:D6) | G6: =COUNTIFS('Lotes Vendidos (todos)'!$K:$K,$A6) | H6: =COUNTIFS('Lotes Vendidos (todos)'!$K:$K,$A6,'Lotes Vendidos (todos)'!$G:$G,"<>") | I6: =SUMIFS('Lotes Vendidos (todos)'!$G:$G,'Lotes Vendidos (todos)'!$K:$K,$A6)
A7: 45261 | B7: =SUMIFS(Consolidado!$H:$H,Consolidado!$A:$A,$A7,Consolidado!$C:$C,B$1) | C7: =SUMIFS(Consolidado!$H:$H,Consolidado!$A:$A,$A7,Consolidado!$C:$C,C$1) | D7: =SUMIFS(Consolidado!$H:$H,Consolidado!$A:$A,$A7,Consolidado!$C:$C,D$1) | E7: =SUM(B7:D7) | G7: =COUNTIFS('Lotes Vendidos (todos)'!$K:$K,$A7) | H7: =COUNTIFS('Lotes Vendidos (todos)'!$K:$K,$A7,'Lotes Vendidos (todos)'!$G:$G,"<>") | I7: =SUMIFS('Lotes Vendidos (todos)'!$G:$G,'Lotes Vendidos (todos)'!$K:$K,$A7)
A8: 45292 | B8: =SUMIFS(Consolidado!$H:$H,Consolidado!$A:$A,$A8,Consolidado!$C:$C,B$1) | C8: =SUMIFS(Consolidado!$H:$H,Consolidado!$A:$A,$A8,Consolidado!$C:$C,C$1) | D8: =SUMIFS(Consolidado!$H:$H,Consolidado!$A:$A,$A8,Consolidado!$C:$C,D$1) | E8: =SUM(B8:D8) | G8: =COUNTIFS('Lotes Vendidos (todos)'!$K:$K,$A8) | H8: =COUNTIFS('Lotes Vendidos (todos)'!$K:$K,$A8,'Lotes Vendidos (todos)'!$G:$G,"<>") | I8: =SUMIFS('Lotes Vendidos (todos)'!$G:$G,'Lotes Vendidos (todos)'!$K:$K,$A8)
A9: 45323 | B9: =SUMIFS(Consolidado!$H:$H,Consolidado!$A:$A,$A9,Consolidado!$C:$C,B$1) | C9: =SUMIFS(Consolidado!$H:$H,Consolidado!$A:$A,$A9,Consolidado!$C:$C,C$1) | D9: =SUMIFS(Consolidado!$H:$H,Consolidado!$A:$A,$A9,Consolidado!$C:$C,D$1) | E9: =SUM(B9:D9) | G9: =COUNTIFS('Lotes Vendidos (todos)'!$K:$K,$A9) | H9: =COUNTIFS('Lotes Vendidos (todos)'!$K:$K,$A9,'Lotes Vendidos (todos)'!$G:$G,"<>") | I9: =SUMIFS('Lotes Vendidos (todos)'!$G:$G,'Lotes Vendidos (todos)'!$K:$K,$A9)
A10: 45352 | B10: =SUMIFS(Consolidado!$H:$H,Consolidado!$A:$A,$A10,Consolidado!$C:$C,B$1) | C10: =SUMIFS(Consolidado!$H:$H,Consolidado!$A:$A,$A10,Consolidado!$C:$C,C$1) | D10: =SUMIFS(Consolidado!$H:$H,Consolidado!$A:$A,$A10,Consolidado!$C:$C,D$1) | E10: =SUM(B10:D10) | G10: =COUNTIFS('Lotes Vendidos (todos)'!$K:$K,$A10) | H10: =COUNTIFS('Lotes Vendidos (todos)'!$K:$K,$A10,'Lotes Vendidos (todos)'!$G:$G,"<>") | I10: =SUMIFS('Lotes Vendidos (todos)'!$G:$G,'Lotes Vendidos (todos)'!$K:$K,$A10)
A11: 45383 | B11: =SUMIFS(Consolidado!$H:$H,Consolidado!$A:$A,$A11,Consolidado!$C:$C,B$1) | C11: =SUMIFS(Consolidado!$H:$H,Consolidado!$A:$A,$A11,Consolidado!$C:$C,C$1) | D11: =SUMIFS(Consolidado!$H:$H,Consolidado!$A:$A,$A11,Consolidado!$C:$C,D$1) | E11: =SUM(B11:D11) | G11: =COUNTIFS('Lotes Vendidos (todos)'!$K:$K,$A11) | H11: =COUNTIFS('Lotes Vendidos (todos)'!$K:$K,$A11,'Lotes Vendidos (todos)'!$G:$G,"<>") | I11: =SUMIFS('Lotes Vendidos (todos)'!$G:$G,'Lotes Vendidos (todos)'!$K:$K,$A11)
A12: 45413 | B12: =SUMIFS(Consolidado!$H:$H,Consolidado!$A:$A,$A12,Consolidado!$C:$C,B$1) | C12: =SUMIFS(Consolidado!$H:$H,Consolidado!$A:$A,$A12,Consolidado!$C:$C,C$1) | D12: =SUMIFS(Consolidado!$H:$H,Consolidado!$A:$A,$A12,Consolidado!$C:$C,D$1) | E12: =SUM(B12:D12) | G12: =COUNTIFS('Lotes Vendidos (todos)'!$K:$K,$A12) | H12: =COUNTIFS('Lotes Vendidos (todos)'!$K:$K,$A12,'Lotes Vendidos (todos)'!$G:$G,"<>") | I12: =SUMIFS('Lotes Vendidos (todos)'!$G:$G,'Lotes Vendidos (todos)'!$K:$K,$A12)
A13: 45444 | B13: =SUMIFS(Consolidado!$H:$H,Consolidado!$A:$A,$A13,Consolidado!$C:$C,B$1) | C13: =SUMIFS(Consolidado!$H:$H,Consolidado!$A:$A,$A13,Consolidado!$C:$C,C$1) | D13: =SUMIFS(Consolidado!$H:$H,Consolidado!$A:$A,$A13,Consolidado!$C:$C,D$1) | E13: =SUM(B13:D13) | G13: =COUNTIFS('Lotes Vendidos (todos)'!$K:$K,$A13) | H13: =COUNTIFS('Lotes Vendidos (todos)'!$K:$K,$A13,'Lotes Vendidos (todos)'!$G:$G,"<>") | I13: =SUMIFS('Lotes Vendidos (todos)'!$G:$G,'Lotes Vendidos (todos)'!$K:$K,$A13)
A14: 45474 | B14: =SUMIFS(Consolidado!$H:$H,Consolidado!$A:$A,$A14,Consolidado!$C:$C,B$1) | C14: =SUMIFS(Consolidado!$H:$H,Consolidado!$A:$A,$A14,Consolidado!$C:$C,C$1) | D14: =SUMIFS(Consolidado!$H:$H,Consolidado!$A:$A,$A14,Consolidado!$C:$C,D$1) | E14: =SUM(B14:D14) | G14: =COUNTIFS('Lotes Vendidos (todos)'!$K:$K,$A14) | H14: =COUNTIFS('Lotes Vendidos (todos)'!$K:$K,$A14,'Lotes Vendidos (todos)'!$G:$G,"<>") | I14: =SUMIFS('Lotes Vendidos (todos)'!$G:$G,'Lotes Vendidos (todos)'!$K:$K,$A14)
A15: 45505 | B15: =SUMIFS(Consolidado!$H:$H,Consolidado!$A:$A,$A15,Consolidado!$C:$C,B$1) | C15: =SUMIFS(Consolidado!$H:$H,Consolidado!$A:$A,$A15,Consolidado!$C:$C,C$1) | D15: =SUMIFS(Consolidado!$H:$H,Consolidado!$A:$A,$A15,Consolidado!$C:$C,D$1) | E15: =SUM(B15:D15) | G15: =COUNTIFS('Lotes Vendidos (todos)'!$K:$K,$A15) | H15: =COUNTIFS('Lotes Vendidos (todos)'!$K:$K,$A15,'Lotes Vendidos (todos)'!$G:$G,"<>") | I15: =SUMIFS('Lotes Vendidos (todos)'!$G:$G,'Lotes Vendidos (todos)'!$K:$K,$A15)
A16: 45536 | B16: =SUMIFS(Consolidado!$H:$H,Consolidado!$A:$A,$A16,Consolidado!$C:$C,B$1) | C16: =SUMIFS(Consolidado!$H:$H,Consolidado!$A:$A,$A16,Consolidado!$C:$C,C$1) | D16: =SUMIFS(Consolidado!$H:$H,Consolidado!$A:$A,$A16,Consolidado!$C:$C,D$1) | E16: =SUM(B16:D16) | G16: =COUNTIFS('Lotes Vendidos (todos)'!$K:$K,$A16) | H16: =COUNTIFS('Lotes Vendidos (todos)'!$K:$K,$A16,'Lotes Vendidos (todos)'!$G:$G,"<>") | I16: =SUMIFS('Lotes Vendidos (todos)'!$G:$G,'Lotes Vendidos (todos)'!$K:$K,$A16)
A17: 45566 | B17: =SUMIFS(Consolidado!$H:$H,Consolidado!$A:$A,$A17,Consolidado!$C:$C,B$1) | C17: =SUMIFS(Consolidado!$H:$H,Consolidado!$A:$A,$A17,Consolidado!$C:$C,C$1) | D17: =SUMIFS(Consolidado!$H:$H,Consolidado!$A:$A,$A17,Consolidado!$C:$C,D$1) | E17: =SUM(B17:D17) | G17: =COUNTIFS('Lotes Vendidos (todos)'!$K:$K,$A17) | H17: =COUNTIFS('Lotes Vendidos (todos)'!$K:$K,$A17,'Lotes Vendidos (todos)'!$G:$G,"<>") | I17: =SUMIFS('Lotes Vendidos (todos)'!$G:$G,'Lotes Vendidos (todos)'!$K:$K,$A17)
A18: Total | B18: =SUM(B2:B17) | C18: =SUM(C2:C17) | D18: =SUM(D2:D17) | E18: =SUM(E2:E17) | G18: =SUM(G2:G17) | H18: =SUM(H2:H17) | I18: =SUM(I2:I17)
A20: Notas:
A21: Saídas = coluna Valor Dupl. dos relatórios de Contas Pagas (jul/2023 a out/2024). Setembro/2023 não tem relatório na pasta.
A22: Lotes = lista "17 - LOTES VENDIDOS DE JANEIRO DE 2018 A OUTUBRO DE 2025 - REV.13.08.2026", que não tem coluna de valor.
A23: "Valor citado" é o valor em R$ que aparece no texto da observação do lote (o total quando o texto o indica; vazio quando não há valor ou há vários sem total).
A24: Esse valor pode ser parcial (só a parte em permuta ou em dinheiro) e, em vendas conjuntas, o mesmo valor se repete em cada lote; a soma mensal é só indicativa.
A25: Lotes fora do período (1992-2026) e o lote sem data estão na aba "Lotes Vendidos (todos)".

Sheet Consolidado
A1: Mês | B1: Página | C1: Empresa | D1: Fornecedor | E1: Vencimento | F1: Pagamento | G1: Valor NF | H1: Valor Dupl. | I1: Observações | K1: Mês | L1: Data | M1: Loteamento | N1: Município | O1: Lote | P1: Quadra | Q1: Comprador | R1: Valor citado | S1: Valores no texto | T1: Venda conjunta | U1: Observações
A2: 45108 | B2: 1 | C2: SIVIERO EMPREENDIMENTOS IMOBILIARIOS LTD | D2: DORVAL FRANCISCO BOFF - CAXIAS DO SUL | E2: 45110 | F2: 45110 | G2: 100000 | H2: 10000 | I2: P.04/10-CFE CONTRATO ANTECIPACAO VALORES - LO | K2: 45108 | L2: 45111 | M2: SOL NASCENTE I | N2: ANTÔNIO PRADO | O2: 24 | P2: D | Q2: Cassiano Damiani | R2: 67000 | S2: R$ 67.000,00 | U2: Vendido à vista, sendo R$ 67.000,00 em permuta veículo GM/S10 – JID 4877.
A3: 45108 | B3: 1 | C3: SIVIERO EMPREENDIMENTOS IMOBILIARIOS LTD | D3: PROGETEC - ALENCAR TRINDADE - P.FUNDO | E3: 45110 | F3: 45110 | G3: 25000 | H3: 5000 | I3: P.3/5-INSTALACAO D+ HASTES CERCA ELETRICA+INS | K3: 45108 | L3: 45113 | M3: INDUSTRIAL PEDRA LISA | N3: VERANÓPOLIS | O3: 01 | P3: 07 | Q3: Ind. Concretos Rivacci | R3: 55000 | S3: R$ 55.000,00 | T3: Sim (2 lotes) | U3: Vendido à vista, com permuta de um pavilhão pré fabricado (a entregar) e uma camionete I/Toyota Hilux e o valor em espécie de R$ 55.000,00.
A4: 45108 | B4: 1 | C4: SIVIERO EMPREENDIMENTOS IMOBILIARIOS LTD | D4: PREFEITURA MUNICIPAL DE NOVA PRATA | E4: 45110 | F4: 45110 | G4: 36.96 | H4: 36.96 | I4: CERTIDAO DE LOCALIZAÇAO AREA-BELLA VISIONE-NO | K4: 45108 | L4: 45113 | M4: INDUSTRIAL PEDRA LISA | N4: VERANÓPOLIS | O4: 02 | P4: 07 | Q4: Ind. Concretos Rivacci | R4: 55000 | S4: R$ 55.000,00 | T4: Sim (2 lotes) | U4: Vendido à vista, com permuta de um pavilhão pré fabricado (a entregar) e uma camionete I/Toyota Hilux e o valor em espécie de R$ 55.000,00.
A5: 45108 | B5: 1 | C5: SIVIERO EMPREENDIMENTOS IMOBILIARIOS LTD | D5: SIM REDE DE POSTOS LTDA. - VERANOPOLI | E5: 45109 | F5: 45110 | G5: 521.89 | H5: 521.89 | I5: ABASTECIMENTOS CARROS+CACAMBAS+OFICINA=VER | K5: 45108 | L5: 45125 | M5: CARNEVALLI | N5: NOVA PRATA | O5: 06 | P5: C | Q5: Érica Basso | U5: Vendido à prazo, em 02x.
A6: 45108 | B6: 1 | C6: SIVIERO EMPREENDIMENTOS IMOBILIARIOS LTD | D6: INES TREVISAN PICCOLI - JUROS | E6: 45108 | F6: 45110 | G6: 250000 | H6: 2500 | I6: JUROS 1.00% S/ R$ 250.000,00 - EMPRESTIMO | K6: 45139 | L6: 45146 | M6: BALDASSO | N6: CARLOS BARBOSA | O6: 40 | P6: 06 | Q6: Edmar Camillo | U6: Vendido à prazo, em 14x.
A7: 45108 | B7: 1 | C7: SIVIERO EMPREENDIMENTOS IMOBILIARIOS LTD | D7: ANDRE LUIZ SIVIERO - JUROS | E7: 45108 | F7: 45110 | G7: 100000 | H7: 800 | I7: JUROS 0,80% S/ R$ 100.000,00 - EMPRESTIMO | K7: 45139 | L7: 45149 | M7: CONDOMÍNIO MORADA DOS IPÊS | N7: PASSO FUNDO | O7: 012 | P7: 04 | Q7: Leandro Capelesso | R7: 75000 | S7: R$ 75.000,00 | U7: Vendido à prazo, em 05x, com parte em permuta de um carro pelo valor de R$ 75.000,00 e reparceladas as parcelas para viabilizar o pagamento em 21x.
A8: 45108 | B8: 1 | C8: SIVIERO EMPREENDIMENTOS IMOBILIARIOS LTD | D8: SAMIR TREVISAN PICCOLI - JUROS | E8: 45108 | F8: 45110 | G8: 350000 | H8: 3500 | I8: JUROS 1.00% S/ R$ 350.000,00 - EMPRESTIMO | K8: 45139 | L8: 45155 | M8: CONDOMÍNIO MORADA DOS IPÊS | N8: PASSO FUNDO | O8: 004 | P8: 04 | Q8: Luiz Fernando Klaus | U8: Vendido à prazo, em 07x.
A9: 45108 | B9: 1 | C9: SIVIERO EMPREENDIMENTOS IMOBILIARIOS LTD | D9: SAMIR TREVISAN PICCOLI - JUROS | E9: 45108 | F9: 45110 | G9: 150000 | H9: 1500 | I9: JUROS 1.00% S/ R$ 150.000,00 - EMPRESTIMO | K9: 45139 | L9: 45161 | M9: SOLAR NORTE | N9: VERANÓPOLIS | O9: 06 | P9: 01 | Q9: Lindolfo Lago | R9: 350000 | S9: R$ 350.000,00 | U9: Vendido, como forma de pagamento pela aquisição de uma área de 3.100,00m² junto com a área da FAMÍLIA LAGO, em Sapopema, pelo valor total de R$ 350.000,00.
A10: 45108 | B10: 1 | C10: SIVIERO EMPREENDIMENTOS IMOBILIARIOS LTD | D10: SAMIR TREVISAN PICCOLI - JUROS | E10: 45108 | F10: 45110 | G10: 250000 | H10: 2500 | I10: JUROS 1.00% S/ R$ 250.000,00 - EMPRESTIMO | K10: 45139 | L10: 45168 | M10: ALTOS DA JULIETA | N10: FARROUPILHA | O10: 01 | P10: 1734 | Q10: Gláucio da Rosa Monteiro | U10: Vendido à vista.
A11: 45108 | B11: 1 | C11: SIVIERO EMPREENDIMENTOS IMOBILIARIOS LTD | D11: SAMIR TREVISAN PICCOLI - JUROS | E11: 45108 | F11: 45110 | G11: 250000 | H11: 2500 | I11: JUROS 1.00% S/ R$ 250.000,00 - EMPRESTIMO EM | K11: 45170 | L11: 45175 | M11: ALTOS DAS GRAÇAS | N11: CAXIAS DO SUL | O11: 02 | P11: 6373 | Q11: Rosa Maria Nascimento | U11: Vendido à vista.
A12: 45108 | B12: 1 | C12: SIVIERO EMPREENDIMENTOS IMOBILIARIOS LTD | D12: BANCO SICREDI - VERANÓPOLIS | E12: 45110 | F12: 45110 | G12: 0.18 | H12: 0.18 | I12: JUROS BANCO CREDITO ROTATIVO MES JUNHO/2023 | K12: 45170 | L12: 45177 | M12: SALVADOR – FEMAÇÃ II | N12: VERANÓPOLIS | O12: 04 | P12: 04 | Q12: Prefeitura de Veranópolis | U12: Doação conforme Lei.
A13: 45108 | B13: 1 | C13: SIVIERO EMPREENDIMENTOS IMOBILIARIOS LTD | D13: IOF BANCARIO SIVIERO EMP IMOBILIARIOS | E13: 45110 | F13: 45110 | G13: 308.55 | H13: 308.55 | I13: IOF CONTA SEI MES DE JUNHO DE 2023 - BANRISUL | K13: 45170 | L13: 45182 | M13: LAGO NEGRO | N13: GRAMADO | O13: 01 | P13: 07 | Q13: Fruti Frango Adm Imóveis | U13: Vendido à vista.
A14: 45108 | B14: 1 | C14: SIVIERO EMPREENDIMENTOS IMOBILIARIOS LTD | D14: IOF BANCARIO SIVIERO EMP IMOBILIARIOS | E14: 45110 | F14: 45110 | G14: 657.74 | H14: 657.74 | I14: IOF CONTA SEI MES DE JUNHO DE 2023 - BANRISUL | K14: 45170 | L14: 45190 | M14: COLINA DO RETIRO I | N14: VERANÓPOLIS | O14: 01 | P14: 02 | Q14: Maicon A. Mikoaski | U14: Vendido à vista.
A15: 45108 | B15: 1 | C15: SIVIERO EMPREENDIMENTOS IMOBILIARIOS LTD | D15: MULTAS DE TRANSITO | E15: 45111 | F15: 45111 | G15: 156.19 | H15: 156.19 | I15: CACAMBA ILD 3959 - NAO IDENTIFICAÇÃO DE CONDU | K15: 45170 | L15: 45191 | M15: INDUSTRIAL PEDRA LISA | N15: VERANÓPOLIS | O15: 03 | P15: 03 | Q15: Ivo José Frainer | R15: 388000 | S15: R$ 388.000,00 | U15: Vendido, como forma de pagamento na aquisição de 0,67 há de terras ao lado do Loteamento Industrial Pedra Lisa, pelo valor de R$ 388.000,00.
A16: 45108 | B16: 1 | C16: SIVIERO EMPREENDIMENTOS IMOBILIARIOS LTD | D16: PORTAL EMPREENDIMENTOS IMOBILIARIOS L | E16: 45111 | F16: 45111 | G16: 10000 | H16: 2000 | I16: P.1/4-COMISSAO LT 06-QDRA 1342-SAN MARINO=DAN | K16: 45170 | L16: 45195 | M16: SALVADOR – FEMAÇÃ II | N16: VERANÓPOLIS | O16: 01 | P16: 04 | Q16: Volmir Marinello | U16: Vendido à prazo.
A17: 45108 | B17: 1 | C17: SIVIERO EMPREENDIMENTOS IMOBILIARIOS LTD | D17: PORTAL EMPREENDIMENTOS IMOBILIARIOS L | E17: 45111 | F17: 45111 | G17: 10000 | H17: 2000 | I17: P.2/4-COMISSAO LT 06-QDRA 1342-SAN MARINO=DAN | K17: 45200 | L17: 45230 | M17: MONTE VÊNETO | N17: COTIPORÃ | O17: 04 | P17: 04 | Q17: Nilton de Oliveira Vieira | T17: Sim (2 lotes) | U17: Vendido à prazo, em 26x.
A18: 45108 | B18: 1 | C18: SIVIERO EMPREENDIMENTOS IMOBILIARIOS LTD | D18: CASSIANO DAMIANI - ANTONIO PRADO | E18: 45111 | F18: 45111 | G18: 67000 | H18: 67000 | I18: LT 24-Q.D-SOL NASCEN CASSIANO DAMIANI-CAMIONE | K18: 45200 | L18: 45230 | M18: MONTE VÊNETO | N18: COTIPORÃ | O18: 05 | P18: 04 | Q18: Nilton de Oliveira Vieira | T18: Sim (2 lotes) | U18: Vendido à prazo, em 26x.
A19: 45108 | B19: 1 | C19: SIVIERO EMPREENDIMENTOS IMOBILIARIOS LTD | D19: BANCO ESTADO RIO GRANDE DO SUL - SEI | E19: 45111 | F19: 45111 | G19: 180 | H19: 180 | I19: SEI - TAXA MENSALIDADE PACOTE CONTA SEI - BAN | K19: 45231 | L19: 45231 | M19: VIERO | N19: FARROUPILHA | O19: 12 | P19: 1467 | Q19: Elizete/Rosália de Oliveira | U19: Vendido à vista.
A20: 45108 | B20: 1 | C20: SIVIERO EMPREENDIMENTOS IMOBILIARIOS LTD | D20: ANTONINHO JOSE ZANELLA - PASSO FUNDO | E20: 45112 | F20: 45112 | G20: 2000 | H20: 1000 | I20: RADIO PLANALTO-DIVULGACAO VENDAS LOTES MORAD | K20: 45231 | L20: 45238 | M20: CONDOMÍNIO MORADA DOS IPÊS | N20: PASSO FUNDO | O20: 008 | P20: 04 | Q20: Raul Martini | U20: Vendido à prazo, em 02x.
A21: 45108 | B21: 1 | C21: SIVIERO EMPREENDIMENTOS IMOBILIARIOS LTD | D21: D KEKOS COM MANGUEIRAS E CONEXOES LTI | E21: 45112 | F21: 45112 | G21: 556.5 | H21: 556.5 | I21: MANGUEIRA E CONEXAO - ESCAVADEIRA HIDRAULICA | K21: 45261 | L21: 45278 | M21: SALVADOR – FEMAÇÃ II | N21: VERANÓPOLIS | O21: 01 | P21: 03 | Q21: Rogério Binda | T21: Sim (2 lotes) | U21: Vendido à vista.
A22: 45108 | B22: 1 | C22: SIVIERO EMPREENDIMENTOS IMOBILIARIOS LTD | D22: HOTEL ARACA LTDA | E22: 45112 | F22: 45112 | G22: 11500 | H22: 6000 | I22: RAUL SIVIERO+PAGTO CONTAS INDIVIDUAIS+DIF DEP | K22: 45261 | L22: 45278 | M22: SALVADOR – FEMAÇÃ II | N22: VERANÓPOLIS | O22: 02 | P22: 03 | Q22: Rogério Binda | T22: Sim (2 lotes) | U22: Vendido à vista.
A23: 45108 | B23: 1 | C23: SIVIERO EMPREENDIMENTOS IMOBILIARIOS LTD | D23: A. R. T. | E23: 45112 | F23: 45112 | G23: 96.62 | H23: 96.62 | I23: PEDRO ELIAS SIVIERO-RELATORIO ATERRO 03 LOTES | K23: 45261 | L23: 45280 | M23: ALTOS DAS GRAÇAS | N23: CAXIAS DO SUL | O23: 14 | P23: 6369 | Q23: MSL Incorporadora Ltda. | U23: Vendido à prazo, em 02x.
A24: 45108 | B24: 1 | C24: SIVIERO EMPREENDIMENTOS IMOBILIARIOS LTD | D24: COMBUSTIVEIS | E24: 45112 | F24: 45112 | G24: 100 | H24: 100 | I24: FUNCIONARIO EVERTON-PAGTO COMBUSTIVEIS VIAGE | K24: 45292 | L24: 45292 | M24: BARBIERO | N24: NOVA PRATA | O24: 08 | P24: 02 | Q24: André Luiz Siviero | U24: Vendido, como forma de devolução de empréstimo e pagamento de juros.
A25: 45108 | B25: 1 | C25: SIVIERO EMPREENDIMENTOS IMOBILIARIOS LTD | D25: LOJA DO PARABRISA LTDA. - GOIANIA | E25: 45112 | F25: 45112 | G25: 583 | H25: 583 | I25: 01 PARABRISA - VIDRO INFERIOR ESCAVADEIRA DO | K25: 45292 | L25: 45306 | M25: CONDOMÍNIO MORADA DOS IPÊS | N25: PASSO FUNDO | O25: 001 | P25: 06 | Q25: Juliano Pretto Elton Sobiesiak | U25: Vendido, como forma de pagamento de DAÇÃO EM PAGAMENTO, referente a aquisição de uma área de terras doada para o Município de Passo Fundo, para compensação de áreas para as 02 (duas) fases do Condomínio Morada dos Ipês II, em Passo Fundo, num total de 03 (três) lotes dentro do Condomínio, em parceria com a Família Zanella.
A26: 45108 | B26: 1 | C26: SIVIERO EMPREENDIMENTOS IMOBILIARIOS LTD | D26: MULTAS DE TRANSITO | E26: 45112 | F26: 45112 | G26: 78.09 | H26: 78.09 | I26: TOYOTA IYJ 8I14-PEDRO SIVIERO-EXCESSO VELOC.- | K26: 45323 | L26: 45349 | M26: MONTE VÊNETO | N26: COTIPORÃ | O26: 09 | P26: 01 | Q26: Rovílio Antônio Dal Más | R26: 190000 | S26: R$ 190.000,00 | T26: Sim (2 lotes) | U26: Vendido à vista, com permuta de outro imóvel – Lote 03, Quadra 04 – Loteamento Femaçã II – Veranópolis, valor de R$ 190.000,00.
A27: 45108 | B27: 1 | C27: SIVIERO EMPREENDIMENTOS IMOBILIARIOS LTD | D27: PAULA FARINA - VETERINARIA | E27: 45112 | F27: 45112 | G27: 400 | H27: 400 | I27: MEDICACAO PARA CACHORROS OFICINA SIVIERO - GI | K27: 45323 | L27: 45349 | M27: MONTE VÊNETO | N27: COTIPORÃ | O27: 10 | P27: 01 | Q27: Rovílio Antônio Dal Más | R27: 190000 | S27: R$ 190.000,00 | T27: Sim (2 lotes) | U27: Vendido à vista, com permuta de outro imóvel – Lote 03, Quadra 04 – Loteamento Femaçã II – Veranópolis, valor de R$ 190.000,00.
A28: 45108 | B28: 1 | C28: SIVIERO EMPREENDIMENTOS IMOBILIARIOS LTD | D28: RESTAURANTE - CAXIAS DO SUL | E28: 45112 | F28: 45112 | G28: 1369 | H28: 1369 | I28: PAGAMENTO REFEICOES MES DE MARCO/2023 - FUNCI | K28: 45352 | L28: 45370 | M28: ALTOS DAS GRAÇAS | N28: CAXIAS DO SUL | O28: 13 | P28: 6372 | Q28: Evandro Mário Zanrosso | U28: Vendido, conforme acordo ajustado dentre as partes, no Instrumento Particular de Acordo Extrajudicial, firmado em 19 de março de 2024, na forma de DAÇÃO EM PAGAMENTO.
A29: 45108 | B29: 1 | C29: SIVIERO EMPREENDIMENTOS IMOBILIARIOS LTD | D29: BANCO ESTADO RIO GRANDE DO SUL - SEI | E29: 45112 | F29: 45112 | G29: 245.45 | H29: 245.45 | I29: CONTA SEI - SEGURO VIDA PEDRO SIVIERO MAIO/20 | K29: 45352 | L29: 45372 | M29: SALVADOR – FEMAÇÃ II | N29: VERANÓPOLIS | O29: 02 | P29: 05 | Q29: Marcos Vinicius Dalazen | U29: Vendido à vista.
A30: 45108 | B30: 1 | C30: SIVIERO EMPREENDIMENTOS IMOBILIARIOS LTD | D30: VERAPECAS - PECAS E VEICULOS LTDA | E30: 45112 | F30: 45112 | G30: 970 | H30: 970 | I30: DISCO+FLUIDO+PASTILHAS DE FREIO+PALHETAS - FO | K30: 45383 | L30: 45398 | M30: ALTOS DA JULIETA | N30: FARROUPILHA | O30: 01 | P30: 1735 | Q30: Janete Basso | U30: Vendido à vista.
A31: 45108 | B31: 1 | C31: SIVIERO EMPREENDIMENTOS IMOBILIARIOS LTD | D31: RESTAURANTE - CAXIAS DO SUL | E31: 45112 | F31: 45112 | G31: 479.5 | H31: 479.5 | I31: PAGAMENTO REFEICOES MES DE JUNHO/2023 - FUNCI | K31: 45383 | L31: 45406 | M31: ADITIVO MEDIANEIRA | N31: VERANÓPOLIS | O31: 02 | P31: 07 | Q31: Solar Serra Ltda. | U31: Vendido, como forma de pagamento placas solares Hotel Araçá Ltda.
A32: 45108 | B32: 1 | C32: SIVIERO EMPREENDIMENTOS IMOBILIARIOS LTD | D32: CHAVES XAVIER - VERANOPOLIS | E32: 45112 | F32: 45112 | G32: 50 | H32: 50 | I32: ABERTURA PORTA APARTAMENTO GENI SIVIERO-APTO | K32: 45383 | L32: 45407 | M32: SOL NASCENTE II | N32: ANTÔNIO PRADO | O32: 11 | P32: C | Q32: Sustenseg Ltda. – Diego Zulian | U32: Vendido, como forma de pagamento pela prestação serviços – Topografia, Licenciamento, Aprovação e Registro do Loteamento Sol Nascente III.
A33: 45108 | B33: 1 | C33: SIVIERO EMPREENDIMENTOS IMOBILIARIOS LTD | D33: BANCO SICREDI - VERANÓPOLIS | E33: 45112 | F33: 45112 | G33: 67 | H33: 67 | I33: PAGTO TAXA MENSALIDADE BANCARIA CONTA SEI-SIC | K33: 45413 | L33: 45418 | M33: SAN MARINO | N33: FARROUPILHA | O33: 03 | P33: 1342 | Q33: Natalina Schwaiser | R33: 270000 | S33: R$ 270.000,00 | U33: Acordo – Arlindo Píccoli – Loteamento Vale das Colinas. Dívida de R$ 270.000,00.
A34: 45108 | B34: 1 | C34: SIVIERO EMPREENDIMENTOS IMOBILIARIOS LTD | D34: LADIR MADRUGA - CAXIAS DO SUL | E34: 45113 | F34: 45113 | G34: 3500 | H34: 3500 | I34: ROCADA LOTES LOTEAMENTOS EM FARROUPILHA - AC | K34: 45413 | L34: 45439 | M34: MONTE VÊNETO | N34: COTIPORÃ | O34: 07 | P34: 02 | Q34: Leonardo R. Kazienko | U34: Vendido à vista.
A35: 45108 | B35: 1 | C35: SIVIERO EMPREENDIMENTOS IMOBILIARIOS LTD | D35: INDUSTRIA DE CONCRETOS RIVACCI LTDA. | E35: 45113 | F35: 45113 | G35: 225000 | H35: 225000 | I35: TOYOTA HILUX-IZR 2E40-PAGTO LOTES 01 E 02-Q.7 | K35: 45413 | L35: 45440 | M35: BAÚ | N35: CARLOS BARBOSA | O35: 08 | P35: 04 | Q35: Rafael de Conti | U35: Vendido à vista.
A36: 45108 | B36: 1 | C36: SIVIERO EMPREENDIMENTOS IMOBILIARIOS LTD | D36: INDUSTRIA DE CONCRETOS RIVACCI LTDA. | E36: 45113 | F36: 45113 | G36: 370000 | H36: 370000 | I36: PAVILHAO PRE FABRICADO-PAGTO LOTES 01 E 02-Q. | K36: 45413 | L36: 45440 | M36: SOL NASCENTE I | N36: ANTÔNIO PRADO | O36: 09 | P36: B | Q36: Clóvis Pedro Zulian | T36: Sim (2 lotes) | U36: Vendidos, como forma de acerto pela Divisão Lotes pela participação nas despesas e custos na implantação dos Loteamentos (Fracionamentos) Sol Nascente I e II, de Antônio Prado, conforme Termo de Acordo.
A37: 45108 | B37: 1 | C37: SIVIERO EMPREENDIMENTOS IMOBILIARIOS LTD | D37: CHIQUINHO PNEUS | E37: 45113 | F37: 45114 | G37: 6600 | H37: 3300 | I37: P.2/2-CHEQUE-COMPRA 04 PNEUS NOVOS BORRACHUD | K37: 45413 | L37: 45440 | M37: SOL NASCENTE I | N37: ANTÔNIO PRADO | O37: 23 | P37: D | Q37: Clóvis Pedro Zulian | T37: Sim (2 lotes) | U37: Vendidos, como forma de acerto pela Divisão Lotes pela participação nas despesas e custos na implantação dos Loteamentos (Fracionamentos) Sol Nascente I e II, de Antônio Prado, conforme Termo de Acordo.
A38: 45108 | B38: 1 | C38: SIVIERO EMPREENDIMENTOS IMOBILIARIOS LTD | D38: PREFEITURA MUNICIPAL DE NOVA PRATA | E38: 45114 | F38: 45114 | G38: 4825.56 | H38: 4825.56 | I38: P.1/4-IPTU ANO 2023-LOTEAMENTO CARNEVALLI-NOV | K38: 45413 | L38: 45443 | M38: ALTOS DAS GRAÇAS | N38: CAXIAS DO SUL | O38: 08 | P38: 6365 | Q38: Soraya Dias Mais | U38: Vendido à prazo, em 02x.
A39: 45108 | B39: 1 | C39: SIVIERO EMPREENDIMENTOS IMOBILIARIOS LTD | D39: PREFEITURA MUNICIPAL DE NOVA PRATA | E39: 45114 | F39: 45114 | G39: 238.32 | H39: 238.32 | I39: P.1/4-IPTU ANO 2023-LOTEAMENTO TRUCCOLLO-NOVA | K39: 45444 | L39: 45467 | M39: SAN MARINO | N39: FARROUPILHA | O39: 02 | P39: 1342 | Q39: Eduardo Rossim | U39: Vendido à vista.
A40: 45108 | B40: 1 | C40: SIVIERO EMPREENDIMENTOS IMOBILIARIOS LTD | D40: PREFEITURA MUNICIPAL DE NOVA PRATA | E40: 45114 | F40: 45114 | G40: 1528.21 | H40: 1528.21 | I40: P.1/4-IPTU ANO 2023-LOTEAMENTO COLINA DO BASA | K40: 45474 | L40: 45475 | M40: SALVADOR – FEMAÇÃ II | N40: VERANÓPOLIS | O40: 03 | P40: 02 | Q40: Inês Ansolin Pessutto | R40: 714000 | S40: R$ 714.000,00 | T40: Sim (2 lotes) | U40: Vendido, como forma pagamento área terras em Vila Azul, valor de R$ 714.000,00.
...

Sheet Lotes Vendidos (todos)
A1: Data | B1: Loteamento | C1: Município | D1: Lote | E1: Quadra | F1: Comprador | G1: Valor citado | H1: Valores no texto | I1: Venda conjunta | J1: Observações | K1: Mês | L1: No período dos relatórios | M1: Página PDF
A2: 33744 | B2: SALVADOR – FEMAÇÃ II | C2: VERANÓPOLIS | D2: 02 | E2: 04 | F2: Volmir Marinello | J2: Vendido à vista. | K2: 33725 | L2: Não | M2: 3
A3: 34673 | B3: PRATA | C3: NOVA PRATA | D3: 03 | E3: E | F3: Quadri – CVC Construções / Cigano-Alfredo Estevan / Umberto Colla | J3: Lote dado como forma de pagamento pavimentação. Estava em aberto, pois faltava a cadeia de contratos. | K3: 34669 | L3: Não | M3: 1
A4: 36907 | B4: PRATA | C4: NOVA PRATA | D4: 13 | E4: K | F4: Quadri – CVC Construções Cigano-Jorge Saul / Bordignon / Vuelma / Almir Rui | J4: Lote dado como forma de pagamento pavimentação. Estava em aberto, pois faltava a cadeia de contratos. | K4: 36892 | L4: Não | M4: 1
A5: 38860 | B5: SALVADOR – FEMAÇÃ II | C5: VERANÓPOLIS | D5: 02 | E5: 01 | F5: Leonildo Marinello | J5: Vendido à vista. | K5: 38838 | L5: Não | M5: 3
A6: 39010 | B6: COLINA DO RETIRO II | C6: VERANÓPOLIS | D6: 14 | E6: 16 | F6: Cesar Sebben | J6: Julcimar Frainer, em troca de pavimentação. | K6: 38991 | L6: Não | M6: 2
A7: 39965 | B7: COLINA DO RETIRO II | C7: VERANÓPOLIS | D7: 04 | E7: 16 | F7: Cristiano Lucchetta | J7: Julcimar Frainer, em troca de pavimentação. | K7: 39965 | L7: Não | M7: 2
A8: 40592 | B8: MONTE VÊNETO | C8: COTIPORÃ | D8: 01 | E8: 09 | F8: Irineu Siviero | I8: Sim (2 lotes) | J8: Vendido, como forma de adiantamento para acerto futuro com os demais sócios da empresa. | K8: 40575 | L8: Não | M8: 10
A9: 40592 | B9: MONTE VÊNETO | C9: COTIPORÃ | D9: 02 | E9: 09 | F9: Irineu Siviero | I9: Sim (2 lotes) | J9: Vendido, como forma de adiantamento para acerto futuro com os demais sócios da empresa. | K9: 40575 | L9: Não | M9: 10
A10: 41467 | B10: INDUSTRIAL PEDRA LISA | C10: VERANÓPOLIS | D10: 06 | E10: 05 | F10: Poletto Metalúrgica Ltda. | J10: Vendido à prazo, em 06x. | K10: 41456 | L10: Não | M10: 8
A11: 41592 | B11: INDUSTRIAL PEDRA LISA | C11: VERANÓPOLIS | D11: 04 | E11: 03 | F11: Ivo José Frainer | J11: Vendido à vista. | K11: 41579 | L11: Não | M11: 8
A12: 41611 | B12: ALTOS DAS GRAÇAS | C12: CAXIAS DO SUL | D12: 12 | E12: 6370 | F12: João Daniel Pereira | J12: Vendido â vista. | K12: 41609 | L12: Não | M12: 15
A13: 41696 | B13: INDUSTRIAL VICENTINO | C13: FARROUPILHA | D13: 04 | E13: 1302 | F13: Alcides Basso Imóveis. | G13: 1427000 | H13: R$ 552.000,00; R$ 1.427.000,00 | J13: Vendido, com permuta de 03 veículos – ônibus + R$ 552.000,00 em 60 parcelas, pagas pela Siviero = R$ 1.427.000,00. | K13: 41671 | L13: Não | M13: 3
A14: 41729 | B14: INDUSTRIAL VICENTINO | C14: FARROUPILHA | D14: 04 | E14: 1303 | F14: L. F. Transportes Ltda. | G14: 1170000 | H14: R$ 1.170.000,00 | J14: Vendido à vista, com parte permuta de outro imóvel, valor de R$ 1.170.000,00. | K14: 41699 | L14: Não | M14: 3
A15: 41783 | B15: ALTOS DAS GRAÇAS | C15: CAXIAS DO SUL | D15: 09 | E15: 6371 | F15: Bruno Pinheiro Bitencourt | J15: Vendido à vista. | K15: 41760 | L15: Não | M15: 15
A16: 41815 | B16: ALTOS DAS GRAÇAS | C16: CAXIAS DO SUL | D16: 02 | E16: 6374 | F16: Pedreira SS Ltda. | I16: Sim (2 lotes) | J16: Vendido, como forma de pagamento na prestação de serviços de pavimentação do Sistema Viário do Loteamento Altos das Graças, com o fornecimento de materiais e mão-de-obra. | K16: 41791 | L16: Não | M16: 16
A17: 41815 | B17: ALTOS DAS GRAÇAS | C17: CAXIAS DO SUL | D17: 03 | E17: 6374 | F17: Pedreira SS Ltda. | I17: Sim (2 lotes) | J17: Vendido, como forma de pagamento na prestação de serviços de pavimentação do Sistema Viário do Loteamento Altos das Graças, com o fornecimento de materiais e mão-de-obra. | K17: 41791 | L17: Não | M17: 16
A18: 41844 | B18: DALLA COSTA | C18: NOVA BASSANO | D18: 05 | E18: 02 | F18: Domício Mileski | J18: Proprietário dos lotes adquiridos e instalado um bar. | K18: 41821 | L18: Não | M18: 1
A19: 41876 | B19: ALTOS DAS GRAÇAS | C19: CAXIAS DO SUL | D19: 01 | E19: 6365 | F19: Bidal Empreend.Imob.Ltda | G19: 380000 | H19: R$ 210.000,00; R$ 380.000,00 | I19: Sim (2 lotes) | J19: Vendido, como forma de pagamento de parte do apartamento de Luís Artur Siviero, em Caixas do Sul + o valor de R$ 210.000,00, pagos em 21 parcelas, totalizando R$ 380.000,00. | K19: 41852 | L19: Não | M19: 15
A20: 41876 | B20: ALTOS DAS GRAÇAS | C20: CAXIAS DO SUL | D20: 02 | E20: 6365 | F20: Bidal Empreend.Imob.Ltda | G20: 380000 | H20: R$ 210.000,00; R$ 380.000,00 | I20: Sim (2 lotes) | J20: Vendido, como forma de pagamento de parte do apartamento de Luís Artur Siviero, em Caixas do Sul + o valor de R$ 210.000,00, pagos em 21 parcelas, totalizando R$ 380.000,00. | K20: 41852 | L20: Não | M20: 15
A21: 42017 | B21: INDUSTRIAL PEDRA LISA | C21: VERANÓPOLIS | D21: 07 | E21: 05 | F21: Poletto Metalúrgica Ltda. | J21: Vendido à vista. | K21: 42005 | L21: Não | M21: 8
A22: 42166 | B22: INDUSTRIAL PEDRA LISA | C22: VERANÓPOLIS | D22: 02 | E22: 05 | F22: Poletto Metalúrgica Ltda. | G22: 170000 | H22: R$ 170.000,00 | J22: Vendido à prazo, com permuta de 01 veículo por R$ 170.000,00 e a diferença em 06x. | K22: 42156 | L22: Não | M22: 8
A23: 42719 | B23: ALTOS DAS GRAÇAS | C23: CAXIAS DO SUL | D23: 12 | E23: 6373 | F23: Via Nova Engenharia Ltda. | J23: Vendido, como forma de pagamento de prestação de serviços, PERMUTADO com 01 lote do Loteamento Caminhos do Sol, no percentual de 2,00%, conforme contratado no contrato de prestação de serviços para legalização e aprovação do Loteamento Boff. | K23: 42705 | L23: Não | M23: 16
A24: 42745 | B24: DALLA COSTA | C24: NOVA BASSANO | D24: 06 | E24: 02 | F24: Domício Mileski | J24: Proprietário dos lotes adquiridos e instalado um bar. | K24: 42736 | L24: Não | M24: 1
A25: 42814 | B25: ADITIVO MEDIANEIRA | C25: VERANÓPOLIS | D25: 05 | E25: 06 | F25: Agustinho Dall Agnol | J25: Vendido à vista. | K25: 42795 | L25: Não | M25: 4
A26: 42857 | B26: BARBIERO | C26: NOVA PRATA | D26: 09 | E26: 03 | F26: Valdecir Berlato | I26: Sim (2 lotes) | J26: Vendido à vista. | K26: 42856 | L26: Não | M26: 4
A27: 42857 | B27: BARBIERO | C27: NOVA PRATA | D27: 10 | E27: 03 | F27: Valdecir Berlato | I27: Sim (2 lotes) | J27: Vendido à vista. | K27: 42856 | L27: Não | M27: 4
A28: 42867 | B28: BARBIERO | C28: NOVA PRATA | D28: 03 | E28: 04 | F28: Paulo Rogério Belaver | J28: Vendido à vista. | K28: 42856 | L28: Não | M28: 4
A29: 42926 | B29: BAÚ | C29: CARLOS BARBOSA | D29: 03 | E29: 14 | F29: Eduardo Campanha | J29: Vendido à vista. | K29: 42917 | L29: Não | M29: 2
A30: 42983 | B30: BARBIERO | C30: NOVA PRATA | D30: 04 | E30: 03 | F30: Banco Sicredi Nova Prata | J30: Vendido à vista. | K30: 42979 | L30: Não | M30: 3
A31: 43090 | B31: BARBIERO | C31: NOVA PRATA | D31: 05 | E31: 02 | F31: Rafael Mattiuz | J31: Vendido à prazo | K31: 43070 | L31: Não | M31: 3
A32: 43102 | B32: CARNEVALLI | C32: NOVA PRATA | D32: 04 | E32: F | F32: CVC Construções Ltda. | J32: Vendido, como forma de pagamento de pavimentação no Loteamento Barbiero, de Nova Prata. | K32: 43101 | L32: Não | M32: 11
A33: 43102 | B33: CARNEVALLI | C33: NOVA PRATA | D33: 05 | E33: F | F33: CVC Construções Ltda. | I33: Sim (3 lotes) | J33: Percentual referente à Pavimentação do Loteamento Carnevalli, de Nova Prata. | K33: 43101 | L33: Não | M33: 11
A34: 43102 | B34: CARNEVALLI | C34: NOVA PRATA | D34: 06 | E34: F | F34: CVC Construções Ltda. | I34: Sim (3 lotes) | J34: Percentual referente à Pavimentação do Loteamento Carnevalli, de Nova Prata. | K34: 43101 | L34: Não | M34: 11
A35: 43102 | B35: CARNEVALLI | C35: NOVA PRATA | D35: 07 | E35: G | F35: CVC Construções Ltda. | I35: Sim (3 lotes) | J35: Percentual referente à Pavimentação do Loteamento Carnevalli, de Nova Prata. | K35: 43101 | L35: Não | M35: 11
A36: 43136 | B36: ALTOS DA JULIETA | C36: FARROUPILHA | D36: 07 | E36: 1724 | F36: Inês Colombo Bartelle | I36: Sim (2 lotes) | J36: Vendido, conforme acordo extrajudicial pelo distrato do Contrato do Loteamento, em virtude da não execução do Loteamento dentro do prazo contratual, no todo da Família Colombo. | K36: 43132 | L36: Não | M36: 12
A37: 43136 | B37: ALTOS DA JULIETA | C37: FARROUPILHA | D37: 07 | E37: 1731 | F37: Inês Colombo Bartelle | I37: Sim (2 lotes) | J37: Vendido, conforme acordo extrajudicial pelo distrato do Contrato do Loteamento, em virtude da não execução do Loteamento dentro do prazo contratual, no todo da Família Colombo. | K37: 43132 | L37: Não | M37: 12
A38: 43174 | B38: LAGO NEGRO | C38: GRAMADO | D38: 09 | E38: 05 | F38: Vanderson José Baumgratz | J38: Vendido à vista. | K38: 43160 | L38: Não | M38: 9
A39: 43202 | B39: LAGO NEGRO | C39: GRAMADO | D39: 08 | E39: 06 | F39: Ronei Alencar Ferronatto | J39: Vendido à vista. | K39: 43191 | L39: Não | M39: 9
A40: 43297 | B40: CARNEVALLI | C40: NOVA PRATA | D40: 10 | E40: A | F40: Lindomar A. dos Santos | J40: Vendido à vista. | K40: 43282 | L40: Não | M40: 11
...

Sheet Conferência
A1: Mês | B1: Arquivo | C1: Empresa | D1: Linhas | E1: Soma Valor Dupl. | F1: Subtotal impresso | G1: Diferença | H1: Notas
A2: 45108 | B2: 2023-07 | C2: SIVIERO EMPREENDIMENTOS IMOBILIARIOS LTD | D2: 177 | E2: 1165697.9 | F2: 1165697.9 | G2: 0 | H2: Periodo impresso 01/07/2023 - 31/07/2023 confere com a tag 2023-07; emissao 02/08/2023; 5 paginas; 3 secoes (SIVIERO EMPREENDIMENTOS, TRANSPORTADORA IRMAOS SIVIERO, ABASTECEDORA).; Observacoes cortadas na margem direita do scan: mantido o texto visivel; letra parcialmente cortada na borda foi mantida quando reconhecivel (ex.: 'MOTONIVELADO', 'JUNHO').; Fornecedor encostado na data de Venc.: o 37o caractere aparece pela metade. Gravado como 'LTI' quando era a metade de um D (D KEKOS, PROMED, SAO JOAO), 'MATRICU' (OPERADOR NACIONAL DO REGISTRO) e 'ELETRICO' (ENERTEC) quando a meia-letra era reconhecivel como U/O.; L.R. BETT PAVIMENTACOES (p2): Venc. impresso 13/05/23 com Pgto. 13/07/23 - mantido como impresso.; Erros de digitacao do proprio relatorio mantidos: 'EMPRREND.', 'EMPREEEND.', 'PRESTRADOS', 'RALATORIO', 'CAIXIAS', 'PROGAMA', 'MAMOMETRO'.; RADAX DO BRASIL (p4): Valor NF 3.582,13 com Valor Dupl. 358,00 (P. 02/10) - conferido com zoom, impresso assim.
A3: 45108 | B3: 2023-07 | C3: TRANSPORTADORA IRMAOS SIVIERO LTDA. | D3: 67 | E3: 170937.95 | F3: 170937.95 | G3: 0
A4: 45108 | B4: 2023-07 | C4: ABASTECEDORA DE COMBUSTIVEIS SIVIERO LTD | D4: 16 | E4: 14885.25 | F4: 14885.25 | G4: 0
A5: 45139 | B5: 2023-08 | C5: SIVIERO EMPREENDIMENTOS IMOBILIARIOS LTD | D5: 181 | E5: 668125.99 | F5: 668125.99 | G5: 0 | H5: Periodo impresso 01/08/2023 - 31/08/2023 confere com a tag 2023-08; emissao 06/09/2023; 5 paginas; 3 secoes (SIVIERO EMPREENDIMENTOS, TRANSPORTADORA IRMAOS SIVIERO, ABASTECEDORA). Nenhuma celula ilegivel.; Observacoes cortadas na margem direita do scan: mantido o texto visivel; letra parcialmente cortada na borda mantida quando reconhecivel (ex.: 'PRACA G', 'TIS/SEI/A', 'MARCO', 'RETRO+CAC', 'DE 202'); omitida quando irreconhecivel (ex.: depois de 'PAVIMENTACAO' p1 RODRIGO KAISER, 'IUV' p1 RAMPA, 'GELATINA+' p3 SUPERMERCADO FRASSUL).; Fornecedor encostado na data de Venc.: 37o caractere pela metade. Gravado como 'LTI' (D KEKOS, SAO JOAO, PROMED), 'MATRICU' (OPERADOR NACIONAL DO REGISTRO), 'ELETRICO' (ENERTEC), 'VERANOPOL' (RAMPA DE LAVAGEM VALVERDE), seguindo a convencao de 2023-07.; L.R. BETT PAVIMENTACOES (p2): Venc. impresso 13/06/23 com Pgto. 14/08/23 - conferido com zoom, mantido como impresso.; Valores conferidos com zoom e impressos assim: CARBONERA (p3) NF 2.400,00 / Dupl 819,39 (P.1/3); RADAX (p5) NF 1.542,38 / Dupl 428,51 (P. 01/04); RADAX (p4) NF 3.582,13 / Dupl 358,00; TSD (p4) 831,13 / 207,79 e (p5) 831,13 / 207,78; ANTONIO ANSOLIN (p2) NF 586.666,00.; Pontilhados copiados com a contagem impressa: LADIR MADRUGA (p2) 'EM ............. - A' (13 pontos); PREFEITURA DE GUAPORE (p3) 'QDRA ..........' (10 pontos).; 'O1' com letra O (nao zero) em 'O1 PULVERIZADOR' (p3 ORSO) e 'CONST-O1' (p3 ZANELLA), como impresso.; Erros de digitacao do proprio relatorio mantidos: 'EMPRREND.' (PIS p3), 'EMPREEEND.', 'PROGAMA', 'MAMOMETRO', 'ELETRECISTA', 'HERBECIDAS', 'P.20/22--COMPRA'.; Linhas impressas com distorcao do scan (MOLIN & SLOMP p1, POSITIVA p2, HOTEL ARACA p3) lidas sem ambiguidade.
A6: 45139 | B6: 2023-08 | C6: TRANSPORTADORA IRMAOS SIVIERO LTDA. | D6: 71 | E6: 183210.32 | F6: 183210.32 | G6: 0
A7: 45139 | B7: 2023-08 | C7: ABASTECEDORA DE COMBUSTIVEIS SIVIERO LTD | D7: 14 | E7: 4275.02 | F7: 4275.02 | G7: 0
A8: 45200 | B8: 2023-10 | C8: SIVIERO EMPREENDIMENTOS IMOBILIARIOS LTD | D8: 184 | E8: 385521.64 | F8: 385521.64 | G8: 0 | H8: Periodo impresso 01/10/2023 - 31/10/2023 confere com a tag 2023-10; emissao 07/11/2023; 6 paginas; 3 secoes (SIVIERO EMPREENDIMENTOS, TRANSPORTADORA IRMAOS SIVIERO, ABASTECEDORA). A pagina 6 contem apenas o Subtotal da ABASTECEDORA (3.790,28) e o Total; suas linhas estao todas na pagina 5. A metade inferior da pagina 6 esta em branco.; Observacoes cortadas na margem direita do scan: mantido o texto visivel; letra parcialmente cortada mantida quando reconhecivel (ex.: 'BIA', 'SETEMBRO', 'MARCO', 'VERA', 'MOTONIVELADO', 'BOBINA=V'). Fragmentos irreconheciveis na borda foram omitidos: DIGITAL WAY p3 ('COMPUTADOR SUZI' + meia letra) e ANTONINHO JOSE ZANELLA p3 25/10 ('ENTULHO O' + meia letra).; Fornecedor encostado na data de Venc.: o 37o caractere aparece pela metade. Seguindo a convencao do mes 2023-07: 'LTI' para a metade de um D (D KEKOS x3, PROMED, SAO JOAO x2), 'MATRICU' (OPERADOR NACIONAL DO REGISTRO x2), 'ELETRICO' (ENERTEC) e 'CHAPEAC' (CLAIRTON VENDRAMIN, p2). 'SIMONETTO ... LTDA' (p1 e p3) cabe inteiro antes da data.; CONSULTAMB - JAQUELINE BONATT0 (p3): o ultimo caractere e impresso como algarismo zero (mais estreito que a letra O) - mantido como impresso.; Venc. posterior ao Pgto. mantido como impresso (ex.: L.R. BETT e LUIS CARLOS MERCALI 13/10 pagos 11/10; COOPERATIVA SANTA CLARA 13/10 paga 11/10). Venc. de setembro pagos em outubro: SIMONETTO 27/09/23, CHAPEACAO BIDJA 29/09/23.; Erros de digitacao do proprio relatorio mantidos: 'EMPRREND.', 'EMPREEEND.', 'CONTRUCAO', 'CATTERPILAR', 'PROGAMA', 'MAMOMETRO', 'SETEEMBRO', 'PINHERIOS', 'THINER'. TSD LOGISTICA NF 1.146,44: Dupl. 229,28 (p4) e 229,29 (p5, duas vezes) - conferido, impresso assim. RADAX (p4) NF 3.582,13 com Dupl. 358,00 (P. 05/10), igual ao padrao de 2023-07.; Linhas RESTAURANTE - CAXIAS DO SUL (p1), POSITIVA COMUNICACAO E MARKETING LTDA (p2) e BANCO SICREDI 26/10 (p3) impressas em fonte menor; lidas com zoom.
A9: 45200 | B9: 2023-10 | C9: TRANSPORTADORA IRMAOS SIVIERO LTDA. | D9: 75 | E9: 157363.96 | F9: 157363.96 | G9: 0
A10: 45200 | B10: 2023-10 | C10: ABASTECEDORA DE COMBUSTIVEIS SIVIERO LTD | D10: 13 | E10: 3790.28 | F10: 3790.28 | G10: 0
A11: 45231 | B11: 2023-11 | C11: SIVIERO EMPREENDIMENTOS IMOBILIARIOS LTD | D11: 163 | E11: 666440.05 | F11: 666440.05 | G11: 0 | H11: Periodo impresso 01/11/2023 - 30/11/2023 confere com a tag 2023-11; emissao 12/12/2023; 5 paginas (metade inferior da p5 em branco); 3 secoes (SIVIERO EMPREENDIMENTOS, TRANSPORTADORA IRMAOS SIVIERO, ABASTECEDORA). Secao TRANSPORTADORA comeca na p4 (titulo no fim da p3) e continua na p5 sem repetir o titulo.; Anotacoes manuscritas no scan (nao transcritas): 'Visto' e rubrica no cabecalho da p1; tracos a caneta apos a data de Pgto. nas linhas 1-10 da p1.; Observacoes cortadas na margem direita do scan: mantido o texto visivel; letra parcialmente cortada na borda foi mantida quando reconhecivel (ex.: 'CHAPEAC' no fornecedor CLAIRTON, 'WOLKS', 'SAFRA', 'NOVO', 'BOFF-REPO', 'CALCAMENTO', 'OUTUB', 'BOBINA=V'). Fornecedor encostado na data de Venc.: meia-letra gravada como 'LTI' (PROMED, metade de D) e 'COL/' (CHAPEACAO TRANSFORMES), como impresso.; Linhas impressas comprimidas/achatadas verticalmente (falha de impressao, mas legiveis e conferidas com zoom): p1 FABIANO ROGERIO MINOZZO 825,00; p2 VILSON JOSE RIBEIRO 3.000,00; p3 FORUM DE NOVA PRATA 380,78; p4 BRADESCO 4.216,63/1.054,16.; p3 PREFEITURA MUNICIPAL DE PASSO FUNDO 210,33: Observacao termina em 'IPE - I' (letra I, sem a serifa do digito 1, conferido com zoom), mantido como impresso; a linha seguinte termina em 'IPE - 2'.; Erros de digitacao do proprio relatorio mantidos: 'IMOBILARIOS' (JDRX), 'BONATT0' (com zero), 'O1 PAR' (letra O), 'PROGAMA', 'CAIXAS DO SUL', 'EMPREEEND.', 'EMPRREND.', 'NOVEMRO', 'TACOGROFO', 'MAMOMETRO', 'CHAMFRADO'.; Valores NF/Dupl. de todas as paginas conferidos com recortes ampliados; nenhuma celula ilegivel.
A12: 45231 | B12: 2023-11 | C12: TRANSPORTADORA IRMAOS SIVIERO LTDA. | D12: 58 | E12: 154753.09 | F12: 154753.09 | G12: 0
A13: 45231 | B13: 2023-11 | C13: ABASTECEDORA DE COMBUSTIVEIS SIVIERO LTD | D13: 14 | E13: 4056.08 | F13: 4056.08 | G13: 0
A14: 45261 | B14: 2023-12 | C14: SIVIERO EMPREENDIMENTOS IMOBILIARIOS LTD | D14: 185 | E14: 1022872.6 | F14: 1022872.6 | G14: 0 | H14: Periodo impresso 01/12/2023 - 31/12/2023 confere com a tag 2023-12; emissao 11/01/2024; 6 paginas (p6 so com 5 linhas da ABASTECEDORA, Subtotal e Total; metade inferior da p6 em branco); 3 secoes (SIVIERO EMPREENDIMENTOS, TRANSPORTADORA IRMAOS SIVIERO, ABASTECEDORA).; Observacoes cortadas na margem direita do scan: mantido o texto visivel; letra parcialmente cortada mantida quando reconhecivel (ex.: 'NOVEMBR', 'VAGNER', 'RESERVATORIOS', 'MATRICULA', 'BOBINA=V'); fragmento irreconhecivel omitido (ex.: 'CAMPES' p3) ou gravado como aparece ('NOVEMBRO DI' p5, 'FRANCEL' p4).; Fornecedor encostado na data de Venc.: gravado 'LTI' para meia-letra D (D KEKOS p1, SAO JOAO TRANSPORTES p4, PROMED p5), 'MATRICU' (OPERADOR NACIONAL DO REGISTRO p1/p2), 'VERANOPOL' (MARCOS ROSSA p2, RAMPA DE LAVAGEM p4), 'L' (RODOBENS), 'PRA' (CVC CONSTRUCOES), 'LTD' (ARDRILL, D inteiro visivel), 'LTDA' (EQUIPAMENTOS ESCRITORIO REGIONAL).; ANTONINHO JOSE ZANELLA (p1, venc 01/12/23): Valor Dupl. 910,05 maior que Valor NF 887,00 - conferido com zoom, impresso assim.; Vencimentos anteriores ao periodo mantidos como impressos (29/11/23, 24/11/23, 28/11/23 na p1); PARANA EQUIPAMENTOS e SIM REDE (p4) e SIM REDE FLORES DA CU (p5) com Venc. 31/12/23 e Pgto. 28/12/23, e ANTONINHO ZANELLA (p4) Venc. 29/12/23 Pgto. 28/12/23 - mantidos como impressos.; Erros de digitacao do proprio relatorio mantidos: 'EMPRREND.', 'EMPREEEND.', 'EMPREED.', 'PROGAMA', 'DEZEMRO', 'MAMOMETRO', 'RENOVAAO', 'PLAHET'.; Varias linhas repetidas identicas impressas (ex.: 4x e 7x BANCO ESTADO - TIS 11,50; 3x BANCO ESTADO - SEI 207,87; 2x DIANA FIORI 100,59) - todas transcritas; a soma confere com os subtotais.
A15: 45261 | B15: 2023-12 | C15: TRANSPORTADORA IRMAOS SIVIERO LTDA. | D15: 78 | E15: 216221.5 | F15: 216221.5 | G15: 0
A16: 45261 | B16: 2023-12 | C16: ABASTECEDORA DE COMBUSTIVEIS SIVIERO LTD | D16: 14 | E16: 3840.28 | F16: 3840.28 | G16: 0
A17: 45292 | B17: 2024-01 | C17: SIVIERO EMPREENDIMENTOS IMOBILIARIOS LTD | D17: 148 | E17: 343100.52 | F17: 343100.52 | G17: 0 | H17: Periodo impresso 01/01/2024 - 31/01/2024 confere com a tag 2024-01; emissao 21/02/2024; 5 paginas (pagina 5 so tem a metade superior impressa; metade inferior em branco); 3 secoes (SIVIERO EMPREENDIMENTOS, TRANSPORTADORA IRMAOS SIVIERO, ABASTECEDORA).; Observacoes cortadas na margem direita do scan: mantido o texto visivel; letra parcialmente cortada mantida quando reconhecivel (ex.: 'FORD RANGE', 'CONTAS-TIS/SEI/A', 'SENHORA DE LOUR', 'FLORES DA CUNHA', 'PERTO DO', 'CONTRATO FAMILIA', 'MORADA DO', 'CARRO-ACIDENT', 'PNEUS CACAM', 'RS.COM.BR-DEZEM', 'CONTABEIS-DEZEMBRO DE'). Traco vertical solto nao identificavel na borda foi omitido (p1 'ANTAS=24 M', 'TABELIONATO/VERANOPOLIS-', 'FRETES+CORREIOS+'; p2 'LOTE PERTO HOSPI' (resto de possivel T), 'RECONHECIMENTOS = DEZEMBRO/'; p4 'ESCRITORIO SIVIERO-VERANOPOLI').; Fornecedor encostado na data de Venc.: o 37o caractere aparece pela metade. Gravado como 'LTI' quando era a metade de um D (PROMED, SAO JOAO), 'ELETRICO' (ENERTEC), 'MATRICU' (OPERADOR NACIONAL DO REGISTRO) e 'CHAPEAC' (CLAIRTON VENDRAMIN) conforme a meia-letra visivel.; PAULO RICARDO PALUDO (p1, 04/01/24, 770,00): Observacao comeca com 'O1' (letra O, como impresso, nao zero) - conferido com zoom.; CONSULTAMB - JAQUELINE BONATT0 (p1): ultimo caractere impresso como digito zero ('BONATT0'), mantido.; BANCO ESTADO RIO GRANDE DO SUL - TIS (p5, 30/01/24, 43,44): mancha sobre o O de 'ESCRITORIO' parece sujeira do scan, nao acento; gravado 'ESCRITORIO' (mesmo texto da linha de 02/01/24 na p3).; MULTI CELTACAR (p2): Valor NF 1.005,00 com Valor Dupl. 502,00 (P. 1/2) - conferido com zoom, impresso assim (nao 502,50).; SUL TURBOS (p1 P.2/3 = 833,33; p3 P.3/3 = 833,34) e RSC COMERCIO KIT EMBREAGEM (p4 P.01/03 = 1.108,34; P.02/03 = 1.108,33) - centavos de arredondamento conferidos.; MARQUESFRIO (p3): Venc. impresso 28/12/23 com Pgto. 24/01/24 - mantido como impresso.; Erros de digitacao do proprio relatorio mantidos: 'EMPRREND.', 'EMPREEEND.', 'PRESTRADOS', 'PROGAMA', 'MAMOMETRO', 'UINICA', 'JEPP', 'ESPUMATES', 'TRASSEIRA', 'MOTOSSERA', 'VIVIERO', 'SIVIEROU', 'RAVA', '1.00%'.; Acentos impressos mantidos: 'VERANÓPOLIS' (BANCO SICREDI), 'INFORMÁTICA' (RS MICRO), 'PAVILHÃO', 'QUÍMICA' (BOFF ENGENHARIA), 'IPÊS', 'ÁREA', 'M²'.; Espacos duplos estimados pelo espacamento visivel: 'ADYL NET - INTERNET LTDA.' (p1, p4), 'FLAVIA MANICA - ENGENHEIRA CIVIL' (p2), 'LADIR MADRUGA - CAXIAS DO SUL' (p3), 'CH 024074' (p3, MARQUESFRIO).
A18: 45292 | B18: 2024-01 | C18: TRANSPORTADORA IRMAOS SIVIERO LTDA. | D18: 73 | E18: 154069.3 | F18: 154069.3 | G18: 0
A19: 45292 | B19: 2024-01 | C19: ABASTECEDORA DE COMBUSTIVEIS SIVIERO LTD | D19: 13 | E19: 3812.25 | F19: 3812.25 | G19: 0
A20: 45323 | B20: 2024-02 | C20: SIVIERO EMPREENDIMENTOS IMOBILIARIOS LTD | D20: 140 | E20: 295923.8 | F20: 295923.8 | G20: 0 | H20: Periodo impresso 01/02/2024 - 29/02/2024 confere com a tag 2024-02; emissao 28/03/2024; 4 paginas; 3 secoes (SIVIERO EMPREENDIMENTOS, TRANSPORTADORA IRMAOS SIVIERO, ABASTECEDORA).; Observacoes cortadas na margem direita do scan: mantido o texto visivel; letra parcialmente cortada na borda mantida quando reconhecivel.; Fornecedor encostado na data de Venc.: gravado 'LTI' para meia-letra D (D KEKOS p2, PROMED p4, SAO JOAO p4), como na referencia 2023-07; 'CONSORCIOS L', 'DE IMOV', 'TOPOGRAFI', 'LTDA.' gravados como visiveis.; L.R. BETT PAVIMENTACOES (p1): Venc. impresso 13/07/23 com Pgto. 14/02/24, mesmo valor e obs (P. 07/10) que a linha L.R. BETT de 21/02/24 na p2 - mantido como impresso.; Venc. posterior ao Pgto. impresso em OFICINA MECANICA VACCARI (p1, 02/02/24 x 01/02/24) e MARANGONI (p3, 02/02/24 x 01/02/24) - mantido.; Erros de digitacao do proprio relatorio mantidos: 'EMPRREND.', 'EMPREEEND.', 'EMPREED.', 'PROGAMA', 'MAMOMETRO', 'REREAPROVACAO', 'ELETRECISTA', 'FRANCELICIOC'.; RADAX DO BRASIL (p4): Valor NF 3.582,13 com Valor Dupl. 358,00 (P. 10/10); RGE (p4) 0,01; BANCO SICREDI (p1) 0,17 - conferidos com zoom, impressos assim.
A21: 45323 | B21: 2024-02 | C21: TRANSPORTADORA IRMAOS SIVIERO LTDA. | D21: 58 | E21: 158589.35 | F21: 158589.35 | G21: 0
A22: 45323 | B22: 2024-02 | C22: ABASTECEDORA DE COMBUSTIVEIS SIVIERO LTD | D22: 13 | E22: 5319.73 | F22: 5319.73 | G22: 0
A23: 45352 | B23: 2024-03 | C23: SIVIERO EMPREENDIMENTOS IMOBILIARIOS LTD | D23: 177 | E23: 674950.76 | F23: 674950.76 | G23: 0 | H23: Periodo impresso 01/03/2024 - 31/03/2024 confere com a tag 2024-03; emissao 17/05/2024; 5 paginas; 3 secoes (SIVIERO EMPREENDIMENTOS, TRANSPORTADORA IRMAOS SIVIERO, ABASTECEDORA). Pagina 5 (metade inferior) contem apenas o Total.; Observacoes cortadas na margem direita do scan: mantido o texto visivel; meia-letra na borda gravada conforme a forma visivel/reconhecivel (ex.: 'COMPRA A', 'CALCADA', 'FEVEREIRO/202', 'ARQUIVO', 'ESPACO SO', 'ESPACO SOC', 'AREA CAMP', 'GESSO ESP', 'VERANOPOLIS OU'); quando so aparece um traco vertical foi gravado 'I' (ex.: 'ARBORIZACAO UI', 'CAMIONETI', 'LOTEAMENTO I', 'RETROESCAVAI', 'TANQUI', 'FEVEREIRO DI').; Fornecedor encostado na data de Venc.: 'OPERADOR NACIONAL DO REGISTRO-MATRICU' (p1 e p4, meia-letra lida como U, mesma convencao de 2023-07); 'RAMPA DE LAVAGEM VALVERDE - VERANOPOL' (p3, L meio visivel).; Linhas com impressao achatada/cortada na base mas legiveis (conferidas com zoom): INST. ELETRICA LIDER LTDA. (p1), SAO LUIZ CONSTRUCOES E SERVICOS LTDA. x2 (p3), COMABE AUTOMACAO ... 18/03/24 (p4).; Venc. anterior ao mes mantido como impresso: INST. ELETRICA LIDER (p1) venc 10/02/24; ROVILIO ANTONIO DAL MAS (p1) venc 27/02/24; L.R. BETT PAVIMENTACOES (p3) venc 13/10/23; SAO LUIZ CONSTRUCOES x2 (p3) venc 27/11/23.; Erros/grafias do proprio relatorio mantidos: 'EMPRREND.' (PIS p3), 'EMPREEEND.', 'LEMPEZA', 'PROGAMA', 'PINHERIOS', 'QADRA', 'PLAHET', 'VIVIERO NPR', 'NPQ 0I67', 'IYJ 8I14', 'MATRICULA ATUALIZADA 28. 118 ......... ???' (p2, impresso assim).; Valor NF x Valor Dupl. atipicos conferidos com zoom e impressos assim: SUPER PNEUS (p2) NF 4.900,00 / Dupl 1.634,00 (P.01/03); CARBONERA (p3) NF 4.057,28 / Dupl 1.012,28 (P.4/4); EDIR DAL SASSO (p2) duas linhas NF 1.300,00 com Dupl 1.050,00 e 250,00; LUBIA CORSO (p1) duas linhas P.2/2 NF 7.800,00 com Dupl 3.100,00 e 800,00; SAO LUIZ (p3) NF 18.500,00 com Dupl 6.000,00 e 1.500,00; SANDRA MARIA MORO NF 8.200,00 com Dupl 4.200,00 (p2) e 4.000,00 (p3).
A24: 45352 | B24: 2024-03 | C24: TRANSPORTADORA IRMAOS SIVIERO LTDA. | D24: 47 | E24: 148559.03 | F24: 148559.03 | G24: 0
A25: 45352 | B25: 2024-03 | C25: ABASTECEDORA DE COMBUSTIVEIS SIVIERO LTD | D25: 13 | E25: 5867.78 | F25: 5867.78 | G25: 0
A26: 45383 | B26: 2024-04 | C26: SIVIERO EMPREENDIMENTOS IMOBILIARIOS LTD | D26: 192 | E26: 881710.15 | F26: 881710.16 | G26: -0.01 | H26: Diferenca de -0,01 no subtotal SIVIERO EMPREENDIMENTOS confirmada no proprio relatorio (releitura independente das 192 linhas): AZUL COMPANHIA DE SEGUROS GERAIS (p3) imprime 1.500,17 como parcela P.4/4 de NF 6.000,72 (6.000,72/4 = 1.500,18); o sistema provavelmente somou 1.500,18 no subtotal. Mantido o valor impresso.; Periodo impresso 01/04/2024 - 30/04/2024 confere com a tag 2024-04; emissao 22/05/2024; 5 paginas; 3 secoes (SIVIERO EMPREENDIMENTOS, TRANSPORTADORA IRMAOS SIVIERO, ABASTECEDORA).; SIVIERO EMPREENDIMENTOS: soma das 192 linhas = 881.710,15, subtotal impresso = 881.710,16 (diferenca de 0,01 nao reconciliada). Todos os Valor Dupl. da secao foram relidos com zoom (2,5x-4x) e conferem com o impresso; parcelas nao exatas (ex.: SUL TURBOS 766,66 = 2.300,00/3; DELL 291,35; SUHAI 479,42; RADAX 781,09) sugerem arredondamento de centavos interno do sistema. Nenhum valor foi ajustado. As outras duas secoes e o Total (881.710,16 + 168.891,18 + 7.283,77 = 1.057.885,11) conferem.; Observacoes cortadas na margem direita do scan: mantido o texto visivel; letra parcialmente cortada mantida quando reconhecivel (ex.: 'BARBIERO' p1, 'MOTONIVELADORA' p2, 'EQUIPAMENT' p2, 'HIDRAUL' p2). Meia-letra irreconhecivel omitida: 'LISA-NA' (p2 FEPAM), 'MANGUEIRA' (p2 CAVEMAQ 188,20), 'ESCAVADEIRA - O' (p3 D KEKOS 822,25), 'DAS EMP' (p4 DIGITAL WAY 50,00), 'MARC' (p5 PRESSA), 'IKR 2' (p5 INSPESUL), 'MARCO DE 20' (p5 MERCATO/ABASTECEDORA).; Fornecedor encostado na data de Venc.: meia-letra final gravada como 'LTI' (D KEKOS p2/p3, SAO JOAO p4, PROMED p4), seguindo a convencao do mes de referencia; 'CONSORCIOS L', 'LTD' (CAVEMAQ), 'NOVA PRA', 'VALVER', 'VERANOPO', 'REGIONAL LTDA' como impressos.; Datas fora do padrao mantidas como impressas: PEDRO SIVIERO venc 30/11/23 (p2 e p3) e 28/12/23 (p3); HOTEL ARACA LTDA venc 28/04/24 com pgto 24/04/24 (p3); RAUL SIVIERO venc 28/04/24 e IRINEU SIVIERO venc 25/04/24 com pgto 24/04/24 (p3).; Erros de digitacao do proprio relatorio mantidos: 'EMPREEEND.', 'EMPRREND.' (PIS p3), 'PROGAMA', 'D0S' (zero, p3 MARCIO FRESCHI), 'RETICIACAO', 'TONNER', 'VIVIERO NPR'.; BANCO ESTADO RIO GRANDE DO SUL - SEI 25/04/24 232,26 aparece na ultima linha da p3 e na primeira da p4: sao linhas distintas no impresso (cada uma em sua pagina), ambas transcritas.; Valores pequenos conferidos com zoom: BANCO SICREDI 0,16 (p1) e RGE 0,01 (p5).
A27: 45383 | B27: 2024-04 | C27: TRANSPORTADORA IRMAOS SIVIERO LTDA. | D27: 55 | E27: 168891.18 | F27: 168891.18 | G27: 0
A28: 45383 | B28: 2024-04 | C28: ABASTECEDORA DE COMBUSTIVEIS SIVIERO LTD | D28: 14 | E28: 7283.77 | F28: 7283.77 | G28: 0
A29: 45413 | B29: 2024-05 | C29: SIVIERO EMPREENDIMENTOS IMOBILIARIOS LTD | D29: 187 | E29: 824089.36 | F29: 824089.36 | G29: 0 | H29: Periodo impresso 01/05/2024 - 31/05/2024 confere com a tag 2024-05; emissao 18/07/2024; 5 paginas; 3 secoes (SIVIERO EMPREENDIMENTOS, TRANSPORTADORA IRMAOS SIVIERO, ABASTECEDORA).; MARIA TEREZA FILIPPIN DAL PONTE/FAMIL (p3, 2 linhas): Valor NF impresso '1.010.000,0' - o numero excede a largura da coluna e o ultimo digito nao foi impresso (conferido com zoom). Mantido como impresso; o validador acusa formato nesses 2 campos. Valor Dupl. (70.000,00 e 8.750,74) legivel e conferido.; MARIA TEREZA FILIPPIN DAL PONTE/FAMIL (p3): segunda linha com Venc. 10/06/24 e Pgto. 20/05/24 - mantido como impresso.; CONNECT SISTEMAS LTDA. - NICOLAS SART (p4): Venc. impresso 12/09/24 com Pgto. 28/05/24 - mantido como impresso.; ABASTECEDORA (p5): BANCO ESTADO RIO GRANDE DO SUL - ABA 09/05/24 127,79 aparece duas vezes (ultima linha de p5_a e primeira de p5_b); conferido na emenda das metades: sao duas linhas distintas, e o subtotal 7.726,51 so fecha com as duas.; Observacoes cortadas na margem direita do scan: mantido o texto visivel; letra parcialmente cortada mantida quando reconhecivel (ex.: 'TOYOTAIWB 5G54', 'LTDA', 'CAMPO', 'PAVILHAO', 'ENCHEN', 'TIS/SEI/A', 'PEDRO SIVIERO', 'ESCAVA', 'LOT COL', 'PARTIDA', 'PECA', 'MOTONIVELADO', '- ES'); tracos nao reconheciveis na borda foram omitidos (ex.: apos 'LOTEAMENTO SOLAR', 'AUTENTICACOES', 'CASA FUNCIONARIOS PASSO').; Fornecedor encostado na data de Venc. (37o caractere pela metade), seguindo a convencao de 2023-07: 'LTI' (D KEKOS), 'MATRICU' (OPERADOR NACIONAL DO REGISTRO), 'ELETRICO' (ENERTEC). RODOBENS ADMINISTRADORA CONSORCIOS L: o 'L' aparece inteiro, encostado na data.; Erros de digitacao/grafias do proprio relatorio mantidos: 'PROGAMA', 'EMPREEEND.', 'EMPRREND.', 'TACOGROFOS', 'MOTOSSERA', 'TONNER', 'MAUSES', 'VIVIERO NPR', 'O1 PLACA', '2024-O1 AREA' (letra O no lugar de zero), 'MORADA D0S' (zero no lugar de O, conferido com zoom).
A30: 45413 | B30: 2024-05 | C30: TRANSPORTADORA IRMAOS SIVIERO LTDA. | D30: 50 | E30: 148233.29 | F30: 148233.29 | G30: 0
A31: 45413 | B31: 2024-05 | C31: ABASTECEDORA DE COMBUSTIVEIS SIVIERO LTD | D31: 16 | E31: 7726.51 | F31: 7726.51 | G31: 0
A32: 45444 | B32: 2024-06 | C32: SIVIERO EMPREENDIMENTOS IMOBILIARIOS LTD | D32: 167 | E32: 472050.79 | F32: 472050.79 | G32: 0 | H32: Periodo impresso 01/06/2024 - 30/06/2024 confere com a tag 2024-06; emissao 18/07/2024; 5 paginas (p5 sem linhas da TRANSPORTADORA: so o Subtotal dela no topo); 3 secoes (SIVIERO EMPREENDIMENTOS, TRANSPORTADORA IRMAOS SIVIERO, ABASTECEDORA).; MARIA TEREZA FILIPPIN DAL PONTE/FAMIL (p1): Valor NF impresso '1.010.000,0' (coluna estreita cortou o ultimo digito decimal) - mantido exatamente como impresso; nao completado para ',00'. Unico campo fora do formato 1.234,56 do validador.; Observacoes cortadas na margem direita do scan (campo de 45 caracteres): mantido o texto visivel; letra parcialmente cortada mantida quando reconhecivel (ex.: 'CACAMBAS', 'F.CUNHA', 'DESMEMBRAMENTO A', 'RETIFICACAO A', 'SALVADOR / S', 'KLEITON CANSAN - PF', 'OFICINA=VE', 'PASQUAL-RE', 'PARTIDA', 'ESCA'). Fragmento irreconhecivel omitido em: 'LAVAGEM MOTOR -' (p1), 'ANTONIO PRADO/FLORES' (p2 e p3), 'AUTENTICACOES' (p3), 'HIDRAULICA NO' (p3).; Fornecedor encostado na data de Venc.: meia-letra gravada como 'MATRICU' (OPERADOR NACIONAL DO REGISTRO, p1), 'SERVICOS' (ROBSON DAMMER, p2) e 'LTI' para a metade de um D (D KEKOS, p2), seguindo a convencao de 2023-07.; ROBSON DAMMER - PRESTADOR DE SERVICOS (p2): Venc. 14/06/24 posterior ao Pgto. 13/06/24 - mantido como impresso. IVO JOSE FRAINER (p1): Venc. 25/05/24 com Pgto. 05/06/24 - impresso assim.; Letra O no lugar do zero mantida como impressa: 'O1 AREA' (NOVA PRATA, p2) e 'O2 LOTES' (DESPESAS DIVERSAS, p2).; Erros de digitacao do proprio relatorio mantidos: 'EMPRREND.', 'EMPREEEND.', 'PROGAMA', 'MOTOSSERA', 'TONNER', 'CONEXAO', 'FERRAMENTAIS'.; I.C.M.S. - IMPOSTO ESTADUAL (p4): linha impressa mais clara/fina que as demais, mas legivel (115,93 / 115,93).
A33: 45444 | B33: 2024-06 | C33: TRANSPORTADORA IRMAOS SIVIERO LTDA. | D33: 52 | E33: 142941.11 | F33: 142941.11 | G33: 0
A34: 45444 | B34: 2024-06 | C34: ABASTECEDORA DE COMBUSTIVEIS SIVIERO LTD | D34: 13 | E34: 5867.77 | F34: 5867.77 | G34: 0
