Workbook

Sheet Ativos
A1: Inventários de 31.12.2024 - bens com avaliação de valor
A2: Fonte: pasta 2025/inventário-2025 (coluna J) e inventário-estudo-rafael.pdf (coluna K). Valores em azul transcritos dos documentos. Coluna L (amarela) = participação da Valter conforme cada inventário (1/6 nos itens só do estudo); editável. Quinhão = J x L, ou K x L nos itens que só constam no estudo (a partir da linha marcada em verde).
A3: Versão corrigida em 26/10/2026. Correções aplicadas e pendências: ver aba 'Correções e pendências'. Células com comentário dependem de confirmação.
A4: Nº | B4: Empresa | C4: Categoria | D4: Item no inv. | E4: Descrição | F4: Lote | G4: Quadra | H4: Matrícula | I4: Área | J4: Valor avaliado (R$) | K4: Valor no estudo Rafael (R$) | L4: % Valter | M4: Quinhão Valter (R$) | N4: Arquivo | O4: Observações
A5: 1 | B5: 04 - Ceval Terraplenagem e Escavações Ltda. | C5: Veículo / máquina | D5: 01 | E5: Escavadeira hidráulica Caterpillar 320 D, ano 2009 / modelo 2010 (NF 4946) | J5: 200000 | L5: =1/6 | M5: =J5*L5 | N5: 04. Inventário 31.12.2024 - Ceval Terraplenagem | O5: Avaliada na data da compra.
A6: 2 | B6: 04 - Ceval Terraplenagem e Escavações Ltda. | C6: Veículo / máquina | D6: 02 | E6: Retroescavadeira Case MA 580 L, ano/modelo 2001, placa IKI 4325, chassi JHF0048344 | J6: 70000 | L6: =1/6 | M6: =J6*L6 | N6: 04. Inventário 31.12.2024 - Ceval Terraplenagem
A7: 3 | B7: 04 - Ceval Terraplenagem e Escavações Ltda. | C7: Veículo / máquina | D7: 03 | E7: Caminhão caçamba Mercedes-Benz LK 1313, diesel, 1982, vermelho, placa IHM 0033, Renavam 54294247-0 | J7: 45000 | L7: =1/6 | M7: =J7*L7 | N7: 04. Inventário 31.12.2024 - Ceval Terraplenagem | O7: Avaliado na data da compra.
A8: 4 | B8: 06 - Hotel Araçá Ltda. | C8: Imóvel urbano | D8: 01 | E8: HOTEL ARAÇÁ - 18 terrenos na Quadra 37 (12 matrículas) com prédio de 4 andares, 144 apartamentos, restaurante, convenções, piscinas etc., Rua Miguel Main Felo, 333, Praia do Araçá, Capão da Canoa-RS | F8: 01-12, 18-22 + nesga | G8: 37 | H8: 34.768, 34.769, 34.770, 34.771, 6.411, 29.855, 24.584, 24.585, 33.101, 29.856, 0672, 34.772 | I8: 6.900,00 m² terreno; 10.500,00 m² construídos | J8: 49606823 | L8: =1/6 | M8: =J8*L8 | N8: 06. Inventário 31.12.2024 - Hotel Araçá | O8: Composição na aba 'Composição'. Inventário estima redução de ~R$ 2.000.000,00 (4%) para regularização; INSS da obra ~R$ 1.601.357,90.
A9: 5 | B9: 06 - Hotel Araçá Ltda. | C9: Imóvel urbano | D9: 02 | E9: Lote urbano nº 03 - Quadra 19 - Casa da Praça, Capão da Canoa-RS | F9: 03 | G9: 19 | H9: 77.832 (antiga 37.549) | I9: 450,00 m² | J9: 400000 | K9: 400000 | L9: =1/6 | M9: =J9*L9 | N9: 06. Inventário 31.12.2024 - Hotel Araçá | O9: Inscrição 360.0019.003.000; Código 038998. Também no estudo Rafael (item 02, p. 6), mesmo valor.
A10: 6 | B10: 06 - Hotel Araçá Ltda. | C10: Imóvel urbano | D10: 03 | E10: Lote urbano nº 16 - Quadra 37 - Fundos do Hotel, Capão da Canoa-RS | F10: 16 | G10: 37 | H10: 64.782 | I10: 360,00 m² | J10: 360000 | L10: =1/6 | M10: =J10*L10 | N10: 06. Inventário 31.12.2024 - Hotel Araçá | O10: Inscrição 360.0037.016.000; Código 039395.
A11: 7 | B11: 06 - Hotel Araçá Ltda. | C11: Imóvel urbano | D11: 04 | E11: Lote urbano nº 23 - Quadra 37 - Fundos do Hotel, Capão da Canoa-RS | F11: 23 | G11: 37 | H11: 26.373 | I11: 360,00 m² | J11: 360000 | L11: =1/6 | M11: =J11*L11 | N11: 06. Inventário 31.12.2024 - Hotel Araçá | O11: Inscrição 360.0071.023.000; Código 039839.
A12: 8 | B12: 06 - Hotel Araçá Ltda. | C12: Imóvel urbano | D12: 05 | E12: Lote urbano nº 24 - Quadra 37 - Fundos do Hotel, Capão da Canoa-RS | F12: 24 | G12: 37 | H12: 26.374 | I12: 307,80 m² | J12: 360000 | L12: =1/6 | M12: =J12*L12 | N12: 06. Inventário 31.12.2024 - Hotel Araçá | O12: Inscrição 360.0071.024.000; Código 039840.
A13: 9 | B13: 06 - Hotel Araçá Ltda. | C13: Imóvel urbano | D13: 06 | E13: Lote urbano nº 25 - Quadra 37 - Fundos do Hotel, Capão da Canoa-RS | F13: 25 | G13: 37 | H13: 26.375 | I13: 307,80 m² | J13: 360000 | L13: =1/6 | M13: =J13*L13 | N13: 06. Inventário 31.12.2024 - Hotel Araçá | O13: Inscrição 360.0071.025.000; Código 039841.
A14: 10 | B14: 06 - Hotel Araçá Ltda. | C14: Imóvel urbano | D14: 07 | E14: Lote urbano nº 26 - Quadra 37 - Fundos do Hotel, Capão da Canoa-RS | F14: 26 | G14: 37 | H14: 26.376 | I14: 307,80 m² | J14: 360000 | L14: =1/6 | M14: =J14*L14 | N14: 06. Inventário 31.12.2024 - Hotel Araçá | O14: Inscrição 360.0071.026.000; Código 039842.
A15: 11 | B15: 06 - Hotel Araçá Ltda. | C15: Imóvel urbano | D15: 08 | E15: Lote urbano nº 27 - Quadra 37 - Fundos do Hotel, Capão da Canoa-RS | F15: 27 | G15: 37 | H15: 26.377 | I15: 307,80 m² | J15: 360000 | L15: =1/6 | M15: =J15*L15 | N15: 06. Inventário 31.12.2024 - Hotel Araçá | O15: Inscrição 360.0071.027.000; Código 039843.
A16: 12 | B16: 06 - Hotel Araçá Ltda. | C16: Imóvel urbano | D16: 09 | E16: Lote urbano nº 28 - Quadra 37 - Fundos do Hotel, Capão da Canoa-RS | F16: 28 | G16: 37 | H16: 26.378 | I16: 307,80 m² | J16: 360000 | L16: =1/6 | M16: =J16*L16 | N16: 06. Inventário 31.12.2024 - Hotel Araçá | O16: Inscrição 360.0071.028.000; Código 039844.
A17: 13 | B17: 06 - Hotel Araçá Ltda. | C17: Imóvel urbano | D17: 10 | E17: Lote urbano nº 29 - Quadra 37 - Fundos do Hotel, Capão da Canoa-RS | F17: 29 | G17: 37 | H17: 26.379 | I17: 360,00 m² | J17: 360000 | L17: =1/6 | M17: =J17*L17 | N17: 06. Inventário 31.12.2024 - Hotel Araçá | O17: Inscrição 360.0071.029.000; Código 039845.
A18: 14 | B18: 06 - Hotel Araçá Ltda. | C18: Imóvel urbano | D18: 11 | E18: Lote urbano nº 09 - Quadra 38, próximo ao Hotel, Capão da Canoa-RS. Adquirido de Hugo Ferri | F18: 09 | G18: 38 | H18: 37.846 | I18: 360,00 m² | J18: 390000 | K18: 390000 | L18: =1/6 | M18: =J18*L18 | N18: 06. Inventário 31.12.2024 - Hotel Araçá | O18: Inscrição 360.0038.009.000; Código 039410. Também no estudo Rafael (item 11, p. 6), mesmo valor.
A19: 15 | B19: 06 - Hotel Araçá Ltda. | C19: Imóvel urbano | D19: 12 | E19: Lote urbano nº 10 - Quadra 38, próximo ao Hotel, Capão da Canoa-RS. Adquirido de Hugo Ferri | F19: 10 | G19: 38 | H19: 11.990 | I19: 360,00 m² | J19: 390000 | K19: 390000 | L19: =1/6 | M19: =J19*L19 | N19: 06. Inventário 31.12.2024 - Hotel Araçá | O19: Inscrição 360.0038.010.000; Código 039411. Também no estudo Rafael (item 12, p. 6), mesmo valor.
A20: 16 | B20: 06 - Hotel Araçá Ltda. | C20: Imóvel urbano | D20: 13 | E20: Lote urbano nº 11 - Quadra 38, próximo ao Hotel, Capão da Canoa-RS. Adquirido de Hugo Ferri | F20: 11 | G20: 38 | H20: 43.389 | I20: 360,00 m² | J20: 390000 | L20: =1/6 | M20: =J20*L20 | N20: 06. Inventário 31.12.2024 - Hotel Araçá | O20: Inscrição 360.0038.011.000; Código 039412.
A21: 17 | B21: 06 - Hotel Araçá Ltda. | C21: Imóvel urbano | D21: 14 | E21: Lote urbano nº 12 - Quadra 38, próximo ao Hotel, Capão da Canoa-RS. Adquirido de Hugo Ferri | F21: 12 | G21: 38 | H21: 29.803 | I21: 360,00 m² | J21: 390000 | L21: =1/6 | M21: =J21*L21 | N21: 06. Inventário 31.12.2024 - Hotel Araçá | O21: Inscrição 360.0038.012.000; Código 039413.
A22: 18 | B22: 06 - Hotel Araçá Ltda. | C22: Imóvel urbano | D22: 15 | E22: Lote urbano nº 13 - Quadra 38, próximo ao Hotel, Capão da Canoa-RS. Adquirido de Hugo Ferri | F22: 13 | G22: 38 | H22: 30.294 | I22: 360,00 m² | J22: 390000 | L22: =1/6 | M22: =J22*L22 | N22: 06. Inventário 31.12.2024 - Hotel Araçá | O22: Inscrição 360.0038.013.000; Código 039414.
A23: 19 | B23: 06 - Hotel Araçá Ltda. | C23: Imóvel urbano | D23: 16 | E23: Lote urbano nº 14 - Quadra 38, próximo ao Hotel, Capão da Canoa-RS. Adquirido de Hugo Ferri | F23: 14 | G23: 38 | H23: 29.802 | I23: 360,00 m² | J23: 390000 | L23: =1/6 | M23: =J23*L23 | N23: 06. Inventário 31.12.2024 - Hotel Araçá | O23: Inscrição 360.0038.014.000; Código 039415.
A24: 20 | B24: 06 - Hotel Araçá Ltda. | C24: Imóvel urbano | D24: 17 | E24: Lote urbano nº 15 - Quadra 38, próximo ao Hotel, Capão da Canoa-RS. Adquirido de Hugo Ferri | F24: 15 | G24: 38 | H24: 33.003 | I24: 360,00 m² | J24: 390000 | L24: =1/6 | M24: =J24*L24 | N24: 06. Inventário 31.12.2024 - Hotel Araçá | O24: Inscrição 360.0038.015.000; Código 039416.
A25: 21 | B25: 06 - Hotel Araçá Ltda. | C25: Imóvel urbano | D25: 18 | E25: Lote urbano nº 27 - Quadra 38 - Lote Estacionamento do Bigode, Capão da Canoa-RS | F25: 27 | G25: 38 | H25: 73.482 | I25: 360,00 m² | J25: 350000 | K25: 350000 | L25: =1/6 | M25: =J25*L25 | N25: 06. Inventário 31.12.2024 - Hotel Araçá | O25: Inscrição 360.0038.027.000; Código 039426. Mesma matrícula do item 19. Também no estudo Rafael (item 18, p. 6-7), mesmo valor.
A26: 22 | B26: 06 - Hotel Araçá Ltda. | C26: Imóvel urbano | D26: 19 | E26: Lote urbano nº 28 - Quadra 38 - Lote Estacionamento do Bigode, Capão da Canoa-RS | F26: 28 | G26: 38 | H26: 73.482 | I26: 360,00 m² | J26: 350000 | K26: 350000 | L26: =1/6 | M26: =J26*L26 | N26: 06. Inventário 31.12.2024 - Hotel Araçá | O26: Inscrição 360.0038.028.000; Código 039427. Mesma matrícula do item 18. Também no estudo Rafael (item 19, p. 7), mesmo valor.
A27: 23 | B27: 06 - Hotel Araçá Ltda. | C27: Imóvel urbano | D27: 20 | E27: Lote nº 15, quadra 02, Condado de Capão, com casa de alvenaria de 158,18 m² e móveis, Capão da Canoa-RS | F27: 15 | G27: 02 | H27: 69.488 | I27: 725,39 m² | J27: 1000000 | L27: =1/6 | M27: =J27*L27 | N27: 06. Inventário 31.12.2024 - Hotel Araçá | O27: Inscrição 645.0027.015.000; Código 076891. Adquirida em maio/2014 por R$ 750.000,00.
A28: 24 | B28: 06 - Hotel Araçá Ltda. | C28: Imóvel urbano | D28: 21 | E28: Lote urbano nº 15 - Quadra 37 - Lateral do Hotel, Capão da Canoa-RS | F28: 15 | G28: 37 | H28: 86.669 | I28: 360,00 m² | J28: 380000 | L28: =1/6 | M28: =J28*L28 | N28: 06. Inventário 31.12.2024 - Hotel Araçá | O28: Inscrição 360.0037.015.000.000; Código 39394.
A29: 25 | B29: 06 - Hotel Araçá Ltda. | C29: Imóvel urbano | D29: 22 | E29: Lote urbano nº 17 - Quadra 37 - Lateral do Hotel, Capão da Canoa-RS | F29: 17 | G29: 37 | H29: 124.906 | I29: 360,00 m² | J29: 380000 | L29: =1/6 | M29: =J29*L29 | N29: 06. Inventário 31.12.2024 - Hotel Araçá | O29: Inscrição 360.0037.017.000.000; Código 39396. Inventário indica registro na Comarca de Osório.
A30: 26 | B30: 07 - Rádio Comunidade Princesa dos Vales FM Ltda. | C30: Imóvel urbano | D30: 01 | E30: Sala comercial nº 311 - ESTÚDIO, Ed. Comendador José de Mello, Av. Osvaldo Aranha, 1395, Palugana, Veranópolis-RS | H30: 11.382 | I30: 94,51 m² | J30: 210000 | L30: 0.165 | M30: =J30*L30 | N30: 07. Inventário 31.12.2024 - Rádio Comunidade Princesa dos Vales FM | O30: Adquirida por R$ 100.000,00.
A31: 27 | B31: 07 - Rádio Comunidade Princesa dos Vales FM Ltda. | C31: Móveis, equipamentos e concessão | D31: 02 | E31: Móveis, instalações e utensílios | J31: 150000 | L31: 0.165 | M31: =J31*L31 | N31: 07. Inventário 31.12.2024 - Rádio Comunidade Princesa dos Vales FM
A32: 28 | B32: 07 - Rádio Comunidade Princesa dos Vales FM Ltda. | C32: Móveis, equipamentos e concessão | D32: 03 | E32: Equipamentos do estúdio (computadores, transmissão etc.) + canal FM 96.1 + concessão no Ministério das Comunicações e clientes | J32: 1900000 | L32: 0.165 | M32: =J32*L32 | N32: 07. Inventário 31.12.2024 - Rádio Comunidade Princesa dos Vales FM | O32: Valor do canal estimado com base em informações verbais de Élcio Siviero.
A33: 29 | B33: 07 - Rádio Comunidade Princesa dos Vales FM Ltda. | C33: Móveis, equipamentos e concessão | D33: 04 | E33: Antena de transmissão, casa de equipamentos e gerador (sem o imóvel) | J33: 300000 | L33: 0.165 | M33: =J33*L33 | N33: 07. Inventário 31.12.2024 - Rádio Comunidade Princesa dos Vales FM | O33: Antena está em terreno da Siviero Empreendimentos (Matrícula 3.751); há custo de deslocamento e de novo terreno.
A34: 30 | B34: 07 - Rádio Comunidade Princesa dos Vales FM Ltda. | C34: Imóvel urbano | D34: 05 | E34: Box de estacionamento, Ed. Comendador José de Mello, Av. Osvaldo Aranha, 1395, Veranópolis-RS | H34: 11.324 | I34: 17,28 m² | J34: 40000 | L34: 0.165 | M34: =J34*L34 | N34: 07. Inventário 31.12.2024 - Rádio Comunidade Princesa dos Vales FM
A35: 31 | B35: 07 - Rádio Comunidade Princesa dos Vales FM Ltda. | C35: Veículo / máquina | D35: 06 | E35: VW Fox, gasolina/álcool, 2011/2011, preto, placa IRO 2562 | J35: 28000 | L35: 0.165 | M35: =J35*L35 | N35: 07. Inventário 31.12.2024 - Rádio Comunidade Princesa dos Vales FM
A36: 32 | B36: 07 - Rádio Comunidade Princesa dos Vales FM Ltda. | C36: Veículo / máquina | D36: 07 | E36: Toyota Bandeirante, diesel, 1980/1980, verde, placa IHW 0285 | J36: 70000 | K36: 70000 | L36: 0.165 | M36: =J36*L36 | N36: 07. Inventário 31.12.2024 - Rádio Comunidade Princesa dos Vales FM | O36: Também no estudo Rafael (item s/nº, p. 7), mesmo valor.
A37: 33 | B37: 08 - Transportadora Irmãos Siviero Ltda. | C37: Imóvel urbano | D37: 01 | E37: Terreno urbano - OFICINA MECÂNICA, Rodovia BR 470, Km 175,4, Bairro São Pelegrino, Veranópolis-RS (fundos com a Abastecedora Siviero) | H37: 3.753 | I37: 8.700,00 m² | J37: 8637186 | L37: =1/6 | M37: =J37*L37 | N37: 08. Inventário 31.12.2024 - Transportadora Irmãos Siviero | O37: 8.700 m² x R$ 992,78/m². Ver aba 'Composição'.
A38: 34 | B38: 08 - Transportadora Irmãos Siviero Ltda. | C38: Benfeitoria / edificação | D38: 02 | E38: Pavilhão novo da oficina mecânica, em fase final de construção (sem mezanino) | I38: 1.298,00 m² | J38: 1427800 | L38: =1/6 | M38: =J38*L38 | N38: 08. Inventário 31.12.2024 - Transportadora Irmãos Siviero | O38: 1.298 m² x R$ 1.100,00. Obra não regularizada (projeto, APPCI, INSS).
A39: 35 | B39: 08 - Transportadora Irmãos Siviero Ltda. | C39: Móveis, equipamentos e concessão | D39: 03 | E39: Equipamentos em geral da oficina (macacos, guindastes, ferramentas, estoque de peças, óleos, câmeras etc.) | J39: 500000 | L39: =1/6 | M39: =J39*L39 | N39: 08. Inventário 31.12.2024 - Transportadora Irmãos Siviero
A40: 36 | B40: 08 - Transportadora Irmãos Siviero Ltda. | C40: Benfeitoria / edificação | D40: 04 | E40: Rampa de lavagem licenciada para caminhões e carros | J40: 300000 | L40: =1/6 | M40: =J40*L40 | N40: 08. Inventário 31.12.2024 - Transportadora Irmãos Siviero | O40: Obra não regularizada. Equipamentos são da locatária.
...

Sheet Resumo
A1: Resumo por empresa e categoria
A2: Colunas 'declarado' transcritas do total geral e da linha da Valter de cada inventário; 'Dif.' deve ser zero.
A4: Empresa | B4: Qtde. bens | C4: Valor avaliado 2025 (R$) | D4: Valor no estudo Rafael (R$) | E4: Total declarado no inventário (R$) | F4: Dif. (R$) | G4: Quinhão Valter (R$) | H4: Valter declarado no inventário (R$) | I4: Dif. (R$) | J4: Observações
A5: 03 - Associação Cultural Princesa dos Vales | B5: =COUNTIF(Ativos!$B$5:$B$151,A5) | C5: =SUMIF(Ativos!$B$5:$B$151,A5,Ativos!$J$5:$J$151) | D5: =SUMIF(Ativos!$B$5:$B$151,A5,Ativos!$K$5:$K$151) | E5: 0 | F5: =C5-E5 | G5: =SUMIF(Ativos!$B$5:$B$151,A5,Ativos!$M$5:$M$151) | H5: 0 | I5: =ROUND(G5-H5,2) | J5: Sem bens. Empresa baixada em 09/07/2020.
A6: 04 - Ceval Terraplenagem e Escavações Ltda. | B6: =COUNTIF(Ativos!$B$5:$B$151,A6) | C6: =SUMIF(Ativos!$B$5:$B$151,A6,Ativos!$J$5:$J$151) | D6: =SUMIF(Ativos!$B$5:$B$151,A6,Ativos!$K$5:$K$151) | E6: 315000 | F6: =C6-E6 | G6: =SUMIF(Ativos!$B$5:$B$151,A6,Ativos!$M$5:$M$151) | H6: 52500 | I6: =ROUND(G6-H6,2)
A7: 06 - Hotel Araçá Ltda. | B7: =COUNTIF(Ativos!$B$5:$B$151,A7) | C7: =SUMIF(Ativos!$B$5:$B$151,A7,Ativos!$J$5:$J$151) | D7: =SUMIF(Ativos!$B$5:$B$151,A7,Ativos!$K$5:$K$151) | E7: 58076823 | F7: =C7-E7 | G7: =SUMIF(Ativos!$B$5:$B$151,A7,Ativos!$M$5:$M$151) | H7: 9679470.5 | I7: =ROUND(G7-H7,2)
A8: 07 - Rádio Comunidade Princesa dos Vales FM Ltda. | B8: =COUNTIF(Ativos!$B$5:$B$151,A8) | C8: =SUMIF(Ativos!$B$5:$B$151,A8,Ativos!$J$5:$J$151) | D8: =SUMIF(Ativos!$B$5:$B$151,A8,Ativos!$K$5:$K$151) | E8: 2698000 | F8: =C8-E8 | G8: =SUMIF(Ativos!$B$5:$B$151,A8,Ativos!$M$5:$M$151) | H8: 445170 | I8: =ROUND(G8-H8,2) | J8: Valter = 16,50% neste inventário.
A9: 08 - Transportadora Irmãos Siviero Ltda. | B9: =COUNTIF(Ativos!$B$5:$B$151,A9) | C9: =SUMIF(Ativos!$B$5:$B$151,A9,Ativos!$J$5:$J$151) | D9: =SUMIF(Ativos!$B$5:$B$151,A9,Ativos!$K$5:$K$151) | E9: 16374986 | F9: =C9-E9 | G9: =SUMIF(Ativos!$B$5:$B$151,A9,Ativos!$M$5:$M$151) | H9: 2729164.3 | I9: =ROUND(G9-H9,2)
A10: 09 - Turismo Siviero Ltda. | B10: =COUNTIF(Ativos!$B$5:$B$151,A10) | C10: =SUMIF(Ativos!$B$5:$B$151,A10,Ativos!$J$5:$J$151) | D10: =SUMIF(Ativos!$B$5:$B$151,A10,Ativos!$K$5:$K$151) | E10: 0 | F10: =C10-E10 | G10: =SUMIF(Ativos!$B$5:$B$151,A10,Ativos!$M$5:$M$151) | H10: 0 | I10: =ROUND(G10-H10,2) | J10: Sem bens. Empresa baixada em 04/09/2023.
A11: 10 - Siviero Transportes Ltda. | B11: =COUNTIF(Ativos!$B$5:$B$151,A11) | C11: =SUMIF(Ativos!$B$5:$B$151,A11,Ativos!$J$5:$J$151) | D11: =SUMIF(Ativos!$B$5:$B$151,A11,Ativos!$K$5:$K$151) | E11: 0 | F11: =C11-E11 | G11: =SUMIF(Ativos!$B$5:$B$151,A11,Ativos!$M$5:$M$151) | H11: 0 | I11: =ROUND(G11-H11,2) | J11: Sem bens. Empresa baixada em 08/04/2024.
A12: 05 - Hotel Princesa dos Vales Ltda. | B12: =COUNTIF(Ativos!$B$5:$B$151,A12) | C12: =SUMIF(Ativos!$B$5:$B$151,A12,Ativos!$J$5:$J$151) | D12: =SUMIF(Ativos!$B$5:$B$151,A12,Ativos!$K$5:$K$151) | G12: =SUMIF(Ativos!$B$5:$B$151,A12,Ativos!$M$5:$M$151) | J12: Sem inventário na pasta 2025; bens apenas no estudo Rafael.
A13: Siviero Empreendimentos Imobiliários Ltda. (Empresa 10 no estudo) | B13: =COUNTIF(Ativos!$B$5:$B$151,A13) | C13: =SUMIF(Ativos!$B$5:$B$151,A13,Ativos!$J$5:$J$151) | D13: =SUMIF(Ativos!$B$5:$B$151,A13,Ativos!$K$5:$K$151) | G13: =SUMIF(Ativos!$B$5:$B$151,A13,Ativos!$M$5:$M$151) | J13: Sem inventário na pasta 2025; bens apenas no estudo Rafael.
A14: TOTAL | B14: =SUM(B5:B13) | C14: =SUM(C5:C13) | D14: =SUM(D5:D13) | E14: =SUM(E5:E13) | F14: =SUM(F5:F13) | G14: =SUM(G5:G13) | H14: =SUM(H5:H13) | I14: =SUM(I5:I13)
A17: Categoria | B17: Qtde. bens | C17: Valor avaliado 2025 (R$) | D17: Valor no estudo Rafael (R$) | G17: Quinhão Valter (R$)
A18: Imóvel urbano | B18: =COUNTIF(Ativos!$C$5:$C$151,A18) | C18: =SUMIF(Ativos!$C$5:$C$151,A18,Ativos!$J$5:$J$151) | D18: =SUMIF(Ativos!$C$5:$C$151,A18,Ativos!$K$5:$K$151) | G18: =SUMIF(Ativos!$C$5:$C$151,A18,Ativos!$M$5:$M$151)
A19: Imóvel rural | B19: =COUNTIF(Ativos!$C$5:$C$151,A19) | C19: =SUMIF(Ativos!$C$5:$C$151,A19,Ativos!$J$5:$J$151) | D19: =SUMIF(Ativos!$C$5:$C$151,A19,Ativos!$K$5:$K$151) | G19: =SUMIF(Ativos!$C$5:$C$151,A19,Ativos!$M$5:$M$151)
A20: Lote em loteamento | B20: =COUNTIF(Ativos!$C$5:$C$151,A20) | C20: =SUMIF(Ativos!$C$5:$C$151,A20,Ativos!$J$5:$J$151) | D20: =SUMIF(Ativos!$C$5:$C$151,A20,Ativos!$K$5:$K$151) | G20: =SUMIF(Ativos!$C$5:$C$151,A20,Ativos!$M$5:$M$151)
A21: Benfeitoria / edificação | B21: =COUNTIF(Ativos!$C$5:$C$151,A21) | C21: =SUMIF(Ativos!$C$5:$C$151,A21,Ativos!$J$5:$J$151) | D21: =SUMIF(Ativos!$C$5:$C$151,A21,Ativos!$K$5:$K$151) | G21: =SUMIF(Ativos!$C$5:$C$151,A21,Ativos!$M$5:$M$151)
A22: Móveis, equipamentos e concessão | B22: =COUNTIF(Ativos!$C$5:$C$151,A22) | C22: =SUMIF(Ativos!$C$5:$C$151,A22,Ativos!$J$5:$J$151) | D22: =SUMIF(Ativos!$C$5:$C$151,A22,Ativos!$K$5:$K$151) | G22: =SUMIF(Ativos!$C$5:$C$151,A22,Ativos!$M$5:$M$151)
A23: Veículo / máquina | B23: =COUNTIF(Ativos!$C$5:$C$151,A23) | C23: =SUMIF(Ativos!$C$5:$C$151,A23,Ativos!$J$5:$J$151) | D23: =SUMIF(Ativos!$C$5:$C$151,A23,Ativos!$K$5:$K$151) | G23: =SUMIF(Ativos!$C$5:$C$151,A23,Ativos!$M$5:$M$151)
A24: TOTAL | B24: =SUM(B18:B23) | C24: =SUM(C18:C23) | D24: =SUM(D18:D23) | G24: =SUM(G18:G23)

Sheet Composição
A1: Composição dos valores com memória de cálculo
A2: Parâmetros em azul transcritos dos inventários; totais por fórmula, comparados ao valor declarado.
A4: Parcela | B4: Quantidade | C4: Unidade | D4: Valor unitário / % (R$) | E4: Valor (R$) | F4: Observação
A5: 06 - Hotel Araçá - Item 01 - Hotel (terreno + edifício + móveis)
A6: Terreno do hotel (R$ 1.000,00/m²) | B6: 6900 | C6: m² | D6: 1000 | E6: =B6*D6
A7: Móveis e equipamentos novos - 36 apartamentos (sem depreciação) | B7: 36 | C7: apto | D7: 42000 | E7: =B7*D7
A8: Móveis e equipamentos - 108 apartamentos (R$ 30.000,00 cada, -20%) | B8: 108 | C8: apto | D8: 30000 | E8: =B8*D8*(1-0.2) | F8: R$ 3.240.000,00 - 20% = R$ 2.592.000,00.
A9: Edifício - obra civil, 10.500 m² x CUB dez/2022 (-20%) | B9: 10500 | C9: m² | D9: 3170.52 | E9: =B9*D9*(1-0.2) | F9: R$ 33.290.460,00 - 20% = R$ 26.632.368,00.
A10: Móveis e equipamentos diversos (cozinha, restaurante, lavanderia, poço etc.) (-20%) | E10: =8000000*(1-0.2) | F10: R$ 8.000.000,00 - 20% = R$ 6.400.000,00.
A11: Obras / valor agregado = 15% da obra feita | D11: 0.15 | E11: =D11*SUM(E7:E10) | F11: Base R$ 37.136.368,00 = soma das 4 parcelas acima (exceto terreno).
A12: Total calculado | E12: =SUM(E6:E11)
A13: Total declarado no inventário | E13: 49606823
A14: Diferença (calculado - declarado) | E14: =E12-E13
A16: 08 - Transportadora Irmãos Siviero - Item 01 - Terreno da oficina
A17: Terreno (R$ 992,78/m²) | B17: 8700 | C17: m² | D17: 992.78 | E17: =B17*D17
A18: Total calculado | E18: =SUM(E17:E17)
A19: Total declarado no inventário | E19: 8637186
A20: Diferença (calculado - declarado) | E20: =E18-E19
A22: 08 - Transportadora Irmãos Siviero - Item 02 - Pavilhão da oficina
A23: Pavilhão (sem mezanino), R$ 1.100,00/m² | B23: 1298 | C23: m² | D23: 1100 | E23: =B23*D23 | F23: Os 30% de obra feita não foram calculados (obra não regularizada).
A24: Total calculado | E24: =SUM(E23:E23)
A25: Total declarado no inventário | E25: 1427800
A26: Diferença (calculado - declarado) | E26: =E24-E25
A28: 08 - Transportadora Irmãos Siviero - Item 07 - Lotes rurais 63, 65, 66 e 'N' (Cotiporã)
A29: Área rural (R$ 50.000,00/ha) | B29: 69.8 | C29: ha | D29: 50000 | E29: =B29*D29
A30: Total calculado | E30: =SUM(E29:E29)
A31: Total declarado no inventário | E31: 3500000
A32: Diferença (calculado - declarado) | E32: =E30-E31 | F32: Inventário arredonda R$ 3.490.000,00 para R$ 3.500.000,00.
A34: 08 - Transportadora Irmãos Siviero - Item 08 - Parte do lote rural 63 (Cotiporã)
A35: Área rural (R$ 50.000,00/ha) | B35: 4.5 | C35: ha | D35: 50000 | E35: =B35*D35
A36: Total calculado | E36: =SUM(E35:E35)
A37: Total declarado no inventário | E37: 250000
A38: Diferença (calculado - declarado) | E38: =E36-E37 | F38: Pelo critério declarado o valor seria R$ 225.000,00; inventário registra R$ 250.000,00.
A40: Estudo Rafael - 05 Hotel Princesa dos Vales - Item 04 - Sede Campestre (9,4 ha)
A41: Área de terras | B41: 9.4 | C41: ha | D41: 450000 | E41: =B41*D41
A42: Pavilhão construído - obra civil (CUB ago/2017) | B42: 891 | C42: m² | D42: 746 | E42: =B42*D42
A43: Benfeitoria - Quiosque | E43: 150000
A44: Casa de alvenaria nos fundos | E44: 250000 | F44: Área construída em branco no estudo.
A45: Obras e infraestrutura = 25% de (pavilhão + quiosque + casa) | D45: 0.25 | E45: =D45*SUM(E42:E44) | F45: Estudo escreve '25,00% (Vinte por cento)'; o valor R$ 266.171,50 corresponde a 25%.
A46: Total calculado | E46: =SUM(E41:E45)
...

Sheet Vendas e créditos
A1: Hotel Princesa dos Vales - áreas vendidas e créditos em produto
A2: Fonte: Hotel Princesa dos Vales - Áreas vendidas + loteamentos SEI.docx. Fazenda São Crispin: 686,75 ha - 190,00 ha (Rigo) - 85,32 ha (Pellegrini) = 411,43 ha remanescentes.
A4: Venda | B4: Ano | C4: Área (ha) | D4: R$ / ha | E4: Valor da venda (R$) | F4: Forma de pagamento / observação
A5: Fazenda São Crispin - Família Rigo | B5: 2018 | C5: 190 | D5: 49726.3 | E5: 9448000 | F5: 118.100 sacas de soja a R$ 80,00 (out/2018): R$ 3.000.000,00 à vista (37.500 sc) + 4 x 20.150 sc (maio/2019 a maio/2022). Safras 2021 e 2022 constam como 'falta receber'.
A6: Fazenda São Crispin - Família Pellegrini | B6: 2018 | C6: 85.32 | D6: 23441.16 | E6: 2100000 | F6: R$ 2.000.000,00 pela área + R$ 100.000,00 em 41 cabeças de gado. R$ 1.100.000,00 à vista + R$ 1.000.000,00 em jun/2019.
A7: Cotiporã - parte do lote rural 24 e 24/E (Mat. 2.424 e 2.425) - Sr. Angeli | B7: 2018 | C7: 10.2 | D7: 50000 | E7: 510000 | F7: À vista. Adquirida de Celito Pierozan. CCIR 2.481.949-2.
A8: Total recebido das áreas vendidas | C8: =SUM(C5:C7) | E8: =SUM(E5:E7)
A9: Total declarado no documento | E9: 12058000
A10: Diferença | E10: =E8-E9
A12: Créditos em sacas de soja ainda não vendidos (documento deixa o preço em branco)
A13: Preço da saca de soja (R$) - preencher:
A14: Crédito | C14: Sacas | E14: Valor (R$) | F14: Observação
A15: Família Rigo - safra maio/2021 | C15: 20150 | E15: =C15*$E$13 | F15: Vendidas 2.606 sacas em 2024 para aquisição da escavadeira hidráulica.
A16: Família Rigo - safra maio/2021 - vendidas em 2024 | C16: -2606 | E16: =C16*$E$13
A17: Família Rigo - safra maio/2022 | C17: 20150 | E17: =C17*$E$13
A18: Família Lorenzetti - 2021 (Hotel/Oleoplan) | C18: 2606 | E18: =C18*$E$13
A19: Família Lorenzetti - 2022 (Hotel/Oleoplan) | C19: 3206 | E19: =C19*$E$13
A20: Família Lorenzetti - 2023 (Hotel/Oleoplan) | C20: 3591 | E20: =C20*$E$13
A21: Família Lorenzetti - 2024 (Agropecuária/Oleoplan) | C21: 3682 | E21: =C21*$E$13
A22: Total de sacas a receber / vender | C22: =SUM(C15:C21) | E22: =SUM(E15:E21) | F22: Documento: Rigo 37.694 sacas + Lorenzetti 13.085 sacas = 50.779 sacas.
A24: Arrendamento à Família Lorenzetti (02/05/2023 a 30/04/2026) - receita anual em produto
A25: Área arrendada | C25: Área (ha) | D25: Produto / ano | F25: Observação
A26: a) Lavoura - 18 sacas de soja/ha | C26: 155 | D26: 2.790 sacas de soja
A27: b) Batata - 30 sacas de soja/ha | C27: 30 | D27: 900 sacas de soja
A28: c) Campo nativo para bovinos | C28: 157.5 | D28: 3.000 kg de boi por 100 ha | F28: Pago em dezembro, ao preço da época.
A29: d) Matos, capões e pedras - sem pagamento | C29: 68.9 | D29: -
A30: Total | C30: =SUM(C26:C29) | F30: Documento: área total de 411,4 ha.
A32: Áreas contratadas pela Siviero Empreendimentos Imobiliários para urbanização - sem obras e sem valor atribuído
A33: Loteamento | B33: Nº | D33: Cidade | E33: Valor (R$) | F33: Observação
A34: Loteamento Alto das Graças II | B34: 01 | D34: Caxias do Sul | F34: Documento: áreas contratadas para urbanização, sem obras e ainda em estudo de viabilidade ambiental, e/ou com obras em execução com saldo zero e possíveis prejuízos a apurar na conclusão do empreendimento. Sem valor no documento.
A35: Loteamento Santa Corona III | B35: 02 | D35: Caxias do Sul
A36: Condomínio Morada dos Ipês II | B36: 03 | D36: Passo Fundo
A37: Loteamento da Congregação das Irmãos de São Carlos (grafia do documento) | B37: 04 | D37: Passo Fundo
A38: Loteamento Bella Visione | B38: 05 | D38: Nova Prata
A39: Loteamento Bonetto | B39: 06 | D39: Farroupilha
A40: Loteamento Pascoal | B40: 07 | D40: Farroupilha
A41: Loteamento Letti | B41: 08 | D41: Farroupilha
A42: Loteamento Colombo | B42: 09 | D42: Farroupilha
A43: Loteamento Champagnat | B43: 10 | D43: Veranópolis
A44: Loteamento Simioni | B44: 11 | D44: Veranópolis
...

Sheet Acertos e acordos
A1: Acertos com terceiros (comissões, distratos, acordos judiciais, devoluções)
A2: Fonte: ACERTOS E ACORDOS.pdf, páginas 1-3. As páginas não identificam a empresa. Lotes valorados conforme o 'Resumo dos acordos' do documento.
A4: Nº | B4: Credor / parte | C4: Lotes | D4: Valor em dinheiro (R$) | E4: Valor atribuído a lote (R$) | F4: Descrição
A5: 1 | B5: Valdir Angest | C5: 1 | F5: 01 lote (05/6372 - Altos das Graças).
A6: 2 | B6: Valdir Angest | D6: 270000 | F6: Pago em dinheiro.
A7: 3 | B7: Alexandre Susin | C7: 7 | F7: 07 lotes em um acordo.
A8: 4 | B8: Alexandre Susin | C8: 17 | F8: 17 lotes em um acordo.
A9: 5 | B9: Alexandre Susin | D9: 200000 | F9: Pago em dinheiro.
A10: 6 | B10: Ambitec | C10: 11 | F10: 11 lotes em acordo.
A11: 7 | B11: Ambitec | D11: 15000 | F11: Pago em dinheiro.
A12: 8 | B12: Família Farina | C12: 17 | F12: 17 lotes - acordo judicial.
A13: 9 | B13: Família Farina | C13: 1 | E13: 830000 | F13: 01 lote de R$ 830.000,00 (honorários). Novo acordo trocou este lote (Lot. Industrial Vicentino) por 04 lotes em Farroupilha.
A14: 10 | B14: Família Farina | D14: 220000 | F14: Honorários advocatícios - pago em dinheiro.
A15: 11 | B15: Alceones Salvador | C15: 4 | F15: 04 lotes em acordo.
A16: 12 | B16: Telmo Fantinel | C16: 1 | F16: 01 lote em acordo - Loteamento Monte Vêneto.
A17: 13 | B17: Fochesato - Caxias do Sul | C17: 4 | F17: 04 lotes em acordo, referente a lotes negociados no Loteamento Zanandréa.
A18: 14 | B18: Via Nova - Boschetti + Sandro + Rafael | C18: 9 | F18: 09 lotes em acordo.
A19: 15 | B19: Via Nova - Boschetti + Sandro + Rafael | D19: 90000 | F19: Pago em dinheiro.
A20: 16 | B20: Flávia Mânica Siviero | D20: 500000 | F20: Acordo sendo pago em dinheiro - 24/50 parcelas.
A21: 17 | B21: Verona - Farroupilha | C21: 2 | F21: 02 lotes (01 San Marino + 01 Altos da Julieta).
A22: 18 | B22: Celestino Rossi | F22: A acertar os honorários (sem valor).
A23: 19 | B23: Antônio Ansolin | D23: 55000 | F23: Compra de 06 lotes.
A24: 20 | B24: Antônio Ansolin | D24: 156666 | F24: Em dinheiro, referente à compra de 7,0 ha.
A25: 21 | B25: Antônio Ansolin | C25: 1 | E25: 375000 | F25: 01 lote no Loteamento Industrial Pedra Lisa, referente à compra de 7,0 ha.
A26: 22 | B26: Lori Fioreze | D26: 120000 | F26: Compra de 02 lotes.
A27: 23 | B27: Ezequiel Fioreze | D27: 170000 | F27: Compra de 01 ha, que está sendo pago.
A28: 24 | B28: Cândido Fioreze | D28: 120000 | F28: Compra de 02 lotes.
A29: 25 | B29: Asdrubal Antoniazzi - Colunata | C29: 3 | F29: 01 lote no Vale das Colinas + 02 lotes no Basso.
A30: 26 | B30: Rodrigo Razera - Susin | C30: 1 | F30: 01 lote em Farroupilha - Viero.
A31: 27 | B31: Inês Colombo | C31: 2 | F31: 02 lotes no Altos da Julieta - multa por rescisão de contrato.
A32: 28 | B32: Edoardo Bovo - Farroupilha | D32: 120000 | F32: Acordo judicial.
A33: 29 | B33: Família Acordi - Farroupilha - TAC Ministério Público | D33: 88457.52 | F33: Multa de +/- R$ 1.200.000,00 acordada nas 3 parcelas do item 29.
A34: 29 | B34: Família Acordi - Farroupilha - multa na Prefeitura | D34: 61920.3
A35: 29 | B35: Família Acordi - Farroupilha - acerto com o Município | D35: 130000
A36: 30 | B36: Família Basso - dívida na Prefeitura de Caxias do Sul | D36: 156100.41 | F36: 40 parcelas; pagas 11/40 de R$ 4.473,71.
A37: 30 | B37: Família Basso - dívida na Prefeitura de Caxias do Sul | D37: 69060.32 | F37: 40 parcelas; pagas 11/40 de R$ 1.971,21.
A38: 31 | B38: Família Pedrotti - Casa Fochesatto - Nova Prata | D38: 270000 | F38: R$ 190.000,00 + R$ 80.000,00.
A39: 32 | B39: Alan - advogado das famílias do Lot. Monte Vêneto | C39: 1 | F39: 01 lote no Loteamento Monte Vêneto - L.11/Q.09.
A40: 32 | B40: Alan - advogado das famílias do Lot. Monte Vêneto | D40: 70000 | F40: Pago em dinheiro.
B41: TOTAIS | C41: =SUM(C5:C40) | D41: =SUM(D5:D40) | E41: =SUM(E5:E40)
...

Sheet Contratos Boff
A1: Siviero Empreendimentos Imobiliários - contratos com a Família Boff (Caxias do Sul)
A2: Fonte: ACERTOS E ACORDOS.pdf, páginas 4-6. Pagamentos e depósitos antecipados pela Siviero para execução do loteamento. Valores nominais, sem correção.
A4: Contrato | B4: Pagamento | C4: Valor (R$) | D4: Contrapartida prevista em contrato | E4: Corrigir a partir de
A5: Família Boff (Ludovico Dante Boff) | B5: Impostos das 3 áreas e adiantamentos (corrigido até mar/2010) | C5: 983724.02 | D5: 05 lotes de frente para a Rodovia (junto com a linha abaixo) | E5: mar/2010 até 2022
A6: Família Boff (Ludovico Dante Boff) | B6: Adiantamento para despesas do Sr. Ludovico Dante Boff | C6: 140000 | D6: 05 lotes de frente para a Rodovia (total firmado R$ 1.123.724,02) | E6: mar/2010 até 2022
A7: Família Boff (Ludovico Dante Boff) | B7: Adiantamento para despesas do Sr. Ludovico Dante Boff | C7: 100000 | D7: 01 lote na rua paralela à Rodovia, fundos com a Área Verde | E7: mar/2010 até 2022
A8: Família Boff | B8: IPTU das 3 áreas do loteamento, 2011 a 2022 | C8: 1555898.9 | D8: - (IPTU de R$ 3,30/m² pela área total) | E8: 2011 até 2022
A9: Dorval Francisco Boff | B9: Ação trabalhista em Gramado (fev/2013) | C9: 221052.27 | D9: 03 lotes na primeira quadra do loteamento (Termo de Divisão) | E9: fev/2013 até 2022
A10: Dorval Francisco Boff | B10: Compra de 02 lotes (contrato de 03/09/2012) | C10: 165000 | D10: 02 lotes na divisa do colégio | E10: set/2012 até 2022
A11: Odir Marcos Boff | B11: Compra de 01 lote (contrato de 23/02/2011) | C11: 50000 | D11: 01 lote de 390,00 m² nos fundos da casa do Sr. Odir | E11: fev/2011 até 2022
A12: Odir Marcos Boff | B12: Compra de 01 lote (contrato de 05/03/2012) | C12: 100000 | D12: 01 lote de 360,00 m² na rua paralela à Rodovia, divisa com a Área Verde | E12: mar/2012 até 2022
A13: Total calculado | C13: =SUM(C5:C12)
A14: Total declarado no documento | C14: 3315675.2
A15: Diferença | C15: =C13-C14

Sheet Passivos e contingências
A1: Passivos, contingências, créditos a receber e reduções estimadas citados nos inventários
A2: Valores estimados pelos próprios inventários; não estão deduzidos dos valores da aba 'Ativos'.
A4: Empresa | B4: Tipo | C4: Descrição | D4: Valor (R$) | E4: % sobre o total | F4: Arquivo
A5: 06 - Hotel Araçá Ltda. | B5: Redução estimada | C5: Regularização do hotel (item 01) - redução estimada de ~4% | D5: 2000000 | F5: 06. Inventário 31.12.2024 - Hotel Araçá
A6: 06 - Hotel Araçá Ltda. | B6: Custo de regularização | C6: INSS da obra do hotel (fora APPCI, ART, engenheiro, taxas, emolumentos) | D6: 1601357.9 | F6: 06. Inventário 31.12.2024 - Hotel Araçá
A7: 07 - Rádio Comunidade Princesa dos Vales FM Ltda. | B7: Redução estimada | C7: Regularização dos imóveis - 8% do valor total | D7: ='Resumo'!C8*E7 | E7: 0.08 | F7: 07. Inventário 31.12.2024 - Rádio Comunidade Princesa dos Vales FM
A8: 08 - Transportadora Irmãos Siviero Ltda. | B8: Redução estimada | C8: Regularização dos imóveis - 1,5% do valor total | D8: ='Resumo'!C9*E8 | E8: 0.015 | F8: 08. Inventário 31.12.2024 - Transportadora Irmãos Siviero
A9: 08 - Transportadora Irmãos Siviero Ltda. | B9: Custo de regularização | C9: INSS da obra do pavilhão da oficina mecânica | D9: 122254.73 | F9: 08. Inventário 31.12.2024 - Transportadora Irmãos Siviero
A10: 08 - Transportadora Irmãos Siviero Ltda. | B10: Custo de regularização | C10: INSS das obras da borracharia e rampa de lavagem | D10: 62555.51 | F10: 08. Inventário 31.12.2024 - Transportadora Irmãos Siviero
A11: 08 - Transportadora Irmãos Siviero Ltda. | B11: Crédito a receber (processo) | C11: Cobrança judicial contra Joveni Transportes / JBS / Frangosul (dez/2011 a abr/2012) - valor aproximado, sujeito a acordo | D11: 340000 | F11: 08. Inventário 31.12.2024 - Transportadora Irmãos Siviero
A12: 08 - Transportadora Irmãos Siviero Ltda. | B12: Contingência (processo) | C12: Processo Sottili (Bahia) - pensão estimada: R$ 1.518,00 x 12 x 20 anos | D12: 364320 | F12: 08. Inventário 31.12.2024 - Transportadora Irmãos Siviero
A13: 08 - Transportadora Irmãos Siviero Ltda. | B13: Contingência (processo) | C13: Processo Sottili - dano moral pedido: 1.000 salários mínimos | D13: 1518000 | F13: 08. Inventário 31.12.2024 - Transportadora Irmãos Siviero
A14: 08 - Transportadora Irmãos Siviero Ltda. | B14: Contingência (processo) | C14: Processo Sottili - dano moral alternativo: 150 SM de 2001 com juros e correção | D14: 627000 | F14: 08. Inventário 31.12.2024 - Transportadora Irmãos Siviero
A15: 10 - Siviero Transportes Ltda. | B15: Crédito a receber (processo) | C15: Venda do ônibus IXO 6000 - acordo judicial (R$ 20.000,00 de despesas + parcelas de R$ 5.000,00 desde nov/2024) | D15: 115000 | F15: 10. Inventário 31.12.2024 - Siviero Transportes
A16: 08 - Transportadora Irmãos Siviero Ltda. | B16: Nota contábil | C16: Inventário informa ter acrescentado R$ 1.135.000,00 ao capital de bens do balanço patrimonial (código 1060), itens 03, 04 e 05. A soma desses itens no inventário é R$ 1.020.000,00 (500.000 + 300.000 + 220.000); a diferença de R$ 115.000,00 não está explicada no documento. | D16: 1135000 | F16: 08. Inventário 31.12.2024 - Transportadora Irmãos Siviero
A17: 08 - Transportadora Irmãos Siviero Ltda. | B17: Alteração societária | C17: Venda das quotas de Rovílio Siviero (2,00%) aos demais sócios, em partes iguais - instrumento particular de compra e venda de quotas de 28/08/2025. Não altera a tabela 'valor real de cada sócio' do inventário, que já distribui em 6 partes de 16,66%. | F17: 08. Inventário 31.12.2024 - Transportadora Irmãos Siviero
A18: 09 - Turismo Siviero Ltda. | B18: Alteração societária | C18: Venda das quotas de Rovílio Siviero (1,00%) aos demais sócios, em partes iguais - instrumento particular de compra e venda de quotas de 28/08/2025. Não altera a tabela 'valor real de cada sócio' do inventário, que já distribui em 6 partes de 16,66%. | F18: 09. Inventário 31.12.2024 - Turismo Siviero
A19: 10 - Siviero Transportes Ltda. | B19: Alteração societária | C19: Venda das quotas de Rovílio Siviero (1,00%) aos demais sócios, em partes iguais - instrumento particular de compra e venda de quotas de 28/08/2025. Não altera a tabela 'valor real de cada sócio' do inventário, que já distribui em 6 partes de 16,66%. | F19: 10. Inventário 31.12.2024 - Siviero Transportes
A20: 09 - Turismo Siviero Ltda. | B20: Pendência | C20: Rescindir o contrato particular das quotas societárias e dar baixa dos lançamentos na declaração do IRPF junto à Receita Federal (empresa baixada em 04/09/2023). | F20: 09. Inventário 31.12.2024 - Turismo Siviero
A21: 10 - Siviero Transportes Ltda. | B21: Pendência | C21: Rescindir o contrato particular das quotas societárias e dar baixa dos lançamentos na declaração do IRPF junto à Receita Federal (empresa baixada em 08/04/2024). | F21: 10. Inventário 31.12.2024 - Siviero Transportes
A23: Observação: o inventário 08 informa que a condenação no processo Sottili pode superar R$ 1.000.000,00; as três linhas do processo são cenários alternativos e não devem ser somadas.
A24: Observação: as linhas 'Nota contábil', 'Alteração societária' e 'Pendência' são informativas e não representam passivo nem redução de valor.

Sheet Correções e pendências
A1: Correções aplicadas e pendências desta versão
A2: Fonte: conferencia-discrepancias.md (26/10/2026). Valores das fontes não foram alterados; itens pendentes estão marcados com comentário nas células indicadas.
A4: Nº | B4: Situação | C4: Aba / células | D4: Descrição | E4: O que falta
A5: 1 | B5: Corrigido | C5: Ativos!F8 | D5: Descrição dos lotes do Hotel Araçá passou de '01 a 22 (vários)' para '01-12, 18-22 + nesga', conforme o inventário 06. | E5: -
A6: 2 | B6: Corrigido | C6: Composição!A47, A57, A65 | D6: Rótulo dos blocos do estudo Rafael passou de 'Total declarado no inventário' para 'Total declarado no estudo'. | E6: -
A7: 3 | B7: Incluído | C7: Vendas e créditos!A32:F48 | D7: Lista dos 12 loteamentos contratados pela Siviero Empreendimentos sem obras e sem valor atribuído (2ª parte do .docx do Hotel Princesa dos Vales). | E7: -
A8: 4 | B8: Incluído | C8: Passivos e contingências!A16:F21 | D8: Nota contábil de R$ 1.135.000,00 da Transportadora, venda das quotas de Rovílio Siviero (inventários 08, 09 e 10) e pendência de rescisão do contrato de quotas (09 e 10). | E8: -
A9: 5 | B9: Pendente | C9: Ativos!H51 | D9: Matrícula 00.760 aparece duas vezes no estudo (48,0 ha e 100,0 ha). | E9: Confirmar a matrícula correta com o autor do estudo.
A10: 6 | B10: Pendente | C10: Ativos!I51, K51; Composição!A55 | D10: Fazenda São Crispin: estudo avalia 407,53 ha; pasta 2025 indica 411,43 ha remanescentes e vendas de 190,00 ha (Rigo) e 85,32 ha (Pellegrini), contra 83,47 ha no estudo. | E10: Decidir qual base de área vale; o valor de R$ 44.828.300,00 depende disso.
A11: 7 | B11: Pendente | C11: Ativos!K59; Composição!E60:E66 | D11: Imóvel BR 470 (Oleoplan): total declarado R$ 10.631.378,60; parcelas somam R$ 13.631.378,60. | E11: Confirmar com o autor qual número está errado.
A12: 8 | B12: Pendente | C12: Passivos e contingências!D16 | D12: Nota contábil de R$ 1.135.000,00 contra R$ 1.020.000,00 dos itens 03 a 05 do inventário 08. | E12: Confirmar a origem da diferença de R$ 115.000,00.
A13: 9 | B13: Premissa | C13: Ativos!L5:L49 | D13: Participação da Valter segue a tabela 'valor real de cada sócio' de cada inventário (1/6, ou 16,50% na Rádio), e não o quadro societário original (18,00% a 18,60%). | E13: Confirmar a premissa.
A14: 10 | B14: Ausente | C14: Resumo!A12:A13 | D14: Sem inventário de 31.12.2024 na pasta 2025 para as empresas 01, 02, 05 (Hotel Princesa dos Vales), 11 e Siviero Empreendimentos Imobiliários; valores dessas empresas vêm só do estudo. | E14: Localizar os inventários, se existirem.
A15: 11 | B15: Arquivo | C15: - | D15: Existe outra versão em inventario-irmaos/inventario-2025-siviero.xlsx, diferente desta e não conferida. | E15: Definir qual é a versão oficial.
