Workbook

Sheet Ativos selecionados
A1: Nº empresa | B1: Empresa | C1: CNPJ | D1: Categoria | E1: Item | F1: Loteamento | G1: Lote | H1: Quadra | I1: Descrição | J1: Matrícula(s) | K1: Área | L1: Valor (R$) | M1: Observação | N1: Página PDF
A2: 05 | B2: HOTEL PRINCESA DOS VALES LTDA. | C2: 89.471.270/0001-94 | D2: Imóvel rural | E2: 04 | I2: Terreno rural – SEDE CAMPESTRE (pavilhão, piscinas, casa, campos de futebol, lagos, alicerces para cabanas), Rua Luiz Siviero, Bairro Femaçã, Veranópolis. CCIR 2.481.947-6. | J2: 1.941 e 7.104 | K2: 9,4 ha | L2: 5560857.5 | M2: Valor composto: terra + pavilhão + quiosque + casa + obras (ver aba Composição). | N2: 4-5
A3: 05 | B3: HOTEL PRINCESA DOS VALES LTDA. | C3: 89.471.270/0001-94 | D3: Imóvel rural | E3: 05 | I3: Área de terras rurais – FAZENDA SÃO CRISPIN, Capela de São Sebastião, Distrito do Chimarrão, André da Rocha – RS. Área total 491,0 ha. CCIR 2.898.196-0. | J3: 14.221; 13.615; 13.650; 00.760; 11.462; 05.435; 09.959; 04.443; 00.760; 12.473 | K3: 407,53 ha (491,0 ha total) | L3: 44828300 | M3: VENDIDA para a Família Rigo somente 83,47 ha desta área total, da Matrícula 00.760. Valor composto por áreas (ver aba Composição). | N3: 5
A4: 05 | B4: HOTEL PRINCESA DOS VALES LTDA. | C4: 89.471.270/0001-94 | D4: Imóvel rural | E4: 06 | I4: Área de terras rurais – FAZENDA SÃO CRISPIN, 4,0 ha dentro de um todo maior, André da Rocha – RS, adquirida de Dirceu Prestes e Lairton por contrato de compra e venda (dez/2015). | J4: 11.090 | K4: 4,0 ha | L4: 440000 | M4: Área Dirceu/Lairton – parte produtiva 100% = 4,0 ha × R$ 110.000,00. CCIR em branco no PDF. | N4: 5
A5: 05 | B5: HOTEL PRINCESA DOS VALES LTDA. | C5: 89.471.270/0001-94 | D5: Veículo | E5: 08 | I5: Veículo Mercedinha MB 709 com boiadeiro, MERCEDES BENZ, ano/modelo 1991, placa JTB 8585. | L5: 85000 | N5: 5-6
A6: 06 | B6: HOTEL ARAÇÁ LTDA. | C6: 91.889.543/0001-67 | D6: Lote urbano | E6: 12 | G6: 10 | H6: 38 | I6: Lote urbano nº 10 – Quadra 38, Capão da Canoa – RS, Insc. Imob. 360.0038.010.000, Cód. Imóvel 039411, próximo ao Hotel Araçá. Adquirido de Hugo Ferri. | J6: 11.990 | K6: 360,00 m² | L6: 390000 | N6: 6
A7: 06 | B7: HOTEL ARAÇÁ LTDA. | C7: 91.889.543/0001-67 | D7: Lote urbano | E7: 11 | G7: 09 | H7: 38 | I7: Lote urbano nº 09 – Quadra 38, Capão da Canoa – RS, Insc. Imob. 360.0038.009.000, Cód. Imóvel 039410, próximo ao Hotel Araçá. Adquirido de Hugo Ferri. | J7: 37.846 | K7: 360,00 m² | L7: 390000 | N7: 6
A8: 06 | B8: HOTEL ARAÇÁ LTDA. | C8: 91.889.543/0001-67 | D8: Lote urbano | E8: 02 | G8: 03 | H8: 19 | I8: Lote urbano nº 03 – Quadra 19, Capão da Canoa – RS, Insc. Imob. 360.0019.003.000, Cód. Imóvel 038998, próximo ao Hotel Araçá – Casa da Praça. | J8: 77.832 (antiga 37.549) | K8: 450,00 m² | L8: 400000 | N8: 6
A9: 06 | B9: HOTEL ARAÇÁ LTDA. | C9: 91.889.543/0001-67 | D9: Lote urbano | E9: 18 | G9: 27 | H9: 38 | I9: Lote urbano nº 27 – Quadra 38, Capão da Canoa – RS, Insc. Imob. 360.0038.027.000, Cód. Imóvel 039426, próximo ao Hotel Araçá. Lote Estacionamento do Bigode. | J9: 73.482 | K9: 360,00 m² | L9: 350000 | N9: 6-7
A10: 06 | B10: HOTEL ARAÇÁ LTDA. | C10: 91.889.543/0001-67 | D10: Lote urbano | E10: 19 | G10: 28 | H10: 38 | I10: Lote urbano nº 28 – Quadra 38, Capão da Canoa – RS, Insc. Imob. 360.0038.028.000, Cód. Imóvel 039427, próximo ao Hotel Araçá. Lote Estacionamento do Bigode. | J10: 73.482 | K10: 360,00 m² | L10: 350000 | M10: Mesma matrícula (73.482) do item 18 no PDF – conferir. | N10: 7
A11: 07 | B11: RÁDIO COMUNIDADE PRINCESA DOS VALES FM LTDA. | C11: 91.113.399/0001-72 | D11: Veículo | I11: Veículo TOYOTA / BANDEIRANTE, diesel, ano/modelo 1980, cor verde, placa IHW 0285, emplacado em Veranópolis – RS. | L11: 70000 | M11: Sem número de item no PDF. | N11: 7
A12: 10 | B12: SIVIERO EMPREENDIMENTOS IMOBILIÁRIOS LTDA. | C12: 89.472.195/0001-86 | D12: Veículo | E12: 14 | I12: Camionete FORD RANGER, cor prata, ano 2010, placa NPQ OI67. | L12: 67000 | M12: Placa transcrita como no PDF ("NPQ OI67"). | N12: 8
A13: 10 | B13: SIVIERO EMPREENDIMENTOS IMOBILIÁRIOS LTDA. | C13: 89.472.195/0001-86 | D13: Lote urbano | E13: 03 | I13: Lote urbano com casa/prédio, Av. Osvaldo Aranha nº 1398, Bairro Palugana, Veranópolis – escritório velho, alugado ao Sr. André (Bar do André). 19,00 m × 30,00 m. | J13: 9 | K13: 570,00 m² | L13: 850000 | N13: 8
A14: 10 | B14: SIVIERO EMPREENDIMENTOS IMOBILIÁRIOS LTDA. | C14: 89.472.195/0001-86 | D14: Lote urbano | E14: 05 | I14: Lote urbano, Av. Osvaldo Aranha esquina com Rua Eduardo Duarte, Veranópolis, alugado ao Sr. Paulinho (baterias). 23,00 m × 15,00 m. | J14: 1.507 | K14: 345,00 m² | L14: 550000 | N14: 8
A15: 10 | B15: SIVIERO EMPREENDIMENTOS IMOBILIÁRIOS LTDA. | C15: 89.472.195/0001-86 | D15: Lote urbano | E15: 06 | G15: 0092 | H15: 020 | I15: Lote urbano, Rua General Flores da Cunha, Centro, Veranópolis, adquirido da Família Dal Ponte – lote 0092, quadra 020, zona 02, distrito 01. | J15: 3.788 | K15: 750,00 m² | L15: 1010000 | N15: 8
A16: 10 | B16: SIVIERO EMPREENDIMENTOS IMOBILIÁRIOS LTDA. | C16: 89.472.195/0001-86 | D16: Lote urbano | E16: 08 | F16: LOTEAMENTO VERONA (Bento Gonçalves) | G16: 188/62 | H16: 163/G | I16: Lote urbano em Bento Gonçalves – RS, lote 188/62, quadra 163/G, cadastro P.M. Bento Gonçalves nº 12482700, Loteamento Verona. | L16: 160000 | M16: Área e matrícula em branco no PDF. | N16: 8
A17: 10 | B17: SIVIERO EMPREENDIMENTOS IMOBILIÁRIOS LTDA. | C17: 89.472.195/0001-86 | D17: Área urbana | E17: 04 | I17: Imóvel urbano, Rodovia BR 470 km 175,4, Bairro Valverde, Veranópolis, ao lado da Oleoplan S/A (unificação das matrículas 17.409 e 6.136). Pavilhões de 4.170,00 m² locados à Oleoplan S/A. | J17: 29.954 | K17: 4.792,03 m² | L17: 10631379 | M17: Total do PDF não fecha com os componentes (R$ 9.584.060,00 + R$ 933.996,60 = R$ 10.518.056,60) – ver aba Composição. | N17: 8-9
A18: 10 | B18: SIVIERO EMPREENDIMENTOS IMOBILIÁRIOS LTDA. | C18: 89.472.195/0001-86 | D18: Área urbana | E18: 02 | G18: 0292 | H18: 009 | I18: Imóvel urbano, lote 0292, quadra 009, zona 12, distrito 01, Linha Tomaz Flores, Estrada Velha da Vacaria, Sapopema, Veranópolis (próximo ao CTG Rincão da Roça Reúna). Adquirido da Família Lago. | J18: 33.516 | K18: 4,0 ha (40.027,41 m² medidos) | L18: 1500000 | M18: Listado no PDF sob "Áreas rurais em Veranópolis, Cotiporã, Fagundes Varela e Caxias do Sul", mas descrito como área urbana. | N18: 9
A19: 10 | B19: SIVIERO EMPREENDIMENTOS IMOBILIÁRIOS LTDA. | C19: 89.472.195/0001-86 | D19: Lote em loteamento | F19: 01. LOTEAMENTO SOL NASCENTE I | G19: 021 | H19: D | L19: 389000 | N19: 9
A20: 10 | B20: SIVIERO EMPREENDIMENTOS IMOBILIÁRIOS LTDA. | C20: 89.472.195/0001-86 | D20: Lote em loteamento | F20: 01. LOTEAMENTO SOL NASCENTE I | G20: 022 | H20: D | L20: 354000 | N20: 9
A21: 10 | B21: SIVIERO EMPREENDIMENTOS IMOBILIÁRIOS LTDA. | C21: 89.472.195/0001-86 | D21: Lote em loteamento | F21: 06. LOTEAMENTO ADITIVO MEDIANEIRA | G21: 003 | H21: 1 | L21: 214000 | N21: 9
A22: 10 | B22: SIVIERO EMPREENDIMENTOS IMOBILIÁRIOS LTDA. | C22: 89.472.195/0001-86 | D22: Lote em loteamento | F22: 06. LOTEAMENTO ADITIVO MEDIANEIRA | G22: 002 | H22: 6 | L22: 156000 | N22: 9
A23: 10 | B23: SIVIERO EMPREENDIMENTOS IMOBILIÁRIOS LTDA. | C23: 89.472.195/0001-86 | D23: Lote em loteamento | F23: 06. LOTEAMENTO ADITIVO MEDIANEIRA | G23: 003 | H23: 6 | L23: 156000 | N23: 9
A24: 10 | B24: SIVIERO EMPREENDIMENTOS IMOBILIÁRIOS LTDA. | C24: 89.472.195/0001-86 | D24: Lote em loteamento | F24: 06. LOTEAMENTO ADITIVO MEDIANEIRA | G24: 007 | H24: 8 | L24: 152000 | N24: 9
A25: 10 | B25: SIVIERO EMPREENDIMENTOS IMOBILIÁRIOS LTDA. | C25: 89.472.195/0001-86 | D25: Lote em loteamento | F25: 07. COLINA DO RETIRO | G25: 002 | H25: 05 | L25: 160000 | N25: 9
A26: 10 | B26: SIVIERO EMPREENDIMENTOS IMOBILIÁRIOS LTDA. | C26: 89.472.195/0001-86 | D26: Lote em loteamento | F26: 07. COLINA DO RETIRO | G26: 002 | H26: 09 | L26: 159000 | N26: 9
A27: 10 | B27: SIVIERO EMPREENDIMENTOS IMOBILIÁRIOS LTDA. | C27: 89.472.195/0001-86 | D27: Lote em loteamento | F27: 07. COLINA DO RETIRO | G27: 003 | H27: 09 | L27: 159000 | N27: 9
A28: 10 | B28: SIVIERO EMPREENDIMENTOS IMOBILIÁRIOS LTDA. | C28: 89.472.195/0001-86 | D28: Lote em loteamento | F28: 08. LOTEAMENTO SALVADOR – ALBERTO SALVADOR – FEMAÇA II | G28: 002 | H28: 02 | L28: 413000 | N28: 10
A29: 10 | B29: SIVIERO EMPREENDIMENTOS IMOBILIÁRIOS LTDA. | C29: 89.472.195/0001-86 | D29: Lote em loteamento | F29: 08. LOTEAMENTO SALVADOR – ALBERTO SALVADOR – FEMAÇA II | G29: 004 | H29: 02 | L29: 440000 | N29: 10
A30: 10 | B30: SIVIERO EMPREENDIMENTOS IMOBILIÁRIOS LTDA. | C30: 89.472.195/0001-86 | D30: Lote em loteamento | F30: 08. LOTEAMENTO SALVADOR – ALBERTO SALVADOR – FEMAÇA II | G30: 005 | H30: 02 | L30: 326000 | N30: 10
... A70: 10 | B70: SIVIERO EMPREENDIMENTOS IMOBILIÁRIOS LTDA. | C70: 89.472.195/0001-86 | D70: Lote em loteamento | F70: 20. LOTEAMENTO SAN MARINO | G70: 003 | H70: 1676 | L70: 253000 | N70: 11
A71: 10 | B71: SIVIERO EMPREENDIMENTOS IMOBILIÁRIOS LTDA. | C71: 89.472.195/0001-86 | D71: Lote em loteamento | F71: 21. LOTEAMENTO FIRMINIO DALZÓCHIO | G71: O13 | H71: 0907 | L71: 360000 | M71: Lote transcrito como "O13" no PDF (provavelmente 013). | N71: 11
A72: 10 | B72: SIVIERO EMPREENDIMENTOS IMOBILIÁRIOS LTDA. | C72: 89.472.195/0001-86 | D72: Lote em loteamento | F72: 21. LOTEAMENTO FIRMINIO DALZÓCHIO | G72: 003 | H72: 1046 | L72: 385000 | N72: 11
A73: 10 | B73: SIVIERO EMPREENDIMENTOS IMOBILIÁRIOS LTDA. | C73: 89.472.195/0001-86 | D73: Lote em loteamento | F73: 24. LOTEAMENTO INDUSTRIAL VICENTINO | G73: 007 | H73: 1303 | L73: 1355000 | N73: 11
A74: 10 | B74: SIVIERO EMPREENDIMENTOS IMOBILIÁRIOS LTDA. | C74: 89.472.195/0001-86 | D74: Lote em loteamento | F74: 25. LOTEAMENTO RESIDENCIAL JARDIM ITALIA I, II, III | G74: 001 | H74: 1736 | L74: 198000 | N74: 11-12
A75: 10 | B75: SIVIERO EMPREENDIMENTOS IMOBILIÁRIOS LTDA. | C75: 89.472.195/0001-86 | D75: Lote em loteamento | F75: 25. LOTEAMENTO RESIDENCIAL JARDIM ITALIA I, II, III | G75: 009 | H75: 1736 | L75: 220000 | N75: 11-12
A76: 10 | B76: SIVIERO EMPREENDIMENTOS IMOBILIÁRIOS LTDA. | C76: 89.472.195/0001-86 | D76: Lote em loteamento | F76: 25. LOTEAMENTO RESIDENCIAL JARDIM ITALIA I, II, III | G76: 007 | H76: 1738 | L76: 253000 | N76: 11-12
A77: 10 | B77: SIVIERO EMPREENDIMENTOS IMOBILIÁRIOS LTDA. | C77: 89.472.195/0001-86 | D77: Lote em loteamento | F77: 25. LOTEAMENTO RESIDENCIAL JARDIM ITALIA I, II, III | G77: 002 | H77: 1739 | L77: 209000 | N77: 11-12
A78: 10 | B78: SIVIERO EMPREENDIMENTOS IMOBILIÁRIOS LTDA. | C78: 89.472.195/0001-86 | D78: Lote em loteamento | F78: 25. LOTEAMENTO RESIDENCIAL JARDIM ITALIA I, II, III | G78: 001 | H78: 1740 | L78: 220000 | N78: 11-12
A79: 10 | B79: SIVIERO EMPREENDIMENTOS IMOBILIÁRIOS LTDA. | C79: 89.472.195/0001-86 | D79: Lote em loteamento | F79: 25. LOTEAMENTO RESIDENCIAL JARDIM ITALIA I, II, III | G79: 006 | H79: 1744 | L79: 198000 | N79: 11-12
...

Sheet Resumo por empresa
A1: Nº empresa | B1: Empresa | C1: Categoria | D1: Qtd. ativos | E1: Valor (R$)
A2: 05 | B2: HOTEL PRINCESA DOS VALES LTDA. | C2: Imóvel rural | D2: =COUNTIFS('Ativos selecionados'!$A$2:$A$109,A2,'Ativos selecionados'!$D$2:$D$109,C2) | E2: =SUMIFS('Ativos selecionados'!$L$2:$L$109,'Ativos selecionados'!$A$2:$A$109,A2,'Ativos selecionados'!$D$2:$D$109,C2)
A3: 05 | B3: HOTEL PRINCESA DOS VALES LTDA. | C3: Veículo | D3: =COUNTIFS('Ativos selecionados'!$A$2:$A$109,A3,'Ativos selecionados'!$D$2:$D$109,C3) | E3: =SUMIFS('Ativos selecionados'!$L$2:$L$109,'Ativos selecionados'!$A$2:$A$109,A3,'Ativos selecionados'!$D$2:$D$109,C3)
A4: 06 | B4: HOTEL ARAÇÁ LTDA. | C4: Lote urbano | D4: =COUNTIFS('Ativos selecionados'!$A$2:$A$109,A4,'Ativos selecionados'!$D$2:$D$109,C4) | E4: =SUMIFS('Ativos selecionados'!$L$2:$L$109,'Ativos selecionados'!$A$2:$A$109,A4,'Ativos selecionados'!$D$2:$D$109,C4)
A5: 07 | B5: RÁDIO COMUNIDADE PRINCESA DOS VALES FM LTDA. | C5: Veículo | D5: =COUNTIFS('Ativos selecionados'!$A$2:$A$109,A5,'Ativos selecionados'!$D$2:$D$109,C5) | E5: =SUMIFS('Ativos selecionados'!$L$2:$L$109,'Ativos selecionados'!$A$2:$A$109,A5,'Ativos selecionados'!$D$2:$D$109,C5)
A6: 10 | B6: SIVIERO EMPREENDIMENTOS IMOBILIÁRIOS LTDA. | C6: Veículo | D6: =COUNTIFS('Ativos selecionados'!$A$2:$A$109,A6,'Ativos selecionados'!$D$2:$D$109,C6) | E6: =SUMIFS('Ativos selecionados'!$L$2:$L$109,'Ativos selecionados'!$A$2:$A$109,A6,'Ativos selecionados'!$D$2:$D$109,C6)
A7: 10 | B7: SIVIERO EMPREENDIMENTOS IMOBILIÁRIOS LTDA. | C7: Lote urbano | D7: =COUNTIFS('Ativos selecionados'!$A$2:$A$109,A7,'Ativos selecionados'!$D$2:$D$109,C7) | E7: =SUMIFS('Ativos selecionados'!$L$2:$L$109,'Ativos selecionados'!$A$2:$A$109,A7,'Ativos selecionados'!$D$2:$D$109,C7)
A8: 10 | B8: SIVIERO EMPREENDIMENTOS IMOBILIÁRIOS LTDA. | C8: Área urbana | D8: =COUNTIFS('Ativos selecionados'!$A$2:$A$109,A8,'Ativos selecionados'!$D$2:$D$109,C8) | E8: =SUMIFS('Ativos selecionados'!$L$2:$L$109,'Ativos selecionados'!$A$2:$A$109,A8,'Ativos selecionados'!$D$2:$D$109,C8)
A9: 10 | B9: SIVIERO EMPREENDIMENTOS IMOBILIÁRIOS LTDA. | C9: Lote em loteamento | D9: =COUNTIFS('Ativos selecionados'!$A$2:$A$109,A9,'Ativos selecionados'!$D$2:$D$109,C9) | E9: =SUMIFS('Ativos selecionados'!$L$2:$L$109,'Ativos selecionados'!$A$2:$A$109,A9,'Ativos selecionados'!$D$2:$D$109,C9)
C11: TOTAL GERAL | D11: =SUM(D2:D9) | E11: =SUM(E2:E9)

Sheet Composição
A1: Empresa | B1: Item | C1: Componente | D1: Base de cálculo (como no PDF) | E1: Valor (R$)
A2: 05 | B2: 04 | C2: Área de terras | D2: 9,4 ha × R$ 450.000,00/ha | E2: 4230000
A3: 05 | B3: 04 | C3: Pavilhão – obra civil | D3: 891,00 m² × R$ 746,00 (CUB ago/2017) | E3: 664686
A4: 05 | B4: 04 | C4: Benfeitoria – Quiosque | E4: 150000
A5: 05 | B5: 04 | C5: Casa de alvenaria (fundos da Sede) | D5: área construída em branco no PDF | E5: 250000
A6: 05 | B6: 04 | C6: Obras feitas e infraestrutura | D6: 25% × R$ 1.064.686,00 | E6: 266171.5
A7: 05 | B7: 04 | C7: Soma dos componentes | E7: =SUM(E2:E6)
A8: 05 | B8: 04 | C8: Valor total no PDF | E8: 5560857.5
A9: 05 | B9: 04 | C9: Diferença (PDF − soma) | E9: =E8-E7
A11: 05 | B11: 05 | C11: Área Dona Rita – parte produtiva (35%) | D11: 100,0 ha × R$ 110.000,00 | E11: 11000000
A12: 05 | B12: 05 | C12: Área Dona Rita – parte não produtiva (65%) | D12: 186,0 ha × R$ 110.000,00 | E12: 20460000
A13: 05 | B13: 05 | C13: Área Zancheta – parte produtiva (80%) | D13: 45,6 ha × R$ 110.000,00 | E13: 5016000
A14: 05 | B14: 05 | C14: Área Zancheta – parte não produtiva (20%) | D14: 11,4 ha × R$ 110.000,00 | E14: 1254000
A15: 05 | B15: 05 | C15: Área Jane/João Paulo – parte produtiva (100%) | D15: 148,0 ha − 83,47 ha vendidos = 64,53 ha × R$ 110.000,00 | E15: 7098300
A16: 05 | B16: 05 | C16: Soma dos componentes | E16: =SUM(E10:E15)
A17: 05 | B17: 05 | C17: Valor total no PDF | E17: 44828300
A18: 05 | B18: 05 | C18: Diferença (PDF − soma) | E18: =E17-E16
A20: 10 | B20: 04 | C20: Terreno BR 470 (Oleoplan) | D20: 4.792,03 m² × R$ 2.000,00/m² | E20: 9584060
A21: 10 | B21: 04 | C21: Pavilhões – obra civil (30% agregado) | D21: 30% × (4.170,00 m² × R$ 746,60 = R$ 3.113.322,00) | E21: 933996.6
A22: 10 | B22: 04 | C22: Soma dos componentes | E22: =SUM(E19:E21)
A23: 10 | B23: 04 | C23: Valor total no PDF | E23: 10631379
A24: 10 | B24: 04 | C24: Diferença (PDF − soma) | E24: =E23-E22
