Workbook

Sheet GERAL
A1: 11 | B1: SIVIERO EMPREENDIMENTOS IMOBILIÁRIOS LTDA. | C1: =C3+C664 -> 1.3747126e+08 | D1: =D3 -> 2.672202e+08 | E1: =E3+E664 -> 1.0087403e+08
C2: valores 2018 -> 2025: | F2: Estudo Rafael (Valter) | G2: Dif. Rafael − Inv. 2025 | J2: =IF(J1<0,"patrimônio diminuiu","patrimônio aumentou") -> patrimônio aumentou
A3: 11.1 | B3: PATRIMÔNIO | C3: =C5+C29+C47+C62+C66+C73+C92 -> 1.3747126e+08 | D3: =D5+D29+D47+D66+D73+D92 -> 2.672202e+08 | E3: =E5+E29+E47+E66+E73+E92 -> 1.5279626e+08 | J3: =E3-D3 -> -1.1442394e+08
D4: =(D3/C3)-1 -> 0.94382591 | J4: =IF(#REF!<0,"patrimônio diminuiu","patrimônio aumentou") -> #REF!
A5: 11.1.1 | B5: Veículos | C5: =SUM(C7:C27) -> 983000 | D5: =SUM(D7:D27) -> 963000 | E5: =SUM(E7:E27) -> 1217000 | J5: =SUM(J7:J27) -> 254000
C6: =COUNTIF(C7:C28,">1") -> 18 | D6: =(D5/C5)-1 -> -0.02034588 | E6: =COUNTIF(E7:E28,">1") -> 15
A7: 1 | B7: Um veículo caminhão basculante, marca VW = PLACA IUV 8D25, cor branca, ano 2013, adquirido da empresa Dalfovo. | valor: R$ 198.000,00 | C7: 198000 | D7: 198000 | E7: 198000 | J7: =E7-D7 -> 0
A8: 2 | B8: Um veículo caminhão basculante, marca VW = PLACA IUV 8D09, cor branca, ano 2013, adquirido da empresa Dalfovo. | valor: R$ 198.000,00 | C8: 198000 | D8: 198000 | E8: 198000 | J8: =E8-D8 -> 0
A9: 3 | B9: Um veículo caminhão basculante, marca MERCEDES BENZ, L1620 = PLACA ILQ 1739, cor cinza, ano 2003. | valor: R$ 98.000,00 | C9: 98000 | D9: 98000 | E9: 98000 | J9: =E9-D9 -> 0
A10: 4 | B10: Um veículo caminhão basculante, marca MERCEDES BENZ, = PLACA IBP 3873, cor vermelha, ano 1990. | valor: R$ 53.000,00 | C10: 53000 | D10: 53000 | E10: 53000 | J10: =E10-D10 -> 0
A11: 5 | B11: Um veículo caminhão SCANIA = PLACA IIQ 0751, cor laranja, ano 1963. | valor: R$ 28.000,00 | C11: 28000 | D11: 28000 | E11: 25000 | J11: =E11-D11 -> -3000
A12: 6 | B12: Um semirreboque RANDON = PLACA IHP 6632, cor amarelo, ano 1990. | valor: R$ 25.000,00 | C12: 25000 | D12: 25000 | E12: 25000 | J12: =E12-D12 -> 0
A13: 7 | B13: Um veículo Mercedinha, marca MERCEDES BENZ, L608 = PLACA BWF 0672, cor vermelha, ano 1979. | valor: R$ 20.000,00 | C13: 20000 | D13: 20000 | E13: 20000 | J13: =E13-D13 -> 0
A14: 8 | B14: Um veículo caminhão basculante, marca MERCEDES BENZ, L1316 = PLACA IHZ 0172, cor vermelha, ano 1984. | valor: R$ 50.000,00 | C14: 50000 | D14: 50000 | E14: 50000 | J14: =E14-D14 -> 0
A15: 9 | B15: Um veículo caminhão basculante, marca MERCDES BENZ = PLACA IHW 8294, cor grená, ano 1974. | valor: R$ 30.000,00 | C15: 30000 | D15: 30000 | E15: 30000 | J15: =E15-D15 -> 0
A16: 10 | B16: Um veículo caminhão, marca SCÂNIA = PLACA IHK 2435, cor laranja, ano 1967. | valor: R$ 0.000,00 | C16: 40000 | D16: 25000 | E16: 25000 | J16: =E16-D16 -> 0 | K16: Em 2018 valia R$40mil. Diferença provável depreciação
A17: 11 | B17: Uma camionete TOYOTA HILUX, cor preta, ano 2018 = PLACA IYJ 8I14. | valor: R$ 188.000,00 | C17: 0 | D17: 0 | E17: 188000 | J17: =E17-D17 -> 188000
A18: 12 | B18: Um veículo caminhão, marca SCÂNIA = PLACA IIX 8288, cor laranja, ano 1963. | valor: R$ 30.000,00 | C18: 30000 | D18: 25000 | E18: 25000 | J18: =E18-D18 -> 0 | K18: Em 2018 valia R$35mil. Diferença provável depreciação
A19: 13 | B19: Um carro automóvel FORD, cor vermelha, ano 1929 = PLACA IKR 3B22 – FUBICA. | valor: R$ 40.000,00 | C19: 40000 | D19: 40000 | E19: 60000 | J19: =E19-D19 -> 20000
A20: 14 | B20: Uma camionete FORD RANGER, cor prata, ano 2010 = PLACA NPQ OI67. | valor: R$ 67.000,00 | C20: 0 | D20: 0 | E20: 67000 | J20: =E20-D20 -> 67000
A21: 15 | B21: Um veículo JEEP COMPASS = PLACA GHX 9I84, cor cinza, ano 2022. | valor: R$ 150.000,00 | C21: 0 | D21: 0 | E21: 155000 | I21: Inventário 11, veículo 15: TOYOTA RAV4, placa IZQ 9H36, prata, 2019, R$ 155.000,00. A planilha descreve um JEEP COMPASS GHX 9I84 2022. Valor igual, bem diferente. | J21: =E21-D21 -> 155000
A22: 1 | B22: Um veículo DODGE = PLACA IQJ 5001, cor azul, ano 1978. VENDIDO PELO VALOR DE R$ 30.000,00, EM TROCA DE PALANQUES E POSTES DE MADEIRA. | C22: 30000 | D22: 30000 | E22: 0 | J22: =E22-D22 -> -30000
A23: =A22+1 -> 2 | B23: Um semirreboque ARTESANAL = PLACA IIH 6326, cor branca, ano 1986. | valor: R$ 20.000,00 | C23: 20000 | D23: 20000 | E23: 0 | J23: =E23-D23 -> -20000
A24: =A23+1 -> 3 | B24: Um veículo camionete, marca FORD, F1000 TURBO XL = PLACA IIO 5901, cor prata, ano 1998 – Pedro Siviero. | C24: 35000 | D24: 35000 | E24: 0 | J24: =E24-D24 -> -35000
A25: =A24+1 -> 4 | B25: Um veículo camionete, marca FORD, F1000 4x4 = PLACA IHP 6607, cor prata, ano 1994 – Válter Siviero. | C25: 33000 | D25: 33000 | E25: 0 | J25: =E25-D25 -> -33000
A26: =A25+1 -> 5 | B26: Um veículo GOL, marca VW 1.6 = PLACA IQS 7696, cor cinza, ano 2010 – João Lunelli. | C26: 25000 | D26: 25000 | E26: 0 | J26: =E26-D26 -> -25000
A27: =A26+1 -> 6 | B27: Um veículo caminhão, marca SCÂNIA = PLACA IIX 8288, cor laranja, ano 1963. | valor: R$ 30.000,00 | C27: 30000 | D27: 30000 | E27: 0 | J27: =E27-D27 -> -30000
J28: =IF(or(#REF!=0,#REF!=""),"",IF((#REF!-#REF!)=0,"",IF(AND(#REF!<>0,or(#REF!=0,#REF!="")),"verificar situação",IF((#REF!-#REF!)<>0,#REF!-#REF!,"ERRO")))) -> #REF!
A29: 11.1.2 | B29: Máquinas | C29: =SUM(C31:C45) -> 1350000 | D29: =SUM(D31:D45) -> 1180000 | E29: =SUM(E31:E45) -> 2517000 | J29: =E29-D29 -> 1337000
C30: =COUNTIF(C31:C45,">1") -> 12 | D30: =(D29/C29)-1 -> -0.12592593 | E30: =COUNTIF(E31:E45,">1") -> 14
A31: 1 | B31: Uma Escavadeira Hidráulica, ano 2024, modelo 320, CATERPILLAR. | valor: R$ 887.000,00 | C31: 0 | D31: 0 | E31: 887000 | J31: =E31-D31 -> 887000
A32: =A31+1 -> 2 | B32: Uma Escavadeira Hidráulica, ano 2014, modelo 320DL, CATERPILLAR. | valor: R$ 400.000,00 | C32: 400000 | D32: 350000 | E32: 350000 | J32: =E32-D32 -> 0 | K32: Em 2018 valia R$400mil. Diferença provável depreciação
A33: =A32+1 -> 3 | B33: Uma Escavadeira Hidráulica, ano 2009, modelo 320D, CATERPILLAR – SEI. | valor: R$ 200.000,00 | C33: 250000 | D33: 200000 | E33: 200000 | J33: =E33-D33 -> 0 | K33: Em 2018 valia R$250mil. Diferença provável depreciação
A34: =A33+1 -> 4 | B34: Um Trator de Esteira D6, ano 1980. | valor: R$ 80.000,00 | C34: 80000 | D34: 80000 | E34: 80000 | J34: =E34-D34 -> 0
A35: =A34+1 -> 5 | B35: Um Trator de Esteira D6, ano..... | valor: R$ 100.000,00 | C35: 100000 | D35: 80000 | E35: 80000 | J35: =E35-D35 -> 0 | K35: Em 2018 valia R$100mil. Diferença provável depreciação
A36: =A35+1 -> 6 | B36: Um Trator de Esteira D6, ano..... | valor: R$ 100.000,00 | C36: 100000 | D36: 50000 | E36: 50000 | J36: =E36-D36 -> 0 | K36: Em 2018 valia R$100mil. Diferença provável depreciação
A37: =A36+1 -> 7 | B37: Uma Retroescavadeira CASE 580L, ano 2001, PLACA IKI 4827. | valor: R$ 60.000,00 | C37: 60000 | D37: 60000 | E37: 60000 | J37: =E37-D37 -> 0
A38: =A37+1 -> 8 | B38: Uma Pá carregadeira, ano 1980. | valor: R$ 60.000,00 | C38: 60000 | D38: 60000 | E38: 60000 | J38: =E38-D38 -> 0
A39: =A38+1 -> 9 | B39: Um Compressor, ano 2012, marca ATLAS COPCO. | valor: R$ 150.000,00 | C39: 150000 | D39: 150000 | E39: 150000 | J39: =E39-D39 -> 0
A40: =A39+1 -> 10 | B40: Um Compressor, ano 1980, a ar, CA80, marca ATLAS COPCO. Adquirido por leilão da Prefeitura de Bento Gonçalves. | valor: R$ 10.000,00 | C40: 10000 | D40: 10000 | E40: 10000 | J40: =E40-D40 -> 0
...

Sheet Rafael × Inventário
A1: Estudo 2 do Rafael comparado ao inventário 11 (Siviero Empreendimentos Imobiliários, 31.12.2024)
A2: Valores a 100% da empresa. Inventário 2025 = coluna E da GERAL; Estudo Rafael = coluna F da GERAL (valores do Valter). Resultado para a Valter: crédito (+) ou valor a complementar (−) informado no quadro-resumo de cada PDF.
A4: Seção | B4: Item | C4: Linha na GERAL | D4: Inventário 2025 (R$) | E4: Estudo Rafael (R$) | F4: Diferença (R$) | G4: Resultado p/ Valter no PDF (R$) | H4: Observação
A5: 11.1.3 | B5: Lotes urbanos em Veranópolis e Bento Gonçalves | C5: 47 | D5: =GERAL!E47 -> 3290000 | E5: =GERAL!F47 -> 3510000 | F5: =E5-D5 -> 220000 | G5: -1985000 | H5: Coluna G: R$ 1.985.000 da linha "Diferença nominal a complementar da Valter" do quadro-resumo (p. 11), com sinal negativo por ser valor a complementar. Valter reavalia os itens 02 (+R$ 200.000) e 07 (+R$ 20.000). Escolhe os itens 03, 05, 06 e 08 (R$ 2.570.000) contra 1/6 de R$ 585.000.
A6: 11.1.5 | B6: Áreas rurais em Veranópolis, Cotiporã, Fagundes Varela e Caxias do Sul | C6: 73 | D6: =GERAL!E73 -> 7663866 | E6: =GERAL!F73 -> 10918666 | F6: =E6-D6 -> 3254800 | G6: 319776.66 | H6: Coluna G: linha "Crédito patrimonial da Valter" do quadro-resumo (p. 25). Valter reavalia 7 dos 12 itens. Escolhe o item 02 (R$ 1.500.000) contra 1/6 de R$ 1.819.776,66.
A7: 11.1.6 | B7: Loteamentos executados e registrados (31) | C7: 92 | D7: =GERAL!E92 -> 111179000 | E7: =GERAL!F92 -> 113178000 | F7: =E7-D7 -> 1999000 | H7: Coluna G vazia: o PDF não traz um resultado único para os 31 loteamentos; o saldo de cada um está na coluna G da tabela de loteamentos (linhas 31 a 61). Valter só altera o Lago Negro (+R$ 1.479.000) e o Fracionamento Simioni (+R$ 520.000).
A8: 11.2.1 | B8: Caminhos do Sol | C8: 667 | D8: =GERAL!E667 -> 0 | E8: =GERAL!F667 -> 8601000 | F8: =E8-D8 -> 8601000 | G8: 1433500 | H8: Coluna G: linha "Crédito patrimonial da Valter" do quadro-resumo (p. 6). No inventário o valor é o placeholder R$ 00.000.000,00. Valter: 61 lotes x R$ 141.000.
A9: 11.2.1 | B9: Vale das Colinas | C9: 668 | D9: =GERAL!E668 -> -4211035 | E9: =GERAL!F668 -> 808565 | F9: =E9-D9 -> 5019600 | G9: 134160.84 | H9: Coluna G: linha "Crédito patrimonial da Valter" do quadro-resumo (p. 7). O crédito correto seria R$ 134.760,83 (erro no 1/6 dos encargos).
A10: 11.2.1 | B10: Vista da Colina | C10: 669 | D10: =GERAL!E669 -> -2664900 | E10: =GERAL!F669 -> 719100 | F10: =E10-D10 -> 3384000 | G10: 119850 | H10: Coluna G: linha "Crédito patrimonial da Valter" do quadro-resumo (p. 8). Multa de R$ 2.556.900 difere de 20% do custo (R$ 2.420.000).
A11: 11.2.1 | B11: Famílias Pedrotti, Andreis e Lorandi | C11: 670 | D11: =GERAL!E670 -> -2588646 | E11: =GERAL!F670 -> 795354 | F11: =E11-D11 -> 3384000 | G11: 132559 | H11: Coluna G: linha "Crédito patrimonial da Valter" do quadro-resumo (p. 7). Mesmo número de lotes (242) e custo (R$ 12,1 mi) que Vista da Colina.
A12: 11.2.1 | B12: Família Cecconello | C12: 671 | D12: =GERAL!E671 -> -1300000 | E12: =GERAL!F671 -> 7865000 | F12: =E12-D12 -> 9165000 | G12: 1310833.3 | H12: Coluna G: linha "Valor líquido hipotético" do quadro da p. 5 (R$ 1.310.833,33); o quadro-resumo da p. 6 arredonda para R$ 1.310.834. A p. 1 estima 130 lotes; as pp. 2-5 usam 180.
A13: 11.2.1 | B13: Bonetto | C13: 672 | D13: =GERAL!E672 -> -782000 | E13: =GERAL!F672 -> 2329000 | F13: =E13-D13 -> 3111000 | G13: 388167 | H13: Coluna G: linha "Crédito patrimonial da Valter 1/6" do quadro-resumo (p. 6).
A14: 11.2.1 | B14: Pasqual | C14: 673 | D14: =GERAL!E673 -> -1500000 | E14: =GERAL!F673 -> -21000 | F14: =E14-D14 -> 1479000 | G14: -3500 | H14: Coluna G: linha "Diferença nominal a complementar da Valter" do quadro-resumo (p. 6), negativa no próprio PDF. O valor vem de arredondamento (2,41 x 2,4167 bens).
A15: 11.2.1 | B15: Industrial Dr. Letti | C15: 674 | D15: =GERAL!E674 -> -1650000 | E15: =GERAL!F674 -> -1650000 | F15: =E15-D15 -> 0 | G15: -275000 | H15: Coluna G: "parcela potencial da Valter" (1/6 da multa) no quadro de consolidação dos riscos (p. 4), com sinal negativo por ser obrigação. O quadro-resumo (p. 7) soma Dr. Letti e Sol Nascente III: R$ 451.333,33 a complementar. Sem estimativa de lotes (aparece como ???).
A16: 11.2.1 | B16: Sol Nascente III | C16: 675 | D16: =GERAL!E675 -> -1058000 | E16: =GERAL!F675 -> -1058000 | F16: =E16-D16 -> 0 | G16: -176333.33 | H16: Coluna G: "parcela potencial da Valter" (1/6 da multa) no quadro de consolidação dos riscos (p. 4), com sinal negativo por ser obrigação. Município aparece como Antônio Prado e como Farroupilha.
A17: 11.2.2 | B17: Lotes de terceiros passíveis de indenização | C17: 677 | D17: =GERAL!E677 -> -16240000 | E17: =GERAL!F677 -> -16240000 | F17: =E17-D17 -> 0 | H17: Coluna G vazia: o PDF (p. 5) traz R$ 2.706.333,33 como "crédito patrimonial de referência, 1/6", sem dizer se soma ou subtrai. Mesmos 26 lotes.
A18: 11.2.3 | B18: Obras finais no Colina do Retiro II | C18: 719 | D18: =GERAL!E719 -> -3800000 | E18: =GERAL!F719 -> -3800000 | F18: =E18-D18 -> 0 | H18: Coluna G vazia: o 1/6 da obra (R$ 633.333,33, PDF do Colina do Retiro II, pp. 3 e 9) já está descontado no crédito de R$ 2.730.166,67 desse loteamento.
A19: 11.2.4 e 11.2.5 | B19: Demais compromissos e empréstimos | C19: 721 | D19: =GERAL!E721+GERAL!E738 -> -16127652 | E19: =GERAL!F721 -> -16127652 | F19: =E19-D19 -> 0.030000001 | G19: -2687942 | H19: Coluna G: linha "Reflexo proporcional das obrigações" (1/6) do quadro-resumo do PDF DEMAIS COMPROMISSOS (p. 3), com sinal negativo por ser obrigação. O estudo só traz o total dos itens 1 a 24.
B20: Total dos itens comparados | D20: =SUM(D5:D19) -> 70210633 | E20: =SUM(E5:E19) -> 109828033 | F20: =SUM(F5:F19) -> 39617400
A22: Itens da GERAL sem estudo correspondente
A23: 11.1.1 | B23: Veículos | C23: 5 | D23: =GERAL!E5 -> 1217000
A24: 11.1.2 | B24: Máquinas | C24: 29 | D24: =GERAL!E29 -> 2517000
A25: 11.1.3.A | B25: Imóveis e móveis (11.1.3.A) | C25: 62 | D25: =GERAL!E62 -> 0
A26: 11.1.4 | B26: Áreas urbanas em Veranópolis | C26: 66 | D26: =GERAL!E66 -> 26929395
B27: Total sem estudo | D27: =SUM(D23:D26) -> 30663395
A29: Loteamentos executados: 1/6 da Valter e lotes escolhidos | H29: Coluna F: soma dos lotes que a Valter escolheu, listados no PDF LOTES LOTEAMENTOS EXECUTADOS E REGISTRADOS (sem os lotes em possível APP). Coluna G: calculada nesta aba, 1/6 (coluna E) menos escolhidos (coluna F). Positivo: crédito da Valter; negativo: escolhidos acima do 1/6. O resultado confere com a "diferença nominal" citada no PDF de cada loteamento, exceto no Salvador.
A30: Item | B30: Loteamento | C30: Linha na GERAL | D30: Estudo Rafael (R$) | E30: 1/6 da Valter (R$) | F30: Lotes escolhidos pela Valter (R$) | G30: Saldo da Valter (R$) | H30: Observação
A31: 01 | B31: Loteamento Sol Nascente I | C31: 94 | D31: =GERAL!F94 -> 4031000 | E31: =D31/6 -> 671833.33 | F31: 743000 | G31: =E31-F31 -> -71166.667
A32: 02 | B32: Loteamento Boito | C32: 111 | D32: =GERAL!F111 -> 136000 | E32: =D32/6 -> 22666.667 | F32: 0 | G32: =E32-F32 -> 22666.667
A33: 03 | B33: Condomínio Morada do Ipê I | C33: 115 | D33: =GERAL!F115 -> 629000 | E33: =D33/6 -> 104833.33 | F33: 0 | G33: =E33-F33 -> 104833.33
A34: 04 | B34: Loteamento Fracionamento Simioni | C34: 120 | D34: =GERAL!F120 -> 520000 | E34: =D34/6 -> 86666.667 | F34: 0 | G34: =E34-F34 -> 86666.667 | H34: Grupo: 4 lotes em APP, total R$ 0. Valter: R$ 520.000 para o conjunto e diferença em seu favor de R$ 520.000.
A35: 05 | B35: Loteamento Solar Norte I e II | C35: 127 | D35: =GERAL!F127 -> 1171000 | E35: =D35/6 -> 195166.67 | F35: 0 | G35: =E35-F35 -> 195166.67
A36: 06 | B36: Loteamento Aditivo Medianeira | C36: 136 | D36: =GERAL!F136 -> 2647000 | E36: =D36/6 -> 441166.67 | F36: 678000 | G36: =E36-F36 -> -236833.33 | H36: O quadro traz R$ 236.833,34 como valor dos escolhidos (é a diferença entre R$ 678.000 e o 1/6).
A37: 07 | B37: Loteamento Colina do Retiro I | C37: 154 | D37: =GERAL!F154 -> 2585000 | E37: =D37/6 -> 430833.33 | F37: 478000 | G37: =E37-F37 -> -47166.667
A38: 08 | B38: Loteamento Salvador – Alberto Salvador – FEMAÇÃ II | C38: 170 | D38: =GERAL!F170 -> 8374000 | E38: =D38/6 -> 1395666.7 | F38: 1789000 | G38: =E38-F38 -> -393333.33 | H38: O texto diz que os escolhidos ficam R$ 47.166,67 acima do 1/6 (número do Colina do Retiro I); pelos valores do quadro a diferença é R$ 393.333,33.
A39: 09 | B39: Loteamento Colina do Retiro II | C39: 207 | D39: =GERAL!F207 -> 20181000 | E39: =D39/6 -> 3363500 | F39: 3881000 | G39: =E39-F39 -> -517500 | H39: O crédito informado (R$ 2.730.166,67) usa o 1/6 de referência menos 1/6 da obra, e não a seleção de 20 lotes.
A40: 10 | B40: Loteamento Industrial Pedra Lisa | C40: 316 | D40: =GERAL!F316 -> 10985000 | E40: =D40/6 -> 1830833.3 | F40: 2295000 | G40: =E40-F40 -> -464166.67
A41: 11 | B41: Loteamento Monte Vêneto | C41: 350 | D41: =GERAL!F350 -> 241000 | E41: =D41/6 -> 40166.667 | F41: 0 | G41: =E41-F41 -> 40166.667
A42: 12 | B42: Loteamento Baldasso | C42: 354 | D42: =GERAL!F354 -> 1419000 | E42: =D42/6 -> 236500 | F42: 272000 | G42: =E42-F42 -> -35500
A43: 13 | B43: Loteamento Colina do Basalto | C43: 362 | D43: =GERAL!F362 -> 2180000 | E43: =D43/6 -> 363333.33 | F43: 778000 | G43: =E43-F43 -> -414666.67
...

Sheet Resumo
B2: imóveis que precisam ser avaliados
B3: pedir valor de todas vendas no período (+comissão, +impostos e etc)
B4: questionar diferença entre a avaliação do patrimônio da cisão do Rovílio e a nossa
B5: pedir processos multas ambientais: listar quais
B6: questionar lógica de cobrar multas e processos ainda não pagos (ex.: lot.caxias / lotes farroupilha)
B7: casa joel capão da canoa (condomínio Condado de Capão) + lotes comprados de Cândido Boff e etc
B8: cópia dos contratos buriti
B9: todos urbanísticos e licenças dos loteamentos em execução os contratados
B10: achar contrato da compra de 2 lotes no Caminhos do Sol feitos pelo Dante. Acredito que eles diminuiram os lotes vendidos
A16: =MAX($A$7:A15)+1 -> 1 | B16: VALUATIONS NECESSÁRIAS
B18: A íntegra dos documentos:
B19: 01. Abastecedora
B20: 05. Hotel Princesa dos Vales
B21: 06. Hotel Araçá
B22: 07. Rádio Comunidade
B23: 08. Transportadora
B25: Da Siviero Empreendimentos
B26: Empreendimentos não executados
B27: Contratos com Buriti
B28: Imóveis de valor não corrigido (itens 1.3 / 1.4 / 1.5)
A34: =MAX($A$7:A33)+1 -> 2 | B34: LOTEAMENTOS EXECUTADOS E REGISTRADOS | C34: 2018 | D34: 2025 | E34: Diferença | F34: (%)
B36: Número de lotes apresentados: | C36: =GERAL!C93 -> 751 | D36: =GERAL!E93 -> 418 | E36: =C36-D36 -> 333 | F36: =D36/C36 -> 0.55659121
B37: Valores Atualizado para 2025: | C37: =GERAL!D92 -> 2.2692194e+08 | D37: =GERAL!E92 -> 111179000 | E37: =D37-C37 -> -1.1574294e+08 | F37: =D37/C37 -> 0.48994382
B39: Obs.: | C39: As diferenças de patrimônio e lotes parece grande demais. Seria uma média de 4 lotes vendidos por mês.
C40: Talvez lotes vendidos e não registrados antes de 2018 ainda constem nessa relação.
C42: Para esses números pegamos a média de preço dos lotes que a Siviero ainda possui e aplicamos
A44: =MAX($A$7:A43)+1 -> 3 | B44: LOTEAMENTOS EXECUTADOS E REGISTRADOS QUE CONSTAM APENAS NA RELAÇÃO DE 2018 | C44: 2018 | D44: 2025
B46: Número de Loteamentos | C46: 24 | D46: -
B47: Número de Lotes | D47: -
B48: Número de Loteamentos com ZERO lotes: | C48: 15 | D48: -
B50: Obs.: | C50: Suponho que sejam loteamentos que foram completamente vendidos
C51: Por que loteamentos com ZERO lotes constam na relação? Apenas para informar o nome ou outro motivo?
A53: =MAX($A$7:A52)+1 -> 4 | B53: Ref. 11.2.3 - Item 1: PAGAMENTO DE COTAS DE ROVÍLIO SIVIERO
B55: Sócio tem direito à 2% das empresas: | C55: Ele recebeu: | D55: 3440082 | E55: =D55*50 -> 172004100
D57: Avaliação das Empresas | E57: 2% da avaliação das Empresas
C58: Siviero Emp. Imob. Ltda.: | D58: 1.0087403e+08 | E58: =D58*0.02 -> 2017480.6
C59: Abastecedora de Combustíveis: | D59: 9661414 | E59: =D59*0.02 -> 193228.28
C60: Transportadora Irmãos Siviero: | D60: 16374986 | E60: =D60*0.02 -> 327499.72
D61: =SUM(D58:D60) -> 1.2691043e+08 | E61: =SUM(E58:E60) -> 2538208.6
B63: Obs.: | C63: Diferença de 36.53%
...

Sheet questionamentos
B2: Dúvida:
B3: Houve uma redução de 751 lotes para
B5: TOTAIS: | C5: 751 | D5: 421 | E5: 331
B6: Nome do Loteamento | C6: Lotes 2018 | D6: Lotes 2025 | E6: Negociados
B7: Loteamento Sol Nascente I - Antônio Prado – RS | C7: 14 | D7: 11 | E7: 3
B8: Loteamento Boito - Nova Prata – RS | C8: 0 | D8: 1 | E8: 0
B9: Condomínio Morada do Ipê I - Passo Fundo – RS | C9: 29 | D9: 2 | E9: 27
B10: Loteamento Fracionamento Simioni - Veranópolis – RS | C10: 4 | D10: 4 | E10: 0
B11: Loteamento Solar Norte - Veranópolis – RS | C11: 10 | D11: 6 | E11: 4
B12: Loteamento Aditivo Medianeira - Veranópolis – RS | C12: 20 | D12: 15 | E12: 5
B13: Loteamento Colina do Retiro I – Veranópolis – RS | C13: 23 | D13: 15 | E13: 8
B14: Loteamento Salvador - Veranópolis – RS | C14: 36 | D14: 26 | E14: 10
B15: Loteamento Colina do Retiro II - Frainer - Veranópolis – RS | C15: 105 | D15: 102 | E15: 3
B16: Loteamento Industrial Pedra Lisa - Veranópolis – RS | C16: 39 | D16: 31 | E16: 8
B17: Loteamento Monte Vêneto - Carlos Barbosa – RS | C17: 1 | D17: 1 | E17: 0
B18: Loteamento Baldasso - Carlos Barbosa – RS | C18: 15 | D18: 5 | E18: 10
... B46: Loteamento Viero - Farroupilha – RS | C46: 8 | D46: 0 | E46: 8
B48: Situação dos empreendimentos citados em 2018
B49: Loteamento Morada da Colina - Veranópolis
B50: Loteamento Bella Visione - Carlos Barbosa
B51: Loteamento Lovison - Nova Prata
B52: Loteamento São Roque
B53: Loteamento Desmembramento Tedesco I - Veranópolis
B54: Loteamento Desmembramento Tedesco II - Veranópolis
B55: Loteamento Colina do Lindóia - Farroupilha
B56: Loteamento Fracionamento Pagliari - Carlos Barbosa
B57: Loteamento Fracionamento Primavera - Farroupilha
B61: Multas de Distratos | C61: =SUM(C62:C70) -> 15754581
B62: Loteamento Caminhos do Sol | C62: 0
B63: Loteamento Vale das Colinas | C63: 4211035
B64: Loteamento Vista da Colina | C64: 2664900
B65: Loteamento Pedrotti + Andreis + Lorandi | C65: 2588646
B66: Loteamento Cecconello | C66: 1300000
B67: Loteamento Bonetto | C67: 782000
B68: Loteamento Pasqual | C68: 1500000
B69: Loteamento Industrial Dr. Letti | C69: 1650000
B70: Loteamento Sol Nascente II | C70: 1058000
B73: Lotes de terceiros passíveis de indenização por APP em Farroupilha | C73: -16240000
B74: Loteamento Firminio Dalzóchio, num saldo de 03 lotes. | C74: -400000
B75: Loteamento Jardim Itália I – II – III, num saldo de 05 lotes. | C75: -986000
...

Sheet Relatórios Mensais
B1: Empreendimentos | C1: Transportadora | D1: Abastecedora
A2: 45108 | B2: 1165697.9 | C2: 170937.95 | D2: 14885.25 | E2: =SUM(B2:D2) -> 1351521.1
A3: ago.2023 | B3: 668125.99 | C3: 183210.32 | D3: 4275.02 | E3: =SUM(B3:D3) -> 855611.33
A4: Set. 2023 | B4: 707103.09 | C4: 193804.09 | D4: 4933.15 | E4: =SUM(B4:D4) -> 905840.33
A5: Out. 2023 | B5: 385521.64 | C5: 157363.96 | D5: 3790.28 | E5: =SUM(B5:D5) -> 546675.88
A6: 45231 | B6: 666440.05 | C6: 154753.09 | D6: 4056.08 | E6: =SUM(B6:D6) -> 825249.22
A7: Dez. 2023 | B7: 1022872.6 | C7: 216221.5 | D7: 3840.28 | E7: =SUM(B7:D7) -> 1242934.4
A8: 45292 | B8: 343100.52 | C8: 154069.3 | D8: 3812.25 | E8: =SUM(B8:D8) -> 500982.07
A9: Fev. 2024 | B9: 295923.8 | C9: 158589.35 | D9: 5319.73 | E9: =SUM(B9:D9) -> 459832.88
A10: 45352 | B10: 674950.76 | C10: 148559.03 | D10: 5867.78 | E10: =SUM(B10:D10) -> 829377.57
A11: Abr. 2024 | B11: 881710.16 | C11: 168891.18 | D11: 7283.77 | E11: =SUM(B11:D11) -> 1057885.1
A12: Mai. 2024 | B12: 824089.36 | C12: 148233.29 | D12: 7726.51 | E12: =SUM(B12:D12) -> 980049.16
A13: 45444 | B13: 472050.79 | C13: 142941.11 | D13: 5867.77 | E13: =SUM(B13:D13) -> 620859.67
A14: 45474 | B14: 425155.67 | C14: 175646.25 | D14: 5090.89 | E14: =SUM(B14:D14) -> 605892.81
A15: Ago. 2024 | B15: 539462.61 | C15: 194956.31 | D15: 4933.16 | E15: =SUM(B15:D15) -> 739352.08
A16: Out. 2024 | B16: 805019.42 | C16: 162235.91 | D16: 4949.97 | E16: =SUM(B16:D16) -> 972205.3
E17: =SUM(E2:E16)/COUNT(E2:E16) -> 832951.26 | F17: média
A19: =8*12 -> 96 | B19: =A19*E17 -> 79963321

Sheet 1.Abastecedora
B1: ESTUDO SIVIERO | C1: 2018: apresentado | D1: 2018: atualizado | E1: dezembro 2024 | G1: outubro 2025 | H1: Diferença | I1: OBSERVAÇÕES
B3: patrimônio (sem desconto) | C3: =C5+#REF!+#REF!+#REF!+#REF!+#REF!+#REF!+#REF!+#REF!+#REF!+#REF! -> #REF! | D3: =D5+#REF!+#REF!+#REF!+#REF!+#REF!+#REF!+#REF!+#REF!+#REF!+#REF! -> #REF! | E3: =E5+#REF!+#REF!+#REF!+#REF!+#REF!+#REF!+#REF!+#REF!+#REF!+#REF! -> #REF! | F3: =F5+#REF!+#REF!+#REF!+#REF!+#REF!+#REF!+#REF!+#REF!+#REF!+#REF! -> #REF! | G3: =G5+#REF!+#REF!+#REF!+#REF!+#REF!+#REF!+#REF!+#REF!+#REF!+#REF! -> #REF! | H3: =G3-D3 -> #REF!
A5: 1 | B5: ABASTECEDORA DE COMBUSTÍVEIS SIVIERO LTDA. | C5: =SUM(C7:C10) -> 12361852 | D5: =SUM(D7:D10) -> 9806414 | E5: =SUM(E7:E10) -> 0 | F5: =SUM(F7:F10) -> 9661414 | G5: =SUM(G7:G10) -> 9661414 | H5: =SUM(H7:H10) -> -145000
C6: valores 2018 -> 2025: | D6: =(D5/C5)-1 -> -0.20671967 | F6: =SUM(F7:F10) -> 9661414 | H6: =IF(H5<0,"patrimônio diminuiu","patrimônio aumentou") -> patrimônio diminuiu
A7: 1 | B7: Um imóvel urbano sob Matrícula nº 3.752, com área de 3.450,00m², que compreende um lote urbano e instalação de um Posto de Combustíveis, totalmente equipado e em pleno funcionamento. O contrato com a Companhia Ipiranga está cumprido e com condições de renegociação e/ou renegociação com outra Companhia e/ou também com a possibilidade de exploração direta. Agrega ao valor do Posto, o aluguel da Lancharia/Restaurante. Valor do Terreno e Pavimentação: 3.450,00m² x R$ 2.100,00 = R$ 7.245.000,00 (considerado o valor ao metro quadrado da pavimentação e o valor da área conforme sua localização comercial). Valor do Posto em área construída: 292,85m² x R$ 1.500,00 = R$ 439.275,00 (valor do CUB da construção – agosto de 2017). Valor do Posto em área coberta: 699,55m² x R$ 1.100,00 = R$ 769.505,00 (valor do CUB da construção – agosto de 2017). Valor do Posto com equipamentos, bombas, quadros, tanques, sistema elétrico e licenciamento, etc. = R$ 650.000,00. Valor do Posto em vantagem da coisa feita: 30,00% x R$ 557.634,00. | VALOR R$ 9.661.414,00 | C7: 12216852 | D7: =G7 -> 9661414 | F7: 9661414 | G7: 9661414 | H7: =G7-D7 -> 0 | I7: Por que reduziu R$2.555.437,89
A8: A.1 | B8: Um caminhão carro tanque placa: ICW 8342, ano: 1995, modelo: MERCEBES BENZ/L 1618. | C8: 145000 | D8: =C8 -> 145000 | G8: 0 | H8: =G8-D8 -> -145000
A9: - | B9: Observações: Aprovado o PROJETO do Posto junto a Prefeitura de Veranópolis para fins de legalização da obra e posterior procedimento de averbação da obra junto ao Ofício de Registro de Imóveis, da Comarca de Veranópolis. Aguardando o prazo de 05 (cinco) anos para pagamento dos impostos junto à Receita Federal – INSS, contados a partir de 14 de março de 2022. Processo Judicial em tramitação no Fórum de Veranópolis – CRISTIANO RODRIGO LUCCHETTA – Ação de Indenização = Ponto e pagamento de aluguéis. O valor real acima apontado não é líquido, à medida que: a) O valor patrimonial lançado sofrerá redução pela regularização dos imóveis, o que se estima numa redução de 0,70% (ZERO VÍRGULA SETENTA POR CENTO) do valor acima apontado, afora os ônus de eventual dissolução da empresa em relação a parte de algum(ns) sócio(s). b) Há que se ter em mente, que haverá ônus de eventual dissolução da empresa em relação a parte de algum(ns) sócio(s), não podendo serem considerados como líquidos os valores alcançados na avaliação patrimonial. Conforme INSTRUMENTO PARTICULAR DE COMPRA E VENDA DE QUOTAS DE CAPITAL, NA SOCIEDADE DE EMPRESAS DE RESPONSABILIDADE LIMITADA, datado de 28 de agosto de 2025, o Sócio ROVÍLIO SIVIERO, brasileiro, natural de Veranópolis – RS, Odontólogo, residente e domiciliado na Rua Carijós, nº 427, Bairro Vila Fátima, na cidade de Passo Fundo – RS, CEP.: 99.020-110, inscrito no CPF/MF sob nº 225.676.150-91 e portador da Carteira de Identidade nº 4017098015, emitida pela SSP – RS, casado pelo Regime de Comunhão Universal de Bens com Maristela Pretto Siviero, brasileira, professora, filha de Alberto José Pretto e de Iracema Antônia Pretto, inscrita no CPF/MF sob nº 260.949.670/20 e portadora da Carteira de Identidade nº 22.827.317-1, emitida pela SSP – SC, efetuaram a VENDA das quotas que lhes pertenciam à empresa, diluídas em partes iguais aos demais sócios remanescentes.

Sheet 2.São Crispin
B1: ESTUDO SIVIERO | C1: 2018: apresentado | D1: 2018: atualizado | E1: dezembro 2024 | G1: outubro 2025 | H1: Diferença | I1: OBSERVAÇÕES
A2: 2 | B2: AGROPECUÁRIA FAZENDA SÃO CRISPIN LTDA. | C2: =C4 -> 116600 | D2: =D4 -> 116600 | E2: =E4 | F2: =F4 | G2: =G4 -> 0 | H2: =H4 -> -116600
F3: =SUM(F4:F6) -> 0 | H3: =IF(H2<0,"patrimônio diminuiu","patrimônio aumentou") -> patrimônio diminuiu
A4: A.1 | B4: Um trator agrícola da marca VALTRA, modelo BM100, 4 x 4 – TURBO, ano 2010. | C4: 116600 | D4: 116600 | G4: 0 | H4: =G4-D4 -> -116600
B5: Atualmente, através de CONTRATO PARTICULAR DE ARRENDAMENTO, a área total está arrendada para a FAMÍLIA LORENZETTI, pelo prazo de 03 (três) anos seguidos e ininterruptos, iniciando-se no ano de 2023 (02 de maio de 2023) e tendo como última safra o ano de 2026 (30 de abril de 2026). As áreas estas inseridas dentro da FAZENDA SÃO CRISPIN, localizada na Capela de São Sebastião, no Distrito do Chimarrão, no Município de André da Rocha – RS, dentro de uma área total de 411,4 ha (Quatrocentos e onze hectares + quatro mil metros quadrados). a.) 155,0 hectares = 18 (DEZOITO) sacas de soja, ao hectare plantado = 2.790 (DUAS MIL, SETECENTAS E NOVENTA) sacas de soja, ao ano. b.) 30,0 hectares = 30 (TRINTA) sacas de soja, ao hectare plantado = 900 (NOVECENTAS) sacas de soja, ao ano. Esta área será utilizada para o plantio de batatas. c.) 157,5 hectares, desde o ano de 2023, ficou dentre as partes estabelecido, que os ARREDANTÁRIOS usarão a área do campo nativo – área da fazenda não utilizada para o plantio de produtos agrícolas – para a criação de bovinos, que por este arrendamento de área do campo nativo, pagarão para a ARRENDADORA a quantia de 3.000,00 (TRÊS MIL QUILOS) de BOI, ao ano, ao preço da época, para cada invernada de 100,0 ha (CEM HECTARES) alugada, devendo ser paga no MÊS DE DEZEMBRO, de cada ano. d.) 68,9 hectares, não incidirá qualquer pagamento, visto que se trata de áreas isoladas em toda a extensão da fazenda impróprias para qualquer cultivo agrícola ou uso para pecuária. Trata-se de áreas que são compostas por matos, capões e pedras. | C5: 0 | D5: 0 | G5: 0 | I5: Valor desses custos estão no documento: B.) HOTEL PRINCESA DOS VALES LTDA. - ÁREA DE TERRAS VENDIDAS + LOTEAMENTOS CONTRATADOS PELA SEI - SEM OBRAS

Sheet 4.Ceval
B1: ESTUDO SIVIERO | C1: 2018: apresentado | D1: 2018: atualizado | E1: dezembro 2024 | G1: outubro 2025 | H1: Diferença | I1: OBSERVAÇÕES
A2: 4 | B2: CEVAL TERRAPLENAGEM E ESCAVAÇÕES LTDA. | C2: =SUM(C4:C8) -> 391000 | D2: =SUM(D4:D8) -> 408000 | E2: =SUM(E4:E8) -> 0 | F2: =SUM(F4:F8) -> 315000 | G2: =SUM(G4:G8) -> 315000 | H2: =SUM(H4:H8) -> -93000
C3: valores 2018 -> 2025: | D3: =(D2/C2)-1 -> 0.043478261 | F3: =SUM(F4:F9) -> 315000 | H3: =IF(H2<0,"patrimônio diminuiu","patrimônio aumentou") -> patrimônio diminuiu
A4: 1 | B4: Uma ESCAVADEIRA HIDRÁULICA – MARCA CATERPILLAR – MODELO 320 D, ano 2009 – modelo 2010, adquirida conforme Nota Fiscal nº 4946, avaliada na data da compra no valor de R$ 200.000,00 (Duzentos mil reais). | C4: 200000 | D4: 200000 | F4: 200000 | G4: 200000 | H4: =G4-D4 -> 0
A5: 2 | B5: Uma RETROESCAVADEIRA – CASE / M A 580 L, ano 2001, modelo 2001, placa IKI 4325, chassi nº JHF0048344, avaliada nesta data no valor de R$ 70.000,00 (Setenta mil reais). | C5: 60000 | D5: 70000 | F5: 70000 | G5: 70000 | H5: =G5-D5 -> 0
A6: 3 | B6: Um CAMINHÃO CAÇAMBA MERCEDES, marca-modelo M.BENZ/LK 1313, combustível DIESEL, ano 1982, modelo 1982, cor predominante VERMELHA, placa IHM 0033, chassi nº 34500312579515, Renavam nº 54294247-0, emplacado na cidade de Veranópolis – RS, avaliado na data da compra no valor de R$ 45.000,00 (Quarenta e cinco mil reais). | C6: 38000 | D6: 45000 | F6: 45000 | G6: 45000 | H6: =G6-D6 -> 0
A7: A.1 | B7: Um CAMINHÃO CAÇAMBA MERCEDES, marca-modelo M.BENZ/2423 K, combustível DIESEL, ano 2003, modelo 2003, cor predominante BRANCA, placa ILD 3959, chassi nº 9BM6933863B334489, Renavam nº 802204996, emplacado na cidade de Veranópolis – RS, avaliado na data da compra no valor de R$ 93.000,00 (Noventa e três mil reais). | C7: 93000 | D7: 93000 | G7: 0 | H7: =G7-D7 -> -93000
A8: - | B8: Observações: O valor real acima apontado não é líquido, à medida que: a) O valor patrimonial lançado sofrerá redução pela regularização dos imóveis, o que se estima numa redução de 0,00% (ZERO POR CENTO) do valor acima apontado, afora os ônus de eventual dissolução da empresa em relação a parte de algum(ns) sócio(s). b) Há que se ter em mente, que haverá ônus de eventual dissolução da empresa em relação a parte de algum(ns) sócio(s), não podendo serem considerados como líquidos os valores alcançados na avaliação patrimonial. | H8: =G8-D8 -> 0

Sheet 5.Hotel Princesa
B1: ESTUDO SIVIERO | C1: 2018: apresentado | D1: 2018: atualizado | E1: dezembro 2024 | G1: outubro 2025 | H1: Estudo Rafael | I1: Diferença | J1: OBSERVAÇÕES
A2: 5 | B2: HOTEL PRINCESA DOS VALES LTDA. | C2: =C4+C13+C15+C17+C24+C35+C39+C41 -> 48730898 | D2: =D4+D13+D15+D17+D24+D35+D39+D41 -> 75444030 | E2: =E4+E13+E15+E17+E24+E35+E39+E41 -> 0 | F2: =F4+F13+F15+F17+F24+F35+F39+F41 -> 22198515 | G2: =G4+G13+G15+G17+G24+G35+G39+G41 -> 75410201 | H2: =SUM(H3:H42) -> 50914158 | I2: =I4+I13+I15+I17+I24+I35+I39+I41 -> -33828.5
C3: valores 2018 -> 2025: | D3: =(D2/C2)-1 -> 0.54817647 | F3: =SUM(F4:F9) -> 0 | I3: =IF(I2<0,"patrimônio diminuiu","patrimônio aumentou") -> patrimônio diminuiu
A4: 1 | B4: HOTEL PRINCESA DOS PRINCESA DOS VALES | C4: =SUM(C6:C12) -> 17475786 | D4: =SUM(D6:D12) -> 13504244 | E4: =SUM(E6:E12) -> 0 | F4: =SUM(F6:F12) -> 0 | G4: =SUM(G6:G12) -> 13504244 | J4: Porque a referêcia do valor/m² é o CUB/DEZEMBRO DE 2022
C5: valores 2018 -> 2025: | D5: =(D4/C4)-1 -> -0.22725974
A6: 1.1. | B6: Um terreno urbano, com a área de 1.800,00m² = 30,00m X 60,00m, localizado na esquina da Avenida Osvaldo Aranha com a Rua Mal. Deodoro da Fonseca, devidamente registrado no Ofício de Registro de Imóveis da Comarca de Veranópolis, sob Matrícula nº 1.412, onde possui uma área para PÁTIO DE ESTACIONAMENTO e a área onde está instalado o HOTEL, prédio de 04 andares e subsolo, composto por 48 apartamentos, restaurante, sala de convenções, cozinha, lavanderia, totalmente equipado e em pleno funcionamento.
A7: 1.2. | B7: Valor do terreno onde está construído o Edifício – HOTEL = 12,00m X 60,00m, de terreno: 720,00m² x R$ 6.000,00 = R$ 4.320.000,00 (considerado o valor ao metro quadrado do mercado no centro da cidade e o valor da área conforme sua localização comercial). | C7: 5760000 | D7: =G7 -> 4320000 | G7: 4320000 | I7: =G7-D7 -> 0
A8: 1.3. | B8: Valor do Edifício Construído – obra civil = 04 andares = 510,00m² de área construída: 2.040,00m² x R$ 2.356,10 = R$ 4.806.444,00 (considerado o valor ao metro quadrado da construção – CUB/DEZEMBRO DE 2022 e o valor da área conforme sua localização comercial) = com depreciação de 20,00% (- R$ 961.288,80) = R$ 3.845.155,20. | C8: 4394343.6 | D8: =G8 -> 3845155.2 | G8: 3845155.2 | I8: =G8-D8 -> 0 | J8: Porque CUB 2022
A9: 1.4. | B9: Valor do Edifício Construído – obra civil = 01 andar – SUBSOLO = 510,00m² de área construída: 510,00m² x R$ 1.407,45 = R$ 717.799,50 (considerado o valor ao metro quadrado da construção – CUB/AGOSTO DE 2017 e o valor da área conforme sua localização comercial) = com depreciação de 20,00% (-R$ 143.559,90) = R$ 574.239,60. | C9: 717799.5 | D9: =G9 -> 574239.6 | G9: 574239.6 | I9: =G9-D9 -> 0 | J9: Porque CUB 2017
A10: 1.5. | B10: Reforma de 48 apartamentos do HOTEL: 48 x R$ 45.000,00 = R$ 2.160.000,00 (considerado o valor atualizado no custo da reforma de cada apartamento) = com depreciação de 20,00% = (-R$ 432.000,00) = R$ 1.728.000,00. | C10: 2400000 | D10: =G10 -> 1728000 | G10: 1728000 | I10: =G10-D10 -> 0
A11: 1.6. | B11: Móveis e Equipamentos instalados no HOTEL: cozinha, restaurante, sala de convenções, lavanderia, recepção, etc. = R$ 1.500.000,00 = com depreciação de 20,00% (-R$ 300.000,00) = R$ 1.200.000,00. | C11: 1500000 | D11: =G11 -> 1200000 | G11: 1200000 | I11: =G11-D11 -> 0
A12: 1.7. | B12: Valor do Edifício Construído – obra civil = 05 andares = 25,00% (Vinte e cinco por cento) da obra feita: R$ 7.347.394,80 (considerado o valor agregado à coisa feita, como tal se encontra) = R$ 1.836.848,70. | C12: 2703642.9 | D12: =G12 -> 1836848.7 | G12: 1836848.7 | I12: =G12-D12 -> 0 | J12: Que obra é essa?
A13: 2 | B13: Um terreno urbano, com a área de 1.080,00m² = 18,00m X 60,00m, localizado na esquina da Avenida Osvaldo Aranha com a Rua Marechal Deodoro da Fonseca, devidamente registrado no Ofício de Registro de Imóveis da Comarca de Veranópolis, sob Matrícula nº 1.412 = 1.080,00m² X R$ 7.500,00, ao metro. | C13: 10800000 | D13: =G13 -> 8100000 | F13: 8100000 | G13: 8100000 | I13: =G13-D13 -> 0
C14: valores 2018 -> 2025: | D14: =(D13/C13)-1 -> -0.25
A15: 3 | B15: Um terreno urbano, com a área de 750,00m², localizado na Rua Marechal Deodoro da Fonseca, devidamente registrado no Ofício de Registro de Imóveis da Comarca de Veranópolis, sob Matrícula nº 6.262, fundos do HOTEL, adquirido do Senhor Roberto Munaretti, considerando sua localização e uso construtivo = R$ 3.333,34 ao metro quadrado (considerado os 15,00 metros de frente). | C15: 2250000 | D15: =G15 -> 2500000 | F15: 2500000 | G15: 2500000 | I15: =G15-D15 -> 0
C16: valores 2018 -> 2025: | D16: =(D15/C15)-1 -> 0.11111111
A17: 4 | B17: SEDE CAMPESTRE | C17: =SUM(C19:C23) -> 3879091.8 | D17: =SUM(D19:D23) -> 5294686 | F17: 5560857.5 | G17: =SUM(G19:G23) -> 5560857.5 | H17: 5560857.5 | I17: =G17-D17 -> 266171.5
C18: valores 2018 -> 2025: | D18: =(D17/C17)-1 -> 0.36492929
A19: 4.1. | B19: Um terreno rural, com a área de 9,4 hectares, localizado na Rua Luiz Siviero, no Bairro Femaçã, devidamente registrado no Ofício de Registro de Imóveis da Comarca de Veranópolis, sob Matrículas nº 1.941 e 7.104, conhecido como SEDE CAMPESTRE, composta por pavilhão, piscinas, casa, campos de futebol, lagos e alicerces para construção de cabanas. Cadastrada no CCIR – Receita Federal sob nº 2.481.947-6. Valor da área de terras = 9,4ha X R$ 450.000,00 ao hectare = R$ 4.230.000,00. | C19: 2820000 | D19: =G19 -> 4230000 | G19: 4230000
A20: 4.2. | B20: Valor do Pavilhão Construído – obra civil = 01 andar = 891,00m² de área construída: 891,00m² x R$ 746,00 = R$ 664.686,00 (considerado o valor ao metro quadrado da construção – CUB/AGOSTO DE 2017 e o valor da área conforme sua localização comercial). | C20: 664686 | D20: =G20 -> 664686 | G20: 664686 | J20: Por que CUB/AGOSTO DE 2017
A21: 4.3. | B21: Valor da benfeitoria denominada de Quiosque: R$ 150.000,00. | C21: 150000 | D21: =G21 -> 150000 | G21: 150000
A22: 4.4. | B22: Valor da casa de alvenaria localizada nos fundos da Sede Campestre = ...............m² de área construída: R$ 250.000,00. | C22: 244405.8 | D22: =G22 -> 250000 | G22: 250000
A23: 4.5. | B23: Valor das obras feitas e infraestrutura = 25,00% (Vinte por cento) da obra feita: R$ 1.064.686,00 (considerado o valor agregado à coisa feita, como tal se encontra) = R$ 266.171,50. | C23: 0 | D23: 0 | G23: 266171.5
A24: 5 | B24: FAZENDA SÃO CRISPIN | C24: =C27+C30+C33 -> 13588520 | D24: =D27+D30+D33 -> 44828300 | F24: 5560857.5 | G24: =G27+G30+G33 -> 44828300 | H24: 44828300 | I24: =G24-D24 -> 0
C25: valores 2018 -> 2025: | D25: =(D24/C24)-1 -> 2.2989833
A26: 5.1. | B26: Uma área de terras rurais, denominada de FAZENDA SÃO CRISPIN, localizada na Capela de São Sebastião, no Distrito do Chimarrão, no Município de André da Rocha – RS, com área total de 491,0 hectares, áreas estas registradas sob Matrículas nº.: Matrícula nº 14.221 = 50,0 hectares. - Matrícula nº 13.615 = 37,2 hectares. Matrícula nº 13.650 = 49,0 hectares. - Matrícula nº 00.760 = 48,0 hectares. Matrícula nº 11.462 = 100,0 hectares. - Matrícula nº 05.435 = 25,0 hectares. Matrícula nº 09.959 = 6,8 hectares. - Matrícula nº 04.443 = 25,0 hectares. Matrícula nº 00.760 = 100,0 hectares. - Matrícula nº 12.473 = 50,0 hectares. Cadastrada no CCIR – Receita Federal sob nº 2.898.196-0 | F26: 52978900 | J26: Não bate com 2025 versão anterior
A27: 5.2. | B27: Área Dona Rita | C27: =C28+C29 -> 8492000 | D27: =D28+D29 -> 31460000 | G27: =G28+G29 -> 31460000
A28: 5.2.1. | B28: parte produtiva=35,00% = 100,0 ha – R$ 110.000,00 = R$ 11.000.000,00 | C28: =100*44000 -> 4400000 | D28: =G28 -> 11000000 | G28: =110000*100 -> 11000000
A29: 5.2.2. | B29: parte não produtiva=65,00%=186,0 ha–R$ 110.000,00= R$ 20.460.000,00 | C29: =186*22000 -> 4092000 | D29: =G29 -> 20460000 | G29: =186*110000 -> 20460000
A30: 5.3. | B30: Área Zancheta | C30: =C31+C32 -> 2257200 | D30: =D31+D32 -> 6270000 | G30: =G31+G32 -> 6270000
A31: 5.3.1. | B31: parte produtiva=80,00% = 45,6 ha – R$ 110.000,00 = R$ 5.016.000,00 | C31: =45.6*44000 -> 2006400 | D31: =G31 -> 5016000 | G31: =45.6*110000 -> 5016000
A32: 5.3.2. | B32: parte não produtiva=20,00% = 11,4 ha – R$ 110.000,00 = R$ 1.254.000,00 | C32: =11.4*22000 -> 250800 | D32: =G32 -> 1254000 | G32: =11.4*110000 -> 1254000
A33: 5.4. | B33: Área Jane/João Paulo | C33: =C34 -> 2839320 | D33: =D34 -> 7098300 | G33: =G34 -> 7098300
A34: 5.4.1. | B34: parte produtiva=100,00%=148,0 ha (-) 83,47ha = 64,53 ha – R$ 110.000,00 = R$ 7.098.300,00 | C34: =(148-83.47)*44000 -> 2839320 | D34: =G34 -> 7098300 | G34: =110000*64.53 -> 7098300
A35: 6 | B35: CHIMARRÃO | C35: =C37+C38 -> 476000 | D35: =D37+D38 -> 740000 | G35: =G37 -> 440000 | H35: 440000 | I35: =SUM(I37:I38) -> -300000
C36: valores 2018 -> 2025: | D36: =(D35/C35)-1 -> 0.55462185
A37: 6.1. | B37: Uma área de terras rurais, denominada de FAZENDA SÃO CRISPIN, com área total de 4,0 hectares, DENTRO DE UM TODO MAIOR, localizada na Capela de São Sebastião, no Distrito do Chimarrão, no Município de André da Rocha – RS, adquirida do Senhor Dirceu Prestes e Lairton, área esta registrada sob Matrícula nº.: 11.090. Matrícula nº 11.090 = 4,0 hectares. Cadastrada no CCIR – Receita Federal sob nº ..... Adquirida por CONTRATO DE COMPRA E VENDA, em dezembro de 2015. Área Dirceu/Lairton–parte produtiva=100,00%=4,0 ha – R$ 110.000,00 = R$ 440.000,00 | C37: =4*44000 -> 176000 | D37: =G37 -> 440000 | F37: 520000 | G37: 440000 | I37: =G37-D37 -> 0 | J37: Não bate com 2025 versão anterior
A38: 6.2. | B38: Benfeitorias existentes, como: cercas, terraplenagem de lavouras, construções, banheiras de gado, galpão, implementos agrícolas, roçadeira, moinho, etc. | C38: 300000 | D38: 300000 | G38: 0 | I38: =G38-D38 -> -300000
A39: 7 | B39: Uma área de terras rurais, denominada de PARTE DO LOTE RURAL Nº 52, com área total de 15,1 hectares, localizada na Linha Júlio de Castilhos, no Município de Cotiporã – RS, adquirida da Senhora GLORINHA E GERALDO BASSANI, área está registrada sob Matrícula nº.: 7.391 - Matrícula nº 7.391 = 15,1 hectares X R$ 28.000,00 Cadastrada no CCIR – Receita Federal sob nº 2.481.952-2 | C39: 226500 | D39: =G39 -> 422800 | F39: 422800 | G39: 422800 | I39: =G39-D39 -> 0
C40: valores 2018 -> 2025: | D40: =(D39/C39)-1 -> 0.86666667
...

Sheet 6.Hotel Araçá
B1: ESTUDO SIVIERO | C1: 2018: apresentado | D1: 2018: atualizado | E1: dezembro 2024 | G1: outubro 2025 | H1: Estudo Rafael | I1: Diferença | J1: OBSERVAÇÕES
A2: 6 | B2: HOTEL ARAÇÁ LTDA. | C2: =C4+C12 -> 49484243 | D2: =D4+D12 -> 56576823 | E2: =E4+E12 -> 0 | F2: =F4+F12 -> 61790460 | G2: =G4+G12 -> 58076823 | H2: =SUM(H3:H34) -> 1880000 | I2: =I4+I12 -> 1500000
C3: valores 2018 -> 2025: | D3: =(D2/C2)-1 -> 0.14333007 | F3: =SUM(F4:F18) -> 63630460 | I3: =IF(I2<0,"patrimônio diminuiu","patrimônio aumentou") -> patrimônio aumentou
A4: 1 | B4: Dezoito (18) terrenos urbanos, localizados dentro da Quadra 37, registrados junto ao Ofício de Registros de Imóveis em 12 (Doze) Matrículas, com a área total de 6.900,00m² (Seis mil e novecentos metros quadrados), localizado na Rua Miguel Main Felo, nº 333, na Praia do Araçá, todos devidamente registrados no Ofício de Registro de Imóveis da Comarca de Capão da Canoa – RS, sob Matrículas nº.: 34.768, 34.769, 34.770, 34.771, 6.411, 29.855, 24.584, 24.585, 33.101, 29.856, 0672 e 34.772, onde está instalado o HOTEL, prédio de 04 andares, composto por 144 apartamentos, restaurante, cozinha, sala de convenções, duas piscinas, bar interno e externo, sala de jogos, sauna, mezanino, etc., totalmente equipado e em pleno funcionamento. 04 lotes de 450,00m², cada um. (Lotes nº 01-02-03-04 – Matrícula nº 34.768). 13 lotes de 360,00m², cada um. (Lotes nº 05-22 – Matrícula nº 34.769). (Lotes nº 06-21 – Matrícula nº 34.770). (Lote nº 07 – Matrícula nº 34.771). (Lote nº 08 – Matrícula nº 6.411). (Lote nº 09 – Matrícula nº 29.855). (Lote nº 10 – Matrícula nº 24.584). (Lote nº 11 – Matrícula nº 24.585). (Lote nº 12 – Matrícula nº 33.101). (Lote nº 18 – Matrícula nº 29.856). (Lote nº 19 – Matrícula nº 0672). (Lote nº 20 – Matrícula nº 34.772). 01 lote de 420,00m² - lote da Nesga – sobra com muro. (Parte do Lote nº 12 – Matrícula nº 33.101). | C4: =SUM(C6:C11) -> 45274243 | D4: =SUM(D6:D11) -> 49606823 | F4: 53320460 | G4: =SUM(G6:G11) -> 49606823 | I4: =G4-D4 -> 0
C5: valores 2018 -> 2025: | D5: =(D4/C4)-1 -> 0.095696354
A6: 1.1 | B6: Considerado o valor comercial de R$ 1.000,00, ao metro quadrado. Valor do terreno onde está construído o Edifício – HOTEL = 6.900,00m² de terreno = R$ 6.900.000,00 (considerado o valor ao metro quadrado do mercado no Bairro Araçá e o valor da área conforme sua localização comercial). | C6: 3800000 | D6: =G6 -> 6900000 | G6: 6900000 | I6: =G6-D6 -> 0
A7: 1.2 | B7: Móveis e Equipamentos – novos, instalados nos 36 apartamentos do HOTEL, no valor unitário de R$ 42.000,00, cada apartamento = sem depreciação = R$ 1.512.000,00. | C7: 1800000 | D7: =G7 -> 1512000 | G7: 1512000 | I7: =G7-D7 -> 0
A8: 1.3 | B8: Móveis e Equipamentos, instalados nos 108 apartamentos do HOTEL, no valor unitário de R$ 30.000,00, cada apartamento = R$ 3.240.000,00 = com depreciação de 20,00% = (-) R$ 648.000,00 = R$ 2.592.000,00. | C8: 3024000 | D8: =G8 -> 2592000 | G8: 2592000 | I8: =G8-D8 -> 0
A9: 1.4 | B9: Valor do Edifício Construído – obra civil = 04 andares, com 144 apartamentos do HOTEL, cozinha, restaurante, sala de convenções, lavanderia, bares, piscinas, sala de jogos, sauna, mezanino, = 10.500,00m² de área construída X R$ 3.170,52 = R$ 33.290.460,00 (considerado o valor ao metro quadrado da construção – CUB/DEZEMBRO DE 2022 e o valor da área conforme sua localização comercial) = com depreciação de 20,00% = (-) R$ 6.658.092,00 = R$ 26.632.368,00. | C9: 20679264 | D9: =G9 -> 26632368 | G9: 26632368 | I9: =G9-D9 -> 0
A10: 1.5 | B10: Móveis e Equipamentos Diversos instalados no HOTEL: cozinha, restaurante, sala de convenções, lavanderia, recepção, poço artesiano com outorga, etc. = R$ 8.000.000,00 = com depreciação de 20,00% = (-) R$ 1.600.000,00 = R$ 6.400.000,00. | C10: 6400000 | D10: =G10 -> 6400000 | G10: 6400000 | I10: =G10-D10 -> 0
A11: 1.6 | B11: Valor do Edifício Construído – obra civil = 04 andares = 15,00% (Quinze por cento) da obra feita: R$ 37.136.368,00 (considerado o valor agregado à coisa feita, como tal se encontra) = R$ 5.570.455,20. | C11: 9570979.2 | D11: =G11 -> 5570455.2 | G11: 5570455.2 | I11: =G11-D11 -> 0
B12: Lotes | C12: =SUM(C14:C34) -> 4210000 | D12: =SUM(D14:D34) -> 6970000 | E12: =SUM(E14:E34) -> 0 | F12: =SUM(F14:F34) -> 8470000 | G12: =SUM(G14:G34) -> 8470000 | I12: =SUM(I14:I34) -> 1500000
C13: valores 2018 -> 2025: | D13: =(D12/C12)-1 -> 0.65558195
A14: 2 | B14: Um lote urbano nº 03 – Quadra nº 19, com área de 450,00m², devidamente registrado no Ofício de Registro de Imóveis da Comarca de Capão da Canoa – RS, sob Matrícula nº 77.832 (antiga matrícula 37.549), com a Inscrição Imobiliária nº 360.0019.003.000 e Código de Imóvel nº 038998, localizado nas proximidades do Hotel Araçá Ltda. – Casa da Praça. | C14: 250000 | D14: =G14 -> 400000 | F14: 400000 | G14: 400000 | H14: 400000 | I14: =G14-D14 -> 0
A15: 3 | B15: Um lote urbano nº 16 – Quadra nº 37, com área de 360,00m², devidamente registrado no Ofício de Registro de Imóveis da Comarca de Capão da Canoa – RS, sob Matrícula nº 64.782, com a Inscrição Imobiliária nº 360.0037.016.000 e Código de Imóvel nº 039395 localizado nas proximidades do Hotel Araçá Ltda. – Fundos do Hotel. | C15: 180000 | D15: =G15 -> 360000 | F15: 360000 | G15: 360000 | I15: =G15-D15 -> 0
A16: 4 | B16: Um lote urbano nº 23 – Quadra nº 37, com área de 360,00m², devidamente registrado no Ofício de Registro de Imóveis da Comarca de Capão da Canoa – RS, sob Matrícula nº 26.373, com a Inscrição Imobiliária nº 360.0071.023.000 e Código de Imóvel nº 039839 localizado nas proximidades do Hotel Araçá Ltda. – Fundos do Hotel. | C16: 180000 | D16: =G16 -> 360000 | F16: 360000 | G16: 360000 | I16: =G16-D16 -> 0
A17: 5 | B17: Um lote urbano nº 24 – Quadra nº 37, com área de 307,80m², devidamente registrado no Ofício de Registro de Imóveis da Comarca de Capão da Canoa – RS, sob Matrícula nº 26.374, com a Inscrição Imobiliária nº 360.0071.024.000 e Código de Imóvel nº 039840 localizado nas proximidades do Hotel Araçá Ltda. – Fundos do Hotel. | C17: 180000 | D17: =G17 -> 360000 | F17: 360000 | G17: 360000 | I17: =G17-D17 -> 0
A18: 6 | B18: Um lote urbano nº 25 – Quadra nº 37, com área de 307,80m², devidamente registrado no Ofício de Registro de Imóveis da Comarca de Capão da Canoa – RS, sob Matrícula nº 26.375, com a Inscrição Imobiliária nº 360.0071.025.000 e Código de Imóvel nº 039841 localizado nas proximidades do Hotel Araçá Ltda. – Fundos do Hotel. | C18: 180000 | D18: =G18 -> 360000 | F18: 360000 | G18: 360000 | I18: =G18-D18 -> 0
A19: 7 | B19: Um lote urbano nº 26 – Quadra nº 37, com área de 307,80m², devidamente registrado no Ofício de Registro de Imóveis da Comarca de Capão da Canoa – RS, sob Matrícula nº 26.376, com a Inscrição Imobiliária nº 360.0071.026.000 e Código de Imóvel nº 039842 localizado nas proximidades do Hotel Araçá Ltda. – Fundos do Hotel. | C19: 180000 | D19: =G19 -> 360000 | F19: 360000 | G19: 360000 | I19: =G19-D19 -> 0
A20: 8 | B20: Um lote urbano nº 27 – Quadra nº 37, com área de 307,80m², devidamente registrado no Ofício de Registro de Imóveis da Comarca de Capão da Canoa – RS, sob Matrícula nº 26.377, com a Inscrição Imobiliária nº 360.0071.027.000 e Código de Imóvel nº 039843 localizado nas proximidades do Hotel Araçá Ltda. – Fundos do Hotel. | C20: 180000 | D20: =G20 -> 360000 | F20: 360000 | G20: 360000 | I20: =G20-D20 -> 0
A21: 9 | B21: Um lote urbano nº 28 – Quadra nº 37, com área de 307,80m², devidamente registrado no Ofício de Registro de Imóveis da Comarca de Capão da Canoa – RS, sob Matrícula nº 26.378, com a Inscrição Imobiliária nº 360.0071.028.000 e Código de Imóvel nº 039844 localizado nas proximidades do Hotel Araçá Ltda. – Fundos do Hotel. | C21: 180000 | D21: =G21 -> 360000 | F21: 360000 | G21: 360000 | I21: =G21-D21 -> 0
A22: 10 | B22: Um lote urbano nº 29 – Quadra nº 37, com área de 360,00m², devidamente registrado no Ofício de Registro de Imóveis da Comarca de Capão da Canoa – RS, sob Matrícula nº 26.379, com a Inscrição Imobiliária nº 360.0071.029.000 e Código de Imóvel nº 039845 localizado nas proximidades do Hotel Araçá Ltda. – Fundos do Hotel. | C22: 180000 | D22: =G22 -> 360000 | F22: 360000 | G22: 360000 | I22: =G22-D22 -> 0
A23: 11 | B23: Um lote urbano nº 09 – Quadra nº 38, com área de 360,00m², devidamente registrado no Ofício de Registro de Imóveis da Comarca de Capão da Canoa – RS, sob Matrícula nº 37.846, com a Inscrição Imobiliária nº 360.0038.009.000 e Código de Imóvel nº 039410 localizado nas proximidades do Hotel Araçá Ltda. Adquirido do Senhor Hugo Ferri. | C23: 220000 | D23: =G23 -> 390000 | F23: 390000 | G23: 390000 | H23: 390000 | I23: =G23-D23 -> 0
A24: 12 | B24: Um lote urbano nº 10 – Quadra nº 38, com área de 360,00m², devidamente registrado no Ofício de Registro de Imóveis da Comarca de Capão da Canoa – RS, sob Matrícula nº 11.990, com a Inscrição Imobiliária nº 360.0038.010.000 e Código de Imóvel nº 039411 localizado nas proximidades do Hotel Araçá Ltda. Adquirido do Senhor Hugo Ferri. | C24: 220000 | D24: =G24 -> 390000 | F24: 390000 | G24: 390000 | H24: 390000 | I24: =G24-D24 -> 0
A25: 13 | B25: Um lote urbano nº 11 – Quadra nº 38, com área de 360,00m², devidamente registrado no Ofício de Registro de Imóveis da Comarca de Capão da Canoa – RS, sob Matrícula nº 43.389, com a Inscrição Imobiliária nº 360.0038.011.000 e Código de Imóvel nº 039412 localizado nas proximidades do Hotel Araçá Ltda. Adquirido do Senhor Hugo Ferri. | C25: 220000 | D25: =G25 -> 390000 | F25: 390000 | G25: 390000 | I25: =G25-D25 -> 0
A26: 14 | B26: Um lote urbano nº 12 – Quadra nº 38, com área de 360,00m², devidamente registrado no Ofício de Registro de Imóveis da Comarca de Capão da Canoa – RS, sob Matrícula nº 29.803, com a Inscrição Imobiliária nº 360.0038.012.000 e Código de Imóvel nº 039413 localizado nas proximidades do Hotel Araçá Ltda. Adquirido do Senhor Hugo Ferri. | C26: 220000 | D26: =G26 -> 390000 | F26: 390000 | G26: 390000 | I26: =G26-D26 -> 0
A27: 15 | B27: Um lote urbano nº 13 – Quadra nº 38, com área de 360,00m², devidamente registrado no Ofício de Registro de Imóveis da Comarca de Capão da Canoa – RS, sob Matrícula nº 30.294, com a Inscrição Imobiliária nº 360.0038.013.000 e Código de Imóvel nº 039414 localizado nas proximidades do Hotel Araçá Ltda. Adquirido do Senhor Hugo Ferri. | C27: 220000 | D27: =G27 -> 390000 | F27: 390000 | G27: 390000 | I27: =G27-D27 -> 0
A28: 16 | B28: Um lote urbano nº 14 – Quadra nº 38, com área de 360,00m², devidamente registrado no Ofício de Registro de Imóveis da Comarca de Capão da Canoa – RS, sob Matrícula nº 29.802, com a Inscrição Imobiliária nº 360.0038.014.000 e Código de Imóvel nº 039415 localizado nas proximidades do Hotel Araçá Ltda. Adquirido do Senhor Hugo Ferri. | C28: 220000 | D28: =G28 -> 390000 | F28: 390000 | G28: 390000 | I28: =G28-D28 -> 0
A29: 17 | B29: Um lote urbano nº 15 – Quadra nº 38, com área de 360,00m², devidamente registrado no Ofício de Registro de Imóveis da Comarca de Capão da Canoa – RS, sob Matrícula nº 33.003, com a Inscrição Imobiliária nº 360.0038.015.000 e Código de Imóvel nº 039416 localizado nas proximidades do Hotel Araçá Ltda. Adquirido do Senhor Hugo Ferri. | C29: 0 | D29: 0 | F29: 390000 | G29: 390000 | I29: =G29-D29 -> 390000
A30: 18 | B30: Um lote urbano nº 27 – Quadra nº 38, com área de 360,00m², devidamente registrado no Ofício de Registro de Imóveis da Comarca de Capão da Canoa – RS, sob Matrícula nº 73.482, com a Inscrição Imobiliária nº 360.0038.027.000 e Código de Imóvel nº 039426 localizado nas proximidades do Hotel Araçá Ltda. Lote Estacionamento do Bigode. | C30: 200000 | D30: =G30 -> 350000 | F30: 350000 | G30: 350000 | H30: 350000 | I30: =G30-D30 -> 0
A31: 19 | B31: Um lote urbano nº 28 – Quadra nº 38, com área de 360,00m², devidamente registrado no Ofício de Registro de Imóveis da Comarca de Capão da Canoa – RS, sob Matrícula nº 73.482, com a Inscrição Imobiliária nº 360.0038.028.000 e Código de Imóvel nº 039427 localizado nas proximidades do Hotel Araçá Ltda. Lote Estacionamento do Bigode. | C31: 0 | D31: 0 | F31: 350000 | G31: 350000 | H31: 350000 | I31: =G31-D31 -> 350000
A32: 20 | B32: Um lote urbano denominado de lote nº 15, da quadra nº 02, com área total de 725,39m², devidamente registrado no Ofício de Registro de Imóveis da Comarca de Capão da Canoa – RS, sob Matrícula nº 69.488, com a Inscrição Imobiliária nº 645.0027.015.000 e Código de Imóvel nº 076891 localizado no CONDADO DE CAPÃO, com casa de alvenaria com 158,18m² de área construída, adquirida em maio de 2014, por Contrato de Particular Compra e Venda, com móveis e utensílios, no valor total global de R$ 750.000,00, totalmente quitada | C32: 1000000 | D32: =G32 -> 1000000 | F32: 1000000 | G32: 1000000 | I32: =G32-D32 -> 0
A33: 21 | B33: Um lote urbano nº 15 – Quadra nº 37, com área de 360,00m², devidamente registrado no Ofício de Registro de Imóveis da Comarca de Capão da Canoa – RS, sob Matrícula nº 86.669, com a Inscrição Imobiliária nº 360.0037.015.000.000 e Código de Imóvel nº 39394, localizado nas proximidades do Hotel Araçá Ltda. – Lateral do Hotel. | C33: 0 | D33: 0 | F33: 380000 | G33: 380000 | I33: =G33-D33 -> 380000
A34: 22 | B34: Um lote urbano nº 17 – Quadra nº 37, com área de 360,00m², devidamente registrado no Ofício de Registro de Imóveis da Comarca de Osório – RS, sob Matrícula nº 124.906, com a Inscrição Imobiliária nº 360.0037.017.000.000 e Código de Imóvel nº 39396, localizado nas proximidades do Hotel Araçá Ltda. – Lateral do Hotel. | C34: 0 | D34: 0 | F34: 380000 | G34: 380000 | I34: =G34-D34 -> 380000
A35: - | B35: OBSERVAÇÕES: É necessário UNIFICAR OS LOTES ONDE ESTÁ CONSTRUÍDO O HOTEL, com mais os lotes que fazem parte do mesmo quarteirão, conforme o interesse e necessidade, para fins de efetuar a averbação da obra – prédio – na Matrícula unificada no Ofício de Registro de Imóveis da Comarca de Capão da Canoa – RS. É necessário APROVAR todos os PROJETOS DO HOTEL (arquitetônico, elétrico, hidrossanitário, etc.), conforme como a obra está executada, junto à Prefeitura Municipal de Capão da Canoa – RS, para a devida obtenção do HABITE-SE. É necessário PAGAR o I.N.S.S. DA OBRA, para fins de efetuar a averbação da obra – prédio – na Matrícula unificada no Ofício de Registro de Imóveis da Comarca de Capão da Canoa – RS. Dos bens imóveis instalados sobre a propriedade da empresa, carecem de regularização: A EDIFICAÇÃO DA PRÉDIO DO HOTEL (04 ANDARES), ÁREA DAS PISCINAS EXTERNAS E SALÃO DE CONVENÇÕES/EVENTOS: APROVAR o PROJETO junto à Prefeitura de Capão da Canoa - RS, pagar o I.N.S.S. resultante sobre a obra – HOTEL E DEPENDÊNCIAS ADJACENTES – para fins de averbação das benfeitorias na Matrícula do Imóvel Unificada, junto o Ofício de Registro de Imóveis da Comarca de Capão da Canoa – RS. Conforme cálculo realizado para projetar o custo do imposto – I.N.S.S. – resulta numa importância de aproximadamente R$ 1.601.357,90 (Hum milhão, seiscentos e um mil, trezentos e cinquenta e sete reais e noventa centavos), afora ainda os custos de: A.P.P.C.I., A.R.T., ENGENHEIRO CIVIL, TAXAS PARA UNIFICAÇÃO DOS LOTES E APROVAÇÕES, EMOLUMENTOS DE REGISTRO, dentre outras despesas afins. O valor real acima apontado não é líquido, à medida que: a) O valor patrimonial lançado no “ÍTEM 01 DO INVENTÁRIO”, sofrerá redução pela regularização do imóvel, o que se estima numa redução de aproximadamente 4,00% = R$ 2.000.000,00 (DOIS MILHÕES DE REAIS) do valor avalizado do HOTEL ARAÇÁ LTDA., afora os ônus de eventual dissolução da empresa em relação a parte de algum(ns) sócio(s). b) Há que se ter em mente, que haverá ônus de eventual dissolução da empresa em relação a parte de algum(ns) sócio(s), não podendo serem considerados como líquidos os valores alcançados na avaliação patrimonial.

Sheet 7.Rádio
B1: ESTUDO SIVIERO | C1: 2018: apresentado | D1: 2018: atualizado | E1: dezembro 2024 | G1: outubro 2025 | H1: Estudo Rafael | I1: Diferença | J1: OBSERVAÇÕES
